Workbook

Sheet DASHBOARD
A1: DASHBOARD — PBMM Evidence: Compute
A2: Control ID | B2: Control Name | C2: Primary Tool | D2: Tab | E2: Status
A3: AC-6 | B3: Least Privilege | D3: AC-6 | E3: ='AC-6'!B20 -> Not Started
A4: AC-6(1) | B4: Least Privilege | D4: AC-6-1 | E4: ='AC-6-1'!B20 -> Not Started
A5: AC-7 | B5: Unsuccessful Login Attempts | D5: AC-7 | E5: ='AC-7'!B20 -> Not Started
A6: AC-8 | B6: System Use Notification | D6: AC-8 | E6: ='AC-8'!B20 -> Not Started
A7: AC-11 | B7: Session Lock | D7: AC-11 | E7: ='AC-11'!B20 -> Not Started
A8: AC-11(1) | B8: Session Lock | D8: AC-11-1 | E8: ='AC-11-1'!B20 -> Not Started
A9: AC-12 | B9: Session Termination | D9: AC-12 | E9: ='AC-12'!B20 -> Not Started
A10: AC-17(1) | B10: Remote Access | D10: AC-17-1 | E10: ='AC-17-1'!B20 -> Not Started
A11: AC-17(2) | B11: Remote Access | D11: AC-17-2 | E11: ='AC-17-2'!B20 -> Not Started
A12: AC-17(100) | B12: Remote Access | D12: AC-17-100 | E12: ='AC-17-100'!B20 -> Not Started
A13: AU-2 | B13: Auditable Events | D13: AU-2 | E13: ='AU-2'!B20 -> Not Started
A14: AU-3 | B14: Content of Audit Records | D14: AU-3 | E14: ='AU-3'!B20 -> Not Started
A15: AU-3(1) | B15: Content of Audit Records | D15: AU-3-1 | E15: ='AU-3-1'!B20 -> Not Started
A16: AU-9(2) | B16: Protection of Audit Information | D16: AU-9-2 | E16: ='AU-9-2'!B20 -> Not Started
A17: AU-12 | B17: Audit Generation | D17: AU-12 | E17: ='AU-12'!B20 -> Not Started
A18: CA-3(5) | B18: Information System Connections | D18: CA-3-5 | E18: ='CA-3-5'!B20 -> Not Started
A19: CA-9 | B19: Internal System Connections | D19: CA-9 | E19: ='CA-9'!B20 -> Not Started
A20: CM-6 | B20: Configuration Settings | D20: CM-6 | E20: ='CM-6'!B20 -> Not Started
A21: CM-7 | B21: Least Functionality | D21: CM-7 | E21: ='CM-7'!B20 -> Not Started
A22: CM-7(1) | B22: Least Functionality | D22: CM-7-1 | E22: ='CM-7-1'!B20 -> Not Started
A23: CM-7(5) | B23: Least Functionality | D23: CM-7-5 | E23: ='CM-7-5'!B20 -> Not Started
A24: CM-11 | B24: User Installed Software | D24: CM-11 | E24: ='CM-11'!B20 -> Not Started
A25: CP-6 | B25: Alternate Storage Site | D25: CP-6 | E25: ='CP-6'!B20 -> Not Started
A26: CP-6(2) | B26: Alternate Storage Site | D26: CP-6-2 | E26: ='CP-6-2'!B20 -> Not Started
A27: CP-7 | B27: Alternate Processing Site | D27: CP-7 | E27: ='CP-7'!B20 -> Not Started
A28: CP-7(4) | B28: Alternate Processing Site | D28: CP-7-4 | E28: ='CP-7-4'!B20 -> Not Started
A29: CP-9 | B29: Information System Backup | D29: CP-9 | E29: ='CP-9'!B20 -> Not Started
A30: CP-9(1) | B30: Information System Backup | D30: CP-9-1 | E30: ='CP-9-1'!B20 -> Not Started
A31: CP-9(2) | B31: Information System Backup | D31: CP-9-2 | E31: ='CP-9-2'!B20 -> Not Started
A32: CP-9(5) | B32: Information System Backup | D32: CP-9-5 | E32: ='CP-9-5'!B20 -> Not Started
A33: CP-10 | B33: Information System Recovery and Reconstitution | D33: CP-10 | E33: ='CP-10'!B20 -> Not Started
A34: CP-10(4) | B34: Information System Recovery and Reconstitution | D34: CP-10-4 | E34: ='CP-10-4'!B20 -> Not Started
A35: IA-5(6) | B35: Authenticator Management | D35: IA-5-6 | E35: ='IA-5-6'!B20 -> Not Started
A36: IA-5(7) | B36: Authenticator Management | D36: IA-5-7 | E36: ='IA-5-7'!B20 -> Not Started
A37: SA-9(5) | B37: External Information System Services | D37: SA-9-5 | E37: ='SA-9-5'!B20 -> Not Started
A38: SA-10(1) | B38: Developer Configuration Management | D38: SA-10-1 | E38: ='SA-10-1'!B20 -> Not Started
A39: SC-2 | B39: Application Partitioning | D39: SC-2 | E39: ='SC-2'!B20 -> Not Started
A40: SC-6 | B40: Resource Availability | D40: SC-6 | E40: ='SC-6'!B20 -> Not Started
...

Sheet TABLEAU_DE_BORD
A1: TABLEAU DE BORD — Suivi PBMM : Compute
A2: ID Contrôle | B2: Nom du contrôle | C2: Outil principal | D2: Onglet | E2: Statut
A3: AC-6 | B3: Moindre privilège | D3: AC-6 | E3: ='AC-6'!E20 -> Non commencé
A4: AC-6(1) | B4: Moindre privilège | D4: AC-6-1 | E4: ='AC-6-1'!E20 -> Non commencé
A5: AC-7 | B5: Tentatives infructueuses d’ouverture de session | D5: AC-7 | E5: ='AC-7'!E20 -> Non commencé
A6: AC-8 | B6: Avis d’utilisation du système | D6: AC-8 | E6: ='AC-8'!E20 -> Non commencé
A7: AC-11 | B7: Verrouillage de session | D7: AC-11 | E7: ='AC-11'!E20 -> Non commencé
A8: AC-11(1) | B8: Verrouillage de session | D8: AC-11-1 | E8: ='AC-11-1'!E20 -> Non commencé
A9: AC-12 | B9: Fermeture de session | D9: AC-12 | E9: ='AC-12'!E20 -> Non commencé
A10: AC-17(1) | B10: Accès à distance | D10: AC-17-1 | E10: ='AC-17-1'!E20 -> Non commencé
A11: AC-17(2) | B11: Accès à distance | D11: AC-17-2 | E11: ='AC-17-2'!E20 -> Non commencé
A12: AC-17(100) | B12: Accès à distance | D12: AC-17-100 | E12: ='AC-17-100'!E20 -> Non commencé
A13: AU-2 | B13: Événements vérifiables | D13: AU-2 | E13: ='AU-2'!E20 -> Non commencé
A14: AU-3 | B14: Contenu des enregistrements de vérification | D14: AU-3 | E14: ='AU-3'!E20 -> Non commencé
A15: AU-3(1) | B15: Contenu des enregistrements de vérification | D15: AU-3-1 | E15: ='AU-3-1'!E20 -> Non commencé
A16: AU-9(2) | B16: Protection des renseignements de vérification | D16: AU-9-2 | E16: ='AU-9-2'!E20 -> Non commencé
A17: AU-12 | B17: Génération des vérifications | D17: AU-12 | E17: ='AU-12'!E20 -> Non commencé
A18: CA-3(5) | B18: Connexions aux systèmes d’information | D18: CA-3-5 | E18: ='CA-3-5'!E20 -> Non commencé
A19: CA-9 | B19: Connexions internes au système | D19: CA-9 | E19: ='CA-9'!E20 -> Non commencé
A20: CM-6 | B20: Paramètres de configuration | D20: CM-6 | E20: ='CM-6'!E20 -> Non commencé
A21: CM-7 | B21: Moindre fonctionnalité | D21: CM-7 | E21: ='CM-7'!E20 -> Non commencé
A22: CM-7(1) | B22: Moindre fonctionnalité | D22: CM-7-1 | E22: ='CM-7-1'!E20 -> Non commencé
A23: CM-7(5) | B23: Moindre fonctionnalité | D23: CM-7-5 | E23: ='CM-7-5'!E20 -> Non commencé
A24: CM-11 | B24: Logiciel installé par l’utilisateur | D24: CM-11 | E24: ='CM-11'!E20 -> Non commencé
A25: CP-6 | B25: Site de stockage auxiliaire | D25: CP-6 | E25: ='CP-6'!E20 -> Non commencé
A26: CP-6(2) | B26: Site de stockage auxiliaire | D26: CP-6-2 | E26: ='CP-6-2'!E20 -> Non commencé
A27: CP-7 | B27: Site de traitement auxiliaire | D27: CP-7 | E27: ='CP-7'!E20 -> Non commencé
A28: CP-7(4) | B28: Site de traitement auxiliaire | D28: CP-7-4 | E28: ='CP-7-4'!E20 -> Non commencé
A29: CP-9 | B29: Sauvegarde du système d’information | D29: CP-9 | E29: ='CP-9'!E20 -> Non commencé
A30: CP-9(1) | B30: Sauvegarde du système d’information | D30: CP-9-1 | E30: ='CP-9-1'!E20 -> Non commencé
A31: CP-9(2) | B31: Sauvegarde du système d’information | D31: CP-9-2 | E31: ='CP-9-2'!E20 -> Non commencé
A32: CP-9(5) | B32: Sauvegarde du système d’information | D32: CP-9-5 | E32: ='CP-9-5'!E20 -> Non commencé
A33: CP-10 | B33: Reprise et reconstitution du système d’information | D33: CP-10 | E33: ='CP-10'!E20 -> Non commencé
A34: CP-10(4) | B34: Reprise et reconstitution du système d’information | D34: CP-10-4 | E34: ='CP-10-4'!E20 -> Non commencé
A35: IA-5(6) | B35: Gestion des authentifiants | D35: IA-5-6 | E35: ='IA-5-6'!E20 -> Non commencé
A36: IA-5(7) | B36: Gestion des authentifiants | D36: IA-5-7 | E36: ='IA-5-7'!E20 -> Non commencé
A37: SA-9(5) | B37: Services de systèmes d’information externes | D37: SA-9-5 | E37: ='SA-9-5'!E20 -> Non commencé
A38: SA-10(1) | B38: Gestion de la configuration par le développeur | D38: SA-10-1 | E38: ='SA-10-1'!E20 -> Non commencé
A39: SC-2 | B39: Partitionnement des applications | D39: SC-2 | E39: ='SC-2'!E20 -> Non commencé
A40: SC-6 | B40: Disponibilité des ressources | D40: SC-6 | E40: ='SC-6'!E20 -> Non commencé
...

Sheet AC-6
A1: Control AC-6 — Evidence Tracking | D1: Contrôle AC-6 — Suivi des preuves
A2: Control Information | D2: Informations du contrôle
A3: Control Identifier | B3: AC-6 | D3: Identifiant du contrôle | E3: AC-6
A4: Family | B4: Least Privilege | D4: Famille | E4: Moindre privilège
A5: Profile | B5: CCCS Medium / PBMM Moderate | D5: Profil | E5: CCCS Moyen / PBMM Modéré
A6: Primary Evidence Tool | D6: Outil de preuve principal
A7: Contributing Tools | D7: Outils contributeurs
A8: Control Description | B8: (A) The organization employs the principle of least privilege, allowing only authorized accesses for users (or processes acting on behalf of users) which are necessary to accomplish assigned tasks in accordance with organizational missions and business functions. | D8: Description du contrôle | E8: (A) L’organisation utilise le principe du moindre privilège, qui permet seulement les accès autorisés aux utilisateurs (ou aux processus qui agissent pour le compte des utilisateurs) qui sont nécessaires pour accomplir les tâches assignées conformément aux missions et aux fonctions opérationnelles de l’organisation.
A9: Supplemental Guidance | B9: Organizations employ least privilege for specific duties and information systems. The principle of least privilege is also applied to information system processes, ensuring that the processes operate at privilege levels no higher than necessary to accomplish required organizational missions/business functions. Organizations consider the creation of additional processes, roles, and information system accounts as necessary, to achieve least privilege. Organizations also apply least privilege to the development, implementation, and operation of organizational information systems. Related controls: AC-2, AC-3, AC-5, CM-6, CM-7, PL-2 | D9: Directives supplémentaires | E9: Les organisations utilisent le moindre privilège pour certaines tâches et certains systèmes d’information. Le principe du moindre privilège s’applique également aux processus du système d’information, ce qui fait en sorte que les processus ne fonctionnent pas à des niveaux de privilège plus élevés que nécessaire pour accomplir les missions et les fonctions opérationnelles requises de l’organisation. Les organisations envisagent la création de processus, de rôles et de comptes de système d’information supplémentaires lorsque nécessaire, pour obtenir le moindre privilège. Les organisations appliquent également le moindre privilège au développement, à la mise en œuvre et à l’exploitation de leurs systèmes d’information. Contrôles connexes : AC-2, AC-3, AC-5, CM-6, CM-7, PL-2
A10: Test Case | D10: Cas de test
A11: Test | B11: TEST-AC-6 | D11: Test | E11: TEST-AC-6
A12: Requirement ID | B12: AC-6 | D12: ID Exigence | E12: AC-6
A13: Component | D13: Composant
A14: Requirement | D14: Exigence
A15: Contextual Design Description | D15: Description contextuelle du design
A16: Evidence Provided | D16: Preuve fournie
A17: Preparer Sign Off (Initials, Date) | D17: Signataire préparateur (Initiales, Date)
A18: Owner Sign Off (Initials, Date) | D18: Signataire propriétaire (Initiales, Date)
A19: Assessor Sign Off (Initials, Date) | D19: Signataire évaluateur (Initiales, Date)
A20: Status | B20: Not Started | D20: Statut | E20: Non commencé
A21: Comments | D21: Commentaires

Sheet AC-6-1
A1: Control AC-6(1) — Evidence Tracking | D1: Contrôle AC-6(1) — Suivi des preuves
A2: Control Information | D2: Informations du contrôle
A3: Control Identifier | B3: AC-6(1) | D3: Identifiant du contrôle | E3: AC-6(1)
A4: Family | B4: Least Privilege | D4: Famille | E4: Moindre privilège
A5: Profile | B5: CCCS Medium / PBMM Moderate | D5: Profil | E5: CCCS Moyen / PBMM Modéré
A6: Primary Evidence Tool | D6: Outil de preuve principal
A7: Contributing Tools | D7: Outils contributeurs
A8: Control Description | B8: LEAST PRIVILEGE | AUTHORIZE ACCESS TO SECURITY FUNCTIONS The organization explicitly authorizes access to all security functions not publicly accessible and all security-relevant information not publicly available. | D8: Description du contrôle | E8: MOINDRE PRIVILÈGE | AUTORISATION D’ACCÈS AUX FONCTIONS DE SÉCURITÉ L’organisation autorise explicitement l’accès à toutes les fonctions de sécurité qui ne sont pas accessibles au public et à toute l’information pertinente à la sécurité qui n’est pas accessible au public.
A9: Supplemental Guidance | B9: Security functions include, for example, establishing system accounts, configuring access authorizations (i.e., permissions, privileges), setting events to be audited, and setting intrusion detection parameters. Security-relevant information includes, for example, filtering rules for routers/firewalls, cryptographic key management information, configuration parameters for security services, and access control lists. Explicitly authorized personnel include, for example, security administrators, system and network administrators, system security officers, system maintenance personnel, system programmers, and other privileged users. Related controls: AC-17, AC-18, AC-19. | D9: Directives supplémentaires | E9: Les fonctions de sécurité comprennent, par exemple, l’établissement des comptes système, la configuration des autorisations d’accès (c.-à-d. les permissions, les privilèges), le réglage des événements à vérifier, et l’établissement des paramètres de détection des intrusions. Les renseignements pertinents pour la sécurité comprennent, par exemple, les règles de filtrage pour les routeurs/pare-feu, l’information de gestion des clés cryptographiques, les paramètres de configuration pour les services de sécurité et les listes de contrôle d’accès. Le personnel explicitement autorisé comprend, par exemple, les administrateurs de la sécurité, les administrateurs de systèmes et de réseaux, les agents de sécurité des systèmes, le personnel de maintenance des systèmes, les programmeurs de systèmes et d’autres utilisateurs privilégiés. Contrôles connexes : AC-17, AC-18, AC-19.
A10: Test Case | D10: Cas de test
A11: Test | B11: TEST-AC-6(1) | D11: Test | E11: TEST-AC-6(1)
A12: Requirement ID | B12: AC-6(1) | D12: ID Exigence | E12: AC-6(1)
A13: Component | D13: Composant
A14: Requirement | D14: Exigence
A15: Contextual Design Description | D15: Description contextuelle du design
A16: Evidence Provided | D16: Preuve fournie
A17: Preparer Sign Off (Initials, Date) | D17: Signataire préparateur (Initiales, Date)
A18: Owner Sign Off (Initials, Date) | D18: Signataire propriétaire (Initiales, Date)
A19: Assessor Sign Off (Initials, Date) | D19: Signataire évaluateur (Initiales, Date)
A20: Status | B20: Not Started | D20: Statut | E20: Non commencé
A21: Comments | D21: Commentaires

Sheet AC-7
A1: Control AC-7 — Evidence Tracking | D1: Contrôle AC-7 — Suivi des preuves
A2: Control Information | D2: Informations du contrôle
A3: Control Identifier | B3: AC-7 | D3: Identifiant du contrôle | E3: AC-7
A4: Family | B4: Unsuccessful Login Attempts | D4: Famille | E4: Tentatives infructueuses d’ouverture de session
A5: Profile | B5: CCCS Medium / PBMM Moderate | D5: Profil | E5: CCCS Moyen / PBMM Modéré
A6: Primary Evidence Tool | D6: Outil de preuve principal
A7: Contributing Tools | D7: Outils contributeurs
A8: Control Description | B8: (A) The information system enforces a limit of not more than three consecutive invalid logon attempts by a user during a 15-minute time period. (B) The information system automatically locks the account/node for a minimum of three (3) hours or until unlocked by an administrator. | D8: Description du contrôle | E8: (A) Le système d’information impose une limite de trois tentatives invalides consécutives d’ouverture de session par un utilisateur pendant une période de 15 minutes. (B) Le système d’information verrouille automatiquement le compte ou le nœud pendant au moins trois (3) heures ou jusqu’à ce qu’un administrateur le déverrouille.
A9: Supplemental Guidance | B9: Due to the potential for denial of service, automatic lockouts initiated by the information system are usually temporary and automatically release after a predetermined time period established by the organization. If a delay algorithm is selected, the organization may choose to employ different algorithms for different information system components based on the capabilities of those components. Response to unsuccessful login attempts may be implemented at both the operating system and the application levels. This control applies to all accesses other than those accesses explicitly identified and documented by the organization in AC-14. This security control/enhancement requires careful balance between usability and security. Care needs to be taken to ensure that the appropriate balance between the two seemingly conflicting requirements is achieved. If possible, an increasing time-out period should be used to deter determined attackers. For example, an original time-out of 5 minutes can become 10 minutes after the next 3 unsuccessful attempts, then 20 minutes, then 40 minutes, etc. | D9: Directives supplémentaires | E9: En raison de la possibilité de refus de service, les verrouillages automatiques déclenchés par le système d’information sont habituellement temporaires et automatiquement annulés après une période prédéterminée établie par l’organisation. Si un algorithme d’attente est sélectionné, l’organisation peut choisir d’utiliser différents algorithmes pour différents composants du système d’information en fonction des capacités de ces composants. La réponse aux tentatives d’ouverture de session infructueuses peut être mise en œuvre à la fois au niveau du système d’exploitation et de l’application. Ce contrôle s’applique à tous les accès autres que ceux explicitement identifiés et documentés par l’organisation dans AC-14. Ce contrôle ou cette amélioration de sécurité exige un équilibre prudent entre la facilité d’utilisation et la sécurité. Il faut veiller à assurer l’équilibre approprié entre ces deux exigences apparemment contradictoires. Dans la mesure du possible, une période de temporisation plus longue devrait être utilisée pour dissuader les attaquants déterminés. Par exemple, une temporisation initiale de 5 minutes peut devenir 10 minutes après les 3 tentatives infructueuses suivantes, puis 20 minutes, puis 40 minutes, etc.
A10: Test Case | D10: Cas de test
A11: Test | B11: TEST-AC-7 | D11: Test | E11: TEST-AC-7
A12: Requirement ID | B12: AC-7 | D12: ID Exigence | E12: AC-7
A13: Component | D13: Composant
A14: Requirement | D14: Exigence
A15: Contextual Design Description | D15: Description contextuelle du design
A16: Evidence Provided | D16: Preuve fournie
A17: Preparer Sign Off (Initials, Date) | D17: Signataire préparateur (Initiales, Date)
A18: Owner Sign Off (Initials, Date) | D18: Signataire propriétaire (Initiales, Date)
A19: Assessor Sign Off (Initials, Date) | D19: Signataire évaluateur (Initiales, Date)
A20: Status | B20: Not Started | D20: Statut | E20: Non commencé
A21: Comments | D21: Commentaires

Sheet AC-8
A1: Control AC-8 — Evidence Tracking | D1: Contrôle AC-8 — Suivi des preuves
A2: Control Information | D2: Informations du contrôle
A3: Control Identifier | B3: AC-8 | D3: Identifiant du contrôle | E3: AC-8
A4: Family | B4: System Use Notification | D4: Famille | E4: Avis d’utilisation du système
A5: Profile | B5: CCCS Medium / PBMM Moderate | D5: Profil | E5: CCCS Moyen / PBMM Modéré
A6: Primary Evidence Tool | D6: Outil de preuve principal
A7: Contributing Tools | D7: Outils contributeurs
A8: Control Description | B8: (A) The information system displays to users a organization-defined system use notification message or banner before granting access to the system that provides privacy and security notices in accordance with organization's network use policies. (B) The information system retains the notification message or banner on the screen until users acknowledge the usage conditions and take explicit actions to log on to or further access the information system. (C) The information system for publicly accessible systems: (a) Displays system use information before granting further access; (b) Displays references, if any, to monitoring, recording, or auditing that are consistent with privacy accommodations for such systems that generally prohibit those activities; and (c) Includes a description of the authorized uses of the system. | D8: Description du contrôle | E8: (A) Le système d’information affiche aux utilisateurs une bannière ou un message d’utilisation du système, défini par l’organisation avant d’accorder l’accès au système, qui fournit des avis de confidentialité et de sécurité conformément aux politiques d’utilisation du réseau de l’organisation. (B) Le système d’information maintient le message ou la bannière de notification à l’écran jusqu’à ce que les utilisateurs acceptent les conditions d’utilisation et prennent des mesures explicites pour ouvrir une session ou continuer d’accéder au système d’information. (C) Le système d’information pour les systèmes accessibles au public : (a) Affiche l’information sur l’utilisation du système avant d’accorder l’accès; (b) Affiche les références, le cas échéant, à la surveillance, à l’enregistrement ou à la vérification qui sont conformes aux dispositions de protection de la vie privée pour de tels systèmes qui interdisent généralement ces activités; (c) Comprend une description des utilisations autorisées du système.
A9: Supplemental Guidance | B9: System use notifications can be implemented using messages or warning banners displayed before individuals log in to information systems. System use notifications are used only for access via logon interfaces with human users and are not required when such human interfaces do not exist. Organizations consider system use notification messages/banners displayed in multiple languages based on specific organizational needs and the demographics of information system users. Organizations should also consult with legal services for review and approval of warning banner content | D9: Directives supplémentaires | E9: Les avis d’utilisation du système peuvent être mis en œuvre au moyen de bannières d’avertissement ou de messages affichés avant que les personnes n’ouvrent une session dans les systèmes d’information. Les avis d’utilisation du système sont utilisés uniquement pour l’accès par le biais d’interfaces d’ouverture de session avec des utilisateurs humains et ne sont pas nécessaires en l’absence de telles interfaces humaines. Les organisations envisageront d’utiliser des messages et des bannières d’avis d’utilisation du système affichés dans plusieurs langues en fonction des besoins particuliers de l’organisation et des caractéristiques démographiques des utilisateurs du système d’information. Les organisations doivent également consulter les services juridiques pour l’examen et l’approbation du contenu de la bannière d’avertissement.
A10: Test Case | D10: Cas de test
A11: Test | B11: TEST-AC-8 | D11: Test | E11: TEST-AC-8
A12: Requirement ID | B12: AC-8 | D12: ID Exigence | E12: AC-8
A13: Component | D13: Composant
A14: Requirement | D14: Exigence
A15: Contextual Design Description | D15: Description contextuelle du design
A16: Evidence Provided | D16: Preuve fournie
A17: Preparer Sign Off (Initials, Date) | D17: Signataire préparateur (Initiales, Date)
A18: Owner Sign Off (Initials, Date) | D18: Signataire propriétaire (Initiales, Date)
A19: Assessor Sign Off (Initials, Date) | D19: Signataire évaluateur (Initiales, Date)
A20: Status | B20: Not Started | D20: Statut | E20: Non commencé
A21: Comments | D21: Commentaires

Sheet AC-11
A1: Control AC-11 — Evidence Tracking | D1: Contrôle AC-11 — Suivi des preuves
A2: Control Information | D2: Informations du contrôle
A3: Control Identifier | B3: AC-11 | D3: Identifiant du contrôle | E3: AC-11
A4: Family | B4: Session Lock | D4: Famille | E4: Verrouillage de session
A5: Profile | B5: CCCS Medium / PBMM Moderate | D5: Profil | E5: CCCS Moyen / PBMM Modéré
A6: Primary Evidence Tool | D6: Outil de preuve principal
A7: Contributing Tools | D7: Outils contributeurs
A8: Control Description | B8: (A) The information system prevents further access to the system by initiating a session lock after 15 minutes of inactivity or upon receiving a request from a user. (B) The information system retains the session lock until the user re-establishes access using established identification and authentication procedures. | D8: Description du contrôle | E8: (A) Le système d’information empêche tout accès supplémentaire au système en amorçant un verrouillage de session après 15 minutes d’inactivité ou après en avoir reçu la demande de la part d’un utilisateur. (B) Le système d’information maintient le verrouillage de session jusqu’à ce que l’utilisateur rétablisse l’accès en utilisant les procédures d’identification et d’authentification établies.
A9: Supplemental Guidance | B9: Session locks are temporary actions taken when users stop work and move away from the immediate vicinity of information systems but do not want to log out because of the temporary nature of their absences. Session locks are implemented where session activities can be determined. This is typically at the operating system level, but can also be at the application level. Session locks are not an acceptable substitute for logging out of information systems, for example, if organizations require users to log out at the end of workdays. Related control: AC-7 | D9: Directives supplémentaires | E9: Les verrouillages de session sont des mesures temporaires prises lorsque les utilisateurs arrêtent de travailler et s’éloignent du voisinage immédiat des systèmes d’information, mais ne veulent pas fermer leur session en raison de la nature temporaire de leur absence. Les verrouillages de session sont mis en œuvre là où les activités de session peuvent être déterminées. C’est habituellement au niveau du système d’exploitation, mais cela peut aussi être au niveau de l’application. Les verrouillages de session ne constituent pas un substitut acceptable à la déconnexion des systèmes d’information, par exemple, si les organisations demandent aux utilisateurs de fermer leur session à la fin des journées de travail. Contrôle connexe : AC-7
A10: Test Case | D10: Cas de test
A11: Test | B11: TEST-AC-11 | D11: Test | E11: TEST-AC-11
A12: Requirement ID | B12: AC-11 | D12: ID Exigence | E12: AC-11
A13: Component | D13: Composant
A14: Requirement | D14: Exigence
A15: Contextual Design Description | D15: Description contextuelle du design
A16: Evidence Provided | D16: Preuve fournie
A17: Preparer Sign Off (Initials, Date) | D17: Signataire préparateur (Initiales, Date)
A18: Owner Sign Off (Initials, Date) | D18: Signataire propriétaire (Initiales, Date)
A19: Assessor Sign Off (Initials, Date) | D19: Signataire évaluateur (Initiales, Date)
A20: Status | B20: Not Started | D20: Statut | E20: Non commencé
A21: Comments | D21: Commentaires

Sheet AC-11-1
A1: Control AC-11(1) — Evidence Tracking | D1: Contrôle AC-11(1) — Suivi des preuves
A2: Control Information | D2: Informations du contrôle
A3: Control Identifier | B3: AC-11(1) | D3: Identifiant du contrôle | E3: AC-11(1)
A4: Family | B4: Session Lock | D4: Famille | E4: Verrouillage de session
A5: Profile | B5: CCCS Medium / PBMM Moderate | D5: Profil | E5: CCCS Moyen / PBMM Modéré
A6: Primary Evidence Tool | D6: Outil de preuve principal
A7: Contributing Tools | D7: Outils contributeurs
A8: Control Description | B8: SESSION LOCK | PATTERN-HIDING DISPLAYS The information system conceals, via the session lock, information previously visible on the display with a publicly viewable image. | D8: Description du contrôle | E8: VERROUILLAGE DE SESSION | MASQUES D’ÉCRAN Le système d’information masque, par l’intermédiaire du verrouillage de session, l’information précédemment visible sur l’écran au moyen d’une image visible publiquement.
A9: Supplemental Guidance | B9: Publicly viewable images can include static or dynamic images, for example, patterns used with screen savers, photographic images, solid colors, clock, battery life indicator, or a blank screen, with the additional caveat that none of the images convey sensitive information. | D9: Directives supplémentaires | E9: Les images accessibles au public peuvent comprendre des images statiques ou dynamiques, par exemple, des motifs utilisés avec des économiseurs d’écran, des images photographiques, des couleurs unies, une horloge, un indicateur de durée de vie de la batterie ou un écran vide, pourvu qu’aucune de ces images ne transmette d’information sensible.
A10: Test Case | D10: Cas de test
A11: Test | B11: TEST-AC-11(1) | D11: Test | E11: TEST-AC-11(1)
A12: Requirement ID | B12: AC-11(1) | D12: ID Exigence | E12: AC-11(1)
A13: Component | D13: Composant
A14: Requirement | D14: Exigence
A15: Contextual Design Description | D15: Description contextuelle du design
A16: Evidence Provided | D16: Preuve fournie
A17: Preparer Sign Off (Initials, Date) | D17: Signataire préparateur (Initiales, Date)
A18: Owner Sign Off (Initials, Date) | D18: Signataire propriétaire (Initiales, Date)
A19: Assessor Sign Off (Initials, Date) | D19: Signataire évaluateur (Initiales, Date)
A20: Status | B20: Not Started | D20: Statut | E20: Non commencé
A21: Comments | D21: Commentaires

Sheet AC-12
A1: Control AC-12 — Evidence Tracking | D1: Contrôle AC-12 — Suivi des preuves
A2: Control Information | D2: Informations du contrôle
A3: Control Identifier | B3: AC-12 | D3: Identifiant du contrôle | E3: AC-12
A4: Family | B4: Session Termination | D4: Famille | E4: Fermeture de session
A5: Profile | B5: CCCS Medium / PBMM Moderate | D5: Profil | E5: CCCS Moyen / PBMM Modéré
A6: Primary Evidence Tool | D6: Outil de preuve principal
A7: Contributing Tools | D7: Outils contributeurs
A8: Control Description | B8: (A) The information system automatically terminates a user session after a maximum of 24 hours of inactivity or upon request by the user. | D8: Description du contrôle | E8: (A) Le système d’information met automatiquement fin à une session utilisateur après un maximum de 24 heures d’inactivité ou à la demande de l’utilisateur.
A9: Supplemental Guidance | B9: This control addresses the termination of user-initiated logical sessions in contrast to SC-10 which addresses the termination of network connections that are associated with communications sessions (i.e., network disconnect). A logical session (for local, network, and remote access) is initiated whenever a user (or process acting on behalf of a user) accesses an organizational information system. Such user sessions can be terminated (and thus terminate user access) without terminating network sessions. Session termination terminates all processes associated with a user’s logical session except those processes that are specifically created by the user (i.e., session owner) to continue after the session is terminated. Conditions or trigger events requiring automatic session termination can include, for example, organization-defined periods of user inactivity, targeted responses to certain types of incidents, time-of-day restrictions on information system use. Related controls: SC-10, SC-23 | D9: Directives supplémentaires | E9: Ce contrôle traite de la fermeture des sessions logiques ouvertes par l’utilisateur, contrairement au SC-10, qui traite de l’interruption des connexions réseau associées aux sessions de communication (c.-à-d. déconnexion de réseau). Une session logique (pour l’accès local, réseau, et distant) est lancée chaque fois qu’un utilisateur (ou un processus agissant pour le compte d’un utilisateur) accède à un système d’information de l’organisation. Ces sessions d’utilisateur peuvent être interrompues (ce qui met fin à l’accès utilisateur) sans mettre fin aux sessions de réseau. La fermeture de session met fin à tous les processus associés à la session logique d’un utilisateur, à l’exception des processus créés spécifiquement par l’utilisateur (c.-à-d. le propriétaire de la session) pour se poursuivre après la fermeture de la session. Les conditions ou les événements déclencheurs exigeant une fermeture de session automatique peuvent comprendre, par exemple, les périodes d’inactivité définies par l’organisation, les réponses ciblées à certains types d’incidents, les restrictions d’utilisation du système d’information en fonction de l’heure du jour. Contrôles connexes : SC-10, SC-23
A10: Test Case | D10: Cas de test
A11: Test | B11: TEST-AC-12 | D11: Test | E11: TEST-AC-12
A12: Requirement ID | B12: AC-12 | D12: ID Exigence | E12: AC-12
A13: Component | D13: Composant
A14: Requirement | D14: Exigence
A15: Contextual Design Description | D15: Description contextuelle du design
A16: Evidence Provided | D16: Preuve fournie
A17: Preparer Sign Off (Initials, Date) | D17: Signataire préparateur (Initiales, Date)
A18: Owner Sign Off (Initials, Date) | D18: Signataire propriétaire (Initiales, Date)
A19: Assessor Sign Off (Initials, Date) | D19: Signataire évaluateur (Initiales, Date)
A20: Status | B20: Not Started | D20: Statut | E20: Non commencé
A21: Comments | D21: Commentaires

Sheet AC-17-1
A1: Control AC-17(1) — Evidence Tracking | D1: Contrôle AC-17(1) — Suivi des preuves
A2: Control Information | D2: Informations du contrôle
A3: Control Identifier | B3: AC-17(1) | D3: Identifiant du contrôle | E3: AC-17(1)
A4: Family | B4: Remote Access | D4: Famille | E4: Accès à distance
A5: Profile | B5: CCCS Medium / PBMM Moderate | D5: Profil | E5: CCCS Moyen / PBMM Modéré
A6: Primary Evidence Tool | D6: Outil de preuve principal
A7: Contributing Tools | D7: Outils contributeurs
A8: Control Description | B8: REMOTE ACCESS | AUTOMATED MONITORING / CONTROL The information system monitors and controls remote access methods. | D8: Description du contrôle | E8: ACCÈS À DISTANCE | SURVEILLANCE ET CONTRÔLE AUTOMATISÉS Le système d’information surveille et contrôle les méthodes d’accès à distance.
A9: Supplemental Guidance | B9: Automated monitoring and control of remote access sessions allows organizations to detect cyber-attacks and also ensure ongoing compliance with remote access policies by auditing connection activities of remote users on a variety of information system components (e.g., servers, workstations, notebook computers, smart phones, and tablets). Related controls: AU-2, AU-12. | D9: Directives supplémentaires | E9: La surveillance et le contrôle automatisés des sessions avec accès à distance permettent aux organisations de détecter les cyberattaques et d’assurer la conformité continue aux politiques d’accès à distance en vérifiant les activités de connexion des utilisateurs distants sur une variété de composants du système d’information (p. ex., serveurs, postes de travail, ordinateurs portatifs, téléphones intelligents et tablettes). Contrôles connexes : AU-2, AU-12.
A10: Test Case | D10: Cas de test
A11: Test | B11: TEST-AC-17(1) | D11: Test | E11: TEST-AC-17(1)
A12: Requirement ID | B12: AC-17(1) | D12: ID Exigence | E12: AC-17(1)
A13: Component | D13: Composant
A14: Requirement | D14: Exigence
A15: Contextual Design Description | D15: Description contextuelle du design
A16: Evidence Provided | D16: Preuve fournie
A17: Preparer Sign Off (Initials, Date) | D17: Signataire préparateur (Initiales, Date)
A18: Owner Sign Off (Initials, Date) | D18: Signataire propriétaire (Initiales, Date)
A19: Assessor Sign Off (Initials, Date) | D19: Signataire évaluateur (Initiales, Date)
A20: Status | B20: Not Started | D20: Statut | E20: Non commencé
A21: Comments | D21: Commentaires

Sheet AC-17-2
A1: Control AC-17(2) — Evidence Tracking | D1: Contrôle AC-17(2) — Suivi des preuves
A2: Control Information | D2: Informations du contrôle
A3: Control Identifier | B3: AC-17(2) | D3: Identifiant du contrôle | E3: AC-17(2)
A4: Family | B4: Remote Access | D4: Famille | E4: Accès à distance
A5: Profile | B5: CCCS Medium / PBMM Moderate | D5: Profil | E5: CCCS Moyen / PBMM Modéré
A6: Primary Evidence Tool | D6: Outil de preuve principal
A7: Contributing Tools | D7: Outils contributeurs
A8: Control Description | B8: REMOTE ACCESS | PROTECTION OF CONFIDENTIALITY / INTEGRITY USING ENCRYPTION The information system implements cryptographic mechanisms to protect the confidentiality and integrity of remote access sessions. The cryptography must be compliant with the requirements of SC-13. | D8: Description du contrôle | E8: ACCÈS À DISTANCE | PROTECTION DE LA CONFIDENTIALITÉ ET DE L’INTÉGRITÉ AU MOYEN DU CHIFFREMENT Le système d’information met en œuvre des mécanismes cryptographiques pour protéger la confidentialité et l’intégrité des sessions d’accès à distance. La cryptographie doit être conforme aux exigences de SC-13.
A9: Supplemental Guidance | B9: Guidance on the encryption strength of mechanism can be obtained from CSE upon request. | D9: Directives supplémentaires | E9: Le CST peut, sur demande, conseiller l’organisation quant à la puissance de chiffrement du mécanisme.
A10: Test Case | D10: Cas de test
A11: Test | B11: TEST-AC-17(2) | D11: Test | E11: TEST-AC-17(2)
A12: Requirement ID | B12: AC-17(2) | D12: ID Exigence | E12: AC-17(2)
A13: Component | D13: Composant
A14: Requirement | D14: Exigence
A15: Contextual Design Description | D15: Description contextuelle du design
A16: Evidence Provided | D16: Preuve fournie
A17: Preparer Sign Off (Initials, Date) | D17: Signataire préparateur (Initiales, Date)
A18: Owner Sign Off (Initials, Date) | D18: Signataire propriétaire (Initiales, Date)
A19: Assessor Sign Off (Initials, Date) | D19: Signataire évaluateur (Initiales, Date)
A20: Status | B20: Not Started | D20: Statut | E20: Non commencé
A21: Comments | D21: Commentaires

Sheet AC-17-100
A1: Control AC-17(100) — Evidence Tracking | D1: Contrôle AC-17(100) — Suivi des preuves
A2: Control Information | D2: Informations du contrôle
A3: Control Identifier | B3: AC-17(100) | D3: Identifiant du contrôle | E3: AC-17(100)
A4: Family | B4: Remote Access | D4: Famille | E4: Accès à distance
A5: Profile | B5: CCCS Medium / PBMM Moderate | D5: Profil | E5: CCCS Moyen / PBMM Modéré
A6: Primary Evidence Tool | D6: Outil de preuve principal
A7: Contributing Tools | D7: Outils contributeurs
A8: Control Description | B8: Remote access to privileged accounts is performed on dedicated management consoles governed entirely by the system’s security policies and used exclusively for this purpose (e.g. Internet access not allowed). | D8: Description du contrôle | E8: L’accès à distance aux comptes privilégiés se fait sur des consoles de gestion dédiées entièrement régies par les politiques de sécurité du système et utilisées exclusivement à cette fin (p. ex., accès Internet interdit).
A9: Supplemental Guidance | D9: Directives supplémentaires
A10: Test Case | D10: Cas de test
A11: Test | B11: TEST-AC-17(100) | D11: Test | E11: TEST-AC-17(100)
A12: Requirement ID | B12: AC-17(100) | D12: ID Exigence | E12: AC-17(100)
A13: Component | D13: Composant
A14: Requirement | D14: Exigence
A15: Contextual Design Description | D15: Description contextuelle du design
A16: Evidence Provided | D16: Preuve fournie
A17: Preparer Sign Off (Initials, Date) | D17: Signataire préparateur (Initiales, Date)
A18: Owner Sign Off (Initials, Date) | D18: Signataire propriétaire (Initiales, Date)
A19: Assessor Sign Off (Initials, Date) | D19: Signataire évaluateur (Initiales, Date)
A20: Status | B20: Not Started | D20: Statut | E20: Non commencé
A21: Comments | D21: Commentaires

Sheet AU-2
A1: Control AU-2 — Evidence Tracking | D1: Contrôle AU-2 — Suivi des preuves
A2: Control Information | D2: Informations du contrôle
A3: Control Identifier | B3: AU-2 | D3: Identifiant du contrôle | E3: AU-2
A4: Family | B4: Auditable Events | D4: Famille | E4: Événements vérifiables
A5: Profile | B5: CCCS Medium / PBMM Moderate | D5: Profil | E5: CCCS Moyen / PBMM Modéré
A6: Primary Evidence Tool | D6: Outil de preuve principal
A7: Contributing Tools | D7: Outils contributeurs
A8: Control Description | B8: (A) The organization determines that the information system is capable of auditing the following events: Successful and unsuccessful account logon events, account management events, object access, policy change, privilege functions, process tracking, and system events. For Web applications: all administrator activity, authentication checks, authorization checks, data deletions, data access, data changes, and permission changes. (B) The organization coordinates the security audit function with other organizational entities requiring audit-related information to enhance mutual support and to help guide the selection of auditable events. (C) The organization provides a rationale for why the auditable events are deemed to be adequate to support after-the-fact investigations of security incidents. (D) The organization determines what organizationally-defined audited events (a subset of the auditable events defined in AU-2 a.) and the frequency of (or situation requiring) auditing for each identified event. | D8: Description du contrôle | E8: (A) L’organisation détermine que le système d’information est capable de vérifier les événements suivants : événements d’ouverture de compte, réussis ou non, événements de gestion de compte, accès aux objets, changement de politique, fonctions de privilèges, suivi des processus et événements du système. Pour les applications Web : toutes les activités des administrateurs, les vérifications d’authentification, les vérifications d’autorisation, les suppressions de données, l’accès aux données, les changements de données et les changements d’autorisation. (B) L’organisation coordonne la fonction de vérification de la sécurité avec d’autres entités organisationnelles qui ont besoin de renseignements liés à la vérification pour améliorer le soutien mutuel et aider à orienter le choix des événements vérifiables. (C) L’organisation explique la raison pour laquelle les événements vérifiables sont jugés adéquats pour appuyer les enquêtes effectuées à la suite des incidents de sécurité. (D) L’organisation détermine les événements définis par l’organisation qui sont vérifiés (un sous-ensemble des événements vérifiables définis dans AU-2 a.) et la fréquence (ou la situation exigeant) des vérifications pour chaque événement identifié.
A9: Supplemental Guidance | B9: An event is any observable occurrence in an organizational information system. Organizations identify audit events as those events which are significant and relevant to the security of information systems and the environments in which those systems operate in order to meet specific and ongoing audit needs. Audit events can include, for example, password changes, failed logons, or failed accesses related to information systems, administrative privilege usage, or third-party credential usage. In determining the set of auditable events, organizations consider the auditing appropriate for each of the security controls to be implemented. To balance auditing requirements with other information system needs, this control also requires identifying that subset of auditable events that are audited at a given point in time. For example, organizations may determine that information systems must have the capability to log every file access both successful and unsuccessful, but not activate that capability except for specific circumstances due to the potential burden on system performance. Auditing requirements, including the need for auditable events, may be referenced in other security controls and control enhancements. Organizations also include auditable events that are required by applicable organizational policies, directives, and standards. Audit records can be generated at various levels of abstraction, including at the packet level as information traverses the network. Selecting the appropriate level of abstraction is a critical aspect of an audit capability and can facilitate the identification of root causes to problems. Organizations consider in the definition of auditable events, the auditing necessary to cover related events such as the steps in distributed, transaction-based processes (e.g., processes that are distributed across multiple organizations) and actions that occur in service-oriented architectures. The information system audits the following privileged user/process events at a minimum: (a) Successful and unsuccessful attempts to access, modify, or delete security objects (Security objects include audit data, system configuration files and file or users’ formal access permissions.) (b) Successful and unsuccessful logon attempts (c) Privileged activities or other system level access (see notes for AU-2 (4)) (d) Starting and ending time for user access to the system (e) Concurrent logons from different workstations (f) All program initiations (see notes for AU-2 (4)) In addition, the information system audits the following unprivileged user/process events at a minimum: (a) Successful and unsuccessful attempts to access, modify, or delete security objects (b) Successful and unsuccessful logon attempts (c) Starting and ending time for user access to the system (d) Concurrent logons from different workstations Related controls: AC-6, AC-17, AU-3, AU-12, MA-4, MP-2, MP-4, SI-4 | D9: Directives supplémentaires | E9: Un événement est toute occurrence observable dans un système d’information organisationnel. Les organisations désignent les événements vérifiables comme étant des événements importants et pertinents pour la sécurité des systèmes d’information et des environnements dans lesquels ces systèmes sont utilisés afin de répondre à des exigences de vérification particulières et continues. Les événements vérifiés peuvent comprendre, par exemple, les changements de mot de passe, les échecs d’ouverture de session ou les échecs accès liés aux systèmes d’information, l’utilisation des privilèges administratifs ou l’utilisation de justificatifs d’identité par des tiers. Lorsqu’elles déterminent l’ensemble des événements vérifiables, les organisations considèrent que la vérification est appropriée pour chacun des contrôles de sécurité à mettre en œuvre. Pour assurer l’équilibre entre les exigences en matière de vérification et les autres besoins du système d’information, ce contrôle exige également de déterminer le sous-ensemble d’événements vérifiables qui sont vérifiés à un moment donné. Par exemple, les organisations peuvent déterminer que les systèmes d’information doivent avoir la capacité d’enregistrer chaque accès aux fichiers, qu’il soit réussi ou non, mais n’activeront cette capacité que dans des circonstances particulières en raison du fardeau potentiel sur le rendement du système. Les exigences en matière de vérification, y compris la nécessité de déterminer des événements vérifiables, peuvent être mentionnées dans d’autres contrôles et améliorations des contrôles de sécurité. Les organisations incluent également les événements vérifiables qui sont exigés par les politiques, les directives et les normes organisationnelles applicables. Les enregistrements de vérification peuvent être générés à divers niveaux d’abstraction, y compris au niveau des paquets, à mesure que l’information traverse le réseau. Le choix du niveau d’abstraction approprié est un aspect essentiel d’une capacité de vérification et peut faciliter l’identification des causes profondes des problèmes. Dans la définition des événements vérifiables, les organisations prennent en compte la vérification nécessaire pour couvrir les événements connexes, comme les étapes des processus distribués, fondés sur les transactions (p. ex., les processus qui sont répartis entre de multiples organisations) et les actions qui ont lieu dans les architectures orientées service. Le système d’information vérifie au minimum les événements suivants liés aux utilisateurs/processus privilégiés : (a) Tentatives réussies et infructueuses d’accéder aux objets de sécurité, de les modifier ou de les supprimer (les objets de sécurité comprennent les données de vérification, les fichiers de configuration de système et les autorisations d’accès officielles des utilisateurs). (b) Tentatives d’ouverture de session réussies et infructueuses (c) Activités privilégiées ou autre accès au niveau du système (voir les notes pour AU-2 [4]) (d) Heures de début et de fin de l’accès des utilisateurs au système (e) Ouvertures de session simultanées à partir de différents postes de travail (f) Tous les lancements de programmes (voir les notes pour AU-2 [4]) De plus, le système d’information vérifie au minimum les événements suivants liés aux utilisateurs/processus non privilégiés : (a) Tentatives réussies et infructueuses d’accès, de modification ou de suppression d’objets de sécurité (b) Tentatives d’ouverture de session réussies et infructueuses (c) Heures de début et de fin de l’accès de l’utilisateur au système (d) Ouvertures de session simultanées à partir de différents postes de travail Contrôles connexes : AC-6, AC-17, AU-3, AU-12, MA-4, MP-2, MP-4, SI-4
A10: Test Case | D10: Cas de test
A11: Test | B11: TEST-AU-2 | D11: Test | E11: TEST-AU-2
A12: Requirement ID | B12: AU-2 | D12: ID Exigence | E12: AU-2
A13: Component | D13: Composant
A14: Requirement | D14: Exigence
A15: Contextual Design Description | D15: Description contextuelle du design
A16: Evidence Provided | D16: Preuve fournie
A17: Preparer Sign Off (Initials, Date) | D17: Signataire préparateur (Initiales, Date)
A18: Owner Sign Off (Initials, Date) | D18: Signataire propriétaire (Initiales, Date)
A19: Assessor Sign Off (Initials, Date) | D19: Signataire évaluateur (Initiales, Date)
A20: Status | B20: Not Started | D20: Statut | E20: Non commencé
A21: Comments | D21: Commentaires

Sheet AU-3
A1: Control AU-3 — Evidence Tracking | D1: Contrôle AU-3 — Suivi des preuves
A2: Control Information | D2: Informations du contrôle
A3: Control Identifier | B3: AU-3 | D3: Identifiant du contrôle | E3: AU-3
A4: Family | B4: Content of Audit Records | D4: Famille | E4: Contenu des enregistrements de vérification
A5: Profile | B5: CCCS Medium / PBMM Moderate | D5: Profil | E5: CCCS Moyen / PBMM Modéré
A6: Primary Evidence Tool | D6: Outil de preuve principal
A7: Contributing Tools | D7: Outils contributeurs
A8: Control Description | B8: (A) The information system generates audit records containing information that establishes what type of event occurred, when the event occurred, where the event occurred, the source of the event, the outcome of the event, and the identity of any individuals or subjects associated with the event. | D8: Description du contrôle | E8: (A) Le système d’information génère des enregistrements de vérification qui contiennent les renseignements permettant d’établir le type d’événement qui a eu lieu, le moment et l’endroit où l’événement a eu lieu, la source de l’événement, le résultat de l’événement, ainsi que l’identité de toute personne ou de tout sujet associé à l’événement.
A9: Supplemental Guidance | B9: Audit record content that may be necessary to satisfy the requirement of this control, includes, for example, time stamps, source and destination addresses, user/process identifiers, event descriptions, success/fail indications, filenames involved, and access control or flow control rules invoked. Event outcomes can include indicators of event success or failure and event-specific results (e.g., the security state of the information system after the event occurred). Related controls: AU-2, AU-8, AU-12, SI-11 | D9: Directives supplémentaires | E9: Le contenu des enregistrements de vérification qui peut être nécessaire pour satisfaire à l’exigence de ce contrôle comprend, par exemple, les estampilles temporelles, les adresses de source et de destination, les identifiants d’utilisateurs ou de processus, les descriptions d’événements, les indications de réussite ou d’échec, les noms des fichiers en cause et les règles de contrôle d’accès ou de flux invoquées. Les résultats de l’événement peuvent comprendre des indicateurs de réussite ou d’échec de l’événement et des résultats propres à l’événement (p. ex., l’état de sécurité du système d’information après l’événement). Contrôles connexes : AU-2, AU-8, AU-12, SI-11
A10: Test Case | D10: Cas de test
A11: Test | B11: TEST-AU-3 | D11: Test | E11: TEST-AU-3
A12: Requirement ID | B12: AU-3 | D12: ID Exigence | E12: AU-3
A13: Component | D13: Composant
A14: Requirement | D14: Exigence
A15: Contextual Design Description | D15: Description contextuelle du design
A16: Evidence Provided | D16: Preuve fournie
A17: Preparer Sign Off (Initials, Date) | D17: Signataire préparateur (Initiales, Date)
A18: Owner Sign Off (Initials, Date) | D18: Signataire propriétaire (Initiales, Date)
A19: Assessor Sign Off (Initials, Date) | D19: Signataire évaluateur (Initiales, Date)
A20: Status | B20: Not Started | D20: Statut | E20: Non commencé
A21: Comments | D21: Commentaires

Sheet AU-3-1
A1: Control AU-3(1) — Evidence Tracking | D1: Contrôle AU-3(1) — Suivi des preuves
A2: Control Information | D2: Informations du contrôle
A3: Control Identifier | B3: AU-3(1) | D3: Identifiant du contrôle | E3: AU-3(1)
A4: Family | B4: Content of Audit Records | D4: Famille | E4: Contenu des enregistrements de vérification
A5: Profile | B5: CCCS Medium / PBMM Moderate | D5: Profil | E5: CCCS Moyen / PBMM Modéré
A6: Primary Evidence Tool | D6: Outil de preuve principal
A7: Contributing Tools | D7: Outils contributeurs
A8: Control Description | B8: CONTENT OF AUDIT RECORDS | ADDITIONAL AUDIT INFORMATION The information system generates audit records containing the following additional information: session, connection, transaction, or activity duration; for client-server transactions, the number of bytes received and bytes sent; additional informational messages to diagnose or identify the event; characteristics that describe or identify the object or resource being acted upon. | D8: Description du contrôle | E8: CONTENU DES ENREGISTREMENTS DE VÉRIFICATION | RENSEIGNEMENTS DE VÉRIFICATION SUPPLÉMENTAIRES Le système d’information génère des enregistrements de vérification contenant les renseignements supplémentaires suivants : la durée de la session, de la connexion, de la transaction ou de l’activité; pour les transactions client-serveur, le nombre d’octets reçus et d’octets envoyés; des messages d’information supplémentaires pour diagnostiquer ou identifier l’événement; les caractéristiques qui décrivent ou identifient l’objet ou la ressource concernés.
A9: Supplemental Guidance | B9: Detailed information that organizations may consider in audit records includes, for example, full text recording of privileged commands or the individual identities of group account users. Organizations consider limiting the additional audit information to only that information explicitly needed for specific audit requirements. This facilitates the use of audit trails and audit logs by not including information that could potentially be misleading or could make it more difficult to locate information of interest. Additional guidance for enhancement (1): Audit events should always be capable of being associated with an individual identity. Associating audit events with a group or role is insufficient. | D9: Directives supplémentaires | E9: Les renseignements détaillés dont les organisations peuvent tenir compte dans les enregistrements de vérification comprennent, par exemple, l’enregistrement en texte intégral des commandes privilégiées ou les identités individuelles des utilisateurs de comptes de groupe. Les organisations devraient envisager de limiter les renseignements de vérification supplémentaires aux seuls renseignements explicitement nécessaires pour répondre à des exigences de vérification particulières. Cela facilitera l’utilisation des pistes de vérification et des journaux de vérification en n’incluant pas les renseignements qui pourraient être trompeurs ou rendre plus difficile la recherche de renseignements utiles. Conseils supplémentaires pour l’amélioration (1) : Les événements vérifiés devraient toujours pouvoir être associés à une identité individuelle. Associer des événements vérifiés à un groupe ou à un rôle est insuffisant.
A10: Test Case | D10: Cas de test
A11: Test | B11: TEST-AU-3(1) | D11: Test | E11: TEST-AU-3(1)
A12: Requirement ID | B12: AU-3(1) | D12: ID Exigence | E12: AU-3(1)
A13: Component | D13: Composant
A14: Requirement | D14: Exigence
A15: Contextual Design Description | D15: Description contextuelle du design
A16: Evidence Provided | D16: Preuve fournie
A17: Preparer Sign Off (Initials, Date) | D17: Signataire préparateur (Initiales, Date)
A18: Owner Sign Off (Initials, Date) | D18: Signataire propriétaire (Initiales, Date)
A19: Assessor Sign Off (Initials, Date) | D19: Signataire évaluateur (Initiales, Date)
A20: Status | B20: Not Started | D20: Statut | E20: Non commencé
A21: Comments | D21: Commentaires

Sheet AU-9-2
A1: Control AU-9(2) — Evidence Tracking | D1: Contrôle AU-9(2) — Suivi des preuves
A2: Control Information | D2: Informations du contrôle
A3: Control Identifier | B3: AU-9(2) | D3: Identifiant du contrôle | E3: AU-9(2)
A4: Family | B4: Protection of Audit Information | D4: Famille | E4: Protection des renseignements de vérification
A5: Profile | B5: CCCS Medium / PBMM Moderate | D5: Profil | E5: CCCS Moyen / PBMM Modéré
A6: Primary Evidence Tool | D6: Outil de preuve principal
A7: Contributing Tools | D7: Outils contributeurs
A8: Control Description | B8: PROTECTION OF AUDIT INFORMATION | AUDIT BACKUP ON SEPARATE PHYSICAL SYSTEMS / COMPONENTS The information system backs up audit records at least weekly onto a physically different system or system component than the system or component being audited. | D8: Description du contrôle | E8: PROTECTION DES RENSEIGNEMENTS DE VÉRIFICATION | SAUVEGARDE DES VÉRIFICATIONS SUR DES SYSTÈMES/COMPOSANTS PHYSIQUES SÉPARÉS Le système d’information sauvegarde les enregistrements de vérification au moins une fois par semaine sur un système ou un composant système physiquement différent du système ou du composant faisant l’objet de la vérification.
A9: Supplemental Guidance | B9: This control enhancement helps to ensure that a compromise of the information system being audited does not also result in a compromise of the audit records. Related controls: AU-4, AU-5, AU-11. | D9: Directives supplémentaires | E9: Cette amélioration permet de s’assurer qu’une compromission du système d’information faisant l’objet d’une vérification n’entraîne pas également la compromission des enregistrements de vérification. Contrôles connexes : AU-4, AU-5, AU-11.
A10: Test Case | D10: Cas de test
A11: Test | B11: TEST-AU-9(2) | D11: Test | E11: TEST-AU-9(2)
A12: Requirement ID | B12: AU-9(2) | D12: ID Exigence | E12: AU-9(2)
A13: Component | D13: Composant
A14: Requirement | D14: Exigence
A15: Contextual Design Description | D15: Description contextuelle du design
A16: Evidence Provided | D16: Preuve fournie
A17: Preparer Sign Off (Initials, Date) | D17: Signataire préparateur (Initiales, Date)
A18: Owner Sign Off (Initials, Date) | D18: Signataire propriétaire (Initiales, Date)
A19: Assessor Sign Off (Initials, Date) | D19: Signataire évaluateur (Initiales, Date)
A20: Status | B20: Not Started | D20: Statut | E20: Non commencé
A21: Comments | D21: Commentaires

Sheet AU-12
A1: Control AU-12 — Evidence Tracking | D1: Contrôle AU-12 — Suivi des preuves
A2: Control Information | D2: Informations du contrôle
A3: Control Identifier | B3: AU-12 | D3: Identifiant du contrôle | E3: AU-12
A4: Family | B4: Audit Generation | D4: Famille | E4: Génération des vérifications
A5: Profile | B5: CCCS Medium / PBMM Moderate | D5: Profil | E5: CCCS Moyen / PBMM Modéré
A6: Primary Evidence Tool | D6: Outil de preuve principal
A7: Contributing Tools | D7: Outils contributeurs
