Workbook

Sheet DASHBOARD
A1: DASHBOARD — PBMM Evidence: Identity
A2: Control ID | B2: Control Name | C2: Primary Tool | D2: Tab | E2: Status
A3: AC-2 | B3: Account Management | D3: AC-2 | E3: ='AC-2'!B20 -> Not Started
A4: AC-2(1) | B4: Account Management | D4: AC-2-1 | E4: ='AC-2-1'!B20 -> Not Started
A5: AC-2(2) | B5: Account Management | D5: AC-2-2 | E5: ='AC-2-2'!B20 -> Not Started
A6: AC-2(3) | B6: Account Management | D6: AC-2-3 | E6: ='AC-2-3'!B20 -> Not Started
A7: AC-2(4) | B7: Account Management | D7: AC-2-4 | E7: ='AC-2-4'!B20 -> Not Started
A8: AC-2(5) | B8: Account Management | D8: AC-2-5 | E8: ='AC-2-5'!B20 -> Not Started
A9: AC-2(7) | B9: Account Management | D9: AC-2-7 | E9: ='AC-2-7'!B20 -> Not Started
A10: AC-3 | B10: Access Enforcement | D10: AC-3 | E10: ='AC-3'!B20 -> Not Started
A11: AC-6 | B11: Least Privilege | D11: AC-6 | E11: ='AC-6'!B20 -> Not Started
A12: AC-6(1) | B12: Least Privilege | D12: AC-6-1 | E12: ='AC-6-1'!B20 -> Not Started
A13: AC-6(9) | B13: Least Privilege | D13: AC-6-9 | E13: ='AC-6-9'!B20 -> Not Started
A14: AC-6(10) | B14: Least Privilege | D14: AC-6-10 | E14: ='AC-6-10'!B20 -> Not Started
A15: AC-7 | B15: Unsuccessful Login Attempts | D15: AC-7 | E15: ='AC-7'!B20 -> Not Started
A16: AC-10 | B16: Concurrent Session Control | D16: AC-10 | E16: ='AC-10'!B20 -> Not Started
A17: AC-11 | B17: Session Lock | D17: AC-11 | E17: ='AC-11'!B20 -> Not Started
A18: AC-17(1) | B18: Remote Access | D18: AC-17-1 | E18: ='AC-17-1'!B20 -> Not Started
A19: AC-17(9) | B19: Remote Access | D19: AC-17-9 | E19: ='AC-17-9'!B20 -> Not Started
A20: AC-21 | B20: User-Based Collaboration and Information Sharing | D20: AC-21 | E20: ='AC-21'!B20 -> Not Started
A21: AU-2 | B21: Auditable Events | D21: AU-2 | E21: ='AU-2'!B20 -> Not Started
A22: AU-3 | B22: Content of Audit Records | D22: AU-3 | E22: ='AU-3'!B20 -> Not Started
A23: AU-3(1) | B23: Content of Audit Records | D23: AU-3-1 | E23: ='AU-3-1'!B20 -> Not Started
A24: AU-9 | B24: Protection of Audit Information | D24: AU-9 | E24: ='AU-9'!B20 -> Not Started
A25: AU-9(2) | B25: Protection of Audit Information | D25: AU-9-2 | E25: ='AU-9-2'!B20 -> Not Started
A26: AU-9(4) | B26: Protection of Audit Information | D26: AU-9-4 | E26: ='AU-9-4'!B20 -> Not Started
A27: AU-12 | B27: Audit Generation | D27: AU-12 | E27: ='AU-12'!B20 -> Not Started
A28: CM-5(1) | B28: Access Restrictions for Change | D28: CM-5-1 | E28: ='CM-5-1'!B20 -> Not Started
A29: CM-5(5) | B29: Access Restrictions for Change | D29: CM-5-5 | E29: ='CM-5-5'!B20 -> Not Started
A30: CM-5(6) | B30: Access Restrictions for Change | D30: CM-5-6 | E30: ='CM-5-6'!B20 -> Not Started
A31: CM-6 | B31: Configuration Settings | D31: CM-6 | E31: ='CM-6'!B20 -> Not Started
A32: CM-7 | B32: Least Functionality | D32: CM-7 | E32: ='CM-7'!B20 -> Not Started
A33: CM-7(1) | B33: Least Functionality | D33: CM-7-1 | E33: ='CM-7-1'!B20 -> Not Started
A34: CP-7 | B34: Alternate Processing Site | D34: CP-7 | E34: ='CP-7'!B20 -> Not Started
A35: CP-7(4) | B35: Alternate Processing Site | D35: CP-7-4 | E35: ='CP-7-4'!B20 -> Not Started
A36: CP-10 | B36: Information System Recovery and Reconstitution | D36: CP-10 | E36: ='CP-10'!B20 -> Not Started
A37: CP-10(4) | B37: Information System Recovery and Reconstitution | D37: CP-10-4 | E37: ='CP-10-4'!B20 -> Not Started
A38: IA-2 | B38: Identification and Authentication (Organizational Users) | D38: IA-2 | E38: ='IA-2'!B20 -> Not Started
A39: IA-2(1) | B39: Identification and Authentication (Organizational Users) | D39: IA-2-1 | E39: ='IA-2-1'!B20 -> Not Started
A40: IA-2(3) | B40: Identification and Authentication (Organizational Users) | D40: IA-2-3 | E40: ='IA-2-3'!B20 -> Not Started
...

Sheet TABLEAU_DE_BORD
A1: TABLEAU DE BORD — Suivi PBMM : Identity
A2: ID Contrôle | B2: Nom du contrôle | C2: Outil principal | D2: Onglet | E2: Statut
A3: AC-2 | B3: Gestion des comptes | D3: AC-2 | E3: ='AC-2'!E20 -> Non commencé
A4: AC-2(1) | B4: Gestion des comptes | D4: AC-2-1 | E4: ='AC-2-1'!E20 -> Non commencé
A5: AC-2(2) | B5: Gestion des comptes | D5: AC-2-2 | E5: ='AC-2-2'!E20 -> Non commencé
A6: AC-2(3) | B6: Gestion des comptes | D6: AC-2-3 | E6: ='AC-2-3'!E20 -> Non commencé
A7: AC-2(4) | B7: Gestion des comptes | D7: AC-2-4 | E7: ='AC-2-4'!E20 -> Non commencé
A8: AC-2(5) | B8: Gestion des comptes | D8: AC-2-5 | E8: ='AC-2-5'!E20 -> Non commencé
A9: AC-2(7) | B9: Gestion des comptes | D9: AC-2-7 | E9: ='AC-2-7'!E20 -> Non commencé
A10: AC-3 | B10: Application des contrôles d’accès | D10: AC-3 | E10: ='AC-3'!E20 -> Non commencé
A11: AC-6 | B11: Moindre privilège | D11: AC-6 | E11: ='AC-6'!E20 -> Non commencé
A12: AC-6(1) | B12: Moindre privilège | D12: AC-6-1 | E12: ='AC-6-1'!E20 -> Non commencé
A13: AC-6(9) | B13: Moindre privilège | D13: AC-6-9 | E13: ='AC-6-9'!E20 -> Non commencé
A14: AC-6(10) | B14: Moindre privilège | D14: AC-6-10 | E14: ='AC-6-10'!E20 -> Non commencé
A15: AC-7 | B15: Tentatives infructueuses d’ouverture de session | D15: AC-7 | E15: ='AC-7'!E20 -> Non commencé
A16: AC-10 | B16: Contrôle des sessions simultanées | D16: AC-10 | E16: ='AC-10'!E20 -> Non commencé
A17: AC-11 | B17: Verrouillage de session | D17: AC-11 | E17: ='AC-11'!E20 -> Non commencé
A18: AC-17(1) | B18: Accès à distance | D18: AC-17-1 | E18: ='AC-17-1'!E20 -> Non commencé
A19: AC-17(9) | B19: Accès à distance | D19: AC-17-9 | E19: ='AC-17-9'!E20 -> Non commencé
A20: AC-21 | B20: Collaboration et partage d’information entre utilisateurs | D20: AC-21 | E20: ='AC-21'!E20 -> Non commencé
A21: AU-2 | B21: Événements vérifiables | D21: AU-2 | E21: ='AU-2'!E20 -> Non commencé
A22: AU-3 | B22: Contenu des enregistrements de vérification | D22: AU-3 | E22: ='AU-3'!E20 -> Non commencé
A23: AU-3(1) | B23: Contenu des enregistrements de vérification | D23: AU-3-1 | E23: ='AU-3-1'!E20 -> Non commencé
A24: AU-9 | B24: Protection des renseignements de vérification | D24: AU-9 | E24: ='AU-9'!E20 -> Non commencé
A25: AU-9(2) | B25: Protection des renseignements de vérification | D25: AU-9-2 | E25: ='AU-9-2'!E20 -> Non commencé
A26: AU-9(4) | B26: Protection des renseignements de vérification | D26: AU-9-4 | E26: ='AU-9-4'!E20 -> Non commencé
A27: AU-12 | B27: Génération des vérifications | D27: AU-12 | E27: ='AU-12'!E20 -> Non commencé
A28: CM-5(1) | B28: Restrictions d’accès pour les changements | D28: CM-5-1 | E28: ='CM-5-1'!E20 -> Non commencé
A29: CM-5(5) | B29: Restrictions d’accès pour les changements | D29: CM-5-5 | E29: ='CM-5-5'!E20 -> Non commencé
A30: CM-5(6) | B30: Restrictions d’accès pour les changements | D30: CM-5-6 | E30: ='CM-5-6'!E20 -> Non commencé
A31: CM-6 | B31: Paramètres de configuration | D31: CM-6 | E31: ='CM-6'!E20 -> Non commencé
A32: CM-7 | B32: Moindre fonctionnalité | D32: CM-7 | E32: ='CM-7'!E20 -> Non commencé
A33: CM-7(1) | B33: Moindre fonctionnalité | D33: CM-7-1 | E33: ='CM-7-1'!E20 -> Non commencé
A34: CP-7 | B34: Site de traitement auxiliaire | D34: CP-7 | E34: ='CP-7'!E20 -> Non commencé
A35: CP-7(4) | B35: Site de traitement auxiliaire | D35: CP-7-4 | E35: ='CP-7-4'!E20 -> Non commencé
A36: CP-10 | B36: Reprise et reconstitution du système d’information | D36: CP-10 | E36: ='CP-10'!E20 -> Non commencé
A37: CP-10(4) | B37: Reprise et reconstitution du système d’information | D37: CP-10-4 | E37: ='CP-10-4'!E20 -> Non commencé
A38: IA-2 | B38: Identification et authentification (utilisateurs au sein de l’organisation) | D38: IA-2 | E38: ='IA-2'!E20 -> Non commencé
A39: IA-2(1) | B39: Identification et authentification (utilisateurs au sein de l’organisation) | D39: IA-2-1 | E39: ='IA-2-1'!E20 -> Non commencé
A40: IA-2(3) | B40: Identification et authentification (utilisateurs au sein de l’organisation) | D40: IA-2-3 | E40: ='IA-2-3'!E20 -> Non commencé
...

Sheet AC-2
A1: Control AC-2 — Evidence Tracking | D1: Contrôle AC-2 — Suivi des preuves
A2: Control Information | D2: Informations du contrôle
A3: Control Identifier | B3: AC-2 | D3: Identifiant du contrôle | E3: AC-2
A4: Family | B4: Account Management | D4: Famille | E4: Gestion des comptes
A5: Profile | B5: CCCS Medium / PBMM Moderate | D5: Profil | E5: CCCS Moyen / PBMM Modéré
A6: Primary Evidence Tool | D6: Outil de preuve principal
A7: Contributing Tools | D7: Outils contributeurs
A8: Control Description | B8: (A) The organization identifies and selects which types of information system accounts support organizational missions/business functions. (B) The organization assigns account managers for information system accounts. (C) The organization establishes conditions for group and role membership. (D) The organization specifies authorized users of the information system, group and role membership, and access authorizations (i.e., privileges) and other attributes (as required) for each account. (E) The organization requires approvals by responsible managers for requests to create information system accounts. (F) The organization creates, enables, modifies, disables, and removes information system accounts in accordance with information system account management procedures. (G) The organization monitors the use of information system accounts. (H) The organization notifies account managers: (a) When accounts are no longer required; (b) When users are terminated or transferred; and (c) When individual information system usage or need-to-know changes. (I) The organization authorizes access to the information system based on: (a) A valid access authorization; (b) Intended system usage; and (c) Other attributes as required by the organization or associated missions/business functions. (J) The organization reviews accounts for compliance with account management requirements at least annually. (K) The organization establishes a process for reissuing shared/group account credentials (if deployed) when individuals are removed from the group. | D8: Description du contrôle | E8: (A) L’organisation détermine et sélectionne les types de comptes du système d’information qui soutiennent les fonctions opérationnelles et de mission de l’organisation. (B) L’organisation affecte des gestionnaires de comptes aux comptes du système d’information. (C) L’organisation établit les conditions d’adhésion aux groupes et aux rôles. (D) L’organisation précise les utilisateurs autorisés du système d’information, l’adhésion aux groupes et aux rôles, et les autorisations d’accès (c.-à-d., les privilèges) et autres attributs (au besoin) pour chaque compte. (E) L’organisation requiert l’approbation des gestionnaires responsables des demandes de création de comptes de système d’information. (F) L’organisation crée, active, modifie, désactive et supprime les comptes du système d’information conformément aux procédures de gestion des comptes du système d’information. (G) L’organisation surveille l’utilisation des comptes du système d’information. (H) L’organisation avise les gestionnaires de comptes : (a) lorsque des comptes ne sont plus requis; (b) lorsque des utilisateurs sont congédiés ou transférés; (c) lorsque l’utilisation individuelle du système d’information ou le besoin de savoir change. (I) L’organisation autorise l’accès au système d’information en se basant sur : (a) une autorisation d’accès valide; (b) l’utilisation prévue du système; (c) d’autres attributs requis par l’organisation ou les fonctions opérationnelles ou de mission connexes. (J) L’organisation revoit la conformité aux exigences de gestion des comptes au moins une fois par année. (K) L’organisation établit un processus de réémission des justificatifs d’identité de compte partagé/de groupe (si déployés) lorsque des personnes sont retirées du groupe.
A9: Supplemental Guidance | B9: Information system account types include, for example, individual, shared, group, system, guest/anonymous, emergency, developer/manufacturer/vendor, temporary, and service. Some of the account management requirements listed above can be implemented by organizational information systems. The identification of authorized users of the information system and the specification of access privileges reflects the requirements in other security controls in the security plan. Users requiring administrative privileges on information system accounts receive additional scrutiny by appropriate organizational personnel (e.g., system owner, mission/business owner, or information technology security co-ordinator) responsible for approving such accounts and privileged access. Organizations may choose to define access privileges or other attributes by account, by type of account, or a combination of both. Other attributes required for authorizing access include, for example, restrictions on time-of-day, day-of-week, and point-of-origin. In defining other account attributes, organizations consider system-related requirements (e.g., scheduled maintenance, system upgrades) and mission/business requirements, (e.g., time zone differences, customer requirements, remote access to support travel requirements). Failure to consider these factors could affect information system availability. Temporary and emergency accounts are accounts intended for short-term use. Organizations establish temporary accounts as a part of normal account activation procedures when there is a need for short-term accounts without the demand for immediacy in account activation. Organizations establish emergency accounts in response to crisis situations and with the need for rapid account activation. Therefore, emergency account activation may bypass normal account authorization processes. Emergency and temporary accounts are not to be confused with infrequently used accounts (e.g., local accounts used for special tasks defined by organizations or when network resources are unavailable). Such accounts remain available and are not subject to automatic disabling or removal dates. Conditions for disabling or deactivating accounts include, for example: (i) when shared/group, emergency, or temporary accounts are no longer required; or (ii) when individuals are transferred or terminated. Some types of information system accounts may require specialized training. Related controls: AC-3, AC-4, AC-5, AC-6, AC-10, AC-17, AC-19, AC-20, AU-9, IA-2, IA-4, IA-5, IA-8, CM-5, CM-6, CM-11, MA-3, MA-4, MA-5, PL-4, SC-13 | D9: Directives supplémentaires | E9: Les types de comptes du système d’information comprennent, par exemple, les comptes individuels, partagés, de groupe, de système, d’invité/anonymes, d’urgence, de développeur/fabricant/fournisseur, temporaires et de service. Certaines des exigences de gestion des comptes énumérées ci-dessus peuvent être mises en œuvre par les systèmes d’information de l’organisation. L’identification des utilisateurs autorisés du système d’information et la spécification des privilèges d’accès reflètent les exigences dans les autres contrôles de sécurité du plan de sécurité. Les utilisateurs qui ont besoin de privilèges administratifs sur les comptes du système d’information font l’objet d’un examen plus approfondi par le personnel approprié de l’organisation (p. ex., propriétaire du système, responsable opérationnel/de mission, ou coordonnateur de la sécurité des technologies de l’information) responsable de l’approbation de ces comptes et de l’accès privilégié. Les organisations peuvent choisir de définir les privilèges d’accès ou d’autres attributs par compte, par type de compte, ou par une combinaison des deux. Les autres attributs requis pour autoriser l’accès comprennent, par exemple, les restrictions sur l’heure du jour, le jour de la semaine et le point d’origine. En définissant d’autres attributs de compte, les organisations tiennent compte des exigences liées au système (p. ex., maintenance programmée, mise à niveau du système) et des exigences opérationnelles/de mission (p. ex., différences de fuseau horaire, exigences des clients, accès à distance pour répondre aux besoins en matière de déplacements). Le défaut de tenir compte de ces facteurs pourrait avoir une incidence sur la disponibilité du système d’information. Les comptes temporaires et d’urgence sont des comptes destinés à une utilisation à court terme. Les organisations établissent des comptes temporaires dans le cadre des procédures normales d’activation des comptes lorsqu’elles ont besoin de comptes à court terme sans requérir l’activation immédiate de ces comptes. Les organisations établissent des comptes d’urgence en réponse à des situations de crise et lorsqu’elles doivent activer rapidement les comptes. Par conséquent, l’activation d’un compte d’urgence peut contourner les processus normaux d’autorisation de compte. Il ne faut pas confondre les comptes d’urgence et les comptes temporaires avec les comptes peu utilisés (p. ex., comptes locaux utilisés pour des tâches spéciales définies par les organisations ou lorsque les ressources du réseau ne sont pas disponibles). Ces comptes demeurent disponibles et ne sont pas assujettis à des dates de désactivation ou de retrait automatiques. Les conditions de désactivation des comptes comprennent, par exemple : (i) lorsque les comptes partagés/de groupe, d’urgence ou temporaires ne sont plus requis; ou (ii) lorsque des personnes sont transférées ou licenciées. Certains types de comptes de système d’information peuvent nécessiter une formation spécialisée. Contrôles connexes : AC-3, AC-4, AC-5, AC-6, AC-10, AC-17, AC-19, AC-20, AU-9, IA-2, IA-4, IA-5, IA-8, CM-5, CM-6, CM-11, MA-3, MA-4, MA-5, PL-4, SC-13
A10: Test Case | D10: Cas de test
A11: Test | B11: TEST-AC-2 | D11: Test | E11: TEST-AC-2
A12: Requirement ID | B12: AC-2 | D12: ID Exigence | E12: AC-2
A13: Component | D13: Composant
A14: Requirement | D14: Exigence
A15: Contextual Design Description | D15: Description contextuelle du design
A16: Evidence Provided | D16: Preuve fournie
A17: Preparer Sign Off (Initials, Date) | D17: Signataire préparateur (Initiales, Date)
A18: Owner Sign Off (Initials, Date) | D18: Signataire propriétaire (Initiales, Date)
A19: Assessor Sign Off (Initials, Date) | D19: Signataire évaluateur (Initiales, Date)
A20: Status | B20: Not Started | D20: Statut | E20: Non commencé
A21: Comments | D21: Commentaires

Sheet AC-2-1
A1: Control AC-2(1) — Evidence Tracking | D1: Contrôle AC-2(1) — Suivi des preuves
A2: Control Information | D2: Informations du contrôle
A3: Control Identifier | B3: AC-2(1) | D3: Identifiant du contrôle | E3: AC-2(1)
A4: Family | B4: Account Management | D4: Famille | E4: Gestion des comptes
A5: Profile | B5: CCCS Medium / PBMM Moderate | D5: Profil | E5: CCCS Moyen / PBMM Modéré
A6: Primary Evidence Tool | D6: Outil de preuve principal
A7: Contributing Tools | D7: Outils contributeurs
A8: Control Description | B8: ACCOUNT MANAGEMENT | AUTOMATED SYSTEM ACCOUNT MANAGEMENT The organization employs automated mechanisms to support the management of information system accounts. | D8: Description du contrôle | E8: GESTION DES COMPTES | GESTION AUTOMATISÉE DES COMPTES DU SYSTÈME L’organisation utilise des mécanismes automatisés pour prendre en charge la gestion des comptes du système d’information.
A9: Supplemental Guidance | B9: The use of automated mechanisms can include, for example: using email or text messaging to automatically notify account managers when users are terminated or transferred; using the information system to monitor account usage; and using telephonic notification to report atypical system account usage. | D9: Directives supplémentaires | E9: L’utilisation de mécanismes automatisés peut comprendre, par exemple, l’utilisation de courriels ou de messages texte pour aviser automatiquement les gestionnaires de comptes lorsque des utilisateurs sont licenciés ou transférés; l’utilisation du système d’information pour surveiller les statistiques d’utilisation des comptes; et l’utilisation d’une notification téléphonique pour signaler l’utilisation atypique des comptes du système.
A10: Test Case | D10: Cas de test
A11: Test | B11: TEST-AC-2(1) | D11: Test | E11: TEST-AC-2(1)
A12: Requirement ID | B12: AC-2(1) | D12: ID Exigence | E12: AC-2(1)
A13: Component | D13: Composant
A14: Requirement | D14: Exigence
A15: Contextual Design Description | D15: Description contextuelle du design
A16: Evidence Provided | D16: Preuve fournie
A17: Preparer Sign Off (Initials, Date) | D17: Signataire préparateur (Initiales, Date)
A18: Owner Sign Off (Initials, Date) | D18: Signataire propriétaire (Initiales, Date)
A19: Assessor Sign Off (Initials, Date) | D19: Signataire évaluateur (Initiales, Date)
A20: Status | B20: Not Started | D20: Statut | E20: Non commencé
A21: Comments | D21: Commentaires

Sheet AC-2-2
A1: Control AC-2(2) — Evidence Tracking | D1: Contrôle AC-2(2) — Suivi des preuves
A2: Control Information | D2: Informations du contrôle
A3: Control Identifier | B3: AC-2(2) | D3: Identifiant du contrôle | E3: AC-2(2)
A4: Family | B4: Account Management | D4: Famille | E4: Gestion des comptes
A5: Profile | B5: CCCS Medium / PBMM Moderate | D5: Profil | E5: CCCS Moyen / PBMM Modéré
A6: Primary Evidence Tool | D6: Outil de preuve principal
A7: Contributing Tools | D7: Outils contributeurs
A8: Control Description | B8: ACCOUNT MANAGEMENT | REMOVAL OF TEMPORARY / EMERGENCY ACCOUNTS The information system automatically disables temporary and emergency accounts after no more than 30 days for both temporary and emergency accounts. | D8: Description du contrôle | E8: GESTION DES COMPTES | RETRAIT DES COMPTES TEMPORAIRES/D’URGENCE Le système d’information désactive automatiquement les comptes temporaires et d’urgence après un maximum de 30 jours, pour les comptes temporaires comme pour les comptes d’urgence.
A9: Supplemental Guidance | B9: This control enhancement requires the removal of both temporary and emergency accounts automatically after a predefined period of time has elapsed, rather than at the convenience of the systems administrator. | D9: Directives supplémentaires | E9: Cette amélioration du contrôle exige le retrait automatique des comptes temporaires et d’urgence au terme d’une période prédéfinie, plutôt qu’à la convenance de l’administrateur des systèmes.
A10: Test Case | D10: Cas de test
A11: Test | B11: TEST-AC-2(2) | D11: Test | E11: TEST-AC-2(2)
A12: Requirement ID | B12: AC-2(2) | D12: ID Exigence | E12: AC-2(2)
A13: Component | D13: Composant
A14: Requirement | D14: Exigence
A15: Contextual Design Description | D15: Description contextuelle du design
A16: Evidence Provided | D16: Preuve fournie
A17: Preparer Sign Off (Initials, Date) | D17: Signataire préparateur (Initiales, Date)
A18: Owner Sign Off (Initials, Date) | D18: Signataire propriétaire (Initiales, Date)
A19: Assessor Sign Off (Initials, Date) | D19: Signataire évaluateur (Initiales, Date)
A20: Status | B20: Not Started | D20: Statut | E20: Non commencé
A21: Comments | D21: Commentaires

Sheet AC-2-3
A1: Control AC-2(3) — Evidence Tracking | D1: Contrôle AC-2(3) — Suivi des preuves
A2: Control Information | D2: Informations du contrôle
A3: Control Identifier | B3: AC-2(3) | D3: Identifiant du contrôle | E3: AC-2(3)
A4: Family | B4: Account Management | D4: Famille | E4: Gestion des comptes
A5: Profile | B5: CCCS Medium / PBMM Moderate | D5: Profil | E5: CCCS Moyen / PBMM Modéré
A6: Primary Evidence Tool | D6: Outil de preuve principal
A7: Contributing Tools | D7: Outils contributeurs
A8: Control Description | B8: ACCOUNT MANAGEMENT | DISABLE INACTIVE ACCOUNTS The information system automatically disables inactive accounts after 90 days. | D8: Description du contrôle | E8: GESTION DES COMPTES | DÉSACTIVATION DES COMPTES INACTIFS Le système d’information désactive automatiquement les comptes après 90 jours d’inactivité.
A9: Supplemental Guidance | D9: Directives supplémentaires
A10: Test Case | D10: Cas de test
A11: Test | B11: TEST-AC-2(3) | D11: Test | E11: TEST-AC-2(3)
A12: Requirement ID | B12: AC-2(3) | D12: ID Exigence | E12: AC-2(3)
A13: Component | D13: Composant
A14: Requirement | D14: Exigence
A15: Contextual Design Description | D15: Description contextuelle du design
A16: Evidence Provided | D16: Preuve fournie
A17: Preparer Sign Off (Initials, Date) | D17: Signataire préparateur (Initiales, Date)
A18: Owner Sign Off (Initials, Date) | D18: Signataire propriétaire (Initiales, Date)
A19: Assessor Sign Off (Initials, Date) | D19: Signataire évaluateur (Initiales, Date)
A20: Status | B20: Not Started | D20: Statut | E20: Non commencé
A21: Comments | D21: Commentaires

Sheet AC-2-4
A1: Control AC-2(4) — Evidence Tracking | D1: Contrôle AC-2(4) — Suivi des preuves
A2: Control Information | D2: Informations du contrôle
A3: Control Identifier | B3: AC-2(4) | D3: Identifiant du contrôle | E3: AC-2(4)
A4: Family | B4: Account Management | D4: Famille | E4: Gestion des comptes
A5: Profile | B5: CCCS Medium / PBMM Moderate | D5: Profil | E5: CCCS Moyen / PBMM Modéré
A6: Primary Evidence Tool | D6: Outil de preuve principal
A7: Contributing Tools | D7: Outils contributeurs
A8: Control Description | B8: ACCOUNT MANAGEMENT | AUTOMATED AUDIT ACTIONS The information system automatically audits account creation, modification, enabling, disabling, and removal actions, and notifies responsible managers. Related controls: AU-2, AU-12. | D8: Description du contrôle | E8: GESTION DES COMPTES | MESURES DE VÉRIFICATION AUTOMATISÉES Le système d’information vérifie automatiquement les opérations de création, de modification, d’activation, de désactivation et de retrait des comptes, et avise les gestionnaires responsables. Contrôles connexes : AU-2, AU-12.
A9: Supplemental Guidance | D9: Directives supplémentaires
A10: Test Case | D10: Cas de test
A11: Test | B11: TEST-AC-2(4) | D11: Test | E11: TEST-AC-2(4)
A12: Requirement ID | B12: AC-2(4) | D12: ID Exigence | E12: AC-2(4)
A13: Component | D13: Composant
A14: Requirement | D14: Exigence
A15: Contextual Design Description | D15: Description contextuelle du design
A16: Evidence Provided | D16: Preuve fournie
A17: Preparer Sign Off (Initials, Date) | D17: Signataire préparateur (Initiales, Date)
A18: Owner Sign Off (Initials, Date) | D18: Signataire propriétaire (Initiales, Date)
A19: Assessor Sign Off (Initials, Date) | D19: Signataire évaluateur (Initiales, Date)
A20: Status | B20: Not Started | D20: Statut | E20: Non commencé
A21: Comments | D21: Commentaires

Sheet AC-2-5
A1: Control AC-2(5) — Evidence Tracking | D1: Contrôle AC-2(5) — Suivi des preuves
A2: Control Information | D2: Informations du contrôle
A3: Control Identifier | B3: AC-2(5) | D3: Identifiant du contrôle | E3: AC-2(5)
A4: Family | B4: Account Management | D4: Famille | E4: Gestion des comptes
A5: Profile | B5: CCCS Medium / PBMM Moderate | D5: Profil | E5: CCCS Moyen / PBMM Modéré
A6: Primary Evidence Tool | D6: Outil de preuve principal
A7: Contributing Tools | D7: Outils contributeurs
A8: Control Description | B8: ACCOUNT MANAGEMENT | INACTIVITY LOGOUT The organization requires that users log out at the end of the users’ standard work period unless otherwise defined in formal organizational policy. Related controls: SC-23 | D8: Description du contrôle | E8: GESTION DES COMPTES | FERMETURE DE SESSION INACTIVE L’organisation exige que les utilisateurs ferment leur session à la fin de leur période de travail normale, à moins d’indication contraire dans la politique officielle de l’organisation. Contrôles connexes : SC-23
A9: Supplemental Guidance | D9: Directives supplémentaires
A10: Test Case | D10: Cas de test
A11: Test | B11: TEST-AC-2(5) | D11: Test | E11: TEST-AC-2(5)
A12: Requirement ID | B12: AC-2(5) | D12: ID Exigence | E12: AC-2(5)
A13: Component | D13: Composant
A14: Requirement | D14: Exigence
A15: Contextual Design Description | D15: Description contextuelle du design
A16: Evidence Provided | D16: Preuve fournie
A17: Preparer Sign Off (Initials, Date) | D17: Signataire préparateur (Initiales, Date)
A18: Owner Sign Off (Initials, Date) | D18: Signataire propriétaire (Initiales, Date)
A19: Assessor Sign Off (Initials, Date) | D19: Signataire évaluateur (Initiales, Date)
A20: Status | B20: Not Started | D20: Statut | E20: Non commencé
A21: Comments | D21: Commentaires

Sheet AC-2-7
A1: Control AC-2(7) — Evidence Tracking | D1: Contrôle AC-2(7) — Suivi des preuves
A2: Control Information | D2: Informations du contrôle
A3: Control Identifier | B3: AC-2(7) | D3: Identifiant du contrôle | E3: AC-2(7)
A4: Family | B4: Account Management | D4: Famille | E4: Gestion des comptes
A5: Profile | B5: CCCS Medium / PBMM Moderate | D5: Profil | E5: CCCS Moyen / PBMM Modéré
A6: Primary Evidence Tool | D6: Outil de preuve principal
A7: Contributing Tools | D7: Outils contributeurs
A8: Control Description | B8: ACCOUNT MANAGEMENT | ROLE-BASED SCHEMES (a) The organization establishes and administers privileged user accounts in accordance with a role-based access scheme that organizes allowed information system access and privileges into roles; (b) The organization monitors privileged role assignments; and (c) The organization disables (or revokes) privileged user assignments within 24 hours or sooner when privileged role assignments are no longer appropriate. | D8: Description du contrôle | E8: GESTION DES COMPTES | SCHÉMAS FONDÉS SUR LES RÔLES (a) L’organisation établit et administre les comptes d’utilisateurs privilégiés conformément à un système d’accès basé sur les rôles qui organise les autorisations d’accès au système d’information et les privilèges en fonction des rôles; (b) L’organisation surveille les affectations de rôles privilégiés; (c) L’organisation désactive (ou révoque) les affectations d’utilisateurs privilégiés dans les 24 heures ou plus lorsque les affectations de rôles privilégiés ne sont plus appropriées.
A9: Supplemental Guidance | B9: Privileged roles are organization-defined roles assigned to individuals that allow those individuals to perform certain security-relevant functions that ordinary users are not authorized to perform. These privileged roles include, for example, key management, account management, network and system administration, database administration, and web administration. | D9: Directives supplémentaires | E9: Les rôles privilégiés sont des rôles définis par l’organisation et attribués à des personnes pour leur permettre d’exécuter certaines fonctions ayant une influence sur la sécurité que les utilisateurs ordinaires ne sont pas autorisés à exécuter. Ces rôles privilégiés comprennent, par exemple, la gestion des clés, la gestion des comptes, l’administration des réseaux et des systèmes, l’administration des bases de données et l’administration Web.
A10: Test Case | D10: Cas de test
A11: Test | B11: TEST-AC-2(7) | D11: Test | E11: TEST-AC-2(7)
A12: Requirement ID | B12: AC-2(7) | D12: ID Exigence | E12: AC-2(7)
A13: Component | D13: Composant
A14: Requirement | D14: Exigence
A15: Contextual Design Description | D15: Description contextuelle du design
A16: Evidence Provided | D16: Preuve fournie
A17: Preparer Sign Off (Initials, Date) | D17: Signataire préparateur (Initiales, Date)
A18: Owner Sign Off (Initials, Date) | D18: Signataire propriétaire (Initiales, Date)
A19: Assessor Sign Off (Initials, Date) | D19: Signataire évaluateur (Initiales, Date)
A20: Status | B20: Not Started | D20: Statut | E20: Non commencé
A21: Comments | D21: Commentaires

Sheet AC-3
A1: Control AC-3 — Evidence Tracking | D1: Contrôle AC-3 — Suivi des preuves
A2: Control Information | D2: Informations du contrôle
A3: Control Identifier | B3: AC-3 | D3: Identifiant du contrôle | E3: AC-3
A4: Family | B4: Access Enforcement | D4: Famille | E4: Application des contrôles d’accès
A5: Profile | B5: CCCS Medium / PBMM Moderate | D5: Profil | E5: CCCS Moyen / PBMM Modéré
A6: Primary Evidence Tool | D6: Outil de preuve principal
A7: Contributing Tools | D7: Outils contributeurs
A8: Control Description | B8: (A) The information system enforces approved authorizations for logical access to information and system resources in accordance with applicable access control policies. | D8: Description du contrôle | E8: (A) Le système d’information applique les autorisations approuvées pour l’accès logique à l’information et aux ressources du système conformément aux politiques de contrôle d’accès applicables.
A9: Supplemental Guidance | B9: Access control policies (e.g., identity-based policies, role-based policies, attribute-based policies) and access enforcement mechanisms (e.g.: access control lists, access control matrices, cryptography) control access between active entities or subjects (i.e., users or processes acting on behalf of users) and passive entities or objects (e.g., devices, files, records, domains) in information systems. In addition to enforcing authorized access at the information system level and recognizing that information systems can host many applications and services in support of organizational missions and business operations, access enforcement mechanisms can also be employed at the application and service level to provide increased information security. Related controls: AC-2, AC-4, AC-5, AC-6, AC-16, AC-17, AC-18, AC-19, AC-20, AC-21, AC-22, AU-9, CM-5, CM-6, CM-11, MA-3, MA-4, MA-5, PE-3 | D9: Directives supplémentaires | E9: Les politiques de contrôle d’accès (p. ex., politiques fondées sur l’identité, politiques fondées sur les rôles, politiques fondées sur les attributs) et les mécanismes d’application des contrôles d’accès (p. ex., listes de contrôle d’accès, matrices de contrôle d’accès, cryptographie) contrôlent l’accès entre les entités ou les sujets actifs (c.-à-d. les utilisateurs ou les processus agissant pour le compte des utilisateurs) et les entités ou objets passifs (p. ex., dispositifs, fichiers, enregistrements, domaines) dans les systèmes d’information. En plus d’appliquer l’accès autorisé au niveau du système d’information et de reconnaître que les systèmes d’information peuvent héberger de nombreuses applications et services appuyant les missions et les activités opérationnelles de l’organisation, les mécanismes d’application des contrôles d’accès peuvent également être utilisés au niveau des applications et des services pour accroître la sécurité de l’information. Contrôles connexes : AC-2, AC-4, AC-5, AC-6, AC-16, AC-17, AC-18, AC-19, AC-20, AC-21, AC-22, AU-9, CM-5, CM-6, CM-11, MA-3, MA-4, MA-5, PE-3
A10: Test Case | D10: Cas de test
A11: Test | B11: TEST-AC-3 | D11: Test | E11: TEST-AC-3
A12: Requirement ID | B12: AC-3 | D12: ID Exigence | E12: AC-3
A13: Component | D13: Composant
A14: Requirement | D14: Exigence
A15: Contextual Design Description | D15: Description contextuelle du design
A16: Evidence Provided | D16: Preuve fournie
A17: Preparer Sign Off (Initials, Date) | D17: Signataire préparateur (Initiales, Date)
A18: Owner Sign Off (Initials, Date) | D18: Signataire propriétaire (Initiales, Date)
A19: Assessor Sign Off (Initials, Date) | D19: Signataire évaluateur (Initiales, Date)
A20: Status | B20: Not Started | D20: Statut | E20: Non commencé
A21: Comments | D21: Commentaires

Sheet AC-6
A1: Control AC-6 — Evidence Tracking | D1: Contrôle AC-6 — Suivi des preuves
A2: Control Information | D2: Informations du contrôle
A3: Control Identifier | B3: AC-6 | D3: Identifiant du contrôle | E3: AC-6
A4: Family | B4: Least Privilege | D4: Famille | E4: Moindre privilège
A5: Profile | B5: CCCS Medium / PBMM Moderate | D5: Profil | E5: CCCS Moyen / PBMM Modéré
A6: Primary Evidence Tool | D6: Outil de preuve principal
A7: Contributing Tools | D7: Outils contributeurs
A8: Control Description | B8: (A) The organization employs the principle of least privilege, allowing only authorized accesses for users (or processes acting on behalf of users) which are necessary to accomplish assigned tasks in accordance with organizational missions and business functions. | D8: Description du contrôle | E8: (A) L’organisation utilise le principe du moindre privilège, qui permet seulement les accès autorisés aux utilisateurs (ou aux processus qui agissent pour le compte des utilisateurs) qui sont nécessaires pour accomplir les tâches assignées conformément aux missions et aux fonctions opérationnelles de l’organisation.
A9: Supplemental Guidance | B9: Organizations employ least privilege for specific duties and information systems. The principle of least privilege is also applied to information system processes, ensuring that the processes operate at privilege levels no higher than necessary to accomplish required organizational missions/business functions. Organizations consider the creation of additional processes, roles, and information system accounts as necessary, to achieve least privilege. Organizations also apply least privilege to the development, implementation, and operation of organizational information systems. Related controls: AC-2, AC-3, AC-5, CM-6, CM-7, PL-2 | D9: Directives supplémentaires | E9: Les organisations utilisent le moindre privilège pour certaines tâches et certains systèmes d’information. Le principe du moindre privilège s’applique également aux processus du système d’information, ce qui fait en sorte que les processus ne fonctionnent pas à des niveaux de privilège plus élevés que nécessaire pour accomplir les missions et les fonctions opérationnelles requises de l’organisation. Les organisations envisagent la création de processus, de rôles et de comptes de système d’information supplémentaires lorsque nécessaire, pour obtenir le moindre privilège. Les organisations appliquent également le moindre privilège au développement, à la mise en œuvre et à l’exploitation de leurs systèmes d’information. Contrôles connexes : AC-2, AC-3, AC-5, CM-6, CM-7, PL-2
A10: Test Case | D10: Cas de test
A11: Test | B11: TEST-AC-6 | D11: Test | E11: TEST-AC-6
A12: Requirement ID | B12: AC-6 | D12: ID Exigence | E12: AC-6
A13: Component | D13: Composant
A14: Requirement | D14: Exigence
A15: Contextual Design Description | D15: Description contextuelle du design
A16: Evidence Provided | D16: Preuve fournie
A17: Preparer Sign Off (Initials, Date) | D17: Signataire préparateur (Initiales, Date)
A18: Owner Sign Off (Initials, Date) | D18: Signataire propriétaire (Initiales, Date)
A19: Assessor Sign Off (Initials, Date) | D19: Signataire évaluateur (Initiales, Date)
A20: Status | B20: Not Started | D20: Statut | E20: Non commencé
A21: Comments | D21: Commentaires

Sheet AC-6-1
A1: Control AC-6(1) — Evidence Tracking | D1: Contrôle AC-6(1) — Suivi des preuves
A2: Control Information | D2: Informations du contrôle
A3: Control Identifier | B3: AC-6(1) | D3: Identifiant du contrôle | E3: AC-6(1)
A4: Family | B4: Least Privilege | D4: Famille | E4: Moindre privilège
A5: Profile | B5: CCCS Medium / PBMM Moderate | D5: Profil | E5: CCCS Moyen / PBMM Modéré
A6: Primary Evidence Tool | D6: Outil de preuve principal
A7: Contributing Tools | D7: Outils contributeurs
A8: Control Description | B8: LEAST PRIVILEGE | AUTHORIZE ACCESS TO SECURITY FUNCTIONS The organization explicitly authorizes access to all security functions not publicly accessible and all security-relevant information not publicly available. | D8: Description du contrôle | E8: MOINDRE PRIVILÈGE | AUTORISATION D’ACCÈS AUX FONCTIONS DE SÉCURITÉ L’organisation autorise explicitement l’accès à toutes les fonctions de sécurité qui ne sont pas accessibles au public et à toute l’information pertinente à la sécurité qui n’est pas accessible au public.
A9: Supplemental Guidance | B9: Security functions include, for example, establishing system accounts, configuring access authorizations (i.e., permissions, privileges), setting events to be audited, and setting intrusion detection parameters. Security-relevant information includes, for example, filtering rules for routers/firewalls, cryptographic key management information, configuration parameters for security services, and access control lists. Explicitly authorized personnel include, for example, security administrators, system and network administrators, system security officers, system maintenance personnel, system programmers, and other privileged users. Related controls: AC-17, AC-18, AC-19. | D9: Directives supplémentaires | E9: Les fonctions de sécurité comprennent, par exemple, l’établissement des comptes système, la configuration des autorisations d’accès (c.-à-d. les permissions, les privilèges), le réglage des événements à vérifier, et l’établissement des paramètres de détection des intrusions. Les renseignements pertinents pour la sécurité comprennent, par exemple, les règles de filtrage pour les routeurs/pare-feu, l’information de gestion des clés cryptographiques, les paramètres de configuration pour les services de sécurité et les listes de contrôle d’accès. Le personnel explicitement autorisé comprend, par exemple, les administrateurs de la sécurité, les administrateurs de systèmes et de réseaux, les agents de sécurité des systèmes, le personnel de maintenance des systèmes, les programmeurs de systèmes et d’autres utilisateurs privilégiés. Contrôles connexes : AC-17, AC-18, AC-19.
A10: Test Case | D10: Cas de test
A11: Test | B11: TEST-AC-6(1) | D11: Test | E11: TEST-AC-6(1)
A12: Requirement ID | B12: AC-6(1) | D12: ID Exigence | E12: AC-6(1)
A13: Component | D13: Composant
A14: Requirement | D14: Exigence
A15: Contextual Design Description | D15: Description contextuelle du design
A16: Evidence Provided | D16: Preuve fournie
A17: Preparer Sign Off (Initials, Date) | D17: Signataire préparateur (Initiales, Date)
A18: Owner Sign Off (Initials, Date) | D18: Signataire propriétaire (Initiales, Date)
A19: Assessor Sign Off (Initials, Date) | D19: Signataire évaluateur (Initiales, Date)
A20: Status | B20: Not Started | D20: Statut | E20: Non commencé
A21: Comments | D21: Commentaires

Sheet AC-6-9
A1: Control AC-6(9) — Evidence Tracking | D1: Contrôle AC-6(9) — Suivi des preuves
A2: Control Information | D2: Informations du contrôle
A3: Control Identifier | B3: AC-6(9) | D3: Identifiant du contrôle | E3: AC-6(9)
A4: Family | B4: Least Privilege | D4: Famille | E4: Moindre privilège
A5: Profile | B5: CCCS Medium / PBMM Moderate | D5: Profil | E5: CCCS Moyen / PBMM Modéré
A6: Primary Evidence Tool | D6: Outil de preuve principal
A7: Contributing Tools | D7: Outils contributeurs
A8: Control Description | B8: LEAST PRIVILEGE | AUDITING USE OF PRIVILEGED FUNCTIONS The information system audits the execution of privileged functions. | D8: Description du contrôle | E8: MOINDRE PRIVILÈGE | VÉRIFICATION DE L’UTILISATION DES FONCTIONS PRIVILÉGIÉES Le système d’information vérifie l’exécution des fonctions privilégiées.
A9: Supplemental Guidance | B9: Misuse of privileged functions, either intentionally or unintentionally by authorized users, or by unauthorized external entities that have compromised information system accounts, is a serious and ongoing concern and can have significant adverse impacts on organizations. Auditing the use of privileged functions is one way to detect such misuse, and in doing so, help mitigate the risk from insider threats and the advanced persistent threat (APT). Related control: AU-2. | D9: Directives supplémentaires | E9: L’utilisation abusive des fonctions privilégiées, intentionnellement ou non, par des utilisateurs autorisés ou par des entités externes non autorisées qui ont compromis des comptes de système d’information, est une préoccupation grave et constante qui peut avoir des répercussions négatives importantes sur les organisations. La vérification de l’utilisation des fonctions privilégiées est une façon de détecter un tel abus et, ce faisant, de contribuer à atténuer le risque de menaces internes et de menaces persistantes avancées (MPA). Contrôle connexe : AU-2.
A10: Test Case | D10: Cas de test
A11: Test | B11: TEST-AC-6(9) | D11: Test | E11: TEST-AC-6(9)
A12: Requirement ID | B12: AC-6(9) | D12: ID Exigence | E12: AC-6(9)
A13: Component | D13: Composant
A14: Requirement | D14: Exigence
A15: Contextual Design Description | D15: Description contextuelle du design
A16: Evidence Provided | D16: Preuve fournie
A17: Preparer Sign Off (Initials, Date) | D17: Signataire préparateur (Initiales, Date)
A18: Owner Sign Off (Initials, Date) | D18: Signataire propriétaire (Initiales, Date)
A19: Assessor Sign Off (Initials, Date) | D19: Signataire évaluateur (Initiales, Date)
A20: Status | B20: Not Started | D20: Statut | E20: Non commencé
A21: Comments | D21: Commentaires

Sheet AC-6-10
A1: Control AC-6(10) — Evidence Tracking | D1: Contrôle AC-6(10) — Suivi des preuves
A2: Control Information | D2: Informations du contrôle
A3: Control Identifier | B3: AC-6(10) | D3: Identifiant du contrôle | E3: AC-6(10)
A4: Family | B4: Least Privilege | D4: Famille | E4: Moindre privilège
A5: Profile | B5: CCCS Medium / PBMM Moderate | D5: Profil | E5: CCCS Moyen / PBMM Modéré
A6: Primary Evidence Tool | D6: Outil de preuve principal
A7: Contributing Tools | D7: Outils contributeurs
A8: Control Description | B8: LEAST PRIVILEGE | PROHIBIT NON-PRIVILEGED USERS FROM EXECUTING PRIVILEGED FUNCTIONS The information system prevents non-privileged users from executing privileged functions to include disabling, circumventing, or altering implemented security safeguards/countermeasures. | D8: Description du contrôle | E8: MOINDRE PRIVILÈGE | INTERDICTION AUX UTILISATEURS NON PRIVILÉGIÉS D’EXÉCUTER DES FONCTIONS PRIVILÉGIÉES Le système d’information empêche les utilisateurs non privilégiés d’exécuter des fonctions privilégiées, y compris la désactivation, le contournement ou la modification des mécanismes/contre-mesures de sécurité en place.
A9: Supplemental Guidance | B9: Privileged functions include, for example, establishing information system accounts, performing system integrity checks, or administering cryptographic key management activities. Non-privileged users are individuals that do not possess appropriate authorizations. Circumventing intrusion detection and prevention mechanisms or malicious code protection mechanisms are examples of privileged functions that require protection from non-privileged users. | D9: Directives supplémentaires | E9: Les fonctions privilégiées comprennent, par exemple, l’établissement des comptes du système d’information, l’exécution des vérifications de l’intégrité du système ou l’administration des activités de gestion de clés cryptographiques. Les utilisateurs non privilégiés sont des personnes qui ne possèdent pas les autorisations appropriées. Les contournements de mécanismes de détection et de prévention des intrusions ou de mécanismes de protection contre le code malveillant sont des exemples de fonctions privilégiées qui nécessitent une protection contre les utilisateurs non privilégiés.
A10: Test Case | D10: Cas de test
A11: Test | B11: TEST-AC-6(10) | D11: Test | E11: TEST-AC-6(10)
A12: Requirement ID | B12: AC-6(10) | D12: ID Exigence | E12: AC-6(10)
A13: Component | D13: Composant
A14: Requirement | D14: Exigence
A15: Contextual Design Description | D15: Description contextuelle du design
A16: Evidence Provided | D16: Preuve fournie
A17: Preparer Sign Off (Initials, Date) | D17: Signataire préparateur (Initiales, Date)
A18: Owner Sign Off (Initials, Date) | D18: Signataire propriétaire (Initiales, Date)
A19: Assessor Sign Off (Initials, Date) | D19: Signataire évaluateur (Initiales, Date)
A20: Status | B20: Not Started | D20: Statut | E20: Non commencé
A21: Comments | D21: Commentaires

Sheet AC-7
A1: Control AC-7 — Evidence Tracking | D1: Contrôle AC-7 — Suivi des preuves
A2: Control Information | D2: Informations du contrôle
A3: Control Identifier | B3: AC-7 | D3: Identifiant du contrôle | E3: AC-7
A4: Family | B4: Unsuccessful Login Attempts | D4: Famille | E4: Tentatives infructueuses d’ouverture de session
A5: Profile | B5: CCCS Medium / PBMM Moderate | D5: Profil | E5: CCCS Moyen / PBMM Modéré
A6: Primary Evidence Tool | D6: Outil de preuve principal
A7: Contributing Tools | D7: Outils contributeurs
A8: Control Description | B8: (A) The information system enforces a limit of not more than three consecutive invalid logon attempts by a user during a 15-minute time period. (B) The information system automatically locks the account/node for a minimum of three (3) hours or until unlocked by an administrator. | D8: Description du contrôle | E8: (A) Le système d’information impose une limite de trois tentatives invalides consécutives d’ouverture de session par un utilisateur pendant une période de 15 minutes. (B) Le système d’information verrouille automatiquement le compte ou le nœud pendant au moins trois (3) heures ou jusqu’à ce qu’un administrateur le déverrouille.
A9: Supplemental Guidance | B9: Due to the potential for denial of service, automatic lockouts initiated by the information system are usually temporary and automatically release after a predetermined time period established by the organization. If a delay algorithm is selected, the organization may choose to employ different algorithms for different information system components based on the capabilities of those components. Response to unsuccessful login attempts may be implemented at both the operating system and the application levels. This control applies to all accesses other than those accesses explicitly identified and documented by the organization in AC-14. This security control/enhancement requires careful balance between usability and security. Care needs to be taken to ensure that the appropriate balance between the two seemingly conflicting requirements is achieved. If possible, an increasing time-out period should be used to deter determined attackers. For example, an original time-out of 5 minutes can become 10 minutes after the next 3 unsuccessful attempts, then 20 minutes, then 40 minutes, etc. | D9: Directives supplémentaires | E9: En raison de la possibilité de refus de service, les verrouillages automatiques déclenchés par le système d’information sont habituellement temporaires et automatiquement annulés après une période prédéterminée établie par l’organisation. Si un algorithme d’attente est sélectionné, l’organisation peut choisir d’utiliser différents algorithmes pour différents composants du système d’information en fonction des capacités de ces composants. La réponse aux tentatives d’ouverture de session infructueuses peut être mise en œuvre à la fois au niveau du système d’exploitation et de l’application. Ce contrôle s’applique à tous les accès autres que ceux explicitement identifiés et documentés par l’organisation dans AC-14. Ce contrôle ou cette amélioration de sécurité exige un équilibre prudent entre la facilité d’utilisation et la sécurité. Il faut veiller à assurer l’équilibre approprié entre ces deux exigences apparemment contradictoires. Dans la mesure du possible, une période de temporisation plus longue devrait être utilisée pour dissuader les attaquants déterminés. Par exemple, une temporisation initiale de 5 minutes peut devenir 10 minutes après les 3 tentatives infructueuses suivantes, puis 20 minutes, puis 40 minutes, etc.
A10: Test Case | D10: Cas de test
A11: Test | B11: TEST-AC-7 | D11: Test | E11: TEST-AC-7
A12: Requirement ID | B12: AC-7 | D12: ID Exigence | E12: AC-7
A13: Component | D13: Composant
A14: Requirement | D14: Exigence
A15: Contextual Design Description | D15: Description contextuelle du design
A16: Evidence Provided | D16: Preuve fournie
A17: Preparer Sign Off (Initials, Date) | D17: Signataire préparateur (Initiales, Date)
A18: Owner Sign Off (Initials, Date) | D18: Signataire propriétaire (Initiales, Date)
A19: Assessor Sign Off (Initials, Date) | D19: Signataire évaluateur (Initiales, Date)
A20: Status | B20: Not Started | D20: Statut | E20: Non commencé
A21: Comments | D21: Commentaires

Sheet AC-10
A1: Control AC-10 — Evidence Tracking | D1: Contrôle AC-10 — Suivi des preuves
A2: Control Information | D2: Informations du contrôle
A3: Control Identifier | B3: AC-10 | D3: Identifiant du contrôle | E3: AC-10
A4: Family | B4: Concurrent Session Control | D4: Famille | E4: Contrôle des sessions simultanées
A5: Profile | B5: CCCS Medium / PBMM Moderate | D5: Profil | E5: CCCS Moyen / PBMM Modéré
A6: Primary Evidence Tool | D6: Outil de preuve principal
A7: Contributing Tools | D7: Outils contributeurs
A8: Control Description | B8: (A) The information system limits the number of concurrent sessions for all accounts unless justified for operation requirements to 3 sessions for privileged access and 2 sessions for non-privileged access. | D8: Description du contrôle | E8: (A) Le système d’information limite le nombre de sessions simultanées pour tous les comptes, à moins qu’elles ne soient justifiées par les exigences opérationnelles, à trois sessions pour l’accès privilégié et à deux sessions pour l’accès non privilégié.
A9: Supplemental Guidance | B9: Organizations may define the maximum number of concurrent sessions for information system accounts globally, by account type (e.g., privileged user, non-privileged user, domain, specific application), by account, or a combination. For example, organizations may limit the number of concurrent sessions for system administrators or individuals working in particularly sensitive domains or mission-critical applications. This control addresses concurrent sessions for information system accounts and does not address concurrent sessions by single users via multiple system accounts | D9: Directives supplémentaires | E9: Les organisations peuvent définir globalement le nombre maximal de sessions simultanées pour les comptes du système d’information, par type de compte (p. ex., utilisateur privilégié, utilisateur non privilégié, domaine, application particulière), par compte ou par une combinaison de ces deux critères. Par exemple, les organisations peuvent limiter le nombre de sessions simultanées pour les administrateurs de système ou les personnes qui travaillent dans des domaines particulièrement sensibles ou des applications essentielles à la mission. Ce contrôle porte sur les sessions simultanées pour des comptes du système d’information et ne traite pas des sessions simultanées par des utilisateurs uniques utilisant plusieurs comptes du système.
A10: Test Case | D10: Cas de test
A11: Test | B11: TEST-AC-10 | D11: Test | E11: TEST-AC-10
A12: Requirement ID | B12: AC-10 | D12: ID Exigence | E12: AC-10
A13: Component | D13: Composant
A14: Requirement | D14: Exigence
A15: Contextual Design Description | D15: Description contextuelle du design
A16: Evidence Provided | D16: Preuve fournie
A17: Preparer Sign Off (Initials, Date) | D17: Signataire préparateur (Initiales, Date)
A18: Owner Sign Off (Initials, Date) | D18: Signataire propriétaire (Initiales, Date)
A19: Assessor Sign Off (Initials, Date) | D19: Signataire évaluateur (Initiales, Date)
A20: Status | B20: Not Started | D20: Statut | E20: Non commencé
A21: Comments | D21: Commentaires

Sheet AC-11
A1: Control AC-11 — Evidence Tracking | D1: Contrôle AC-11 — Suivi des preuves
A2: Control Information | D2: Informations du contrôle
A3: Control Identifier | B3: AC-11 | D3: Identifiant du contrôle | E3: AC-11
A4: Family | B4: Session Lock | D4: Famille | E4: Verrouillage de session
A5: Profile | B5: CCCS Medium / PBMM Moderate | D5: Profil | E5: CCCS Moyen / PBMM Modéré
A6: Primary Evidence Tool | D6: Outil de preuve principal
A7: Contributing Tools | D7: Outils contributeurs
A8: Control Description | B8: (A) The information system prevents further access to the system by initiating a session lock after 15 minutes of inactivity or upon receiving a request from a user. (B) The information system retains the session lock until the user re-establishes access using established identification and authentication procedures. | D8: Description du contrôle | E8: (A) Le système d’information empêche tout accès supplémentaire au système en amorçant un verrouillage de session après 15 minutes d’inactivité ou après en avoir reçu la demande de la part d’un utilisateur. (B) Le système d’information maintient le verrouillage de session jusqu’à ce que l’utilisateur rétablisse l’accès en utilisant les procédures d’identification et d’authentification établies.
A9: Supplemental Guidance | B9: Session locks are temporary actions taken when users stop work and move away from the immediate vicinity of information systems but do not want to log out because of the temporary nature of their absences. Session locks are implemented where session activities can be determined. This is typically at the operating system level, but can also be at the application level. Session locks are not an acceptable substitute for logging out of information systems, for example, if organizations require users to log out at the end of workdays. Related control: AC-7 | D9: Directives supplémentaires | E9: Les verrouillages de session sont des mesures temporaires prises lorsque les utilisateurs arrêtent de travailler et s’éloignent du voisinage immédiat des systèmes d’information, mais ne veulent pas fermer leur session en raison de la nature temporaire de leur absence. Les verrouillages de session sont mis en œuvre là où les activités de session peuvent être déterminées. C’est habituellement au niveau du système d’exploitation, mais cela peut aussi être au niveau de l’application. Les verrouillages de session ne constituent pas un substitut acceptable à la déconnexion des systèmes d’information, par exemple, si les organisations demandent aux utilisateurs de fermer leur session à la fin des journées de travail. Contrôle connexe : AC-7
A10: Test Case | D10: Cas de test
A11: Test | B11: TEST-AC-11 | D11: Test | E11: TEST-AC-11
A12: Requirement ID | B12: AC-11 | D12: ID Exigence | E12: AC-11
A13: Component | D13: Composant
A14: Requirement | D14: Exigence
A15: Contextual Design Description | D15: Description contextuelle du design
A16: Evidence Provided | D16: Preuve fournie
A17: Preparer Sign Off (Initials, Date) | D17: Signataire préparateur (Initiales, Date)
A18: Owner Sign Off (Initials, Date) | D18: Signataire propriétaire (Initiales, Date)
A19: Assessor Sign Off (Initials, Date) | D19: Signataire évaluateur (Initiales, Date)
A20: Status | B20: Not Started | D20: Statut | E20: Non commencé
A21: Comments | D21: Commentaires

Sheet AC-17-1
A1: Control AC-17(1) — Evidence Tracking | D1: Contrôle AC-17(1) — Suivi des preuves
A2: Control Information | D2: Informations du contrôle
A3: Control Identifier | B3: AC-17(1) | D3: Identifiant du contrôle | E3: AC-17(1)
A4: Family | B4: Remote Access | D4: Famille | E4: Accès à distance
A5: Profile | B5: CCCS Medium / PBMM Moderate | D5: Profil | E5: CCCS Moyen / PBMM Modéré
A6: Primary Evidence Tool | D6: Outil de preuve principal
A7: Contributing Tools | D7: Outils contributeurs
A8: Control Description | B8: REMOTE ACCESS | AUTOMATED MONITORING / CONTROL The information system monitors and controls remote access methods. | D8: Description du contrôle | E8: ACCÈS À DISTANCE | SURVEILLANCE ET CONTRÔLE AUTOMATISÉS Le système d’information surveille et contrôle les méthodes d’accès à distance.
A9: Supplemental Guidance | B9: Automated monitoring and control of remote access sessions allows organizations to detect cyber-attacks and also ensure ongoing compliance with remote access policies by auditing connection activities of remote users on a variety of information system components (e.g., servers, workstations, notebook computers, smart phones, and tablets). Related controls: AU-2, AU-12. | D9: Directives supplémentaires | E9: La surveillance et le contrôle automatisés des sessions avec accès à distance permettent aux organisations de détecter les cyberattaques et d’assurer la conformité continue aux politiques d’accès à distance en vérifiant les activités de connexion des utilisateurs distants sur une variété de composants du système d’information (p. ex., serveurs, postes de travail, ordinateurs portatifs, téléphones intelligents et tablettes). Contrôles connexes : AU-2, AU-12.
A10: Test Case | D10: Cas de test
