Workbook

Sheet DASHBOARD
A1: DASHBOARD — PBMM Evidence: Networking
A2: Control ID | B2: Control Name | C2: Primary Tool | D2: Tab | E2: Status
A3: AC-4 | B3: Information Flow Enforcement | D3: AC-4 | E3: ='AC-4'!B20 -> Not Started
A4: AC-4(21) | B4: Information Flow Enforcement | D4: AC-4-21 | E4: ='AC-4-21'!B20 -> Not Started
A5: AC-17(1) | B5: Remote Access | D5: AC-17-1 | E5: ='AC-17-1'!B20 -> Not Started
A6: AC-17(2) | B6: Remote Access | D6: AC-17-2 | E6: ='AC-17-2'!B20 -> Not Started
A7: AC-17(3) | B7: Remote Access | D7: AC-17-3 | E7: ='AC-17-3'!B20 -> Not Started
A8: AC-17(9) | B8: Remote Access | D8: AC-17-9 | E8: ='AC-17-9'!B20 -> Not Started
A9: AC-17(100) | B9: Remote Access | D9: AC-17-100 | E9: ='AC-17-100'!B20 -> Not Started
A10: AU-2 | B10: Auditable Events | D10: AU-2 | E10: ='AU-2'!B20 -> Not Started
A11: AU-3 | B11: Content of Audit Records | D11: AU-3 | E11: ='AU-3'!B20 -> Not Started
A12: AU-3(1) | B12: Content of Audit Records | D12: AU-3-1 | E12: ='AU-3-1'!B20 -> Not Started
A13: AU-9(2) | B13: Protection of Audit Information | D13: AU-9-2 | E13: ='AU-9-2'!B20 -> Not Started
A14: AU-12 | B14: Audit Generation | D14: AU-12 | E14: ='AU-12'!B20 -> Not Started
A15: CA-3(5) | B15: Information System Connections | D15: CA-3-5 | E15: ='CA-3-5'!B20 -> Not Started
A16: CA-9 | B16: Internal System Connections | D16: CA-9 | E16: ='CA-9'!B20 -> Not Started
A17: CM-6 | B17: Configuration Settings | D17: CM-6 | E17: ='CM-6'!B20 -> Not Started
A18: CM-7 | B18: Least Functionality | D18: CM-7 | E18: ='CM-7'!B20 -> Not Started
A19: CM-7(1) | B19: Least Functionality | D19: CM-7-1 | E19: ='CM-7-1'!B20 -> Not Started
A20: CM-10 | B20: Software Usage Restrictions | D20: CM-10 | E20: ='CM-10'!B20 -> Not Started
A21: CP-7 | B21: Alternate Processing Site | D21: CP-7 | E21: ='CP-7'!B20 -> Not Started
A22: CP-7(4) | B22: Alternate Processing Site | D22: CP-7-4 | E22: ='CP-7-4'!B20 -> Not Started
A23: CP-10 | B23: Information System Recovery and Reconstitution | D23: CP-10 | E23: ='CP-10'!B20 -> Not Started
A24: CP-10(4) | B24: Information System Recovery and Reconstitution | D24: CP-10-4 | E24: ='CP-10-4'!B20 -> Not Started
A25: IA-3 | B25: Device Identification and Authentication | D25: IA-3 | E25: ='IA-3'!B20 -> Not Started
A26: MA-4(6) | B26: Non-Local Maintenance | D26: MA-4-6 | E26: ='MA-4-6'!B20 -> Not Started
A27: SA-9(5) | B27: External Information System Services | D27: SA-9-5 | E27: ='SA-9-5'!B20 -> Not Started
A28: SC-2 | B28: Application Partitioning | D28: SC-2 | E28: ='SC-2'!B20 -> Not Started
A29: SC-4 | B29: Information in Shared Resources | D29: SC-4 | E29: ='SC-4'!B20 -> Not Started
A30: SC-5 | B30: Denial of Service Protection | D30: SC-5 | E30: ='SC-5'!B20 -> Not Started
A31: SC-7 | B31: Boundary Protection | D31: SC-7 | E31: ='SC-7'!B20 -> Not Started
A32: SC-7(3) | B32: Boundary Protection | D32: SC-7-3 | E32: ='SC-7-3'!B20 -> Not Started
A33: SC-7(4) | B33: Boundary Protection | D33: SC-7-4 | E33: ='SC-7-4'!B20 -> Not Started
A34: SC-7(5) | B34: Boundary Protection | D34: SC-7-5 | E34: ='SC-7-5'!B20 -> Not Started
A35: SC-7(8) | B35: Boundary Protection | D35: SC-7-8 | E35: ='SC-7-8'!B20 -> Not Started
A36: SC-7(13) | B36: Boundary Protection | D36: SC-7-13 | E36: ='SC-7-13'!B20 -> Not Started
A37: SC-7(18) | B37: Boundary Protection | D37: SC-7-18 | E37: ='SC-7-18'!B20 -> Not Started
A38: SC-8 | B38: Transmission Confidentiality and Integrity | D38: SC-8 | E38: ='SC-8'!B20 -> Not Started
A39: SC-8(1) | B39: Transmission Confidentiality and Integrity | D39: SC-8-1 | E39: ='SC-8-1'!B20 -> Not Started
A40: SC-10 | B40: Network Disconnect | D40: SC-10 | E40: ='SC-10'!B20 -> Not Started
...

Sheet TABLEAU_DE_BORD
A1: TABLEAU DE BORD — Suivi PBMM : Networking
A2: ID Contrôle | B2: Nom du contrôle | C2: Outil principal | D2: Onglet | E2: Statut
A3: AC-4 | B3: Application des contrôles du flux d’information | D3: AC-4 | E3: ='AC-4'!E20 -> Non commencé
A4: AC-4(21) | B4: Application des contrôles du flux d’information | D4: AC-4-21 | E4: ='AC-4-21'!E20 -> Non commencé
A5: AC-17(1) | B5: Accès à distance | D5: AC-17-1 | E5: ='AC-17-1'!E20 -> Non commencé
A6: AC-17(2) | B6: Accès à distance | D6: AC-17-2 | E6: ='AC-17-2'!E20 -> Non commencé
A7: AC-17(3) | B7: Accès à distance | D7: AC-17-3 | E7: ='AC-17-3'!E20 -> Non commencé
A8: AC-17(9) | B8: Accès à distance | D8: AC-17-9 | E8: ='AC-17-9'!E20 -> Non commencé
A9: AC-17(100) | B9: Accès à distance | D9: AC-17-100 | E9: ='AC-17-100'!E20 -> Non commencé
A10: AU-2 | B10: Événements vérifiables | D10: AU-2 | E10: ='AU-2'!E20 -> Non commencé
A11: AU-3 | B11: Contenu des enregistrements de vérification | D11: AU-3 | E11: ='AU-3'!E20 -> Non commencé
A12: AU-3(1) | B12: Contenu des enregistrements de vérification | D12: AU-3-1 | E12: ='AU-3-1'!E20 -> Non commencé
A13: AU-9(2) | B13: Protection des renseignements de vérification | D13: AU-9-2 | E13: ='AU-9-2'!E20 -> Non commencé
A14: AU-12 | B14: Génération des vérifications | D14: AU-12 | E14: ='AU-12'!E20 -> Non commencé
A15: CA-3(5) | B15: Connexions aux systèmes d’information | D15: CA-3-5 | E15: ='CA-3-5'!E20 -> Non commencé
A16: CA-9 | B16: Connexions internes au système | D16: CA-9 | E16: ='CA-9'!E20 -> Non commencé
A17: CM-6 | B17: Paramètres de configuration | D17: CM-6 | E17: ='CM-6'!E20 -> Non commencé
A18: CM-7 | B18: Moindre fonctionnalité | D18: CM-7 | E18: ='CM-7'!E20 -> Non commencé
A19: CM-7(1) | B19: Moindre fonctionnalité | D19: CM-7-1 | E19: ='CM-7-1'!E20 -> Non commencé
A20: CM-10 | B20: Restrictions d’utilisation des logiciels | D20: CM-10 | E20: ='CM-10'!E20 -> Non commencé
A21: CP-7 | B21: Site de traitement auxiliaire | D21: CP-7 | E21: ='CP-7'!E20 -> Non commencé
A22: CP-7(4) | B22: Site de traitement auxiliaire | D22: CP-7-4 | E22: ='CP-7-4'!E20 -> Non commencé
A23: CP-10 | B23: Reprise et reconstitution du système d’information | D23: CP-10 | E23: ='CP-10'!E20 -> Non commencé
A24: CP-10(4) | B24: Reprise et reconstitution du système d’information | D24: CP-10-4 | E24: ='CP-10-4'!E20 -> Non commencé
A25: IA-3 | B25: Identification et authentification des dispositifs | D25: IA-3 | E25: ='IA-3'!E20 -> Non commencé
A26: MA-4(6) | B26: Maintenance non locale | D26: MA-4-6 | E26: ='MA-4-6'!E20 -> Non commencé
A27: SA-9(5) | B27: Services de systèmes d’information externes | D27: SA-9-5 | E27: ='SA-9-5'!E20 -> Non commencé
A28: SC-2 | B28: Partitionnement des applications | D28: SC-2 | E28: ='SC-2'!E20 -> Non commencé
A29: SC-4 | B29: Information dans les ressources partagées | D29: SC-4 | E29: ='SC-4'!E20 -> Non commencé
A30: SC-5 | B30: Protection contre le déni de service | D30: SC-5 | E30: ='SC-5'!E20 -> Non commencé
A31: SC-7 | B31: Protection des frontières | D31: SC-7 | E31: ='SC-7'!E20 -> Non commencé
A32: SC-7(3) | B32: Protection des frontières | D32: SC-7-3 | E32: ='SC-7-3'!E20 -> Non commencé
A33: SC-7(4) | B33: Protection des frontières | D33: SC-7-4 | E33: ='SC-7-4'!E20 -> Non commencé
A34: SC-7(5) | B34: Protection des frontières | D34: SC-7-5 | E34: ='SC-7-5'!E20 -> Non commencé
A35: SC-7(8) | B35: Protection des frontières | D35: SC-7-8 | E35: ='SC-7-8'!E20 -> Non commencé
A36: SC-7(13) | B36: Protection des frontières | D36: SC-7-13 | E36: ='SC-7-13'!E20 -> Non commencé
A37: SC-7(18) | B37: Protection des frontières | D37: SC-7-18 | E37: ='SC-7-18'!E20 -> Non commencé
A38: SC-8 | B38: Confidentialité et intégrité des transmissions | D38: SC-8 | E38: ='SC-8'!E20 -> Non commencé
A39: SC-8(1) | B39: Confidentialité et intégrité des transmissions | D39: SC-8-1 | E39: ='SC-8-1'!E20 -> Non commencé
A40: SC-10 | B40: Débranchement du réseau | D40: SC-10 | E40: ='SC-10'!E20 -> Non commencé
...

Sheet AC-4
A1: Control AC-4 — Evidence Tracking | D1: Contrôle AC-4 — Suivi des preuves
A2: Control Information | D2: Informations du contrôle
A3: Control Identifier | B3: AC-4 | D3: Identifiant du contrôle | E3: AC-4
A4: Family | B4: Information Flow Enforcement | D4: Famille | E4: Application des contrôles du flux d’information
A5: Profile | B5: CCCS Medium / PBMM Moderate | D5: Profil | E5: CCCS Moyen / PBMM Modéré
A6: Primary Evidence Tool | D6: Outil de preuve principal
A7: Contributing Tools | D7: Outils contributeurs
A8: Control Description | B8: (A) The information system enforces approved authorizations for controlling the flow of information within the system and between interconnected systems based on deny all, approve by exception information flow policies. | D8: Description du contrôle | E8: (A) Le système d’information applique les autorisations approuvées pour contrôler le flux d’information à l’intérieur du système et entre les systèmes interconnectés en fonction des politiques « Refuser tous, approuver par exception » concernant les flux d’information.
A9: Supplemental Guidance | B9: Information flow control regulates where information is allowed to travel within an information system and between information systems (as opposed to who is allowed to access the information) and without explicit regard to subsequent accesses to that information. Flow control restrictions include, for example, keeping export-controlled information from being transmitted in the clear to the Internet, blocking outside traffic that claims to be from within the organization, restricting web requests to the Internet that are not from the internal web proxy server, and limiting information transfers between organizations based on data structures and content. Transferring information between information systems representing different security domains with different security policies introduces risk that such transfers violate one or more domain security policies. In such situations, information owners/stewards provide guidance at designated policy enforcement points between interconnected systems. Organizations should consider mandating specific architectural solutions when required to enforce specific security policies. Enforcement includes, for example: (i) prohibiting information transfers between interconnected systems (i.e., allowing access only); (ii) employing hardware mechanisms to enforce one-way information flows; and (iii) implementing trustworthy re-grading mechanisms to reassign security attributes and security labels. Organizations commonly employ information flow control policies and enforcement mechanisms to control the flow of information between designated sources and destinations (e.g., networks, individuals, and devices) within information systems and between interconnected systems. Flow control is based on the characteristics of the information and/or the information path. Enforcement occurs, for example, in boundary protection devices (e.g., gateways, routers, guards, encrypted tunnels, firewalls) that employ rule sets or establish configuration settings that restrict information system services, provide a packet-filtering capability based on header information, or message-filtering capability based on message content (e.g., implementing key word searches or using document characteristics). Organizations also consider the trustworthiness of filtering/inspection mechanisms (i.e., hardware, firmware, and software components) that are critical to information flow enforcement. Related controls: AC-3, AC-17, AC-19, AC-21, CM-6, CM-7, SA-8, SC-2, SC-5, SC-7, SC-18. | D9: Directives supplémentaires | E9: Le contrôle du flux d’information détermine les endroits auxquels l’information peut être acheminée au sein d’un système d’information et entre des systèmes d’information (et non les personnes autorisées à accéder à l’information) et sans égard explicite aux accès subséquents à cette information. Les restrictions en matière de contrôle du flux consistent, par exemple, à empêcher la transmission en clair sur l’Internet de l’information dont l’exportation est contrôlée, à bloquer le trafic extérieur qui prétend provenir de l’intérieur de l’organisation, à restreindre les demandes Web à l’Internet qui ne proviennent pas du serveur mandataire Web interne, et à limiter les transferts d’information entre les organisations en fonction des structures et du contenu des données. Les transferts d’information entre systèmes d’information représentant différents domaines de sécurité avec différentes politiques de sécurité présentent le risque que de tels transferts contreviennent à une ou plusieurs politiques de sécurité de domaine. Dans de telles situations, les propriétaires/gardiens de l’information donnent des conseils aux points désignés d’application des politiques entre les systèmes interconnectés. Les organisations devraient envisager d’imposer des solutions architecturales particulières au besoin pour appliquer des politiques de sécurité particulières. L’application des contrôles consiste notamment à : (i) interdire le transfert d’information entre des systèmes interconnectés (c.-à-d. permettre l’accès seulement); (ii) utiliser des mécanismes matériels pour imposer les flux d’information unidirectionnels; et (iii) mettre en œuvre des mécanismes de réévaluation fiables pour réaffecter les attributs de sécurité et les étiquettes de sécurité. Les organisations utilisent couramment des politiques de contrôle du flux d’information et des mécanismes d’application entre des sources et des destinations désignées (p. ex., les réseaux, les personnes et les périphériques) au sein des systèmes d’information et entre les systèmes interconnectés. Le contrôle du flux est fonction des caractéristiques de l’information ou du chemin de l’information. Le contrôle a lieu, par exemple, dans les dispositifs de protection des frontières (p. ex., passerelles, routeurs, gardiens, tunnels chiffrés, pare-feu) qui utilisent des ensembles de règles ou établissent des paramètres de configuration restreignant les services du système d’information, et offrent une capacité de filtrage des paquets en fonction de l’information d’en-tête, ou une capacité de filtrage des messages en fonction de leur contenu (p. ex., la mise en œuvre de recherches par mots clés ou l’utilisation des caractéristiques du document). Les organisations tiennent également compte de la fiabilité des mécanismes de filtrage et d’inspection (c.-à-d. le matériel, les micrologiciels et les composants logiciels) qui sont essentiels au contrôle du flux d’information. Contrôles connexes : AC-3, AC-17, AC-19, AC-21, CM-6, CM-7, SA-8, SC-2, SC-5, SC-7, SC-18.
A10: Test Case | D10: Cas de test
A11: Test | B11: TEST-AC-4 | D11: Test | E11: TEST-AC-4
A12: Requirement ID | B12: AC-4 | D12: ID Exigence | E12: AC-4
A13: Component | D13: Composant
A14: Requirement | D14: Exigence
A15: Contextual Design Description | D15: Description contextuelle du design
A16: Evidence Provided | D16: Preuve fournie
A17: Preparer Sign Off (Initials, Date) | D17: Signataire préparateur (Initiales, Date)
A18: Owner Sign Off (Initials, Date) | D18: Signataire propriétaire (Initiales, Date)
A19: Assessor Sign Off (Initials, Date) | D19: Signataire évaluateur (Initiales, Date)
A20: Status | B20: Not Started | D20: Statut | E20: Non commencé
A21: Comments | D21: Commentaires

Sheet AC-4-21
A1: Control AC-4(21) — Evidence Tracking | D1: Contrôle AC-4(21) — Suivi des preuves
A2: Control Information | D2: Informations du contrôle
A3: Control Identifier | B3: AC-4(21) | D3: Identifiant du contrôle | E3: AC-4(21)
A4: Family | B4: Information Flow Enforcement | D4: Famille | E4: Application des contrôles du flux d’information
A5: Profile | B5: CCCS Medium / PBMM Moderate | D5: Profil | E5: CCCS Moyen / PBMM Modéré
A6: Primary Evidence Tool | D6: Outil de preuve principal
A7: Contributing Tools | D7: Outils contributeurs
A8: Control Description | B8: INFORMATION FLOW ENFORCEMENT | PHYSICAL / LOGICAL SEPARATION OF INFORMATION FLOWS The information system separates information flows logically or physically using session encryption to accomplish separation of all sessions. | D8: Description du contrôle | E8: APPLICATION DES CONTRÔLES DU FLUX D’INFORMATION | SÉPARATION PHYSIQUE/LOGIQUE DES FLUX D’INFORMATION Le système d’information sépare les flux d’information de façon logique ou physique en utilisant le chiffrement des sessions pour effectuer la séparation de toutes les sessions.
A9: Supplemental Guidance | B9: Enforcing the separation of information flows by type can enhance protection by ensuring that information is not commingled while in transit and by enabling flow control by transmission paths perhaps not otherwise achievable. Types of separable information include, for example, inbound and outbound communications traffic, service requests and responses, and information of differing security categories. | D9: Directives supplémentaires | E9: La mise en application de la séparation des flux d’information par type peut améliorer la protection en veillant à ce que l’information ne soit pas mélangée pendant le transport et en permettant un contrôle du flux par les voies de transmission qui ne serait peut-être pas possible autrement. Les types d’information séparable comprennent, par exemple, le trafic des communications entrantes et sortantes, les demandes de service et les réponses, ainsi que l’information de différentes catégories de sécurité.
A10: Test Case | D10: Cas de test
A11: Test | B11: TEST-AC-4(21) | D11: Test | E11: TEST-AC-4(21)
A12: Requirement ID | B12: AC-4(21) | D12: ID Exigence | E12: AC-4(21)
A13: Component | D13: Composant
A14: Requirement | D14: Exigence
A15: Contextual Design Description | D15: Description contextuelle du design
A16: Evidence Provided | D16: Preuve fournie
A17: Preparer Sign Off (Initials, Date) | D17: Signataire préparateur (Initiales, Date)
A18: Owner Sign Off (Initials, Date) | D18: Signataire propriétaire (Initiales, Date)
A19: Assessor Sign Off (Initials, Date) | D19: Signataire évaluateur (Initiales, Date)
A20: Status | B20: Not Started | D20: Statut | E20: Non commencé
A21: Comments | D21: Commentaires

Sheet AC-17-1
A1: Control AC-17(1) — Evidence Tracking | D1: Contrôle AC-17(1) — Suivi des preuves
A2: Control Information | D2: Informations du contrôle
A3: Control Identifier | B3: AC-17(1) | D3: Identifiant du contrôle | E3: AC-17(1)
A4: Family | B4: Remote Access | D4: Famille | E4: Accès à distance
A5: Profile | B5: CCCS Medium / PBMM Moderate | D5: Profil | E5: CCCS Moyen / PBMM Modéré
A6: Primary Evidence Tool | D6: Outil de preuve principal
A7: Contributing Tools | D7: Outils contributeurs
A8: Control Description | B8: REMOTE ACCESS | AUTOMATED MONITORING / CONTROL The information system monitors and controls remote access methods. | D8: Description du contrôle | E8: ACCÈS À DISTANCE | SURVEILLANCE ET CONTRÔLE AUTOMATISÉS Le système d’information surveille et contrôle les méthodes d’accès à distance.
A9: Supplemental Guidance | B9: Automated monitoring and control of remote access sessions allows organizations to detect cyber-attacks and also ensure ongoing compliance with remote access policies by auditing connection activities of remote users on a variety of information system components (e.g., servers, workstations, notebook computers, smart phones, and tablets). Related controls: AU-2, AU-12. | D9: Directives supplémentaires | E9: La surveillance et le contrôle automatisés des sessions avec accès à distance permettent aux organisations de détecter les cyberattaques et d’assurer la conformité continue aux politiques d’accès à distance en vérifiant les activités de connexion des utilisateurs distants sur une variété de composants du système d’information (p. ex., serveurs, postes de travail, ordinateurs portatifs, téléphones intelligents et tablettes). Contrôles connexes : AU-2, AU-12.
A10: Test Case | D10: Cas de test
A11: Test | B11: TEST-AC-17(1) | D11: Test | E11: TEST-AC-17(1)
A12: Requirement ID | B12: AC-17(1) | D12: ID Exigence | E12: AC-17(1)
A13: Component | D13: Composant
A14: Requirement | D14: Exigence
A15: Contextual Design Description | D15: Description contextuelle du design
A16: Evidence Provided | D16: Preuve fournie
A17: Preparer Sign Off (Initials, Date) | D17: Signataire préparateur (Initiales, Date)
A18: Owner Sign Off (Initials, Date) | D18: Signataire propriétaire (Initiales, Date)
A19: Assessor Sign Off (Initials, Date) | D19: Signataire évaluateur (Initiales, Date)
A20: Status | B20: Not Started | D20: Statut | E20: Non commencé
A21: Comments | D21: Commentaires

Sheet AC-17-2
A1: Control AC-17(2) — Evidence Tracking | D1: Contrôle AC-17(2) — Suivi des preuves
A2: Control Information | D2: Informations du contrôle
A3: Control Identifier | B3: AC-17(2) | D3: Identifiant du contrôle | E3: AC-17(2)
A4: Family | B4: Remote Access | D4: Famille | E4: Accès à distance
A5: Profile | B5: CCCS Medium / PBMM Moderate | D5: Profil | E5: CCCS Moyen / PBMM Modéré
A6: Primary Evidence Tool | D6: Outil de preuve principal
A7: Contributing Tools | D7: Outils contributeurs
A8: Control Description | B8: REMOTE ACCESS | PROTECTION OF CONFIDENTIALITY / INTEGRITY USING ENCRYPTION The information system implements cryptographic mechanisms to protect the confidentiality and integrity of remote access sessions. The cryptography must be compliant with the requirements of SC-13. | D8: Description du contrôle | E8: ACCÈS À DISTANCE | PROTECTION DE LA CONFIDENTIALITÉ ET DE L’INTÉGRITÉ AU MOYEN DU CHIFFREMENT Le système d’information met en œuvre des mécanismes cryptographiques pour protéger la confidentialité et l’intégrité des sessions d’accès à distance. La cryptographie doit être conforme aux exigences de SC-13.
A9: Supplemental Guidance | B9: Guidance on the encryption strength of mechanism can be obtained from CSE upon request. | D9: Directives supplémentaires | E9: Le CST peut, sur demande, conseiller l’organisation quant à la puissance de chiffrement du mécanisme.
A10: Test Case | D10: Cas de test
A11: Test | B11: TEST-AC-17(2) | D11: Test | E11: TEST-AC-17(2)
A12: Requirement ID | B12: AC-17(2) | D12: ID Exigence | E12: AC-17(2)
A13: Component | D13: Composant
A14: Requirement | D14: Exigence
A15: Contextual Design Description | D15: Description contextuelle du design
A16: Evidence Provided | D16: Preuve fournie
A17: Preparer Sign Off (Initials, Date) | D17: Signataire préparateur (Initiales, Date)
A18: Owner Sign Off (Initials, Date) | D18: Signataire propriétaire (Initiales, Date)
A19: Assessor Sign Off (Initials, Date) | D19: Signataire évaluateur (Initiales, Date)
A20: Status | B20: Not Started | D20: Statut | E20: Non commencé
A21: Comments | D21: Commentaires

Sheet AC-17-3
A1: Control AC-17(3) — Evidence Tracking | D1: Contrôle AC-17(3) — Suivi des preuves
A2: Control Information | D2: Informations du contrôle
A3: Control Identifier | B3: AC-17(3) | D3: Identifiant du contrôle | E3: AC-17(3)
A4: Family | B4: Remote Access | D4: Famille | E4: Accès à distance
A5: Profile | B5: CCCS Medium / PBMM Moderate | D5: Profil | E5: CCCS Moyen / PBMM Modéré
A6: Primary Evidence Tool | D6: Outil de preuve principal
A7: Contributing Tools | D7: Outils contributeurs
A8: Control Description | B8: REMOTE ACCESS | MANAGED ACCESS CONTROL POINTS The information system routes all remote accesses through approved managed network access control points. | D8: Description du contrôle | E8: ACCÈS À DISTANCE | POINTS DE CONTRÔLE D’ACCÈS GÉRÉS Le système d’information achemine tous les accès à distance au moyen de points de contrôle d’accès au réseau gérés et approuvés.
A9: Supplemental Guidance | B9: Limiting the number of access control points for remote accesses reduces the attack surface for organizations. Related control: SC-7. | D9: Directives supplémentaires | E9: Une limitation du nombre de points de contrôle d’accès à distance réduit la surface d’attaque pour les organisations. Contrôle connexe : SC-7.
A10: Test Case | D10: Cas de test
A11: Test | B11: TEST-AC-17(3) | D11: Test | E11: TEST-AC-17(3)
A12: Requirement ID | B12: AC-17(3) | D12: ID Exigence | E12: AC-17(3)
A13: Component | D13: Composant
A14: Requirement | D14: Exigence
A15: Contextual Design Description | D15: Description contextuelle du design
A16: Evidence Provided | D16: Preuve fournie
A17: Preparer Sign Off (Initials, Date) | D17: Signataire préparateur (Initiales, Date)
A18: Owner Sign Off (Initials, Date) | D18: Signataire propriétaire (Initiales, Date)
A19: Assessor Sign Off (Initials, Date) | D19: Signataire évaluateur (Initiales, Date)
A20: Status | B20: Not Started | D20: Statut | E20: Non commencé
A21: Comments | D21: Commentaires

Sheet AC-17-9
A1: Control AC-17(9) — Evidence Tracking | D1: Contrôle AC-17(9) — Suivi des preuves
A2: Control Information | D2: Informations du contrôle
A3: Control Identifier | B3: AC-17(9) | D3: Identifiant du contrôle | E3: AC-17(9)
A4: Family | B4: Remote Access | D4: Famille | E4: Accès à distance
A5: Profile | B5: CCCS Medium / PBMM Moderate | D5: Profil | E5: CCCS Moyen / PBMM Modéré
A6: Primary Evidence Tool | D6: Outil de preuve principal
A7: Contributing Tools | D7: Outils contributeurs
A8: Control Description | B8: REMOTE ACCESS | DISCONNECT / DISABLE ACCESS The organization provides the capability to expeditiously disconnect or disable remote access to the information system within a period no greater than 15 minutes. | D8: Description du contrôle | E8: ACCÈS À DISTANCE | DÉCONNECTER/DÉSACTIVER L’ACCÈS L’organisation offre la possibilité de déconnecter ou de désactiver rapidement l’accès à distance au système d’information dans un délai maximal de 15 minutes.
A9: Supplemental Guidance | B9: This control enhancement requires organizations to have the capability to rapidly disconnect current users remotely accessing the information system and/or disable further remote access. The speed of disconnect or disablement varies based on the criticality of missions/business functions and the need to eliminate immediate or future remote access to organizational information systems. | D9: Directives supplémentaires | E9: Cette amélioration du contrôle exige que les organisations soient en mesure de déconnecter rapidement les utilisateurs actuels qui accèdent à distance au système d’information ou de désactiver tout accès à distance ultérieur. La rapidité de la déconnexion ou de la désactivation varie en fonction de la criticité des missions et des fonctions opérationnelles et de la nécessité d’éliminer l’accès à distance immédiat ou futur aux systèmes d’information de l’organisation.
A10: Test Case | D10: Cas de test
A11: Test | B11: TEST-AC-17(9) | D11: Test | E11: TEST-AC-17(9)
A12: Requirement ID | B12: AC-17(9) | D12: ID Exigence | E12: AC-17(9)
A13: Component | D13: Composant
A14: Requirement | D14: Exigence
A15: Contextual Design Description | D15: Description contextuelle du design
A16: Evidence Provided | D16: Preuve fournie
A17: Preparer Sign Off (Initials, Date) | D17: Signataire préparateur (Initiales, Date)
A18: Owner Sign Off (Initials, Date) | D18: Signataire propriétaire (Initiales, Date)
A19: Assessor Sign Off (Initials, Date) | D19: Signataire évaluateur (Initiales, Date)
A20: Status | B20: Not Started | D20: Statut | E20: Non commencé
A21: Comments | D21: Commentaires

Sheet AC-17-100
A1: Control AC-17(100) — Evidence Tracking | D1: Contrôle AC-17(100) — Suivi des preuves
A2: Control Information | D2: Informations du contrôle
A3: Control Identifier | B3: AC-17(100) | D3: Identifiant du contrôle | E3: AC-17(100)
A4: Family | B4: Remote Access | D4: Famille | E4: Accès à distance
A5: Profile | B5: CCCS Medium / PBMM Moderate | D5: Profil | E5: CCCS Moyen / PBMM Modéré
A6: Primary Evidence Tool | D6: Outil de preuve principal
A7: Contributing Tools | D7: Outils contributeurs
A8: Control Description | B8: Remote access to privileged accounts is performed on dedicated management consoles governed entirely by the system’s security policies and used exclusively for this purpose (e.g. Internet access not allowed). | D8: Description du contrôle | E8: L’accès à distance aux comptes privilégiés se fait sur des consoles de gestion dédiées entièrement régies par les politiques de sécurité du système et utilisées exclusivement à cette fin (p. ex., accès Internet interdit).
A9: Supplemental Guidance | D9: Directives supplémentaires
A10: Test Case | D10: Cas de test
A11: Test | B11: TEST-AC-17(100) | D11: Test | E11: TEST-AC-17(100)
A12: Requirement ID | B12: AC-17(100) | D12: ID Exigence | E12: AC-17(100)
A13: Component | D13: Composant
A14: Requirement | D14: Exigence
A15: Contextual Design Description | D15: Description contextuelle du design
A16: Evidence Provided | D16: Preuve fournie
A17: Preparer Sign Off (Initials, Date) | D17: Signataire préparateur (Initiales, Date)
A18: Owner Sign Off (Initials, Date) | D18: Signataire propriétaire (Initiales, Date)
A19: Assessor Sign Off (Initials, Date) | D19: Signataire évaluateur (Initiales, Date)
A20: Status | B20: Not Started | D20: Statut | E20: Non commencé
A21: Comments | D21: Commentaires

Sheet AU-2
A1: Control AU-2 — Evidence Tracking | D1: Contrôle AU-2 — Suivi des preuves
A2: Control Information | D2: Informations du contrôle
A3: Control Identifier | B3: AU-2 | D3: Identifiant du contrôle | E3: AU-2
A4: Family | B4: Auditable Events | D4: Famille | E4: Événements vérifiables
A5: Profile | B5: CCCS Medium / PBMM Moderate | D5: Profil | E5: CCCS Moyen / PBMM Modéré
A6: Primary Evidence Tool | D6: Outil de preuve principal
A7: Contributing Tools | D7: Outils contributeurs
A8: Control Description | B8: (A) The organization determines that the information system is capable of auditing the following events: Successful and unsuccessful account logon events, account management events, object access, policy change, privilege functions, process tracking, and system events. For Web applications: all administrator activity, authentication checks, authorization checks, data deletions, data access, data changes, and permission changes. (B) The organization coordinates the security audit function with other organizational entities requiring audit-related information to enhance mutual support and to help guide the selection of auditable events. (C) The organization provides a rationale for why the auditable events are deemed to be adequate to support after-the-fact investigations of security incidents. (D) The organization determines what organizationally-defined audited events (a subset of the auditable events defined in AU-2 a.) and the frequency of (or situation requiring) auditing for each identified event. | D8: Description du contrôle | E8: (A) L’organisation détermine que le système d’information est capable de vérifier les événements suivants : événements d’ouverture de compte, réussis ou non, événements de gestion de compte, accès aux objets, changement de politique, fonctions de privilèges, suivi des processus et événements du système. Pour les applications Web : toutes les activités des administrateurs, les vérifications d’authentification, les vérifications d’autorisation, les suppressions de données, l’accès aux données, les changements de données et les changements d’autorisation. (B) L’organisation coordonne la fonction de vérification de la sécurité avec d’autres entités organisationnelles qui ont besoin de renseignements liés à la vérification pour améliorer le soutien mutuel et aider à orienter le choix des événements vérifiables. (C) L’organisation explique la raison pour laquelle les événements vérifiables sont jugés adéquats pour appuyer les enquêtes effectuées à la suite des incidents de sécurité. (D) L’organisation détermine les événements définis par l’organisation qui sont vérifiés (un sous-ensemble des événements vérifiables définis dans AU-2 a.) et la fréquence (ou la situation exigeant) des vérifications pour chaque événement identifié.
A9: Supplemental Guidance | B9: An event is any observable occurrence in an organizational information system. Organizations identify audit events as those events which are significant and relevant to the security of information systems and the environments in which those systems operate in order to meet specific and ongoing audit needs. Audit events can include, for example, password changes, failed logons, or failed accesses related to information systems, administrative privilege usage, or third-party credential usage. In determining the set of auditable events, organizations consider the auditing appropriate for each of the security controls to be implemented. To balance auditing requirements with other information system needs, this control also requires identifying that subset of auditable events that are audited at a given point in time. For example, organizations may determine that information systems must have the capability to log every file access both successful and unsuccessful, but not activate that capability except for specific circumstances due to the potential burden on system performance. Auditing requirements, including the need for auditable events, may be referenced in other security controls and control enhancements. Organizations also include auditable events that are required by applicable organizational policies, directives, and standards. Audit records can be generated at various levels of abstraction, including at the packet level as information traverses the network. Selecting the appropriate level of abstraction is a critical aspect of an audit capability and can facilitate the identification of root causes to problems. Organizations consider in the definition of auditable events, the auditing necessary to cover related events such as the steps in distributed, transaction-based processes (e.g., processes that are distributed across multiple organizations) and actions that occur in service-oriented architectures. The information system audits the following privileged user/process events at a minimum: (a) Successful and unsuccessful attempts to access, modify, or delete security objects (Security objects include audit data, system configuration files and file or users’ formal access permissions.) (b) Successful and unsuccessful logon attempts (c) Privileged activities or other system level access (see notes for AU-2 (4)) (d) Starting and ending time for user access to the system (e) Concurrent logons from different workstations (f) All program initiations (see notes for AU-2 (4)) In addition, the information system audits the following unprivileged user/process events at a minimum: (a) Successful and unsuccessful attempts to access, modify, or delete security objects (b) Successful and unsuccessful logon attempts (c) Starting and ending time for user access to the system (d) Concurrent logons from different workstations Related controls: AC-6, AC-17, AU-3, AU-12, MA-4, MP-2, MP-4, SI-4 | D9: Directives supplémentaires | E9: Un événement est toute occurrence observable dans un système d’information organisationnel. Les organisations désignent les événements vérifiables comme étant des événements importants et pertinents pour la sécurité des systèmes d’information et des environnements dans lesquels ces systèmes sont utilisés afin de répondre à des exigences de vérification particulières et continues. Les événements vérifiés peuvent comprendre, par exemple, les changements de mot de passe, les échecs d’ouverture de session ou les échecs accès liés aux systèmes d’information, l’utilisation des privilèges administratifs ou l’utilisation de justificatifs d’identité par des tiers. Lorsqu’elles déterminent l’ensemble des événements vérifiables, les organisations considèrent que la vérification est appropriée pour chacun des contrôles de sécurité à mettre en œuvre. Pour assurer l’équilibre entre les exigences en matière de vérification et les autres besoins du système d’information, ce contrôle exige également de déterminer le sous-ensemble d’événements vérifiables qui sont vérifiés à un moment donné. Par exemple, les organisations peuvent déterminer que les systèmes d’information doivent avoir la capacité d’enregistrer chaque accès aux fichiers, qu’il soit réussi ou non, mais n’activeront cette capacité que dans des circonstances particulières en raison du fardeau potentiel sur le rendement du système. Les exigences en matière de vérification, y compris la nécessité de déterminer des événements vérifiables, peuvent être mentionnées dans d’autres contrôles et améliorations des contrôles de sécurité. Les organisations incluent également les événements vérifiables qui sont exigés par les politiques, les directives et les normes organisationnelles applicables. Les enregistrements de vérification peuvent être générés à divers niveaux d’abstraction, y compris au niveau des paquets, à mesure que l’information traverse le réseau. Le choix du niveau d’abstraction approprié est un aspect essentiel d’une capacité de vérification et peut faciliter l’identification des causes profondes des problèmes. Dans la définition des événements vérifiables, les organisations prennent en compte la vérification nécessaire pour couvrir les événements connexes, comme les étapes des processus distribués, fondés sur les transactions (p. ex., les processus qui sont répartis entre de multiples organisations) et les actions qui ont lieu dans les architectures orientées service. Le système d’information vérifie au minimum les événements suivants liés aux utilisateurs/processus privilégiés : (a) Tentatives réussies et infructueuses d’accéder aux objets de sécurité, de les modifier ou de les supprimer (les objets de sécurité comprennent les données de vérification, les fichiers de configuration de système et les autorisations d’accès officielles des utilisateurs). (b) Tentatives d’ouverture de session réussies et infructueuses (c) Activités privilégiées ou autre accès au niveau du système (voir les notes pour AU-2 [4]) (d) Heures de début et de fin de l’accès des utilisateurs au système (e) Ouvertures de session simultanées à partir de différents postes de travail (f) Tous les lancements de programmes (voir les notes pour AU-2 [4]) De plus, le système d’information vérifie au minimum les événements suivants liés aux utilisateurs/processus non privilégiés : (a) Tentatives réussies et infructueuses d’accès, de modification ou de suppression d’objets de sécurité (b) Tentatives d’ouverture de session réussies et infructueuses (c) Heures de début et de fin de l’accès de l’utilisateur au système (d) Ouvertures de session simultanées à partir de différents postes de travail Contrôles connexes : AC-6, AC-17, AU-3, AU-12, MA-4, MP-2, MP-4, SI-4
A10: Test Case | D10: Cas de test
A11: Test | B11: TEST-AU-2 | D11: Test | E11: TEST-AU-2
A12: Requirement ID | B12: AU-2 | D12: ID Exigence | E12: AU-2
A13: Component | D13: Composant
A14: Requirement | D14: Exigence
A15: Contextual Design Description | D15: Description contextuelle du design
A16: Evidence Provided | D16: Preuve fournie
A17: Preparer Sign Off (Initials, Date) | D17: Signataire préparateur (Initiales, Date)
A18: Owner Sign Off (Initials, Date) | D18: Signataire propriétaire (Initiales, Date)
A19: Assessor Sign Off (Initials, Date) | D19: Signataire évaluateur (Initiales, Date)
A20: Status | B20: Not Started | D20: Statut | E20: Non commencé
A21: Comments | D21: Commentaires

Sheet AU-3
A1: Control AU-3 — Evidence Tracking | D1: Contrôle AU-3 — Suivi des preuves
A2: Control Information | D2: Informations du contrôle
A3: Control Identifier | B3: AU-3 | D3: Identifiant du contrôle | E3: AU-3
A4: Family | B4: Content of Audit Records | D4: Famille | E4: Contenu des enregistrements de vérification
A5: Profile | B5: CCCS Medium / PBMM Moderate | D5: Profil | E5: CCCS Moyen / PBMM Modéré
A6: Primary Evidence Tool | D6: Outil de preuve principal
A7: Contributing Tools | D7: Outils contributeurs
A8: Control Description | B8: (A) The information system generates audit records containing information that establishes what type of event occurred, when the event occurred, where the event occurred, the source of the event, the outcome of the event, and the identity of any individuals or subjects associated with the event. | D8: Description du contrôle | E8: (A) Le système d’information génère des enregistrements de vérification qui contiennent les renseignements permettant d’établir le type d’événement qui a eu lieu, le moment et l’endroit où l’événement a eu lieu, la source de l’événement, le résultat de l’événement, ainsi que l’identité de toute personne ou de tout sujet associé à l’événement.
A9: Supplemental Guidance | B9: Audit record content that may be necessary to satisfy the requirement of this control, includes, for example, time stamps, source and destination addresses, user/process identifiers, event descriptions, success/fail indications, filenames involved, and access control or flow control rules invoked. Event outcomes can include indicators of event success or failure and event-specific results (e.g., the security state of the information system after the event occurred). Related controls: AU-2, AU-8, AU-12, SI-11 | D9: Directives supplémentaires | E9: Le contenu des enregistrements de vérification qui peut être nécessaire pour satisfaire à l’exigence de ce contrôle comprend, par exemple, les estampilles temporelles, les adresses de source et de destination, les identifiants d’utilisateurs ou de processus, les descriptions d’événements, les indications de réussite ou d’échec, les noms des fichiers en cause et les règles de contrôle d’accès ou de flux invoquées. Les résultats de l’événement peuvent comprendre des indicateurs de réussite ou d’échec de l’événement et des résultats propres à l’événement (p. ex., l’état de sécurité du système d’information après l’événement). Contrôles connexes : AU-2, AU-8, AU-12, SI-11
A10: Test Case | D10: Cas de test
A11: Test | B11: TEST-AU-3 | D11: Test | E11: TEST-AU-3
A12: Requirement ID | B12: AU-3 | D12: ID Exigence | E12: AU-3
A13: Component | D13: Composant
A14: Requirement | D14: Exigence
A15: Contextual Design Description | D15: Description contextuelle du design
A16: Evidence Provided | D16: Preuve fournie
A17: Preparer Sign Off (Initials, Date) | D17: Signataire préparateur (Initiales, Date)
A18: Owner Sign Off (Initials, Date) | D18: Signataire propriétaire (Initiales, Date)
A19: Assessor Sign Off (Initials, Date) | D19: Signataire évaluateur (Initiales, Date)
A20: Status | B20: Not Started | D20: Statut | E20: Non commencé
A21: Comments | D21: Commentaires

Sheet AU-3-1
A1: Control AU-3(1) — Evidence Tracking | D1: Contrôle AU-3(1) — Suivi des preuves
A2: Control Information | D2: Informations du contrôle
A3: Control Identifier | B3: AU-3(1) | D3: Identifiant du contrôle | E3: AU-3(1)
A4: Family | B4: Content of Audit Records | D4: Famille | E4: Contenu des enregistrements de vérification
A5: Profile | B5: CCCS Medium / PBMM Moderate | D5: Profil | E5: CCCS Moyen / PBMM Modéré
A6: Primary Evidence Tool | D6: Outil de preuve principal
A7: Contributing Tools | D7: Outils contributeurs
A8: Control Description | B8: CONTENT OF AUDIT RECORDS | ADDITIONAL AUDIT INFORMATION The information system generates audit records containing the following additional information: session, connection, transaction, or activity duration; for client-server transactions, the number of bytes received and bytes sent; additional informational messages to diagnose or identify the event; characteristics that describe or identify the object or resource being acted upon. | D8: Description du contrôle | E8: CONTENU DES ENREGISTREMENTS DE VÉRIFICATION | RENSEIGNEMENTS DE VÉRIFICATION SUPPLÉMENTAIRES Le système d’information génère des enregistrements de vérification contenant les renseignements supplémentaires suivants : la durée de la session, de la connexion, de la transaction ou de l’activité; pour les transactions client-serveur, le nombre d’octets reçus et d’octets envoyés; des messages d’information supplémentaires pour diagnostiquer ou identifier l’événement; les caractéristiques qui décrivent ou identifient l’objet ou la ressource concernés.
A9: Supplemental Guidance | B9: Detailed information that organizations may consider in audit records includes, for example, full text recording of privileged commands or the individual identities of group account users. Organizations consider limiting the additional audit information to only that information explicitly needed for specific audit requirements. This facilitates the use of audit trails and audit logs by not including information that could potentially be misleading or could make it more difficult to locate information of interest. Additional guidance for enhancement (1): Audit events should always be capable of being associated with an individual identity. Associating audit events with a group or role is insufficient. | D9: Directives supplémentaires | E9: Les renseignements détaillés dont les organisations peuvent tenir compte dans les enregistrements de vérification comprennent, par exemple, l’enregistrement en texte intégral des commandes privilégiées ou les identités individuelles des utilisateurs de comptes de groupe. Les organisations devraient envisager de limiter les renseignements de vérification supplémentaires aux seuls renseignements explicitement nécessaires pour répondre à des exigences de vérification particulières. Cela facilitera l’utilisation des pistes de vérification et des journaux de vérification en n’incluant pas les renseignements qui pourraient être trompeurs ou rendre plus difficile la recherche de renseignements utiles. Conseils supplémentaires pour l’amélioration (1) : Les événements vérifiés devraient toujours pouvoir être associés à une identité individuelle. Associer des événements vérifiés à un groupe ou à un rôle est insuffisant.
A10: Test Case | D10: Cas de test
A11: Test | B11: TEST-AU-3(1) | D11: Test | E11: TEST-AU-3(1)
A12: Requirement ID | B12: AU-3(1) | D12: ID Exigence | E12: AU-3(1)
A13: Component | D13: Composant
A14: Requirement | D14: Exigence
A15: Contextual Design Description | D15: Description contextuelle du design
A16: Evidence Provided | D16: Preuve fournie
A17: Preparer Sign Off (Initials, Date) | D17: Signataire préparateur (Initiales, Date)
A18: Owner Sign Off (Initials, Date) | D18: Signataire propriétaire (Initiales, Date)
A19: Assessor Sign Off (Initials, Date) | D19: Signataire évaluateur (Initiales, Date)
A20: Status | B20: Not Started | D20: Statut | E20: Non commencé
A21: Comments | D21: Commentaires

Sheet AU-9-2
A1: Control AU-9(2) — Evidence Tracking | D1: Contrôle AU-9(2) — Suivi des preuves
A2: Control Information | D2: Informations du contrôle
A3: Control Identifier | B3: AU-9(2) | D3: Identifiant du contrôle | E3: AU-9(2)
A4: Family | B4: Protection of Audit Information | D4: Famille | E4: Protection des renseignements de vérification
A5: Profile | B5: CCCS Medium / PBMM Moderate | D5: Profil | E5: CCCS Moyen / PBMM Modéré
A6: Primary Evidence Tool | D6: Outil de preuve principal
A7: Contributing Tools | D7: Outils contributeurs
A8: Control Description | B8: PROTECTION OF AUDIT INFORMATION | AUDIT BACKUP ON SEPARATE PHYSICAL SYSTEMS / COMPONENTS The information system backs up audit records at least weekly onto a physically different system or system component than the system or component being audited. | D8: Description du contrôle | E8: PROTECTION DES RENSEIGNEMENTS DE VÉRIFICATION | SAUVEGARDE DES VÉRIFICATIONS SUR DES SYSTÈMES/COMPOSANTS PHYSIQUES SÉPARÉS Le système d’information sauvegarde les enregistrements de vérification au moins une fois par semaine sur un système ou un composant système physiquement différent du système ou du composant faisant l’objet de la vérification.
A9: Supplemental Guidance | B9: This control enhancement helps to ensure that a compromise of the information system being audited does not also result in a compromise of the audit records. Related controls: AU-4, AU-5, AU-11. | D9: Directives supplémentaires | E9: Cette amélioration permet de s’assurer qu’une compromission du système d’information faisant l’objet d’une vérification n’entraîne pas également la compromission des enregistrements de vérification. Contrôles connexes : AU-4, AU-5, AU-11.
A10: Test Case | D10: Cas de test
A11: Test | B11: TEST-AU-9(2) | D11: Test | E11: TEST-AU-9(2)
A12: Requirement ID | B12: AU-9(2) | D12: ID Exigence | E12: AU-9(2)
A13: Component | D13: Composant
A14: Requirement | D14: Exigence
A15: Contextual Design Description | D15: Description contextuelle du design
A16: Evidence Provided | D16: Preuve fournie
A17: Preparer Sign Off (Initials, Date) | D17: Signataire préparateur (Initiales, Date)
A18: Owner Sign Off (Initials, Date) | D18: Signataire propriétaire (Initiales, Date)
A19: Assessor Sign Off (Initials, Date) | D19: Signataire évaluateur (Initiales, Date)
A20: Status | B20: Not Started | D20: Statut | E20: Non commencé
A21: Comments | D21: Commentaires

Sheet AU-12
A1: Control AU-12 — Evidence Tracking | D1: Contrôle AU-12 — Suivi des preuves
A2: Control Information | D2: Informations du contrôle
A3: Control Identifier | B3: AU-12 | D3: Identifiant du contrôle | E3: AU-12
A4: Family | B4: Audit Generation | D4: Famille | E4: Génération des vérifications
A5: Profile | B5: CCCS Medium / PBMM Moderate | D5: Profil | E5: CCCS Moyen / PBMM Modéré
A6: Primary Evidence Tool | D6: Outil de preuve principal
A7: Contributing Tools | D7: Outils contributeurs
A8: Control Description | B8: (A) The information system provides audit record generation capability for the auditable events defined in AU-2 a. of all information system and network components where audit capability is deployed/available. (B) The information system allows organization-defined personnel or roles to select which auditable events are to be audited by specific components of the information system. (C) The information system generates audit records for the events defined in AU-2 d. with the content defined in AU-3. | D8: Description du contrôle | E8: (A) Le système d’information offre une capacité de génération d’enregistrements de vérification pour les événements vérifiables définis dans AU-2 a. de tous les composants du système d’information et du réseau où la capacité de vérification est déployée/disponible. (B) Le système d’information permet au personnel ou aux rôles définis par l’organisation de choisir les événements vérifiables qui doivent être vérifiés par des composants précis du système d’information. (C) Le système d’information génère des enregistrements de vérification pour les événements définis dans AU-2 d. avec le contenu défini dans AU-3.
A9: Supplemental Guidance | B9: Audit records can be generated from many different information system components. The list of audited events is the set of events for which audits are to be generated. These events are typically a subset of all events for which the information system is capable of generating audit records. Related controls: AC-3, AU-2, AU-3, AU-6, AU-7 | D9: Directives supplémentaires | E9: Des enregistrements de vérification peuvent être générés à partir de nombreux composants du système d’information. La liste des événements vérifiés est l’ensemble des événements pour lesquels des vérifications doivent être produites. Ces événements sont habituellement un sous-ensemble de tous les événements pour lesquels le système d’information peut générer des enregistrements de vérification. Contrôles connexes : AC-3, AU-2, AU-3, AU-6, AU-7
A10: Test Case | D10: Cas de test
A11: Test | B11: TEST-AU-12 | D11: Test | E11: TEST-AU-12
A12: Requirement ID | B12: AU-12 | D12: ID Exigence | E12: AU-12
A13: Component | D13: Composant
A14: Requirement | D14: Exigence
A15: Contextual Design Description | D15: Description contextuelle du design
A16: Evidence Provided | D16: Preuve fournie
A17: Preparer Sign Off (Initials, Date) | D17: Signataire préparateur (Initiales, Date)
A18: Owner Sign Off (Initials, Date) | D18: Signataire propriétaire (Initiales, Date)
A19: Assessor Sign Off (Initials, Date) | D19: Signataire évaluateur (Initiales, Date)
A20: Status | B20: Not Started | D20: Statut | E20: Non commencé
A21: Comments | D21: Commentaires

Sheet CA-3-5
A1: Control CA-3(5) — Evidence Tracking | D1: Contrôle CA-3(5) — Suivi des preuves
A2: Control Information | D2: Informations du contrôle
A3: Control Identifier | B3: CA-3(5) | D3: Identifiant du contrôle | E3: CA-3(5)
A4: Family | B4: Information System Connections | D4: Famille | E4: Connexions aux systèmes d’information
A5: Profile | B5: CCCS Medium / PBMM Moderate | D5: Profil | E5: CCCS Moyen / PBMM Modéré
A6: Primary Evidence Tool | D6: Outil de preuve principal
A7: Contributing Tools | D7: Outils contributeurs
A8: Control Description | B8: SYSTEM INTERCONNECTIONS | RESTRICTIONS ON EXTERNAL SYSTEM CONNECTIONS The organization employs allow-all, deny-by-exception; deny-all policy for allowing any systems to connect to external information systems. | D8: Description du contrôle | E8: INTERCONNEXIONS DES SYSTÈMES | RESTRICTIONS SUR LES CONNEXIONS AUX RÉSEAUX EXTERNES L’organisation a recours à la méthode « permettre tout, refuser par exception, refuser tout » pour permettre aux systèmes de se connecter à des systèmes d’information externes.
A9: Supplemental Guidance | B9: Organizations can constrain information system connectivity to external domains (e.g., websites) by employing one of two policies with regard to such connectivity: (i) allow-all, deny by exception, also known as blacklisting (the weaker of the two policies); or (ii) deny-all, allow by exception, also known as whitelisting (the stronger of the two policies). For either policy, organizations determine what exceptions, if any, are acceptable. Related control: CM-7. | D9: Directives supplémentaires | E9: Les organisations peuvent limiter la connectivité des systèmes d’information à des domaines externes (p. ex., sites Web) en utilisant l’une des deux politiques relatives à cette connectivité : (i) permettre tout, refuser par exception, aussi appelée liste noire (la plus faible des deux politiques); ou (ii) refuser tout, permettre par exception, aussi appelée liste blanche (la plus forte des deux politiques). Pour l’une ou l’autre politique, les organisations déterminent les exceptions applicables, le cas échéant. Contrôle connexe : CM-7.
A10: Test Case | D10: Cas de test
A11: Test | B11: TEST-CA-3(5) | D11: Test | E11: TEST-CA-3(5)
A12: Requirement ID | B12: CA-3(5) | D12: ID Exigence | E12: CA-3(5)
A13: Component | D13: Composant
A14: Requirement | D14: Exigence
A15: Contextual Design Description | D15: Description contextuelle du design
A16: Evidence Provided | D16: Preuve fournie
A17: Preparer Sign Off (Initials, Date) | D17: Signataire préparateur (Initiales, Date)
A18: Owner Sign Off (Initials, Date) | D18: Signataire propriétaire (Initiales, Date)
A19: Assessor Sign Off (Initials, Date) | D19: Signataire évaluateur (Initiales, Date)
A20: Status | B20: Not Started | D20: Statut | E20: Non commencé
A21: Comments | D21: Commentaires

Sheet CA-9
A1: Control CA-9 — Evidence Tracking | D1: Contrôle CA-9 — Suivi des preuves
A2: Control Information | D2: Informations du contrôle
A3: Control Identifier | B3: CA-9 | D3: Identifiant du contrôle | E3: CA-9
A4: Family | B4: Internal System Connections | D4: Famille | E4: Connexions internes au système
A5: Profile | B5: CCCS Medium / PBMM Moderate | D5: Profil | E5: CCCS Moyen / PBMM Modéré
A6: Primary Evidence Tool | D6: Outil de preuve principal
A7: Contributing Tools | D7: Outils contributeurs
A8: Control Description | B8: (A) The organization authorizes internal connections of information system components or classes of components to the information system. (B) The organization documents, for each internal connection, the interface characteristics, security requirements, and the nature of the information communicated. | D8: Description du contrôle | E8: (A) L’organisation autorise les connexions internes de composants du système d’information ou de catégories de composants au système d’information. (B) L’organisation documente, pour chaque connexion interne, les caractéristiques de l’interface, les exigences de sécurité et la nature de l’information communiquée.
A9: Supplemental Guidance | B9: This control applies to connections between organizational information systems and (separate) constituent system components (i.e., intra-system connections) including, for example, system connections with mobile devices, notebook/desktop computers, printers, copiers, facsimile machines, scanners, sensors, and servers. Instead of authorizing each individual internal connection, organizations can authorize internal connections for a class of components with common characteristics and/or configurations, for example, all digital printers, scanners, and copiers with a specified processing, storage, and transmission capability or all smart phones with a specific baseline configuration. Related controls: AC-3, AC-4, AC-18, AC-19, AU-2, AU-12, CA-7, CM-2, IA-3, SC-7, SI-4 | D9: Directives supplémentaires | E9: Ce contrôle s’applique aux connexions entre les systèmes d’information organisationnels et les composants (distincts) des systèmes constituants (c.-à-d. les connexions intrasystème) y compris, par exemple, les connexions système avec les appareils mobiles, les ordinateurs portatifs/de bureau, les imprimantes, les photocopieurs, les télécopieurs, les numériseurs, les capteurs et les serveurs. Au lieu d’autoriser chaque connexion interne individuelle, les organisations peuvent autoriser les connexions internes pour une catégorie de composants ayant des caractéristiques ou des configurations communes, par exemple, toutes les imprimantes et tous les numériseurs et photocopieurs numériques ayant une capacité de traitement, de stockage et de transmission spécifiée ou tous les téléphones intelligents ayant une configuration de base spécifique. Contrôles connexes : AC-3, AC-4, AC-18, AC-19, AU-2, AU-12, CA-7, CM-2, IA-3, SC-7, SI-4
A10: Test Case | D10: Cas de test
A11: Test | B11: TEST-CA-9 | D11: Test | E11: TEST-CA-9
A12: Requirement ID | B12: CA-9 | D12: ID Exigence | E12: CA-9
A13: Component | D13: Composant
A14: Requirement | D14: Exigence
A15: Contextual Design Description | D15: Description contextuelle du design
A16: Evidence Provided | D16: Preuve fournie
A17: Preparer Sign Off (Initials, Date) | D17: Signataire préparateur (Initiales, Date)
A18: Owner Sign Off (Initials, Date) | D18: Signataire propriétaire (Initiales, Date)
A19: Assessor Sign Off (Initials, Date) | D19: Signataire évaluateur (Initiales, Date)
A20: Status | B20: Not Started | D20: Statut | E20: Non commencé
A21: Comments | D21: Commentaires

Sheet CM-6
A1: Control CM-6 — Evidence Tracking | D1: Contrôle CM-6 — Suivi des preuves
A2: Control Information | D2: Informations du contrôle
A3: Control Identifier | B3: CM-6 | D3: Identifiant du contrôle | E3: CM-6
A4: Family | B4: Configuration Settings | D4: Famille | E4: Paramètres de configuration
A5: Profile | B5: CCCS Medium / PBMM Moderate | D5: Profil | E5: CCCS Moyen / PBMM Modéré
A6: Primary Evidence Tool | D6: Outil de preuve principal
A7: Contributing Tools | D7: Outils contributeurs
