Workbook

Sheet HOW TO USE
A1: PBMM Gap Analysis — How This Works
A2: What This Is | B2: This workbook sits on top of the Master Tracker and the 21 technology workbooks. It reads the control statuses LIVE and tells you where the gaps are, how big they are, and gives you a place to document what to do about them.
A3: No Manual Input Needed | B3: The EXECUTIVE DASHBOARD and GAPS BY FAMILY tabs are 100% formula-driven from the Master Tracker. As your team updates status dropdowns in the technology workbooks, the tracker updates, and this workbook updates. No maturity scores, no subjective ratings, no double-entry.
A4: EXECUTIVE DASHBOARD | B4: One row per technology. Total controls, Passed, In Progress, Failed, Not Started — all pulled live. % Complete and RAG status calculated automatically. RED = below 50%, AMBER = 50-89%, GREEN = 90%+. Bottom section shows totals and how many technologies are at each RAG level.
A5: GAPS BY FAMILY | B5: Heatmap showing the gap RATE (not count) for each Technology × Control Family intersection. A cell showing 100% means every control in that family for that technology has a gap. 0% means fully covered. Red = high gap rate, green = low. Blank = that family doesn't apply to that technology.
A6: REMEDIATION PLAN | B6: This is where you do the actual work. One row per finding. Document: what control failed, which technology, what's missing, what the risk is, what to do about it, who owns it, and when it's due. Priority dropdown (Critical/High/Medium/Low) and Status dropdown (Not Started/In Progress/Completed/Deferred/Waived). 100 rows pre-formatted. The REMEDIATION SUMMARY tab counts from here automatically.
A7: REMEDIATION SUMMARY | B7: Counts from the Remediation Plan automatically. Shows: how many findings by priority, how many completed vs remaining, % remediated overall, and a per-technology breakdown of open Critical and High items. This is your weekly remediation status view.
A8: SharePoint Setup | B8: Place this file in the SAME SharePoint library as the Master Tracker and all 21 workbooks. Open from SharePoint, click Update Links. The EXECUTIVE DASHBOARD and GAPS BY FAMILY tabs will populate live.

Sheet EXECUTIVE DASHBOARD
A1: PBMM Gap Analysis — Executive Dashboard (LIVE from Tracker)
A2: Technology | B2: Total | C2: Passed | D2: In Progress | E2: Failed | F2: Not Started | G2: % Complete | H2: RAG
A3: Analytics | B3: =COUNTIF('[PBMM_Master_Tracker_v2.xlsx]TRACKER'!$C$3:$C$1275,A3) | C3: =COUNTIFS('[PBMM_Master_Tracker_v2.xlsx]TRACKER'!$C$3:$C$1275,A3,'[PBMM_Master_Tracker_v2.xlsx]TRACKER'!$G$3:$G$1275,"Passed")+COUNTIFS('[PBMM_Master_Tracker_v2.xlsx]TRACKER'!$C$3:$C$1275,A3,'[PBMM_Master_Tracker_v2.xlsx]TRACKER'!$G$3:$G$1275,"Accepted Exception") | D3: =COUNTIFS('[PBMM_Master_Tracker_v2.xlsx]TRACKER'!$C$3:$C$1275,A3,'[PBMM_Master_Tracker_v2.xlsx]TRACKER'!$G$3:$G$1275,"In Progress")+COUNTIFS('[PBMM_Master_Tracker_v2.xlsx]TRACKER'!$C$3:$C$1275,A3,'[PBMM_Master_Tracker_v2.xlsx]TRACKER'!$G$3:$G$1275,"Evidence Provided")+COUNTIFS('[PBMM_Master_Tracker_v2.xlsx]TRACKER'!$C$3:$C$1275,A3,'[PBMM_Master_Tracker_v2.xlsx]TRACKER'!$G$3:$G$1275,"Under Review") | E3: =COUNTIFS('[PBMM_Master_Tracker_v2.xlsx]TRACKER'!$C$3:$C$1275,A3,'[PBMM_Master_Tracker_v2.xlsx]TRACKER'!$G$3:$G$1275,"Failed") | F3: =COUNTIFS('[PBMM_Master_Tracker_v2.xlsx]TRACKER'!$C$3:$C$1275,A3,'[PBMM_Master_Tracker_v2.xlsx]TRACKER'!$G$3:$G$1275,"Not Started") | G3: =IFERROR(C3/B3,0) | H3: =IF(G3>=0.9,"GREEN",IF(G3>=0.5,"AMBER","RED"))
A4: Compute | B4: =COUNTIF('[PBMM_Master_Tracker_v2.xlsx]TRACKER'!$C$3:$C$1275,A4) | C4: =COUNTIFS('[PBMM_Master_Tracker_v2.xlsx]TRACKER'!$C$3:$C$1275,A4,'[PBMM_Master_Tracker_v2.xlsx]TRACKER'!$G$3:$G$1275,"Passed")+COUNTIFS('[PBMM_Master_Tracker_v2.xlsx]TRACKER'!$C$3:$C$1275,A4,'[PBMM_Master_Tracker_v2.xlsx]TRACKER'!$G$3:$G$1275,"Accepted Exception") | D4: =COUNTIFS('[PBMM_Master_Tracker_v2.xlsx]TRACKER'!$C$3:$C$1275,A4,'[PBMM_Master_Tracker_v2.xlsx]TRACKER'!$G$3:$G$1275,"In Progress")+COUNTIFS('[PBMM_Master_Tracker_v2.xlsx]TRACKER'!$C$3:$C$1275,A4,'[PBMM_Master_Tracker_v2.xlsx]TRACKER'!$G$3:$G$1275,"Evidence Provided")+COUNTIFS('[PBMM_Master_Tracker_v2.xlsx]TRACKER'!$C$3:$C$1275,A4,'[PBMM_Master_Tracker_v2.xlsx]TRACKER'!$G$3:$G$1275,"Under Review") | E4: =COUNTIFS('[PBMM_Master_Tracker_v2.xlsx]TRACKER'!$C$3:$C$1275,A4,'[PBMM_Master_Tracker_v2.xlsx]TRACKER'!$G$3:$G$1275,"Failed") | F4: =COUNTIFS('[PBMM_Master_Tracker_v2.xlsx]TRACKER'!$C$3:$C$1275,A4,'[PBMM_Master_Tracker_v2.xlsx]TRACKER'!$G$3:$G$1275,"Not Started") | G4: =IFERROR(C4/B4,0) | H4: =IF(G4>=0.9,"GREEN",IF(G4>=0.5,"AMBER","RED"))
A5: Containers | B5: =COUNTIF('[PBMM_Master_Tracker_v2.xlsx]TRACKER'!$C$3:$C$1275,A5) | C5: =COUNTIFS('[PBMM_Master_Tracker_v2.xlsx]TRACKER'!$C$3:$C$1275,A5,'[PBMM_Master_Tracker_v2.xlsx]TRACKER'!$G$3:$G$1275,"Passed")+COUNTIFS('[PBMM_Master_Tracker_v2.xlsx]TRACKER'!$C$3:$C$1275,A5,'[PBMM_Master_Tracker_v2.xlsx]TRACKER'!$G$3:$G$1275,"Accepted Exception") | D5: =COUNTIFS('[PBMM_Master_Tracker_v2.xlsx]TRACKER'!$C$3:$C$1275,A5,'[PBMM_Master_Tracker_v2.xlsx]TRACKER'!$G$3:$G$1275,"In Progress")+COUNTIFS('[PBMM_Master_Tracker_v2.xlsx]TRACKER'!$C$3:$C$1275,A5,'[PBMM_Master_Tracker_v2.xlsx]TRACKER'!$G$3:$G$1275,"Evidence Provided")+COUNTIFS('[PBMM_Master_Tracker_v2.xlsx]TRACKER'!$C$3:$C$1275,A5,'[PBMM_Master_Tracker_v2.xlsx]TRACKER'!$G$3:$G$1275,"Under Review") | E5: =COUNTIFS('[PBMM_Master_Tracker_v2.xlsx]TRACKER'!$C$3:$C$1275,A5,'[PBMM_Master_Tracker_v2.xlsx]TRACKER'!$G$3:$G$1275,"Failed") | F5: =COUNTIFS('[PBMM_Master_Tracker_v2.xlsx]TRACKER'!$C$3:$C$1275,A5,'[PBMM_Master_Tracker_v2.xlsx]TRACKER'!$G$3:$G$1275,"Not Started") | G5: =IFERROR(C5/B5,0) | H5: =IF(G5>=0.9,"GREEN",IF(G5>=0.5,"AMBER","RED"))
A6: Database | B6: =COUNTIF('[PBMM_Master_Tracker_v2.xlsx]TRACKER'!$C$3:$C$1275,A6) | C6: =COUNTIFS('[PBMM_Master_Tracker_v2.xlsx]TRACKER'!$C$3:$C$1275,A6,'[PBMM_Master_Tracker_v2.xlsx]TRACKER'!$G$3:$G$1275,"Passed")+COUNTIFS('[PBMM_Master_Tracker_v2.xlsx]TRACKER'!$C$3:$C$1275,A6,'[PBMM_Master_Tracker_v2.xlsx]TRACKER'!$G$3:$G$1275,"Accepted Exception") | D6: =COUNTIFS('[PBMM_Master_Tracker_v2.xlsx]TRACKER'!$C$3:$C$1275,A6,'[PBMM_Master_Tracker_v2.xlsx]TRACKER'!$G$3:$G$1275,"In Progress")+COUNTIFS('[PBMM_Master_Tracker_v2.xlsx]TRACKER'!$C$3:$C$1275,A6,'[PBMM_Master_Tracker_v2.xlsx]TRACKER'!$G$3:$G$1275,"Evidence Provided")+COUNTIFS('[PBMM_Master_Tracker_v2.xlsx]TRACKER'!$C$3:$C$1275,A6,'[PBMM_Master_Tracker_v2.xlsx]TRACKER'!$G$3:$G$1275,"Under Review") | E6: =COUNTIFS('[PBMM_Master_Tracker_v2.xlsx]TRACKER'!$C$3:$C$1275,A6,'[PBMM_Master_Tracker_v2.xlsx]TRACKER'!$G$3:$G$1275,"Failed") | F6: =COUNTIFS('[PBMM_Master_Tracker_v2.xlsx]TRACKER'!$C$3:$C$1275,A6,'[PBMM_Master_Tracker_v2.xlsx]TRACKER'!$G$3:$G$1275,"Not Started") | G6: =IFERROR(C6/B6,0) | H6: =IF(G6>=0.9,"GREEN",IF(G6>=0.5,"AMBER","RED"))
A7: Developer Tools | B7: =COUNTIF('[PBMM_Master_Tracker_v2.xlsx]TRACKER'!$C$3:$C$1275,A7) | C7: =COUNTIFS('[PBMM_Master_Tracker_v2.xlsx]TRACKER'!$C$3:$C$1275,A7,'[PBMM_Master_Tracker_v2.xlsx]TRACKER'!$G$3:$G$1275,"Passed")+COUNTIFS('[PBMM_Master_Tracker_v2.xlsx]TRACKER'!$C$3:$C$1275,A7,'[PBMM_Master_Tracker_v2.xlsx]TRACKER'!$G$3:$G$1275,"Accepted Exception") | D7: =COUNTIFS('[PBMM_Master_Tracker_v2.xlsx]TRACKER'!$C$3:$C$1275,A7,'[PBMM_Master_Tracker_v2.xlsx]TRACKER'!$G$3:$G$1275,"In Progress")+COUNTIFS('[PBMM_Master_Tracker_v2.xlsx]TRACKER'!$C$3:$C$1275,A7,'[PBMM_Master_Tracker_v2.xlsx]TRACKER'!$G$3:$G$1275,"Evidence Provided")+COUNTIFS('[PBMM_Master_Tracker_v2.xlsx]TRACKER'!$C$3:$C$1275,A7,'[PBMM_Master_Tracker_v2.xlsx]TRACKER'!$G$3:$G$1275,"Under Review") | E7: =COUNTIFS('[PBMM_Master_Tracker_v2.xlsx]TRACKER'!$C$3:$C$1275,A7,'[PBMM_Master_Tracker_v2.xlsx]TRACKER'!$G$3:$G$1275,"Failed") | F7: =COUNTIFS('[PBMM_Master_Tracker_v2.xlsx]TRACKER'!$C$3:$C$1275,A7,'[PBMM_Master_Tracker_v2.xlsx]TRACKER'!$G$3:$G$1275,"Not Started") | G7: =IFERROR(C7/B7,0) | H7: =IF(G7>=0.9,"GREEN",IF(G7>=0.5,"AMBER","RED"))
A8: DevOps | B8: =COUNTIF('[PBMM_Master_Tracker_v2.xlsx]TRACKER'!$C$3:$C$1275,A8) | C8: =COUNTIFS('[PBMM_Master_Tracker_v2.xlsx]TRACKER'!$C$3:$C$1275,A8,'[PBMM_Master_Tracker_v2.xlsx]TRACKER'!$G$3:$G$1275,"Passed")+COUNTIFS('[PBMM_Master_Tracker_v2.xlsx]TRACKER'!$C$3:$C$1275,A8,'[PBMM_Master_Tracker_v2.xlsx]TRACKER'!$G$3:$G$1275,"Accepted Exception") | D8: =COUNTIFS('[PBMM_Master_Tracker_v2.xlsx]TRACKER'!$C$3:$C$1275,A8,'[PBMM_Master_Tracker_v2.xlsx]TRACKER'!$G$3:$G$1275,"In Progress")+COUNTIFS('[PBMM_Master_Tracker_v2.xlsx]TRACKER'!$C$3:$C$1275,A8,'[PBMM_Master_Tracker_v2.xlsx]TRACKER'!$G$3:$G$1275,"Evidence Provided")+COUNTIFS('[PBMM_Master_Tracker_v2.xlsx]TRACKER'!$C$3:$C$1275,A8,'[PBMM_Master_Tracker_v2.xlsx]TRACKER'!$G$3:$G$1275,"Under Review") | E8: =COUNTIFS('[PBMM_Master_Tracker_v2.xlsx]TRACKER'!$C$3:$C$1275,A8,'[PBMM_Master_Tracker_v2.xlsx]TRACKER'!$G$3:$G$1275,"Failed") | F8: =COUNTIFS('[PBMM_Master_Tracker_v2.xlsx]TRACKER'!$C$3:$C$1275,A8,'[PBMM_Master_Tracker_v2.xlsx]TRACKER'!$G$3:$G$1275,"Not Started") | G8: =IFERROR(C8/B8,0) | H8: =IF(G8>=0.9,"GREEN",IF(G8>=0.5,"AMBER","RED"))
A9: Documentation | B9: =COUNTIF('[PBMM_Master_Tracker_v2.xlsx]TRACKER'!$C$3:$C$1275,A9) | C9: =COUNTIFS('[PBMM_Master_Tracker_v2.xlsx]TRACKER'!$C$3:$C$1275,A9,'[PBMM_Master_Tracker_v2.xlsx]TRACKER'!$G$3:$G$1275,"Passed")+COUNTIFS('[PBMM_Master_Tracker_v2.xlsx]TRACKER'!$C$3:$C$1275,A9,'[PBMM_Master_Tracker_v2.xlsx]TRACKER'!$G$3:$G$1275,"Accepted Exception") | D9: =COUNTIFS('[PBMM_Master_Tracker_v2.xlsx]TRACKER'!$C$3:$C$1275,A9,'[PBMM_Master_Tracker_v2.xlsx]TRACKER'!$G$3:$G$1275,"In Progress")+COUNTIFS('[PBMM_Master_Tracker_v2.xlsx]TRACKER'!$C$3:$C$1275,A9,'[PBMM_Master_Tracker_v2.xlsx]TRACKER'!$G$3:$G$1275,"Evidence Provided")+COUNTIFS('[PBMM_Master_Tracker_v2.xlsx]TRACKER'!$C$3:$C$1275,A9,'[PBMM_Master_Tracker_v2.xlsx]TRACKER'!$G$3:$G$1275,"Under Review") | E9: =COUNTIFS('[PBMM_Master_Tracker_v2.xlsx]TRACKER'!$C$3:$C$1275,A9,'[PBMM_Master_Tracker_v2.xlsx]TRACKER'!$G$3:$G$1275,"Failed") | F9: =COUNTIFS('[PBMM_Master_Tracker_v2.xlsx]TRACKER'!$C$3:$C$1275,A9,'[PBMM_Master_Tracker_v2.xlsx]TRACKER'!$G$3:$G$1275,"Not Started") | G9: =IFERROR(C9/B9,0) | H9: =IF(G9>=0.9,"GREEN",IF(G9>=0.5,"AMBER","RED"))
A10: Hybrid + Multicloud | B10: =COUNTIF('[PBMM_Master_Tracker_v2.xlsx]TRACKER'!$C$3:$C$1275,A10) | C10: =COUNTIFS('[PBMM_Master_Tracker_v2.xlsx]TRACKER'!$C$3:$C$1275,A10,'[PBMM_Master_Tracker_v2.xlsx]TRACKER'!$G$3:$G$1275,"Passed")+COUNTIFS('[PBMM_Master_Tracker_v2.xlsx]TRACKER'!$C$3:$C$1275,A10,'[PBMM_Master_Tracker_v2.xlsx]TRACKER'!$G$3:$G$1275,"Accepted Exception") | D10: =COUNTIFS('[PBMM_Master_Tracker_v2.xlsx]TRACKER'!$C$3:$C$1275,A10,'[PBMM_Master_Tracker_v2.xlsx]TRACKER'!$G$3:$G$1275,"In Progress")+COUNTIFS('[PBMM_Master_Tracker_v2.xlsx]TRACKER'!$C$3:$C$1275,A10,'[PBMM_Master_Tracker_v2.xlsx]TRACKER'!$G$3:$G$1275,"Evidence Provided")+COUNTIFS('[PBMM_Master_Tracker_v2.xlsx]TRACKER'!$C$3:$C$1275,A10,'[PBMM_Master_Tracker_v2.xlsx]TRACKER'!$G$3:$G$1275,"Under Review") | E10: =COUNTIFS('[PBMM_Master_Tracker_v2.xlsx]TRACKER'!$C$3:$C$1275,A10,'[PBMM_Master_Tracker_v2.xlsx]TRACKER'!$G$3:$G$1275,"Failed") | F10: =COUNTIFS('[PBMM_Master_Tracker_v2.xlsx]TRACKER'!$C$3:$C$1275,A10,'[PBMM_Master_Tracker_v2.xlsx]TRACKER'!$G$3:$G$1275,"Not Started") | G10: =IFERROR(C10/B10,0) | H10: =IF(G10>=0.9,"GREEN",IF(G10>=0.5,"AMBER","RED"))
A11: Identity | B11: =COUNTIF('[PBMM_Master_Tracker_v2.xlsx]TRACKER'!$C$3:$C$1275,A11) | C11: =COUNTIFS('[PBMM_Master_Tracker_v2.xlsx]TRACKER'!$C$3:$C$1275,A11,'[PBMM_Master_Tracker_v2.xlsx]TRACKER'!$G$3:$G$1275,"Passed")+COUNTIFS('[PBMM_Master_Tracker_v2.xlsx]TRACKER'!$C$3:$C$1275,A11,'[PBMM_Master_Tracker_v2.xlsx]TRACKER'!$G$3:$G$1275,"Accepted Exception") | D11: =COUNTIFS('[PBMM_Master_Tracker_v2.xlsx]TRACKER'!$C$3:$C$1275,A11,'[PBMM_Master_Tracker_v2.xlsx]TRACKER'!$G$3:$G$1275,"In Progress")+COUNTIFS('[PBMM_Master_Tracker_v2.xlsx]TRACKER'!$C$3:$C$1275,A11,'[PBMM_Master_Tracker_v2.xlsx]TRACKER'!$G$3:$G$1275,"Evidence Provided")+COUNTIFS('[PBMM_Master_Tracker_v2.xlsx]TRACKER'!$C$3:$C$1275,A11,'[PBMM_Master_Tracker_v2.xlsx]TRACKER'!$G$3:$G$1275,"Under Review") | E11: =COUNTIFS('[PBMM_Master_Tracker_v2.xlsx]TRACKER'!$C$3:$C$1275,A11,'[PBMM_Master_Tracker_v2.xlsx]TRACKER'!$G$3:$G$1275,"Failed") | F11: =COUNTIFS('[PBMM_Master_Tracker_v2.xlsx]TRACKER'!$C$3:$C$1275,A11,'[PBMM_Master_Tracker_v2.xlsx]TRACKER'!$G$3:$G$1275,"Not Started") | G11: =IFERROR(C11/B11,0) | H11: =IF(G11>=0.9,"GREEN",IF(G11>=0.5,"AMBER","RED"))
A12: Management and Governance | B12: =COUNTIF('[PBMM_Master_Tracker_v2.xlsx]TRACKER'!$C$3:$C$1275,A12) | C12: =COUNTIFS('[PBMM_Master_Tracker_v2.xlsx]TRACKER'!$C$3:$C$1275,A12,'[PBMM_Master_Tracker_v2.xlsx]TRACKER'!$G$3:$G$1275,"Passed")+COUNTIFS('[PBMM_Master_Tracker_v2.xlsx]TRACKER'!$C$3:$C$1275,A12,'[PBMM_Master_Tracker_v2.xlsx]TRACKER'!$G$3:$G$1275,"Accepted Exception") | D12: =COUNTIFS('[PBMM_Master_Tracker_v2.xlsx]TRACKER'!$C$3:$C$1275,A12,'[PBMM_Master_Tracker_v2.xlsx]TRACKER'!$G$3:$G$1275,"In Progress")+COUNTIFS('[PBMM_Master_Tracker_v2.xlsx]TRACKER'!$C$3:$C$1275,A12,'[PBMM_Master_Tracker_v2.xlsx]TRACKER'!$G$3:$G$1275,"Evidence Provided")+COUNTIFS('[PBMM_Master_Tracker_v2.xlsx]TRACKER'!$C$3:$C$1275,A12,'[PBMM_Master_Tracker_v2.xlsx]TRACKER'!$G$3:$G$1275,"Under Review") | E12: =COUNTIFS('[PBMM_Master_Tracker_v2.xlsx]TRACKER'!$C$3:$C$1275,A12,'[PBMM_Master_Tracker_v2.xlsx]TRACKER'!$G$3:$G$1275,"Failed") | F12: =COUNTIFS('[PBMM_Master_Tracker_v2.xlsx]TRACKER'!$C$3:$C$1275,A12,'[PBMM_Master_Tracker_v2.xlsx]TRACKER'!$G$3:$G$1275,"Not Started") | G12: =IFERROR(C12/B12,0) | H12: =IF(G12>=0.9,"GREEN",IF(G12>=0.5,"AMBER","RED"))
A13: Microsoft-Descoped | B13: =COUNTIF('[PBMM_Master_Tracker_v2.xlsx]TRACKER'!$C$3:$C$1275,A13) | C13: =COUNTIFS('[PBMM_Master_Tracker_v2.xlsx]TRACKER'!$C$3:$C$1275,A13,'[PBMM_Master_Tracker_v2.xlsx]TRACKER'!$G$3:$G$1275,"Passed")+COUNTIFS('[PBMM_Master_Tracker_v2.xlsx]TRACKER'!$C$3:$C$1275,A13,'[PBMM_Master_Tracker_v2.xlsx]TRACKER'!$G$3:$G$1275,"Accepted Exception") | D13: =COUNTIFS('[PBMM_Master_Tracker_v2.xlsx]TRACKER'!$C$3:$C$1275,A13,'[PBMM_Master_Tracker_v2.xlsx]TRACKER'!$G$3:$G$1275,"In Progress")+COUNTIFS('[PBMM_Master_Tracker_v2.xlsx]TRACKER'!$C$3:$C$1275,A13,'[PBMM_Master_Tracker_v2.xlsx]TRACKER'!$G$3:$G$1275,"Evidence Provided")+COUNTIFS('[PBMM_Master_Tracker_v2.xlsx]TRACKER'!$C$3:$C$1275,A13,'[PBMM_Master_Tracker_v2.xlsx]TRACKER'!$G$3:$G$1275,"Under Review") | E13: =COUNTIFS('[PBMM_Master_Tracker_v2.xlsx]TRACKER'!$C$3:$C$1275,A13,'[PBMM_Master_Tracker_v2.xlsx]TRACKER'!$G$3:$G$1275,"Failed") | F13: =COUNTIFS('[PBMM_Master_Tracker_v2.xlsx]TRACKER'!$C$3:$C$1275,A13,'[PBMM_Master_Tracker_v2.xlsx]TRACKER'!$G$3:$G$1275,"Not Started") | G13: =IFERROR(C13/B13,0) | H13: =IF(G13>=0.9,"GREEN",IF(G13>=0.5,"AMBER","RED"))
A14: Networking | B14: =COUNTIF('[PBMM_Master_Tracker_v2.xlsx]TRACKER'!$C$3:$C$1275,A14) | C14: =COUNTIFS('[PBMM_Master_Tracker_v2.xlsx]TRACKER'!$C$3:$C$1275,A14,'[PBMM_Master_Tracker_v2.xlsx]TRACKER'!$G$3:$G$1275,"Passed")+COUNTIFS('[PBMM_Master_Tracker_v2.xlsx]TRACKER'!$C$3:$C$1275,A14,'[PBMM_Master_Tracker_v2.xlsx]TRACKER'!$G$3:$G$1275,"Accepted Exception") | D14: =COUNTIFS('[PBMM_Master_Tracker_v2.xlsx]TRACKER'!$C$3:$C$1275,A14,'[PBMM_Master_Tracker_v2.xlsx]TRACKER'!$G$3:$G$1275,"In Progress")+COUNTIFS('[PBMM_Master_Tracker_v2.xlsx]TRACKER'!$C$3:$C$1275,A14,'[PBMM_Master_Tracker_v2.xlsx]TRACKER'!$G$3:$G$1275,"Evidence Provided")+COUNTIFS('[PBMM_Master_Tracker_v2.xlsx]TRACKER'!$C$3:$C$1275,A14,'[PBMM_Master_Tracker_v2.xlsx]TRACKER'!$G$3:$G$1275,"Under Review") | E14: =COUNTIFS('[PBMM_Master_Tracker_v2.xlsx]TRACKER'!$C$3:$C$1275,A14,'[PBMM_Master_Tracker_v2.xlsx]TRACKER'!$G$3:$G$1275,"Failed") | F14: =COUNTIFS('[PBMM_Master_Tracker_v2.xlsx]TRACKER'!$C$3:$C$1275,A14,'[PBMM_Master_Tracker_v2.xlsx]TRACKER'!$G$3:$G$1275,"Not Started") | G14: =IFERROR(C14/B14,0) | H14: =IF(G14>=0.9,"GREEN",IF(G14>=0.5,"AMBER","RED"))
... A23: Web | B23: =COUNTIF('[PBMM_Master_Tracker_v2.xlsx]TRACKER'!$C$3:$C$1275,A23) | C23: =COUNTIFS('[PBMM_Master_Tracker_v2.xlsx]TRACKER'!$C$3:$C$1275,A23,'[PBMM_Master_Tracker_v2.xlsx]TRACKER'!$G$3:$G$1275,"Passed")+COUNTIFS('[PBMM_Master_Tracker_v2.xlsx]TRACKER'!$C$3:$C$1275,A23,'[PBMM_Master_Tracker_v2.xlsx]TRACKER'!$G$3:$G$1275,"Accepted Exception") | D23: =COUNTIFS('[PBMM_Master_Tracker_v2.xlsx]TRACKER'!$C$3:$C$1275,A23,'[PBMM_Master_Tracker_v2.xlsx]TRACKER'!$G$3:$G$1275,"In Progress")+COUNTIFS('[PBMM_Master_Tracker_v2.xlsx]TRACKER'!$C$3:$C$1275,A23,'[PBMM_Master_Tracker_v2.xlsx]TRACKER'!$G$3:$G$1275,"Evidence Provided")+COUNTIFS('[PBMM_Master_Tracker_v2.xlsx]TRACKER'!$C$3:$C$1275,A23,'[PBMM_Master_Tracker_v2.xlsx]TRACKER'!$G$3:$G$1275,"Under Review") | E23: =COUNTIFS('[PBMM_Master_Tracker_v2.xlsx]TRACKER'!$C$3:$C$1275,A23,'[PBMM_Master_Tracker_v2.xlsx]TRACKER'!$G$3:$G$1275,"Failed") | F23: =COUNTIFS('[PBMM_Master_Tracker_v2.xlsx]TRACKER'!$C$3:$C$1275,A23,'[PBMM_Master_Tracker_v2.xlsx]TRACKER'!$G$3:$G$1275,"Not Started") | G23: =IFERROR(C23/B23,0) | H23: =IF(G23>=0.9,"GREEN",IF(G23>=0.5,"AMBER","RED"))
A25: TOTALS
A26: Total Controls | B26: =SUM(B3:B23) | C26: =SUM(C3:C23) | D26: =SUM(D3:D23) | E26: =SUM(E3:E23) | F26: =SUM(F3:F23) | G26: =IFERROR(C26/B26,0)
A27: Technologies at RED (< 50% complete) | B27: =COUNTIF(H3:H23,"RED")
A28: Technologies at AMBER (50-89% complete) | B28: =COUNTIF(H3:H23,"AMBER")
A29: Technologies at GREEN (90%+ complete) | B29: =COUNTIF(H3:H23,"GREEN")

Sheet GAPS BY FAMILY
A1: Gap Rate by Technology × Control Family (LIVE — lower is better)
A2: Technology | B2: AC | C2: AT | D2: AU | E2: CA | F2: CM | G2: CP | H2: IA | I2: IR | J2: MA | K2: MP | L2: PE | M2: PL | N2: PS | O2: RA | P2: SA | Q2: SC | R2: SI
A3: Analytics | B3: =IFERROR(1-(COUNTIFS('[PBMM_Master_Tracker_v2.xlsx]TRACKER'!$C$3:$C$1275,$A3,'[PBMM_Master_Tracker_v2.xlsx]TRACKER'!$D$3:$D$1275,"AC",'[PBMM_Master_Tracker_v2.xlsx]TRACKER'!$G$3:$G$1275,"Passed")+COUNTIFS('[PBMM_Master_Tracker_v2.xlsx]TRACKER'!$C$3:$C$1275,$A3,'[PBMM_Master_Tracker_v2.xlsx]TRACKER'!$D$3:$D$1275,"AC",'[PBMM_Master_Tracker_v2.xlsx]TRACKER'!$G$3:$G$1275,"Accepted Exception"))/COUNTIFS('[PBMM_Master_Tracker_v2.xlsx]TRACKER'!$C$3:$C$1275,$A3,'[PBMM_Master_Tracker_v2.xlsx]TRACKER'!$D$3:$D$1275,"AC"),"") | C3: =IFERROR(1-(COUNTIFS('[PBMM_Master_Tracker_v2.xlsx]TRACKER'!$C$3:$C$1275,$A3,'[PBMM_Master_Tracker_v2.xlsx]TRACKER'!$D$3:$D$1275,"AT",'[PBMM_Master_Tracker_v2.xlsx]TRACKER'!$G$3:$G$1275,"Passed")+COUNTIFS('[PBMM_Master_Tracker_v2.xlsx]TRACKER'!$C$3:$C$1275,$A3,'[PBMM_Master_Tracker_v2.xlsx]TRACKER'!$D$3:$D$1275,"AT",'[PBMM_Master_Tracker_v2.xlsx]TRACKER'!$G$3:$G$1275,"Accepted Exception"))/COUNTIFS('[PBMM_Master_Tracker_v2.xlsx]TRACKER'!$C$3:$C$1275,$A3,'[PBMM_Master_Tracker_v2.xlsx]TRACKER'!$D$3:$D$1275,"AT"),"") | D3: =IFERROR(1-(COUNTIFS('[PBMM_Master_Tracker_v2.xlsx]TRACKER'!$C$3:$C$1275,$A3,'[PBMM_Master_Tracker_v2.xlsx]TRACKER'!$D$3:$D$1275,"AU",'[PBMM_Master_Tracker_v2.xlsx]TRACKER'!$G$3:$G$1275,"Passed")+COUNTIFS('[PBMM_Master_Tracker_v2.xlsx]TRACKER'!$C$3:$C$1275,$A3,'[PBMM_Master_Tracker_v2.xlsx]TRACKER'!$D$3:$D$1275,"AU",'[PBMM_Master_Tracker_v2.xlsx]TRACKER'!$G$3:$G$1275,"Accepted Exception"))/COUNTIFS('[PBMM_Master_Tracker_v2.xlsx]TRACKER'!$C$3:$C$1275,$A3,'[PBMM_Master_Tracker_v2.xlsx]TRACKER'!$D$3:$D$1275,"AU"),"") | E3: =IFERROR(1-(COUNTIFS('[PBMM_Master_Tracker_v2.xlsx]TRACKER'!$C$3:$C$1275,$A3,'[PBMM_Master_Tracker_v2.xlsx]TRACKER'!$D$3:$D$1275,"CA",'[PBMM_Master_Tracker_v2.xlsx]TRACKER'!$G$3:$G$1275,"Passed")+COUNTIFS('[PBMM_Master_Tracker_v2.xlsx]TRACKER'!$C$3:$C$1275,$A3,'[PBMM_Master_Tracker_v2.xlsx]TRACKER'!$D$3:$D$1275,"CA",'[PBMM_Master_Tracker_v2.xlsx]TRACKER'!$G$3:$G$1275,"Accepted Exception"))/COUNTIFS('[PBMM_Master_Tracker_v2.xlsx]TRACKER'!$C$3:$C$1275,$A3,'[PBMM_Master_Tracker_v2.xlsx]TRACKER'!$D$3:$D$1275,"CA"),"") | F3: =IFERROR(1-(COUNTIFS('[PBMM_Master_Tracker_v2.xlsx]TRACKER'!$C$3:$C$1275,$A3,'[PBMM_Master_Tracker_v2.xlsx]TRACKER'!$D$3:$D$1275,"CM",'[PBMM_Master_Tracker_v2.xlsx]TRACKER'!$G$3:$G$1275,"Passed")+COUNTIFS('[PBMM_Master_Tracker_v2.xlsx]TRACKER'!$C$3:$C$1275,$A3,'[PBMM_Master_Tracker_v2.xlsx]TRACKER'!$D$3:$D$1275,"CM",'[PBMM_Master_Tracker_v2.xlsx]TRACKER'!$G$3:$G$1275,"Accepted Exception"))/COUNTIFS('[PBMM_Master_Tracker_v2.xlsx]TRACKER'!$C$3:$C$1275,$A3,'[PBMM_Master_Tracker_v2.xlsx]TRACKER'!$D$3:$D$1275,"CM"),"") | G3: =IFERROR(1-(COUNTIFS('[PBMM_Master_Tracker_v2.xlsx]TRACKER'!$C$3:$C$1275,$A3,'[PBMM_Master_Tracker_v2.xlsx]TRACKER'!$D$3:$D$1275,"CP",'[PBMM_Master_Tracker_v2.xlsx]TRACKER'!$G$3:$G$1275,"Passed")+COUNTIFS('[PBMM_Master_Tracker_v2.xlsx]TRACKER'!$C$3:$C$1275,$A3,'[PBMM_Master_Tracker_v2.xlsx]TRACKER'!$D$3:$D$1275,"CP",'[PBMM_Master_Tracker_v2.xlsx]TRACKER'!$G$3:$G$1275,"Accepted Exception"))/COUNTIFS('[PBMM_Master_Tracker_v2.xlsx]TRACKER'!$C$3:$C$1275,$A3,'[PBMM_Master_Tracker_v2.xlsx]TRACKER'!$D$3:$D$1275,"CP"),"") | H3: =IFERROR(1-(COUNTIFS('[PBMM_Master_Tracker_v2.xlsx]TRACKER'!$C$3:$C$1275,$A3,'[PBMM_Master_Tracker_v2.xlsx]TRACKER'!$D$3:$D$1275,"IA",'[PBMM_Master_Tracker_v2.xlsx]TRACKER'!$G$3:$G$1275,"Passed")+COUNTIFS('[PBMM_Master_Tracker_v2.xlsx]TRACKER'!$C$3:$C$1275,$A3,'[PBMM_Master_Tracker_v2.xlsx]TRACKER'!$D$3:$D$1275,"IA",'[PBMM_Master_Tracker_v2.xlsx]TRACKER'!$G$3:$G$1275,"Accepted Exception"))/COUNTIFS('[PBMM_Master_Tracker_v2.xlsx]TRACKER'!$C$3:$C$1275,$A3,'[PBMM_Master_Tracker_v2.xlsx]TRACKER'!$D$3:$D$1275,"IA"),"") | I3: =IFERROR(1-(COUNTIFS('[PBMM_Master_Tracker_v2.xlsx]TRACKER'!$C$3:$C$1275,$A3,'[PBMM_Master_Tracker_v2.xlsx]TRACKER'!$D$3:$D$1275,"IR",'[PBMM_Master_Tracker_v2.xlsx]TRACKER'!$G$3:$G$1275,"Passed")+COUNTIFS('[PBMM_Master_Tracker_v2.xlsx]TRACKER'!$C$3:$C$1275,$A3,'[PBMM_Master_Tracker_v2.xlsx]TRACKER'!$D$3:$D$1275,"IR",'[PBMM_Master_Tracker_v2.xlsx]TRACKER'!$G$3:$G$1275,"Accepted Exception"))/COUNTIFS('[PBMM_Master_Tracker_v2.xlsx]TRACKER'!$C$3:$C$1275,$A3,'[PBMM_Master_Tracker_v2.xlsx]TRACKER'!$D$3:$D$1275,"IR"),"") | J3: =IFERROR(1-(COUNTIFS('[PBMM_Master_Tracker_v2.xlsx]TRACKER'!$C$3:$C$1275,$A3,'[PBMM_Master_Tracker_v2.xlsx]TRACKER'!$D$3:$D$1275,"MA",'[PBMM_Master_Tracker_v2.xlsx]TRACKER'!$G$3:$G$1275,"Passed")+COUNTIFS('[PBMM_Master_Tracker_v2.xlsx]TRACKER'!$C$3:$C$1275,$A3,'[PBMM_Master_Tracker_v2.xlsx]TRACKER'!$D$3:$D$1275,"MA",'[PBMM_Master_Tracker_v2.xlsx]TRACKER'!$G$3:$G$1275,"Accepted Exception"))/COUNTIFS('[PBMM_Master_Tracker_v2.xlsx]TRACKER'!$C$3:$C$1275,$A3,'[PBMM_Master_Tracker_v2.xlsx]TRACKER'!$D$3:$D$1275,"MA"),"") | K3: =IFERROR(1-(COUNTIFS('[PBMM_Master_Tracker_v2.xlsx]TRACKER'!$C$3:$C$1275,$A3,'[PBMM_Master_Tracker_v2.xlsx]TRACKER'!$D$3:$D$1275,"MP",'[PBMM_Master_Tracker_v2.xlsx]TRACKER'!$G$3:$G$1275,"Passed")+COUNTIFS('[PBMM_Master_Tracker_v2.xlsx]TRACKER'!$C$3:$C$1275,$A3,'[PBMM_Master_Tracker_v2.xlsx]TRACKER'!$D$3:$D$1275,"MP",'[PBMM_Master_Tracker_v2.xlsx]TRACKER'!$G$3:$G$1275,"Accepted Exception"))/COUNTIFS('[PBMM_Master_Tracker_v2.xlsx]TRACKER'!$C$3:$C$1275,$A3,'[PBMM_Master_Tracker_v2.xlsx]TRACKER'!$D$3:$D$1275,"MP"),"") | L3: =IFERROR(1-(COUNTIFS('[PBMM_Master_Tracker_v2.xlsx]TRACKER'!$C$3:$C$1275,$A3,'[PBMM_Master_Tracker_v2.xlsx]TRACKER'!$D$3:$D$1275,"PE",'[PBMM_Master_Tracker_v2.xlsx]TRACKER'!$G$3:$G$1275,"Passed")+COUNTIFS('[PBMM_Master_Tracker_v2.xlsx]TRACKER'!$C$3:$C$1275,$A3,'[PBMM_Master_Tracker_v2.xlsx]TRACKER'!$D$3:$D$1275,"PE",'[PBMM_Master_Tracker_v2.xlsx]TRACKER'!$G$3:$G$1275,"Accepted Exception"))/COUNTIFS('[PBMM_Master_Tracker_v2.xlsx]TRACKER'!$C$3:$C$1275,$A3,'[PBMM_Master_Tracker_v2.xlsx]TRACKER'!$D$3:$D$1275,"PE"),"") | M3: =IFERROR(1-(COUNTIFS('[PBMM_Master_Tracker_v2.xlsx]TRACKER'!$C$3:$C$1275,$A3,'[PBMM_Master_Tracker_v2.xlsx]TRACKER'!$D$3:$D$1275,"PL",'[PBMM_Master_Tracker_v2.xlsx]TRACKER'!$G$3:$G$1275,"Passed")+COUNTIFS('[PBMM_Master_Tracker_v2.xlsx]TRACKER'!$C$3:$C$1275,$A3,'[PBMM_Master_Tracker_v2.xlsx]TRACKER'!$D$3:$D$1275,"PL",'[PBMM_Master_Tracker_v2.xlsx]TRACKER'!$G$3:$G$1275,"Accepted Exception"))/COUNTIFS('[PBMM_Master_Tracker_v2.xlsx]TRACKER'!$C$3:$C$1275,$A3,'[PBMM_Master_Tracker_v2.xlsx]TRACKER'!$D$3:$D$1275,"PL"),"") | N3: =IFERROR(1-(COUNTIFS('[PBMM_Master_Tracker_v2.xlsx]TRACKER'!$C$3:$C$1275,$A3,'[PBMM_Master_Tracker_v2.xlsx]TRACKER'!$D$3:$D$1275,"PS",'[PBMM_Master_Tracker_v2.xlsx]TRACKER'!$G$3:$G$1275,"Passed")+COUNTIFS('[PBMM_Master_Tracker_v2.xlsx]TRACKER'!$C$3:$C$1275,$A3,'[PBMM_Master_Tracker_v2.xlsx]TRACKER'!$D$3:$D$1275,"PS",'[PBMM_Master_Tracker_v2.xlsx]TRACKER'!$G$3:$G$1275,"Accepted Exception"))/COUNTIFS('[PBMM_Master_Tracker_v2.xlsx]TRACKER'!$C$3:$C$1275,$A3,'[PBMM_Master_Tracker_v2.xlsx]TRACKER'!$D$3:$D$1275,"PS"),"") | O3: =IFERROR(1-(COUNTIFS('[PBMM_Master_Tracker_v2.xlsx]TRACKER'!$C$3:$C$1275,$A3,'[PBMM_Master_Tracker_v2.xlsx]TRACKER'!$D$3:$D$1275,"RA",'[PBMM_Master_Tracker_v2.xlsx]TRACKER'!$G$3:$G$1275,"Passed")+COUNTIFS('[PBMM_Master_Tracker_v2.xlsx]TRACKER'!$C$3:$C$1275,$A3,'[PBMM_Master_Tracker_v2.xlsx]TRACKER'!$D$3:$D$1275,"RA",'[PBMM_Master_Tracker_v2.xlsx]TRACKER'!$G$3:$G$1275,"Accepted Exception"))/COUNTIFS('[PBMM_Master_Tracker_v2.xlsx]TRACKER'!$C$3:$C$1275,$A3,'[PBMM_Master_Tracker_v2.xlsx]TRACKER'!$D$3:$D$1275,"RA"),"") | P3: =IFERROR(1-(COUNTIFS('[PBMM_Master_Tracker_v2.xlsx]TRACKER'!$C$3:$C$1275,$A3,'[PBMM_Master_Tracker_v2.xlsx]TRACKER'!$D$3:$D$1275,"SA",'[PBMM_Master_Tracker_v2.xlsx]TRACKER'!$G$3:$G$1275,"Passed")+COUNTIFS('[PBMM_Master_Tracker_v2.xlsx]TRACKER'!$C$3:$C$1275,$A3,'[PBMM_Master_Tracker_v2.xlsx]TRACKER'!$D$3:$D$1275,"SA",'[PBMM_Master_Tracker_v2.xlsx]TRACKER'!$G$3:$G$1275,"Accepted Exception"))/COUNTIFS('[PBMM_Master_Tracker_v2.xlsx]TRACKER'!$C$3:$C$1275,$A3,'[PBMM_Master_Tracker_v2.xlsx]TRACKER'!$D$3:$D$1275,"SA"),"") | Q3: =IFERROR(1-(COUNTIFS('[PBMM_Master_Tracker_v2.xlsx]TRACKER'!$C$3:$C$1275,$A3,'[PBMM_Master_Tracker_v2.xlsx]TRACKER'!$D$3:$D$1275,"SC",'[PBMM_Master_Tracker_v2.xlsx]TRACKER'!$G$3:$G$1275,"Passed")+COUNTIFS('[PBMM_Master_Tracker_v2.xlsx]TRACKER'!$C$3:$C$1275,$A3,'[PBMM_Master_Tracker_v2.xlsx]TRACKER'!$D$3:$D$1275,"SC",'[PBMM_Master_Tracker_v2.xlsx]TRACKER'!$G$3:$G$1275,"Accepted Exception"))/COUNTIFS('[PBMM_Master_Tracker_v2.xlsx]TRACKER'!$C$3:$C$1275,$A3,'[PBMM_Master_Tracker_v2.xlsx]TRACKER'!$D$3:$D$1275,"SC"),"") | R3: =IFERROR(1-(COUNTIFS('[PBMM_Master_Tracker_v2.xlsx]TRACKER'!$C$3:$C$1275,$A3,'[PBMM_Master_Tracker_v2.xlsx]TRACKER'!$D$3:$D$1275,"SI",'[PBMM_Master_Tracker_v2.xlsx]TRACKER'!$G$3:$G$1275,"Passed")+COUNTIFS('[PBMM_Master_Tracker_v2.xlsx]TRACKER'!$C$3:$C$1275,$A3,'[PBMM_Master_Tracker_v2.xlsx]TRACKER'!$D$3:$D$1275,"SI",'[PBMM_Master_Tracker_v2.xlsx]TRACKER'!$G$3:$G$1275,"Accepted Exception"))/COUNTIFS('[PBMM_Master_Tracker_v2.xlsx]TRACKER'!$C$3:$C$1275,$A3,'[PBMM_Master_Tracker_v2.xlsx]TRACKER'!$D$3:$D$1275,"SI"),"")
A4: Compute | B4: =IFERROR(1-(COUNTIFS('[PBMM_Master_Tracker_v2.xlsx]TRACKER'!$C$3:$C$1275,$A4,'[PBMM_Master_Tracker_v2.xlsx]TRACKER'!$D$3:$D$1275,"AC",'[PBMM_Master_Tracker_v2.xlsx]TRACKER'!$G$3:$G$1275,"Passed")+COUNTIFS('[PBMM_Master_Tracker_v2.xlsx]TRACKER'!$C$3:$C$1275,$A4,'[PBMM_Master_Tracker_v2.xlsx]TRACKER'!$D$3:$D$1275,"AC",'[PBMM_Master_Tracker_v2.xlsx]TRACKER'!$G$3:$G$1275,"Accepted Exception"))/COUNTIFS('[PBMM_Master_Tracker_v2.xlsx]TRACKER'!$C$3:$C$1275,$A4,'[PBMM_Master_Tracker_v2.xlsx]TRACKER'!$D$3:$D$1275,"AC"),"") | C4: =IFERROR(1-(COUNTIFS('[PBMM_Master_Tracker_v2.xlsx]TRACKER'!$C$3:$C$1275,$A4,'[PBMM_Master_Tracker_v2.xlsx]TRACKER'!$D$3:$D$1275,"AT",'[PBMM_Master_Tracker_v2.xlsx]TRACKER'!$G$3:$G$1275,"Passed")+COUNTIFS('[PBMM_Master_Tracker_v2.xlsx]TRACKER'!$C$3:$C$1275,$A4,'[PBMM_Master_Tracker_v2.xlsx]TRACKER'!$D$3:$D$1275,"AT",'[PBMM_Master_Tracker_v2.xlsx]TRACKER'!$G$3:$G$1275,"Accepted Exception"))/COUNTIFS('[PBMM_Master_Tracker_v2.xlsx]TRACKER'!$C$3:$C$1275,$A4,'[PBMM_Master_Tracker_v2.xlsx]TRACKER'!$D$3:$D$1275,"AT"),"") | D4: =IFERROR(1-(COUNTIFS('[PBMM_Master_Tracker_v2.xlsx]TRACKER'!$C$3:$C$1275,$A4,'[PBMM_Master_Tracker_v2.xlsx]TRACKER'!$D$3:$D$1275,"AU",'[PBMM_Master_Tracker_v2.xlsx]TRACKER'!$G$3:$G$1275,"Passed")+COUNTIFS('[PBMM_Master_Tracker_v2.xlsx]TRACKER'!$C$3:$C$1275,$A4,'[PBMM_Master_Tracker_v2.xlsx]TRACKER'!$D$3:$D$1275,"AU",'[PBMM_Master_Tracker_v2.xlsx]TRACKER'!$G$3:$G$1275,"Accepted Exception"))/COUNTIFS('[PBMM_Master_Tracker_v2.xlsx]TRACKER'!$C$3:$C$1275,$A4,'[PBMM_Master_Tracker_v2.xlsx]TRACKER'!$D$3:$D$1275,"AU"),"") | E4: =IFERROR(1-(COUNTIFS('[PBMM_Master_Tracker_v2.xlsx]TRACKER'!$C$3:$C$1275,$A4,'[PBMM_Master_Tracker_v2.xlsx]TRACKER'!$D$3:$D$1275,"CA",'[PBMM_Master_Tracker_v2.xlsx]TRACKER'!$G$3:$G$1275,"Passed")+COUNTIFS('[PBMM_Master_Tracker_v2.xlsx]TRACKER'!$C$3:$C$1275,$A4,'[PBMM_Master_Tracker_v2.xlsx]TRACKER'!$D$3:$D$1275,"CA",'[PBMM_Master_Tracker_v2.xlsx]TRACKER'!$G$3:$G$1275,"Accepted Exception"))/COUNTIFS('[PBMM_Master_Tracker_v2.xlsx]TRACKER'!$C$3:$C$1275,$A4,'[PBMM_Master_Tracker_v2.xlsx]TRACKER'!$D$3:$D$1275,"CA"),"") | F4: =IFERROR(1-(COUNTIFS('[PBMM_Master_Tracker_v2.xlsx]TRACKER'!$C$3:$C$1275,$A4,'[PBMM_Master_Tracker_v2.xlsx]TRACKER'!$D$3:$D$1275,"CM",'[PBMM_Master_Tracker_v2.xlsx]TRACKER'!$G$3:$G$1275,"Passed")+COUNTIFS('[PBMM_Master_Tracker_v2.xlsx]TRACKER'!$C$3:$C$1275,$A4,'[PBMM_Master_Tracker_v2.xlsx]TRACKER'!$D$3:$D$1275,"CM",'[PBMM_Master_Tracker_v2.xlsx]TRACKER'!$G$3:$G$1275,"Accepted Exception"))/COUNTIFS('[PBMM_Master_Tracker_v2.xlsx]TRACKER'!$C$3:$C$1275,$A4,'[PBMM_Master_Tracker_v2.xlsx]TRACKER'!$D$3:$D$1275,"CM"),"") | G4: =IFERROR(1-(COUNTIFS('[PBMM_Master_Tracker_v2.xlsx]TRACKER'!$C$3:$C$1275,$A4,'[PBMM_Master_Tracker_v2.xlsx]TRACKER'!$D$3:$D$1275,"CP",'[PBMM_Master_Tracker_v2.xlsx]TRACKER'!$G$3:$G$1275,"Passed")+COUNTIFS('[PBMM_Master_Tracker_v2.xlsx]TRACKER'!$C$3:$C$1275,$A4,'[PBMM_Master_Tracker_v2.xlsx]TRACKER'!$D$3:$D$1275,"CP",'[PBMM_Master_Tracker_v2.xlsx]TRACKER'!$G$3:$G$1275,"Accepted Exception"))/COUNTIFS('[PBMM_Master_Tracker_v2.xlsx]TRACKER'!$C$3:$C$1275,$A4,'[PBMM_Master_Tracker_v2.xlsx]TRACKER'!$D$3:$D$1275,"CP"),"") | H4: =IFERROR(1-(COUNTIFS('[PBMM_Master_Tracker_v2.xlsx]TRACKER'!$C$3:$C$1275,$A4,'[PBMM_Master_Tracker_v2.xlsx]TRACKER'!$D$3:$D$1275,"IA",'[PBMM_Master_Tracker_v2.xlsx]TRACKER'!$G$3:$G$1275,"Passed")+COUNTIFS('[PBMM_Master_Tracker_v2.xlsx]TRACKER'!$C$3:$C$1275,$A4,'[PBMM_Master_Tracker_v2.xlsx]TRACKER'!$D$3:$D$1275,"IA",'[PBMM_Master_Tracker_v2.xlsx]TRACKER'!$G$3:$G$1275,"Accepted Exception"))/COUNTIFS('[PBMM_Master_Tracker_v2.xlsx]TRACKER'!$C$3:$C$1275,$A4,'[PBMM_Master_Tracker_v2.xlsx]TRACKER'!$D$3:$D$1275,"IA"),"") | I4: =IFERROR(1-(COUNTIFS('[PBMM_Master_Tracker_v2.xlsx]TRACKER'!$C$3:$C$1275,$A4,'[PBMM_Master_Tracker_v2.xlsx]TRACKER'!$D$3:$D$1275,"IR",'[PBMM_Master_Tracker_v2.xlsx]TRACKER'!$G$3:$G$1275,"Passed")+COUNTIFS('[PBMM_Master_Tracker_v2.xlsx]TRACKER'!$C$3:$C$1275,$A4,'[PBMM_Master_Tracker_v2.xlsx]TRACKER'!$D$3:$D$1275,"IR",'[PBMM_Master_Tracker_v2.xlsx]TRACKER'!$G$3:$G$1275,"Accepted Exception"))/COUNTIFS('[PBMM_Master_Tracker_v2.xlsx]TRACKER'!$C$3:$C$1275,$A4,'[PBMM_Master_Tracker_v2.xlsx]TRACKER'!$D$3:$D$1275,"IR"),"") | J4: =IFERROR(1-(COUNTIFS('[PBMM_Master_Tracker_v2.xlsx]TRACKER'!$C$3:$C$1275,$A4,'[PBMM_Master_Tracker_v2.xlsx]TRACKER'!$D$3:$D$1275,"MA",'[PBMM_Master_Tracker_v2.xlsx]TRACKER'!$G$3:$G$1275,"Passed")+COUNTIFS('[PBMM_Master_Tracker_v2.xlsx]TRACKER'!$C$3:$C$1275,$A4,'[PBMM_Master_Tracker_v2.xlsx]TRACKER'!$D$3:$D$1275,"MA",'[PBMM_Master_Tracker_v2.xlsx]TRACKER'!$G$3:$G$1275,"Accepted Exception"))/COUNTIFS('[PBMM_Master_Tracker_v2.xlsx]TRACKER'!$C$3:$C$1275,$A4,'[PBMM_Master_Tracker_v2.xlsx]TRACKER'!$D$3:$D$1275,"MA"),"") | K4: =IFERROR(1-(COUNTIFS('[PBMM_Master_Tracker_v2.xlsx]TRACKER'!$C$3:$C$1275,$A4,'[PBMM_Master_Tracker_v2.xlsx]TRACKER'!$D$3:$D$1275,"MP",'[PBMM_Master_Tracker_v2.xlsx]TRACKER'!$G$3:$G$1275,"Passed")+COUNTIFS('[PBMM_Master_Tracker_v2.xlsx]TRACKER'!$C$3:$C$1275,$A4,'[PBMM_Master_Tracker_v2.xlsx]TRACKER'!$D$3:$D$1275,"MP",'[PBMM_Master_Tracker_v2.xlsx]TRACKER'!$G$3:$G$1275,"Accepted Exception"))/COUNTIFS('[PBMM_Master_Tracker_v2.xlsx]TRACKER'!$C$3:$C$1275,$A4,'[PBMM_Master_Tracker_v2.xlsx]TRACKER'!$D$3:$D$1275,"MP"),"") | L4: =IFERROR(1-(COUNTIFS('[PBMM_Master_Tracker_v2.xlsx]TRACKER'!$C$3:$C$1275,$A4,'[PBMM_Master_Tracker_v2.xlsx]TRACKER'!$D$3:$D$1275,"PE",'[PBMM_Master_Tracker_v2.xlsx]TRACKER'!$G$3:$G$1275,"Passed")+COUNTIFS('[PBMM_Master_Tracker_v2.xlsx]TRACKER'!$C$3:$C$1275,$A4,'[PBMM_Master_Tracker_v2.xlsx]TRACKER'!$D$3:$D$1275,"PE",'[PBMM_Master_Tracker_v2.xlsx]TRACKER'!$G$3:$G$1275,"Accepted Exception"))/COUNTIFS('[PBMM_Master_Tracker_v2.xlsx]TRACKER'!$C$3:$C$1275,$A4,'[PBMM_Master_Tracker_v2.xlsx]TRACKER'!$D$3:$D$1275,"PE"),"") | M4: =IFERROR(1-(COUNTIFS('[PBMM_Master_Tracker_v2.xlsx]TRACKER'!$C$3:$C$1275,$A4,'[PBMM_Master_Tracker_v2.xlsx]TRACKER'!$D$3:$D$1275,"PL",'[PBMM_Master_Tracker_v2.xlsx]TRACKER'!$G$3:$G$1275,"Passed")+COUNTIFS('[PBMM_Master_Tracker_v2.xlsx]TRACKER'!$C$3:$C$1275,$A4,'[PBMM_Master_Tracker_v2.xlsx]TRACKER'!$D$3:$D$1275,"PL",'[PBMM_Master_Tracker_v2.xlsx]TRACKER'!$G$3:$G$1275,"Accepted Exception"))/COUNTIFS('[PBMM_Master_Tracker_v2.xlsx]TRACKER'!$C$3:$C$1275,$A4,'[PBMM_Master_Tracker_v2.xlsx]TRACKER'!$D$3:$D$1275,"PL"),"") | N4: =IFERROR(1-(COUNTIFS('[PBMM_Master_Tracker_v2.xlsx]TRACKER'!$C$3:$C$1275,$A4,'[PBMM_Master_Tracker_v2.xlsx]TRACKER'!$D$3:$D$1275,"PS",'[PBMM_Master_Tracker_v2.xlsx]TRACKER'!$G$3:$G$1275,"Passed")+COUNTIFS('[PBMM_Master_Tracker_v2.xlsx]TRACKER'!$C$3:$C$1275,$A4,'[PBMM_Master_Tracker_v2.xlsx]TRACKER'!$D$3:$D$1275,"PS",'[PBMM_Master_Tracker_v2.xlsx]TRACKER'!$G$3:$G$1275,"Accepted Exception"))/COUNTIFS('[PBMM_Master_Tracker_v2.xlsx]TRACKER'!$C$3:$C$1275,$A4,'[PBMM_Master_Tracker_v2.xlsx]TRACKER'!$D$3:$D$1275,"PS"),"") | O4: =IFERROR(1-(COUNTIFS('[PBMM_Master_Tracker_v2.xlsx]TRACKER'!$C$3:$C$1275,$A4,'[PBMM_Master_Tracker_v2.xlsx]TRACKER'!$D$3:$D$1275,"RA",'[PBMM_Master_Tracker_v2.xlsx]TRACKER'!$G$3:$G$1275,"Passed")+COUNTIFS('[PBMM_Master_Tracker_v2.xlsx]TRACKER'!$C$3:$C$1275,$A4,'[PBMM_Master_Tracker_v2.xlsx]TRACKER'!$D$3:$D$1275,"RA",'[PBMM_Master_Tracker_v2.xlsx]TRACKER'!$G$3:$G$1275,"Accepted Exception"))/COUNTIFS('[PBMM_Master_Tracker_v2.xlsx]TRACKER'!$C$3:$C$1275,$A4,'[PBMM_Master_Tracker_v2.xlsx]TRACKER'!$D$3:$D$1275,"RA"),"") | P4: =IFERROR(1-(COUNTIFS('[PBMM_Master_Tracker_v2.xlsx]TRACKER'!$C$3:$C$1275,$A4,'[PBMM_Master_Tracker_v2.xlsx]TRACKER'!$D$3:$D$1275,"SA",'[PBMM_Master_Tracker_v2.xlsx]TRACKER'!$G$3:$G$1275,"Passed")+COUNTIFS('[PBMM_Master_Tracker_v2.xlsx]TRACKER'!$C$3:$C$1275,$A4,'[PBMM_Master_Tracker_v2.xlsx]TRACKER'!$D$3:$D$1275,"SA",'[PBMM_Master_Tracker_v2.xlsx]TRACKER'!$G$3:$G$1275,"Accepted Exception"))/COUNTIFS('[PBMM_Master_Tracker_v2.xlsx]TRACKER'!$C$3:$C$1275,$A4,'[PBMM_Master_Tracker_v2.xlsx]TRACKER'!$D$3:$D$1275,"SA"),"") | Q4: =IFERROR(1-(COUNTIFS('[PBMM_Master_Tracker_v2.xlsx]TRACKER'!$C$3:$C$1275,$A4,'[PBMM_Master_Tracker_v2.xlsx]TRACKER'!$D$3:$D$1275,"SC",'[PBMM_Master_Tracker_v2.xlsx]TRACKER'!$G$3:$G$1275,"Passed")+COUNTIFS('[PBMM_Master_Tracker_v2.xlsx]TRACKER'!$C$3:$C$1275,$A4,'[PBMM_Master_Tracker_v2.xlsx]TRACKER'!$D$3:$D$1275,"SC",'[PBMM_Master_Tracker_v2.xlsx]TRACKER'!$G$3:$G$1275,"Accepted Exception"))/COUNTIFS('[PBMM_Master_Tracker_v2.xlsx]TRACKER'!$C$3:$C$1275,$A4,'[PBMM_Master_Tracker_v2.xlsx]TRACKER'!$D$3:$D$1275,"SC"),"") | R4: =IFERROR(1-(COUNTIFS('[PBMM_Master_Tracker_v2.xlsx]TRACKER'!$C$3:$C$1275,$A4,'[PBMM_Master_Tracker_v2.xlsx]TRACKER'!$D$3:$D$1275,"SI",'[PBMM_Master_Tracker_v2.xlsx]TRACKER'!$G$3:$G$1275,"Passed")+COUNTIFS('[PBMM_Master_Tracker_v2.xlsx]TRACKER'!$C$3:$C$1275,$A4,'[PBMM_Master_Tracker_v2.xlsx]TRACKER'!$D$3:$D$1275,"SI",'[PBMM_Master_Tracker_v2.xlsx]TRACKER'!$G$3:$G$1275,"Accepted Exception"))/COUNTIFS('[PBMM_Master_Tracker_v2.xlsx]TRACKER'!$C$3:$C$1275,$A4,'[PBMM_Master_Tracker_v2.xlsx]TRACKER'!$D$3:$D$1275,"SI"),"")
A5: Containers | B5: =IFERROR(1-(COUNTIFS('[PBMM_Master_Tracker_v2.xlsx]TRACKER'!$C$3:$C$1275,$A5,'[PBMM_Master_Tracker_v2.xlsx]TRACKER'!$D$3:$D$1275,"AC",'[PBMM_Master_Tracker_v2.xlsx]TRACKER'!$G$3:$G$1275,"Passed")+COUNTIFS('[PBMM_Master_Tracker_v2.xlsx]TRACKER'!$C$3:$C$1275,$A5,'[PBMM_Master_Tracker_v2.xlsx]TRACKER'!$D$3:$D$1275,"AC",'[PBMM_Master_Tracker_v2.xlsx]TRACKER'!$G$3:$G$1275,"Accepted Exception"))/COUNTIFS('[PBMM_Master_Tracker_v2.xlsx]TRACKER'!$C$3:$C$1275,$A5,'[PBMM_Master_Tracker_v2.xlsx]TRACKER'!$D$3:$D$1275,"AC"),"") | C5: =IFERROR(1-(COUNTIFS('[PBMM_Master_Tracker_v2.xlsx]TRACKER'!$C$3:$C$1275,$A5,'[PBMM_Master_Tracker_v2.xlsx]TRACKER'!$D$3:$D$1275,"AT",'[PBMM_Master_Tracker_v2.xlsx]TRACKER'!$G$3:$G$1275,"Passed")+COUNTIFS('[PBMM_Master_Tracker_v2.xlsx]TRACKER'!$C$3:$C$1275,$A5,'[PBMM_Master_Tracker_v2.xlsx]TRACKER'!$D$3:$D$1275,"AT",'[PBMM_Master_Tracker_v2.xlsx]TRACKER'!$G$3:$G$1275,"Accepted Exception"))/COUNTIFS('[PBMM_Master_Tracker_v2.xlsx]TRACKER'!$C$3:$C$1275,$A5,'[PBMM_Master_Tracker_v2.xlsx]TRACKER'!$D$3:$D$1275,"AT"),"") | D5: =IFERROR(1-(COUNTIFS('[PBMM_Master_Tracker_v2.xlsx]TRACKER'!$C$3:$C$1275,$A5,'[PBMM_Master_Tracker_v2.xlsx]TRACKER'!$D$3:$D$1275,"AU",'[PBMM_Master_Tracker_v2.xlsx]TRACKER'!$G$3:$G$1275,"Passed")+COUNTIFS('[PBMM_Master_Tracker_v2.xlsx]TRACKER'!$C$3:$C$1275,$A5,'[PBMM_Master_Tracker_v2.xlsx]TRACKER'!$D$3:$D$1275,"AU",'[PBMM_Master_Tracker_v2.xlsx]TRACKER'!$G$3:$G$1275,"Accepted Exception"))/COUNTIFS('[PBMM_Master_Tracker_v2.xlsx]TRACKER'!$C$3:$C$1275,$A5,'[PBMM_Master_Tracker_v2.xlsx]TRACKER'!$D$3:$D$1275,"AU"),"") | E5: =IFERROR(1-(COUNTIFS('[PBMM_Master_Tracker_v2.xlsx]TRACKER'!$C$3:$C$1275,$A5,'[PBMM_Master_Tracker_v2.xlsx]TRACKER'!$D$3:$D$1275,"CA",'[PBMM_Master_Tracker_v2.xlsx]TRACKER'!$G$3:$G$1275,"Passed")+COUNTIFS('[PBMM_Master_Tracker_v2.xlsx]TRACKER'!$C$3:$C$1275,$A5,'[PBMM_Master_Tracker_v2.xlsx]TRACKER'!$D$3:$D$1275,"CA",'[PBMM_Master_Tracker_v2.xlsx]TRACKER'!$G$3:$G$1275,"Accepted Exception"))/COUNTIFS('[PBMM_Master_Tracker_v2.xlsx]TRACKER'!$C$3:$C$1275,$A5,'[PBMM_Master_Tracker_v2.xlsx]TRACKER'!$D$3:$D$1275,"CA"),"") | F5: =IFERROR(1-(COUNTIFS('[PBMM_Master_Tracker_v2.xlsx]TRACKER'!$C$3:$C$1275,$A5,'[PBMM_Master_Tracker_v2.xlsx]TRACKER'!$D$3:$D$1275,"CM",'[PBMM_Master_Tracker_v2.xlsx]TRACKER'!$G$3:$G$1275,"Passed")+COUNTIFS('[PBMM_Master_Tracker_v2.xlsx]TRACKER'!$C$3:$C$1275,$A5,'[PBMM_Master_Tracker_v2.xlsx]TRACKER'!$D$3:$D$1275,"CM",'[PBMM_Master_Tracker_v2.xlsx]TRACKER'!$G$3:$G$1275,"Accepted Exception"))/COUNTIFS('[PBMM_Master_Tracker_v2.xlsx]TRACKER'!$C$3:$C$1275,$A5,'[PBMM_Master_Tracker_v2.xlsx]TRACKER'!$D$3:$D$1275,"CM"),"") | G5: =IFERROR(1-(COUNTIFS('[PBMM_Master_Tracker_v2.xlsx]TRACKER'!$C$3:$C$1275,$A5,'[PBMM_Master_Tracker_v2.xlsx]TRACKER'!$D$3:$D$1275,"CP",'[PBMM_Master_Tracker_v2.xlsx]TRACKER'!$G$3:$G$1275,"Passed")+COUNTIFS('[PBMM_Master_Tracker_v2.xlsx]TRACKER'!$C$3:$C$1275,$A5,'[PBMM_Master_Tracker_v2.xlsx]TRACKER'!$D$3:$D$1275,"CP",'[PBMM_Master_Tracker_v2.xlsx]TRACKER'!$G$3:$G$1275,"Accepted Exception"))/COUNTIFS('[PBMM_Master_Tracker_v2.xlsx]TRACKER'!$C$3:$C$1275,$A5,'[PBMM_Master_Tracker_v2.xlsx]TRACKER'!$D$3:$D$1275,"CP"),"") | H5: =IFERROR(1-(COUNTIFS('[PBMM_Master_Tracker_v2.xlsx]TRACKER'!$C$3:$C$1275,$A5,'[PBMM_Master_Tracker_v2.xlsx]TRACKER'!$D$3:$D$1275,"IA",'[PBMM_Master_Tracker_v2.xlsx]TRACKER'!$G$3:$G$1275,"Passed")+COUNTIFS('[PBMM_Master_Tracker_v2.xlsx]TRACKER'!$C$3:$C$1275,$A5,'[PBMM_Master_Tracker_v2.xlsx]TRACKER'!$D$3:$D$1275,"IA",'[PBMM_Master_Tracker_v2.xlsx]TRACKER'!$G$3:$G$1275,"Accepted Exception"))/COUNTIFS('[PBMM_Master_Tracker_v2.xlsx]TRACKER'!$C$3:$C$1275,$A5,'[PBMM_Master_Tracker_v2.xlsx]TRACKER'!$D$3:$D$1275,"IA"),"") | I5: =IFERROR(1-(COUNTIFS('[PBMM_Master_Tracker_v2.xlsx]TRACKER'!$C$3:$C$1275,$A5,'[PBMM_Master_Tracker_v2.xlsx]TRACKER'!$D$3:$D$1275,"IR",'[PBMM_Master_Tracker_v2.xlsx]TRACKER'!$G$3:$G$1275,"Passed")+COUNTIFS('[PBMM_Master_Tracker_v2.xlsx]TRACKER'!$C$3:$C$1275,$A5,'[PBMM_Master_Tracker_v2.xlsx]TRACKER'!$D$3:$D$1275,"IR",'[PBMM_Master_Tracker_v2.xlsx]TRACKER'!$G$3:$G$1275,"Accepted Exception"))/COUNTIFS('[PBMM_Master_Tracker_v2.xlsx]TRACKER'!$C$3:$C$1275,$A5,'[PBMM_Master_Tracker_v2.xlsx]TRACKER'!$D$3:$D$1275,"IR"),"") | J5: =IFERROR(1-(COUNTIFS('[PBMM_Master_Tracker_v2.xlsx]TRACKER'!$C$3:$C$1275,$A5,'[PBMM_Master_Tracker_v2.xlsx]TRACKER'!$D$3:$D$1275,"MA",'[PBMM_Master_Tracker_v2.xlsx]TRACKER'!$G$3:$G$1275,"Passed")+COUNTIFS('[PBMM_Master_Tracker_v2.xlsx]TRACKER'!$C$3:$C$1275,$A5,'[PBMM_Master_Tracker_v2.xlsx]TRACKER'!$D$3:$D$1275,"MA",'[PBMM_Master_Tracker_v2.xlsx]TRACKER'!$G$3:$G$1275,"Accepted Exception"))/COUNTIFS('[PBMM_Master_Tracker_v2.xlsx]TRACKER'!$C$3:$C$1275,$A5,'[PBMM_Master_Tracker_v2.xlsx]TRACKER'!$D$3:$D$1275,"MA"),"") | K5: =IFERROR(1-(COUNTIFS('[PBMM_Master_Tracker_v2.xlsx]TRACKER'!$C$3:$C$1275,$A5,'[PBMM_Master_Tracker_v2.xlsx]TRACKER'!$D$3:$D$1275,"MP",'[PBMM_Master_Tracker_v2.xlsx]TRACKER'!$G$3:$G$1275,"Passed")+COUNTIFS('[PBMM_Master_Tracker_v2.xlsx]TRACKER'!$C$3:$C$1275,$A5,'[PBMM_Master_Tracker_v2.xlsx]TRACKER'!$D$3:$D$1275,"MP",'[PBMM_Master_Tracker_v2.xlsx]TRACKER'!$G$3:$G$1275,"Accepted Exception"))/COUNTIFS('[PBMM_Master_Tracker_v2.xlsx]TRACKER'!$C$3:$C$1275,$A5,'[PBMM_Master_Tracker_v2.xlsx]TRACKER'!$D$3:$D$1275,"MP"),"") | L5: =IFERROR(1-(COUNTIFS('[PBMM_Master_Tracker_v2.xlsx]TRACKER'!$C$3:$C$1275,$A5,'[PBMM_Master_Tracker_v2.xlsx]TRACKER'!$D$3:$D$1275,"PE",'[PBMM_Master_Tracker_v2.xlsx]TRACKER'!$G$3:$G$1275,"Passed")+COUNTIFS('[PBMM_Master_Tracker_v2.xlsx]TRACKER'!$C$3:$C$1275,$A5,'[PBMM_Master_Tracker_v2.xlsx]TRACKER'!$D$3:$D$1275,"PE",'[PBMM_Master_Tracker_v2.xlsx]TRACKER'!$G$3:$G$1275,"Accepted Exception"))/COUNTIFS('[PBMM_Master_Tracker_v2.xlsx]TRACKER'!$C$3:$C$1275,$A5,'[PBMM_Master_Tracker_v2.xlsx]TRACKER'!$D$3:$D$1275,"PE"),"") | M5: =IFERROR(1-(COUNTIFS('[PBMM_Master_Tracker_v2.xlsx]TRACKER'!$C$3:$C$1275,$A5,'[PBMM_Master_Tracker_v2.xlsx]TRACKER'!$D$3:$D$1275,"PL",'[PBMM_Master_Tracker_v2.xlsx]TRACKER'!$G$3:$G$1275,"Passed")+COUNTIFS('[PBMM_Master_Tracker_v2.xlsx]TRACKER'!$C$3:$C$1275,$A5,'[PBMM_Master_Tracker_v2.xlsx]TRACKER'!$D$3:$D$1275,"PL",'[PBMM_Master_Tracker_v2.xlsx]TRACKER'!$G$3:$G$1275,"Accepted Exception"))/COUNTIFS('[PBMM_Master_Tracker_v2.xlsx]TRACKER'!$C$3:$C$1275,$A5,'[PBMM_Master_Tracker_v2.xlsx]TRACKER'!$D$3:$D$1275,"PL"),"") | N5: =IFERROR(1-(COUNTIFS('[PBMM_Master_Tracker_v2.xlsx]TRACKER'!$C$3:$C$1275,$A5,'[PBMM_Master_Tracker_v2.xlsx]TRACKER'!$D$3:$D$1275,"PS",'[PBMM_Master_Tracker_v2.xlsx]TRACKER'!$G$3:$G$1275,"Passed")+COUNTIFS('[PBMM_Master_Tracker_v2.xlsx]TRACKER'!$C$3:$C$1275,$A5,'[PBMM_Master_Tracker_v2.xlsx]TRACKER'!$D$3:$D$1275,"PS",'[PBMM_Master_Tracker_v2.xlsx]TRACKER'!$G$3:$G$1275,"Accepted Exception"))/COUNTIFS('[PBMM_Master_Tracker_v2.xlsx]TRACKER'!$C$3:$C$1275,$A5,'[PBMM_Master_Tracker_v2.xlsx]TRACKER'!$D$3:$D$1275,"PS"),"") | O5: =IFERROR(1-(COUNTIFS('[PBMM_Master_Tracker_v2.xlsx]TRACKER'!$C$3:$C$1275,$A5,'[PBMM_Master_Tracker_v2.xlsx]TRACKER'!$D$3:$D$1275,"RA",'[PBMM_Master_Tracker_v2.xlsx]TRACKER'!$G$3:$G$1275,"Passed")+COUNTIFS('[PBMM_Master_Tracker_v2.xlsx]TRACKER'!$C$3:$C$1275,$A5,'[PBMM_Master_Tracker_v2.xlsx]TRACKER'!$D$3:$D$1275,"RA",'[PBMM_Master_Tracker_v2.xlsx]TRACKER'!$G$3:$G$1275,"Accepted Exception"))/COUNTIFS('[PBMM_Master_Tracker_v2.xlsx]TRACKER'!$C$3:$C$1275,$A5,'[PBMM_Master_Tracker_v2.xlsx]TRACKER'!$D$3:$D$1275,"RA"),"") | P5: =IFERROR(1-(COUNTIFS('[PBMM_Master_Tracker_v2.xlsx]TRACKER'!$C$3:$C$1275,$A5,'[PBMM_Master_Tracker_v2.xlsx]TRACKER'!$D$3:$D$1275,"SA",'[PBMM_Master_Tracker_v2.xlsx]TRACKER'!$G$3:$G$1275,"Passed")+COUNTIFS('[PBMM_Master_Tracker_v2.xlsx]TRACKER'!$C$3:$C$1275,$A5,'[PBMM_Master_Tracker_v2.xlsx]TRACKER'!$D$3:$D$1275,"SA",'[PBMM_Master_Tracker_v2.xlsx]TRACKER'!$G$3:$G$1275,"Accepted Exception"))/COUNTIFS('[PBMM_Master_Tracker_v2.xlsx]TRACKER'!$C$3:$C$1275,$A5,'[PBMM_Master_Tracker_v2.xlsx]TRACKER'!$D$3:$D$1275,"SA"),"") | Q5: =IFERROR(1-(COUNTIFS('[PBMM_Master_Tracker_v2.xlsx]TRACKER'!$C$3:$C$1275,$A5,'[PBMM_Master_Tracker_v2.xlsx]TRACKER'!$D$3:$D$1275,"SC",'[PBMM_Master_Tracker_v2.xlsx]TRACKER'!$G$3:$G$1275,"Passed")+COUNTIFS('[PBMM_Master_Tracker_v2.xlsx]TRACKER'!$C$3:$C$1275,$A5,'[PBMM_Master_Tracker_v2.xlsx]TRACKER'!$D$3:$D$1275,"SC",'[PBMM_Master_Tracker_v2.xlsx]TRACKER'!$G$3:$G$1275,"Accepted Exception"))/COUNTIFS('[PBMM_Master_Tracker_v2.xlsx]TRACKER'!$C$3:$C$1275,$A5,'[PBMM_Master_Tracker_v2.xlsx]TRACKER'!$D$3:$D$1275,"SC"),"") | R5: =IFERROR(1-(COUNTIFS('[PBMM_Master_Tracker_v2.xlsx]TRACKER'!$C$3:$C$1275,$A5,'[PBMM_Master_Tracker_v2.xlsx]TRACKER'!$D$3:$D$1275,"SI",'[PBMM_Master_Tracker_v2.xlsx]TRACKER'!$G$3:$G$1275,"Passed")+COUNTIFS('[PBMM_Master_Tracker_v2.xlsx]TRACKER'!$C$3:$C$1275,$A5,'[PBMM_Master_Tracker_v2.xlsx]TRACKER'!$D$3:$D$1275,"SI",'[PBMM_Master_Tracker_v2.xlsx]TRACKER'!$G$3:$G$1275,"Accepted Exception"))/COUNTIFS('[PBMM_Master_Tracker_v2.xlsx]TRACKER'!$C$3:$C$1275,$A5,'[PBMM_Master_Tracker_v2.xlsx]TRACKER'!$D$3:$D$1275,"SI"),"")
A6: Database | B6: =IFERROR(1-(COUNTIFS('[PBMM_Master_Tracker_v2.xlsx]TRACKER'!$C$3:$C$1275,$A6,'[PBMM_Master_Tracker_v2.xlsx]TRACKER'!$D$3:$D$1275,"AC",'[PBMM_Master_Tracker_v2.xlsx]TRACKER'!$G$3:$G$1275,"Passed")+COUNTIFS('[PBMM_Master_Tracker_v2.xlsx]TRACKER'!$C$3:$C$1275,$A6,'[PBMM_Master_Tracker_v2.xlsx]TRACKER'!$D$3:$D$1275,"AC",'[PBMM_Master_Tracker_v2.xlsx]TRACKER'!$G$3:$G$1275,"Accepted Exception"))/COUNTIFS('[PBMM_Master_Tracker_v2.xlsx]TRACKER'!$C$3:$C$1275,$A6,'[PBMM_Master_Tracker_v2.xlsx]TRACKER'!$D$3:$D$1275,"AC"),"") | C6: =IFERROR(1-(COUNTIFS('[PBMM_Master_Tracker_v2.xlsx]TRACKER'!$C$3:$C$1275,$A6,'[PBMM_Master_Tracker_v2.xlsx]TRACKER'!$D$3:$D$1275,"AT",'[PBMM_Master_Tracker_v2.xlsx]TRACKER'!$G$3:$G$1275,"Passed")+COUNTIFS('[PBMM_Master_Tracker_v2.xlsx]TRACKER'!$C$3:$C$1275,$A6,'[PBMM_Master_Tracker_v2.xlsx]TRACKER'!$D$3:$D$1275,"AT",'[PBMM_Master_Tracker_v2.xlsx]TRACKER'!$G$3:$G$1275,"Accepted Exception"))/COUNTIFS('[PBMM_Master_Tracker_v2.xlsx]TRACKER'!$C$3:$C$1275,$A6,'[PBMM_Master_Tracker_v2.xlsx]TRACKER'!$D$3:$D$1275,"AT"),"") | D6: =IFERROR(1-(COUNTIFS('[PBMM_Master_Tracker_v2.xlsx]TRACKER'!$C$3:$C$1275,$A6,'[PBMM_Master_Tracker_v2.xlsx]TRACKER'!$D$3:$D$1275,"AU",'[PBMM_Master_Tracker_v2.xlsx]TRACKER'!$G$3:$G$1275,"Passed")+COUNTIFS('[PBMM_Master_Tracker_v2.xlsx]TRACKER'!$C$3:$C$1275,$A6,'[PBMM_Master_Tracker_v2.xlsx]TRACKER'!$D$3:$D$1275,"AU",'[PBMM_Master_Tracker_v2.xlsx]TRACKER'!$G$3:$G$1275,"Accepted Exception"))/COUNTIFS('[PBMM_Master_Tracker_v2.xlsx]TRACKER'!$C$3:$C$1275,$A6,'[PBMM_Master_Tracker_v2.xlsx]TRACKER'!$D$3:$D$1275,"AU"),"") | E6: =IFERROR(1-(COUNTIFS('[PBMM_Master_Tracker_v2.xlsx]TRACKER'!$C$3:$C$1275,$A6,'[PBMM_Master_Tracker_v2.xlsx]TRACKER'!$D$3:$D$1275,"CA",'[PBMM_Master_Tracker_v2.xlsx]TRACKER'!$G$3:$G$1275,"Passed")+COUNTIFS('[PBMM_Master_Tracker_v2.xlsx]TRACKER'!$C$3:$C$1275,$A6,'[PBMM_Master_Tracker_v2.xlsx]TRACKER'!$D$3:$D$1275,"CA",'[PBMM_Master_Tracker_v2.xlsx]TRACKER'!$G$3:$G$1275,"Accepted Exception"))/COUNTIFS('[PBMM_Master_Tracker_v2.xlsx]TRACKER'!$C$3:$C$1275,$A6,'[PBMM_Master_Tracker_v2.xlsx]TRACKER'!$D$3:$D$1275,"CA"),"") | F6: =IFERROR(1-(COUNTIFS('[PBMM_Master_Tracker_v2.xlsx]TRACKER'!$C$3:$C$1275,$A6,'[PBMM_Master_Tracker_v2.xlsx]TRACKER'!$D$3:$D$1275,"CM",'[PBMM_Master_Tracker_v2.xlsx]TRACKER'!$G$3:$G$1275,"Passed")+COUNTIFS('[PBMM_Master_Tracker_v2.xlsx]TRACKER'!$C$3:$C$1275,$A6,'[PBMM_Master_Tracker_v2.xlsx]TRACKER'!$D$3:$D$1275,"CM",'[PBMM_Master_Tracker_v2.xlsx]TRACKER'!$G$3:$G$1275,"Accepted Exception"))/COUNTIFS('[PBMM_Master_Tracker_v2.xlsx]TRACKER'!$C$3:$C$1275,$A6,'[PBMM_Master_Tracker_v2.xlsx]TRACKER'!$D$3:$D$1275,"CM"),"") | G6: =IFERROR(1-(COUNTIFS('[PBMM_Master_Tracker_v2.xlsx]TRACKER'!$C$3:$C$1275,$A6,'[PBMM_Master_Tracker_v2.xlsx]TRACKER'!$D$3:$D$1275,"CP",'[PBMM_Master_Tracker_v2.xlsx]TRACKER'!$G$3:$G$1275,"Passed")+COUNTIFS('[PBMM_Master_Tracker_v2.xlsx]TRACKER'!$C$3:$C$1275,$A6,'[PBMM_Master_Tracker_v2.xlsx]TRACKER'!$D$3:$D$1275,"CP",'[PBMM_Master_Tracker_v2.xlsx]TRACKER'!$G$3:$G$1275,"Accepted Exception"))/COUNTIFS('[PBMM_Master_Tracker_v2.xlsx]TRACKER'!$C$3:$C$1275,$A6,'[PBMM_Master_Tracker_v2.xlsx]TRACKER'!$D$3:$D$1275,"CP"),"") | H6: =IFERROR(1-(COUNTIFS('[PBMM_Master_Tracker_v2.xlsx]TRACKER'!$C$3:$C$1275,$A6,'[PBMM_Master_Tracker_v2.xlsx]TRACKER'!$D$3:$D$1275,"IA",'[PBMM_Master_Tracker_v2.xlsx]TRACKER'!$G$3:$G$1275,"Passed")+COUNTIFS('[PBMM_Master_Tracker_v2.xlsx]TRACKER'!$C$3:$C$1275,$A6,'[PBMM_Master_Tracker_v2.xlsx]TRACKER'!$D$3:$D$1275,"IA",'[PBMM_Master_Tracker_v2.xlsx]TRACKER'!$G$3:$G$1275,"Accepted Exception"))/COUNTIFS('[PBMM_Master_Tracker_v2.xlsx]TRACKER'!$C$3:$C$1275,$A6,'[PBMM_Master_Tracker_v2.xlsx]TRACKER'!$D$3:$D$1275,"IA"),"") | I6: =IFERROR(1-(COUNTIFS('[PBMM_Master_Tracker_v2.xlsx]TRACKER'!$C$3:$C$1275,$A6,'[PBMM_Master_Tracker_v2.xlsx]TRACKER'!$D$3:$D$1275,"IR",'[PBMM_Master_Tracker_v2.xlsx]TRACKER'!$G$3:$G$1275,"Passed")+COUNTIFS('[PBMM_Master_Tracker_v2.xlsx]TRACKER'!$C$3:$C$1275,$A6,'[PBMM_Master_Tracker_v2.xlsx]TRACKER'!$D$3:$D$1275,"IR",'[PBMM_Master_Tracker_v2.xlsx]TRACKER'!$G$3:$G$1275,"Accepted Exception"))/COUNTIFS('[PBMM_Master_Tracker_v2.xlsx]TRACKER'!$C$3:$C$1275,$A6,'[PBMM_Master_Tracker_v2.xlsx]TRACKER'!$D$3:$D$1275,"IR"),"") | J6: =IFERROR(1-(COUNTIFS('[PBMM_Master_Tracker_v2.xlsx]TRACKER'!$C$3:$C$1275,$A6,'[PBMM_Master_Tracker_v2.xlsx]TRACKER'!$D$3:$D$1275,"MA",'[PBMM_Master_Tracker_v2.xlsx]TRACKER'!$G$3:$G$1275,"Passed")+COUNTIFS('[PBMM_Master_Tracker_v2.xlsx]TRACKER'!$C$3:$C$1275,$A6,'[PBMM_Master_Tracker_v2.xlsx]TRACKER'!$D$3:$D$1275,"MA",'[PBMM_Master_Tracker_v2.xlsx]TRACKER'!$G$3:$G$1275,"Accepted Exception"))/COUNTIFS('[PBMM_Master_Tracker_v2.xlsx]TRACKER'!$C$3:$C$1275,$A6,'[PBMM_Master_Tracker_v2.xlsx]TRACKER'!$D$3:$D$1275,"MA"),"") | K6: =IFERROR(1-(COUNTIFS('[PBMM_Master_Tracker_v2.xlsx]TRACKER'!$C$3:$C$1275,$A6,'[PBMM_Master_Tracker_v2.xlsx]TRACKER'!$D$3:$D$1275,"MP",'[PBMM_Master_Tracker_v2.xlsx]TRACKER'!$G$3:$G$1275,"Passed")+COUNTIFS('[PBMM_Master_Tracker_v2.xlsx]TRACKER'!$C$3:$C$1275,$A6,'[PBMM_Master_Tracker_v2.xlsx]TRACKER'!$D$3:$D$1275,"MP",'[PBMM_Master_Tracker_v2.xlsx]TRACKER'!$G$3:$G$1275,"Accepted Exception"))/COUNTIFS('[PBMM_Master_Tracker_v2.xlsx]TRACKER'!$C$3:$C$1275,$A6,'[PBMM_Master_Tracker_v2.xlsx]TRACKER'!$D$3:$D$1275,"MP"),"") | L6: =IFERROR(1-(COUNTIFS('[PBMM_Master_Tracker_v2.xlsx]TRACKER'!$C$3:$C$1275,$A6,'[PBMM_Master_Tracker_v2.xlsx]TRACKER'!$D$3:$D$1275,"PE",'[PBMM_Master_Tracker_v2.xlsx]TRACKER'!$G$3:$G$1275,"Passed")+COUNTIFS('[PBMM_Master_Tracker_v2.xlsx]TRACKER'!$C$3:$C$1275,$A6,'[PBMM_Master_Tracker_v2.xlsx]TRACKER'!$D$3:$D$1275,"PE",'[PBMM_Master_Tracker_v2.xlsx]TRACKER'!$G$3:$G$1275,"Accepted Exception"))/COUNTIFS('[PBMM_Master_Tracker_v2.xlsx]TRACKER'!$C$3:$C$1275,$A6,'[PBMM_Master_Tracker_v2.xlsx]TRACKER'!$D$3:$D$1275,"PE"),"") | M6: =IFERROR(1-(COUNTIFS('[PBMM_Master_Tracker_v2.xlsx]TRACKER'!$C$3:$C$1275,$A6,'[PBMM_Master_Tracker_v2.xlsx]TRACKER'!$D$3:$D$1275,"PL",'[PBMM_Master_Tracker_v2.xlsx]TRACKER'!$G$3:$G$1275,"Passed")+COUNTIFS('[PBMM_Master_Tracker_v2.xlsx]TRACKER'!$C$3:$C$1275,$A6,'[PBMM_Master_Tracker_v2.xlsx]TRACKER'!$D$3:$D$1275,"PL",'[PBMM_Master_Tracker_v2.xlsx]TRACKER'!$G$3:$G$1275,"Accepted Exception"))/COUNTIFS('[PBMM_Master_Tracker_v2.xlsx]TRACKER'!$C$3:$C$1275,$A6,'[PBMM_Master_Tracker_v2.xlsx]TRACKER'!$D$3:$D$1275,"PL"),"") | N6: =IFERROR(1-(COUNTIFS('[PBMM_Master_Tracker_v2.xlsx]TRACKER'!$C$3:$C$1275,$A6,'[PBMM_Master_Tracker_v2.xlsx]TRACKER'!$D$3:$D$1275,"PS",'[PBMM_Master_Tracker_v2.xlsx]TRACKER'!$G$3:$G$1275,"Passed")+COUNTIFS('[PBMM_Master_Tracker_v2.xlsx]TRACKER'!$C$3:$C$1275,$A6,'[PBMM_Master_Tracker_v2.xlsx]TRACKER'!$D$3:$D$1275,"PS",'[PBMM_Master_Tracker_v2.xlsx]TRACKER'!$G$3:$G$1275,"Accepted Exception"))/COUNTIFS('[PBMM_Master_Tracker_v2.xlsx]TRACKER'!$C$3:$C$1275,$A6,'[PBMM_Master_Tracker_v2.xlsx]TRACKER'!$D$3:$D$1275,"PS"),"") | O6: =IFERROR(1-(COUNTIFS('[PBMM_Master_Tracker_v2.xlsx]TRACKER'!$C$3:$C$1275,$A6,'[PBMM_Master_Tracker_v2.xlsx]TRACKER'!$D$3:$D$1275,"RA",'[PBMM_Master_Tracker_v2.xlsx]TRACKER'!$G$3:$G$1275,"Passed")+COUNTIFS('[PBMM_Master_Tracker_v2.xlsx]TRACKER'!$C$3:$C$1275,$A6,'[PBMM_Master_Tracker_v2.xlsx]TRACKER'!$D$3:$D$1275,"RA",'[PBMM_Master_Tracker_v2.xlsx]TRACKER'!$G$3:$G$1275,"Accepted Exception"))/COUNTIFS('[PBMM_Master_Tracker_v2.xlsx]TRACKER'!$C$3:$C$1275,$A6,'[PBMM_Master_Tracker_v2.xlsx]TRACKER'!$D$3:$D$1275,"RA"),"") | P6: =IFERROR(1-(COUNTIFS('[PBMM_Master_Tracker_v2.xlsx]TRACKER'!$C$3:$C$1275,$A6,'[PBMM_Master_Tracker_v2.xlsx]TRACKER'!$D$3:$D$1275,"SA",'[PBMM_Master_Tracker_v2.xlsx]TRACKER'!$G$3:$G$1275,"Passed")+COUNTIFS('[PBMM_Master_Tracker_v2.xlsx]TRACKER'!$C$3:$C$1275,$A6,'[PBMM_Master_Tracker_v2.xlsx]TRACKER'!$D$3:$D$1275,"SA",'[PBMM_Master_Tracker_v2.xlsx]TRACKER'!$G$3:$G$1275,"Accepted Exception"))/COUNTIFS('[PBMM_Master_Tracker_v2.xlsx]TRACKER'!$C$3:$C$1275,$A6,'[PBMM_Master_Tracker_v2.xlsx]TRACKER'!$D$3:$D$1275,"SA"),"") | Q6: =IFERROR(1-(COUNTIFS('[PBMM_Master_Tracker_v2.xlsx]TRACKER'!$C$3:$C$1275,$A6,'[PBMM_Master_Tracker_v2.xlsx]TRACKER'!$D$3:$D$1275,"SC",'[PBMM_Master_Tracker_v2.xlsx]TRACKER'!$G$3:$G$1275,"Passed")+COUNTIFS('[PBMM_Master_Tracker_v2.xlsx]TRACKER'!$C$3:$C$1275,$A6,'[PBMM_Master_Tracker_v2.xlsx]TRACKER'!$D$3:$D$1275,"SC",'[PBMM_Master_Tracker_v2.xlsx]TRACKER'!$G$3:$G$1275,"Accepted Exception"))/COUNTIFS('[PBMM_Master_Tracker_v2.xlsx]TRACKER'!$C$3:$C$1275,$A6,'[PBMM_Master_Tracker_v2.xlsx]TRACKER'!$D$3:$D$1275,"SC"),"") | R6: =IFERROR(1-(COUNTIFS('[PBMM_Master_Tracker_v2.xlsx]TRACKER'!$C$3:$C$1275,$A6,'[PBMM_Master_Tracker_v2.xlsx]TRACKER'!$D$3:$D$1275,"SI",'[PBMM_Master_Tracker_v2.xlsx]TRACKER'!$G$3:$G$1275,"Passed")+COUNTIFS('[PBMM_Master_Tracker_v2.xlsx]TRACKER'!$C$3:$C$1275,$A6,'[PBMM_Master_Tracker_v2.xlsx]TRACKER'!$D$3:$D$1275,"SI",'[PBMM_Master_Tracker_v2.xlsx]TRACKER'!$G$3:$G$1275,"Accepted Exception"))/COUNTIFS('[PBMM_Master_Tracker_v2.xlsx]TRACKER'!$C$3:$C$1275,$A6,'[PBMM_Master_Tracker_v2.xlsx]TRACKER'!$D$3:$D$1275,"SI"),"")
