Workbook

Sheet HOW TO USE
A1: PBMM Evidence Master Tracker — User Guide
A2: How It Works | B2: Status (EN) and Status (FR) columns pull LIVE from each technology workbook. Update a status dropdown in any workbook and the tracker reflects it automatically.
A3: SharePoint Setup | B3: Upload ALL workbook files AND this tracker to the SAME SharePoint document library. Do NOT save locally first — upload directly. Open this tracker FROM SharePoint and Excel will resolve the links to co-located workbooks automatically.
A4: If Links Show #REF! | B4: 1. Open in Excel Desktop (not Excel Online) 2. Data tab > Edit Links 3. Change Source for any broken link 4. Navigate to the SharePoint library 5. Select the correct workbook 6. Click Update Values
A5: Workbooks Tracked | B5: Analytics.xlsx, Compute.xlsx, Containers.xlsx, Database.xlsx, DevOps.xlsx, Developer_Tools.xlsx, Documentation.xlsx, Hybrid_and_Multicloud.xlsx, Identity.xlsx, Management_and_Governance.xlsx, Microsoft_Descoped.xlsx, Networking.xlsx, Palo_Alto_Firewalls.xlsx, Panorama.xlsx, Security.xlsx, ServiceNow.xlsx, Storage.xlsx, Tenable_Nessus.xlsx, Tenable_Security_Centre_Plus.xlsx, Virtual_Desktop_Infrastructure.xlsx, Web.xlsx

Sheet TRACKER
A1: PBMM / CCCS Medium — Master Evidence Tracker (LIVE) — 21 Workbooks | M1: =TODAY()
A2: Control ID | B2: Control Name | C2: Technology | D2: Family | E2: Source Workbook | F2: Tab | G2: Status (EN) | H2: RAG (EN) | I2: Status (FR) | J2: RAG (FR) | K2: Preparer | L2: Owner | M2: Updated
A3: AU-2 | B3: Auditable Events | C3: Analytics | D3: AU | E3: Analytics | F3: AU-2 | G3: =IFERROR('[Analytics.xlsx]AU-2'!B20,"Not Started") | H3: =IF(OR(G3="Passed",G3="Accepted Exception"),"GREEN",IF(OR(G3="Not Started",G3="Failed"),"RED","AMBER")) | I3: =IFERROR('[Analytics.xlsx]AU-2'!E20,"Non commencé") | J3: =IF(OR(I3="Réussi",I3="Exception acceptée"),"GREEN",IF(OR(I3="Non commencé",I3="Échec"),"RED","AMBER"))
A4: AU-3 | B4: Content of Audit Records | C4: Analytics | D4: AU | E4: Analytics | F4: AU-3 | G4: =IFERROR('[Analytics.xlsx]AU-3'!B20,"Not Started") | H4: =IF(OR(G4="Passed",G4="Accepted Exception"),"GREEN",IF(OR(G4="Not Started",G4="Failed"),"RED","AMBER")) | I4: =IFERROR('[Analytics.xlsx]AU-3'!E20,"Non commencé") | J4: =IF(OR(I4="Réussi",I4="Exception acceptée"),"GREEN",IF(OR(I4="Non commencé",I4="Échec"),"RED","AMBER"))
A5: AU-3(1) | B5: Content of Audit Records | C5: Analytics | D5: AU | E5: Analytics | F5: AU-3-1 | G5: =IFERROR('[Analytics.xlsx]AU-3-1'!B20,"Not Started") | H5: =IF(OR(G5="Passed",G5="Accepted Exception"),"GREEN",IF(OR(G5="Not Started",G5="Failed"),"RED","AMBER")) | I5: =IFERROR('[Analytics.xlsx]AU-3-1'!E20,"Non commencé") | J5: =IF(OR(I5="Réussi",I5="Exception acceptée"),"GREEN",IF(OR(I5="Non commencé",I5="Échec"),"RED","AMBER"))
A6: AU-5 | B6: Response To Audit Processing Failures | C6: Analytics | D6: AU | E6: Analytics | F6: AU-5 | G6: =IFERROR('[Analytics.xlsx]AU-5'!B20,"Not Started") | H6: =IF(OR(G6="Passed",G6="Accepted Exception"),"GREEN",IF(OR(G6="Not Started",G6="Failed"),"RED","AMBER")) | I6: =IFERROR('[Analytics.xlsx]AU-5'!E20,"Non commencé") | J6: =IF(OR(I6="Réussi",I6="Exception acceptée"),"GREEN",IF(OR(I6="Non commencé",I6="Échec"),"RED","AMBER"))
A7: AU-9(2) | B7: Protection of Audit Information | C7: Analytics | D7: AU | E7: Analytics | F7: AU-9-2 | G7: =IFERROR('[Analytics.xlsx]AU-9-2'!B20,"Not Started") | H7: =IF(OR(G7="Passed",G7="Accepted Exception"),"GREEN",IF(OR(G7="Not Started",G7="Failed"),"RED","AMBER")) | I7: =IFERROR('[Analytics.xlsx]AU-9-2'!E20,"Non commencé") | J7: =IF(OR(I7="Réussi",I7="Exception acceptée"),"GREEN",IF(OR(I7="Non commencé",I7="Échec"),"RED","AMBER"))
A8: AU-12 | B8: Audit Generation | C8: Analytics | D8: AU | E8: Analytics | F8: AU-12 | G8: =IFERROR('[Analytics.xlsx]AU-12'!B20,"Not Started") | H8: =IF(OR(G8="Passed",G8="Accepted Exception"),"GREEN",IF(OR(G8="Not Started",G8="Failed"),"RED","AMBER")) | I8: =IFERROR('[Analytics.xlsx]AU-12'!E20,"Non commencé") | J8: =IF(OR(I8="Réussi",I8="Exception acceptée"),"GREEN",IF(OR(I8="Non commencé",I8="Échec"),"RED","AMBER"))
A9: CM-2(3) | B9: Baseline Configuration | C9: Analytics | D9: CM | E9: Analytics | F9: CM-2-3 | G9: =IFERROR('[Analytics.xlsx]CM-2-3'!B20,"Not Started") | H9: =IF(OR(G9="Passed",G9="Accepted Exception"),"GREEN",IF(OR(G9="Not Started",G9="Failed"),"RED","AMBER")) | I9: =IFERROR('[Analytics.xlsx]CM-2-3'!E20,"Non commencé") | J9: =IF(OR(I9="Réussi",I9="Exception acceptée"),"GREEN",IF(OR(I9="Non commencé",I9="Échec"),"RED","AMBER"))
A10: CM-5(1) | B10: Access Restrictions for Change | C10: Analytics | D10: CM | E10: Analytics | F10: CM-5-1 | G10: =IFERROR('[Analytics.xlsx]CM-5-1'!B20,"Not Started") | H10: =IF(OR(G10="Passed",G10="Accepted Exception"),"GREEN",IF(OR(G10="Not Started",G10="Failed"),"RED","AMBER")) | I10: =IFERROR('[Analytics.xlsx]CM-5-1'!E20,"Non commencé") | J10: =IF(OR(I10="Réussi",I10="Exception acceptée"),"GREEN",IF(OR(I10="Non commencé",I10="Échec"),"RED","AMBER"))
A11: CM-6 | B11: Configuration Settings | C11: Analytics | D11: CM | E11: Analytics | F11: CM-6 | G11: =IFERROR('[Analytics.xlsx]CM-6'!B20,"Not Started") | H11: =IF(OR(G11="Passed",G11="Accepted Exception"),"GREEN",IF(OR(G11="Not Started",G11="Failed"),"RED","AMBER")) | I11: =IFERROR('[Analytics.xlsx]CM-6'!E20,"Non commencé") | J11: =IF(OR(I11="Réussi",I11="Exception acceptée"),"GREEN",IF(OR(I11="Non commencé",I11="Échec"),"RED","AMBER"))
A12: CM-7 | B12: Least Functionality | C12: Analytics | D12: CM | E12: Analytics | F12: CM-7 | G12: =IFERROR('[Analytics.xlsx]CM-7'!B20,"Not Started") | H12: =IF(OR(G12="Passed",G12="Accepted Exception"),"GREEN",IF(OR(G12="Not Started",G12="Failed"),"RED","AMBER")) | I12: =IFERROR('[Analytics.xlsx]CM-7'!E20,"Non commencé") | J12: =IF(OR(I12="Réussi",I12="Exception acceptée"),"GREEN",IF(OR(I12="Non commencé",I12="Échec"),"RED","AMBER"))
A13: CM-7(1) | B13: Least Functionality | C13: Analytics | D13: CM | E13: Analytics | F13: CM-7-1 | G13: =IFERROR('[Analytics.xlsx]CM-7-1'!B20,"Not Started") | H13: =IF(OR(G13="Passed",G13="Accepted Exception"),"GREEN",IF(OR(G13="Not Started",G13="Failed"),"RED","AMBER")) | I13: =IFERROR('[Analytics.xlsx]CM-7-1'!E20,"Non commencé") | J13: =IF(OR(I13="Réussi",I13="Exception acceptée"),"GREEN",IF(OR(I13="Non commencé",I13="Échec"),"RED","AMBER"))
A14: CP-6 | B14: Alternate Storage Site | C14: Analytics | D14: CP | E14: Analytics | F14: CP-6 | G14: =IFERROR('[Analytics.xlsx]CP-6'!B20,"Not Started") | H14: =IF(OR(G14="Passed",G14="Accepted Exception"),"GREEN",IF(OR(G14="Not Started",G14="Failed"),"RED","AMBER")) | I14: =IFERROR('[Analytics.xlsx]CP-6'!E20,"Non commencé") | J14: =IF(OR(I14="Réussi",I14="Exception acceptée"),"GREEN",IF(OR(I14="Non commencé",I14="Échec"),"RED","AMBER"))
A15: CP-6(2) | B15: Alternate Storage Site | C15: Analytics | D15: CP | E15: Analytics | F15: CP-6-2 | G15: =IFERROR('[Analytics.xlsx]CP-6-2'!B20,"Not Started") | H15: =IF(OR(G15="Passed",G15="Accepted Exception"),"GREEN",IF(OR(G15="Not Started",G15="Failed"),"RED","AMBER")) | I15: =IFERROR('[Analytics.xlsx]CP-6-2'!E20,"Non commencé") | J15: =IF(OR(I15="Réussi",I15="Exception acceptée"),"GREEN",IF(OR(I15="Non commencé",I15="Échec"),"RED","AMBER"))
A16: CP-7 | B16: Alternate Processing Site | C16: Analytics | D16: CP | E16: Analytics | F16: CP-7 | G16: =IFERROR('[Analytics.xlsx]CP-7'!B20,"Not Started") | H16: =IF(OR(G16="Passed",G16="Accepted Exception"),"GREEN",IF(OR(G16="Not Started",G16="Failed"),"RED","AMBER")) | I16: =IFERROR('[Analytics.xlsx]CP-7'!E20,"Non commencé") | J16: =IF(OR(I16="Réussi",I16="Exception acceptée"),"GREEN",IF(OR(I16="Non commencé",I16="Échec"),"RED","AMBER"))
A17: CP-7(4) | B17: Alternate Processing Site | C17: Analytics | D17: CP | E17: Analytics | F17: CP-7-4 | G17: =IFERROR('[Analytics.xlsx]CP-7-4'!B20,"Not Started") | H17: =IF(OR(G17="Passed",G17="Accepted Exception"),"GREEN",IF(OR(G17="Not Started",G17="Failed"),"RED","AMBER")) | I17: =IFERROR('[Analytics.xlsx]CP-7-4'!E20,"Non commencé") | J17: =IF(OR(I17="Réussi",I17="Exception acceptée"),"GREEN",IF(OR(I17="Non commencé",I17="Échec"),"RED","AMBER"))
A18: CP-9 | B18: Information System Backup | C18: Analytics | D18: CP | E18: Analytics | F18: CP-9 | G18: =IFERROR('[Analytics.xlsx]CP-9'!B20,"Not Started") | H18: =IF(OR(G18="Passed",G18="Accepted Exception"),"GREEN",IF(OR(G18="Not Started",G18="Failed"),"RED","AMBER")) | I18: =IFERROR('[Analytics.xlsx]CP-9'!E20,"Non commencé") | J18: =IF(OR(I18="Réussi",I18="Exception acceptée"),"GREEN",IF(OR(I18="Non commencé",I18="Échec"),"RED","AMBER"))
A19: CP-9(1) | B19: Information System Backup | C19: Analytics | D19: CP | E19: Analytics | F19: CP-9-1 | G19: =IFERROR('[Analytics.xlsx]CP-9-1'!B20,"Not Started") | H19: =IF(OR(G19="Passed",G19="Accepted Exception"),"GREEN",IF(OR(G19="Not Started",G19="Failed"),"RED","AMBER")) | I19: =IFERROR('[Analytics.xlsx]CP-9-1'!E20,"Non commencé") | J19: =IF(OR(I19="Réussi",I19="Exception acceptée"),"GREEN",IF(OR(I19="Non commencé",I19="Échec"),"RED","AMBER"))
A20: CP-9(2) | B20: Information System Backup | C20: Analytics | D20: CP | E20: Analytics | F20: CP-9-2 | G20: =IFERROR('[Analytics.xlsx]CP-9-2'!B20,"Not Started") | H20: =IF(OR(G20="Passed",G20="Accepted Exception"),"GREEN",IF(OR(G20="Not Started",G20="Failed"),"RED","AMBER")) | I20: =IFERROR('[Analytics.xlsx]CP-9-2'!E20,"Non commencé") | J20: =IF(OR(I20="Réussi",I20="Exception acceptée"),"GREEN",IF(OR(I20="Non commencé",I20="Échec"),"RED","AMBER"))
A21: CP-9(5) | B21: Information System Backup | C21: Analytics | D21: CP | E21: Analytics | F21: CP-9-5 | G21: =IFERROR('[Analytics.xlsx]CP-9-5'!B20,"Not Started") | H21: =IF(OR(G21="Passed",G21="Accepted Exception"),"GREEN",IF(OR(G21="Not Started",G21="Failed"),"RED","AMBER")) | I21: =IFERROR('[Analytics.xlsx]CP-9-5'!E20,"Non commencé") | J21: =IF(OR(I21="Réussi",I21="Exception acceptée"),"GREEN",IF(OR(I21="Non commencé",I21="Échec"),"RED","AMBER"))
A22: CP-10 | B22: Information System Recovery and Reconstitution | C22: Analytics | D22: CP | E22: Analytics | F22: CP-10 | G22: =IFERROR('[Analytics.xlsx]CP-10'!B20,"Not Started") | H22: =IF(OR(G22="Passed",G22="Accepted Exception"),"GREEN",IF(OR(G22="Not Started",G22="Failed"),"RED","AMBER")) | I22: =IFERROR('[Analytics.xlsx]CP-10'!E20,"Non commencé") | J22: =IF(OR(I22="Réussi",I22="Exception acceptée"),"GREEN",IF(OR(I22="Non commencé",I22="Échec"),"RED","AMBER"))
A23: CP-10(4) | B23: Information System Recovery and Reconstitution | C23: Analytics | D23: CP | E23: Analytics | F23: CP-10-4 | G23: =IFERROR('[Analytics.xlsx]CP-10-4'!B20,"Not Started") | H23: =IF(OR(G23="Passed",G23="Accepted Exception"),"GREEN",IF(OR(G23="Not Started",G23="Failed"),"RED","AMBER")) | I23: =IFERROR('[Analytics.xlsx]CP-10-4'!E20,"Non commencé") | J23: =IF(OR(I23="Réussi",I23="Exception acceptée"),"GREEN",IF(OR(I23="Non commencé",I23="Échec"),"RED","AMBER"))
A24: SA-9(5) | B24: External Information System Services | C24: Analytics | D24: SA | E24: Analytics | F24: SA-9-5 | G24: =IFERROR('[Analytics.xlsx]SA-9-5'!B20,"Not Started") | H24: =IF(OR(G24="Passed",G24="Accepted Exception"),"GREEN",IF(OR(G24="Not Started",G24="Failed"),"RED","AMBER")) | I24: =IFERROR('[Analytics.xlsx]SA-9-5'!E20,"Non commencé") | J24: =IF(OR(I24="Réussi",I24="Exception acceptée"),"GREEN",IF(OR(I24="Non commencé",I24="Échec"),"RED","AMBER"))
A25: SC-4 | B25: Information in Shared Resources | C25: Analytics | D25: SC | E25: Analytics | F25: SC-4 | G25: =IFERROR('[Analytics.xlsx]SC-4'!B20,"Not Started") | H25: =IF(OR(G25="Passed",G25="Accepted Exception"),"GREEN",IF(OR(G25="Not Started",G25="Failed"),"RED","AMBER")) | I25: =IFERROR('[Analytics.xlsx]SC-4'!E20,"Non commencé") | J25: =IF(OR(I25="Réussi",I25="Exception acceptée"),"GREEN",IF(OR(I25="Non commencé",I25="Échec"),"RED","AMBER"))
A26: SC-13 | B26: Cryptographic Protection | C26: Analytics | D26: SC | E26: Analytics | F26: SC-13 | G26: =IFERROR('[Analytics.xlsx]SC-13'!B20,"Not Started") | H26: =IF(OR(G26="Passed",G26="Accepted Exception"),"GREEN",IF(OR(G26="Not Started",G26="Failed"),"RED","AMBER")) | I26: =IFERROR('[Analytics.xlsx]SC-13'!E20,"Non commencé") | J26: =IF(OR(I26="Réussi",I26="Exception acceptée"),"GREEN",IF(OR(I26="Non commencé",I26="Échec"),"RED","AMBER"))
A27: SC-28 | B27: Protection of Information At Rest | C27: Analytics | D27: SC | E27: Analytics | F27: SC-28 | G27: =IFERROR('[Analytics.xlsx]SC-28'!B20,"Not Started") | H27: =IF(OR(G27="Passed",G27="Accepted Exception"),"GREEN",IF(OR(G27="Not Started",G27="Failed"),"RED","AMBER")) | I27: =IFERROR('[Analytics.xlsx]SC-28'!E20,"Non commencé") | J27: =IF(OR(I27="Réussi",I27="Exception acceptée"),"GREEN",IF(OR(I27="Non commencé",I27="Échec"),"RED","AMBER"))
A28: SC-28(1) | B28: Protection of Information At Rest | C28: Analytics | D28: SC | E28: Analytics | F28: SC-28-1 | G28: =IFERROR('[Analytics.xlsx]SC-28-1'!B20,"Not Started") | H28: =IF(OR(G28="Passed",G28="Accepted Exception"),"GREEN",IF(OR(G28="Not Started",G28="Failed"),"RED","AMBER")) | I28: =IFERROR('[Analytics.xlsx]SC-28-1'!E20,"Non commencé") | J28: =IF(OR(I28="Réussi",I28="Exception acceptée"),"GREEN",IF(OR(I28="Non commencé",I28="Échec"),"RED","AMBER"))
A29: SI-4(2) | B29: Information System Monitoring | C29: Analytics | D29: SI | E29: Analytics | F29: SI-4-2 | G29: =IFERROR('[Analytics.xlsx]SI-4-2'!B20,"Not Started") | H29: =IF(OR(G29="Passed",G29="Accepted Exception"),"GREEN",IF(OR(G29="Not Started",G29="Failed"),"RED","AMBER")) | I29: =IFERROR('[Analytics.xlsx]SI-4-2'!E20,"Non commencé") | J29: =IF(OR(I29="Réussi",I29="Exception acceptée"),"GREEN",IF(OR(I29="Non commencé",I29="Échec"),"RED","AMBER"))
A30: SI-6 | B30: Security Functional Verification | C30: Analytics | D30: SI | E30: Analytics | F30: SI-6 | G30: =IFERROR('[Analytics.xlsx]SI-6'!B20,"Not Started") | H30: =IF(OR(G30="Passed",G30="Accepted Exception"),"GREEN",IF(OR(G30="Not Started",G30="Failed"),"RED","AMBER")) | I30: =IFERROR('[Analytics.xlsx]SI-6'!E20,"Non commencé") | J30: =IF(OR(I30="Réussi",I30="Exception acceptée"),"GREEN",IF(OR(I30="Non commencé",I30="Échec"),"RED","AMBER"))
A31: AC-6 | B31: Least Privilege | C31: Compute | D31: AC | E31: Compute | F31: AC-6 | G31: =IFERROR('[Compute.xlsx]AC-6'!B20,"Not Started") | H31: =IF(OR(G31="Passed",G31="Accepted Exception"),"GREEN",IF(OR(G31="Not Started",G31="Failed"),"RED","AMBER")) | I31: =IFERROR('[Compute.xlsx]AC-6'!E20,"Non commencé") | J31: =IF(OR(I31="Réussi",I31="Exception acceptée"),"GREEN",IF(OR(I31="Non commencé",I31="Échec"),"RED","AMBER"))
A32: AC-6(1) | B32: Least Privilege | C32: Compute | D32: AC | E32: Compute | F32: AC-6-1 | G32: =IFERROR('[Compute.xlsx]AC-6-1'!B20,"Not Started") | H32: =IF(OR(G32="Passed",G32="Accepted Exception"),"GREEN",IF(OR(G32="Not Started",G32="Failed"),"RED","AMBER")) | I32: =IFERROR('[Compute.xlsx]AC-6-1'!E20,"Non commencé") | J32: =IF(OR(I32="Réussi",I32="Exception acceptée"),"GREEN",IF(OR(I32="Non commencé",I32="Échec"),"RED","AMBER"))
A33: AC-7 | B33: Unsuccessful Login Attempts | C33: Compute | D33: AC | E33: Compute | F33: AC-7 | G33: =IFERROR('[Compute.xlsx]AC-7'!B20,"Not Started") | H33: =IF(OR(G33="Passed",G33="Accepted Exception"),"GREEN",IF(OR(G33="Not Started",G33="Failed"),"RED","AMBER")) | I33: =IFERROR('[Compute.xlsx]AC-7'!E20,"Non commencé") | J33: =IF(OR(I33="Réussi",I33="Exception acceptée"),"GREEN",IF(OR(I33="Non commencé",I33="Échec"),"RED","AMBER"))
A34: AC-8 | B34: System Use Notification | C34: Compute | D34: AC | E34: Compute | F34: AC-8 | G34: =IFERROR('[Compute.xlsx]AC-8'!B20,"Not Started") | H34: =IF(OR(G34="Passed",G34="Accepted Exception"),"GREEN",IF(OR(G34="Not Started",G34="Failed"),"RED","AMBER")) | I34: =IFERROR('[Compute.xlsx]AC-8'!E20,"Non commencé") | J34: =IF(OR(I34="Réussi",I34="Exception acceptée"),"GREEN",IF(OR(I34="Non commencé",I34="Échec"),"RED","AMBER"))
A35: AC-11 | B35: Session Lock | C35: Compute | D35: AC | E35: Compute | F35: AC-11 | G35: =IFERROR('[Compute.xlsx]AC-11'!B20,"Not Started") | H35: =IF(OR(G35="Passed",G35="Accepted Exception"),"GREEN",IF(OR(G35="Not Started",G35="Failed"),"RED","AMBER")) | I35: =IFERROR('[Compute.xlsx]AC-11'!E20,"Non commencé") | J35: =IF(OR(I35="Réussi",I35="Exception acceptée"),"GREEN",IF(OR(I35="Non commencé",I35="Échec"),"RED","AMBER"))
A36: AC-11(1) | B36: Session Lock | C36: Compute | D36: AC | E36: Compute | F36: AC-11-1 | G36: =IFERROR('[Compute.xlsx]AC-11-1'!B20,"Not Started") | H36: =IF(OR(G36="Passed",G36="Accepted Exception"),"GREEN",IF(OR(G36="Not Started",G36="Failed"),"RED","AMBER")) | I36: =IFERROR('[Compute.xlsx]AC-11-1'!E20,"Non commencé") | J36: =IF(OR(I36="Réussi",I36="Exception acceptée"),"GREEN",IF(OR(I36="Non commencé",I36="Échec"),"RED","AMBER"))
A37: AC-12 | B37: Session Termination | C37: Compute | D37: AC | E37: Compute | F37: AC-12 | G37: =IFERROR('[Compute.xlsx]AC-12'!B20,"Not Started") | H37: =IF(OR(G37="Passed",G37="Accepted Exception"),"GREEN",IF(OR(G37="Not Started",G37="Failed"),"RED","AMBER")) | I37: =IFERROR('[Compute.xlsx]AC-12'!E20,"Non commencé") | J37: =IF(OR(I37="Réussi",I37="Exception acceptée"),"GREEN",IF(OR(I37="Non commencé",I37="Échec"),"RED","AMBER"))
A38: AC-17(1) | B38: Remote Access | C38: Compute | D38: AC | E38: Compute | F38: AC-17-1 | G38: =IFERROR('[Compute.xlsx]AC-17-1'!B20,"Not Started") | H38: =IF(OR(G38="Passed",G38="Accepted Exception"),"GREEN",IF(OR(G38="Not Started",G38="Failed"),"RED","AMBER")) | I38: =IFERROR('[Compute.xlsx]AC-17-1'!E20,"Non commencé") | J38: =IF(OR(I38="Réussi",I38="Exception acceptée"),"GREEN",IF(OR(I38="Non commencé",I38="Échec"),"RED","AMBER"))
A39: AC-17(2) | B39: Remote Access | C39: Compute | D39: AC | E39: Compute | F39: AC-17-2 | G39: =IFERROR('[Compute.xlsx]AC-17-2'!B20,"Not Started") | H39: =IF(OR(G39="Passed",G39="Accepted Exception"),"GREEN",IF(OR(G39="Not Started",G39="Failed"),"RED","AMBER")) | I39: =IFERROR('[Compute.xlsx]AC-17-2'!E20,"Non commencé") | J39: =IF(OR(I39="Réussi",I39="Exception acceptée"),"GREEN",IF(OR(I39="Non commencé",I39="Échec"),"RED","AMBER"))
A40: AC-17(100) | B40: Remote Access | C40: Compute | D40: AC | E40: Compute | F40: AC-17-100 | G40: =IFERROR('[Compute.xlsx]AC-17-100'!B20,"Not Started") | H40: =IF(OR(G40="Passed",G40="Accepted Exception"),"GREEN",IF(OR(G40="Not Started",G40="Failed"),"RED","AMBER")) | I40: =IFERROR('[Compute.xlsx]AC-17-100'!E20,"Non commencé") | J40: =IF(OR(I40="Réussi",I40="Exception acceptée"),"GREEN",IF(OR(I40="Non commencé",I40="Échec"),"RED","AMBER"))
...

Sheet SUMMARY
A1: PBMM Evidence — LIVE Progress Summary — 21 Workbooks
A2: Metric | B2: EN Count | C2: EN % | D2: FR Count | E2: FR %
A3: Overall Status (LIVE)
A4: Total | B4: =1273 | C4: ="" | D4: =1273 | E4: =""
A5: Not Started | B5: =COUNTIF(TRACKER!G3:G1275,"Not Started") | C5: =IFERROR(COUNTIF(TRACKER!G3:G1275,"Not Started")/1273,0) | D5: =COUNTIF(TRACKER!I3:I1275,"Non commencé") | E5: =IFERROR(COUNTIF(TRACKER!I3:I1275,"Non commencé")/1273,0)
A6: In Progress | B6: =COUNTIF(TRACKER!G3:G1275,"In Progress") | C6: =IFERROR(COUNTIF(TRACKER!G3:G1275,"In Progress")/1273,0) | D6: =COUNTIF(TRACKER!I3:I1275,"En cours") | E6: =IFERROR(COUNTIF(TRACKER!I3:I1275,"En cours")/1273,0)
A7: Evidence Provided | B7: =COUNTIF(TRACKER!G3:G1275,"Evidence Provided") | C7: =IFERROR(COUNTIF(TRACKER!G3:G1275,"Evidence Provided")/1273,0) | D7: =COUNTIF(TRACKER!I3:I1275,"Preuve fournie") | E7: =IFERROR(COUNTIF(TRACKER!I3:I1275,"Preuve fournie")/1273,0)
A8: Under Review | B8: =COUNTIF(TRACKER!G3:G1275,"Under Review") | C8: =IFERROR(COUNTIF(TRACKER!G3:G1275,"Under Review")/1273,0) | D8: =COUNTIF(TRACKER!I3:I1275,"En révision") | E8: =IFERROR(COUNTIF(TRACKER!I3:I1275,"En révision")/1273,0)
A9: Passed | B9: =COUNTIF(TRACKER!G3:G1275,"Passed") | C9: =IFERROR(COUNTIF(TRACKER!G3:G1275,"Passed")/1273,0) | D9: =COUNTIF(TRACKER!I3:I1275,"Réussi") | E9: =IFERROR(COUNTIF(TRACKER!I3:I1275,"Réussi")/1273,0)
A10: Failed | B10: =COUNTIF(TRACKER!G3:G1275,"Failed") | C10: =IFERROR(COUNTIF(TRACKER!G3:G1275,"Failed")/1273,0) | D10: =COUNTIF(TRACKER!I3:I1275,"Échec") | E10: =IFERROR(COUNTIF(TRACKER!I3:I1275,"Échec")/1273,0)
A11: Accepted Exception | B11: =COUNTIF(TRACKER!G3:G1275,"Accepted Exception") | C11: =IFERROR(COUNTIF(TRACKER!G3:G1275,"Accepted Exception")/1273,0) | D11: =COUNTIF(TRACKER!I3:I1275,"Exception acceptée") | E11: =IFERROR(COUNTIF(TRACKER!I3:I1275,"Exception acceptée")/1273,0)
A13: By Technology (21 Workbooks)
A14: Analytics | B14: =COUNTIF(TRACKER!C3:C1275,"Analytics") | C14: =IFERROR(COUNTIF(TRACKER!C3:C1275,"Analytics")/1273,0) | D14: =COUNTIF(TRACKER!C3:C1275,"Analytics") | E14: =IFERROR(COUNTIF(TRACKER!C3:C1275,"Analytics")/1273,0)
A15: Compute | B15: =COUNTIF(TRACKER!C3:C1275,"Compute") | C15: =IFERROR(COUNTIF(TRACKER!C3:C1275,"Compute")/1273,0) | D15: =COUNTIF(TRACKER!C3:C1275,"Compute") | E15: =IFERROR(COUNTIF(TRACKER!C3:C1275,"Compute")/1273,0)
A16: Containers | B16: =COUNTIF(TRACKER!C3:C1275,"Containers") | C16: =IFERROR(COUNTIF(TRACKER!C3:C1275,"Containers")/1273,0) | D16: =COUNTIF(TRACKER!C3:C1275,"Containers") | E16: =IFERROR(COUNTIF(TRACKER!C3:C1275,"Containers")/1273,0)
A17: Database | B17: =COUNTIF(TRACKER!C3:C1275,"Database") | C17: =IFERROR(COUNTIF(TRACKER!C3:C1275,"Database")/1273,0) | D17: =COUNTIF(TRACKER!C3:C1275,"Database") | E17: =IFERROR(COUNTIF(TRACKER!C3:C1275,"Database")/1273,0)
A18: DevOps | B18: =COUNTIF(TRACKER!C3:C1275,"DevOps") | C18: =IFERROR(COUNTIF(TRACKER!C3:C1275,"DevOps")/1273,0) | D18: =COUNTIF(TRACKER!C3:C1275,"DevOps") | E18: =IFERROR(COUNTIF(TRACKER!C3:C1275,"DevOps")/1273,0)
A19: Developer Tools | B19: =COUNTIF(TRACKER!C3:C1275,"Developer Tools") | C19: =IFERROR(COUNTIF(TRACKER!C3:C1275,"Developer Tools")/1273,0) | D19: =COUNTIF(TRACKER!C3:C1275,"Developer Tools") | E19: =IFERROR(COUNTIF(TRACKER!C3:C1275,"Developer Tools")/1273,0)
A20: Documentation | B20: =COUNTIF(TRACKER!C3:C1275,"Documentation") | C20: =IFERROR(COUNTIF(TRACKER!C3:C1275,"Documentation")/1273,0) | D20: =COUNTIF(TRACKER!C3:C1275,"Documentation") | E20: =IFERROR(COUNTIF(TRACKER!C3:C1275,"Documentation")/1273,0)
A21: Hybrid + Multicloud | B21: =COUNTIF(TRACKER!C3:C1275,"Hybrid + Multicloud") | C21: =IFERROR(COUNTIF(TRACKER!C3:C1275,"Hybrid + Multicloud")/1273,0) | D21: =COUNTIF(TRACKER!C3:C1275,"Hybrid + Multicloud") | E21: =IFERROR(COUNTIF(TRACKER!C3:C1275,"Hybrid + Multicloud")/1273,0)
A22: Identity | B22: =COUNTIF(TRACKER!C3:C1275,"Identity") | C22: =IFERROR(COUNTIF(TRACKER!C3:C1275,"Identity")/1273,0) | D22: =COUNTIF(TRACKER!C3:C1275,"Identity") | E22: =IFERROR(COUNTIF(TRACKER!C3:C1275,"Identity")/1273,0)
A23: Management and Governance | B23: =COUNTIF(TRACKER!C3:C1275,"Management and Governance") | C23: =IFERROR(COUNTIF(TRACKER!C3:C1275,"Management and Governance")/1273,0) | D23: =COUNTIF(TRACKER!C3:C1275,"Management and Governance") | E23: =IFERROR(COUNTIF(TRACKER!C3:C1275,"Management and Governance")/1273,0)
A24: Microsoft-Descoped | B24: =COUNTIF(TRACKER!C3:C1275,"Microsoft-Descoped") | C24: =IFERROR(COUNTIF(TRACKER!C3:C1275,"Microsoft-Descoped")/1273,0) | D24: =COUNTIF(TRACKER!C3:C1275,"Microsoft-Descoped") | E24: =IFERROR(COUNTIF(TRACKER!C3:C1275,"Microsoft-Descoped")/1273,0)
A25: Networking | B25: =COUNTIF(TRACKER!C3:C1275,"Networking") | C25: =IFERROR(COUNTIF(TRACKER!C3:C1275,"Networking")/1273,0) | D25: =COUNTIF(TRACKER!C3:C1275,"Networking") | E25: =IFERROR(COUNTIF(TRACKER!C3:C1275,"Networking")/1273,0)
A26: Palo Alto Firewalls | B26: =COUNTIF(TRACKER!C3:C1275,"Palo Alto Firewalls") | C26: =IFERROR(COUNTIF(TRACKER!C3:C1275,"Palo Alto Firewalls")/1273,0) | D26: =COUNTIF(TRACKER!C3:C1275,"Palo Alto Firewalls") | E26: =IFERROR(COUNTIF(TRACKER!C3:C1275,"Palo Alto Firewalls")/1273,0)
A27: Panorama | B27: =COUNTIF(TRACKER!C3:C1275,"Panorama") | C27: =IFERROR(COUNTIF(TRACKER!C3:C1275,"Panorama")/1273,0) | D27: =COUNTIF(TRACKER!C3:C1275,"Panorama") | E27: =IFERROR(COUNTIF(TRACKER!C3:C1275,"Panorama")/1273,0)
A28: Security | B28: =COUNTIF(TRACKER!C3:C1275,"Security") | C28: =IFERROR(COUNTIF(TRACKER!C3:C1275,"Security")/1273,0) | D28: =COUNTIF(TRACKER!C3:C1275,"Security") | E28: =IFERROR(COUNTIF(TRACKER!C3:C1275,"Security")/1273,0)
A29: ServiceNow | B29: =COUNTIF(TRACKER!C3:C1275,"ServiceNow") | C29: =IFERROR(COUNTIF(TRACKER!C3:C1275,"ServiceNow")/1273,0) | D29: =COUNTIF(TRACKER!C3:C1275,"ServiceNow") | E29: =IFERROR(COUNTIF(TRACKER!C3:C1275,"ServiceNow")/1273,0)
A30: Storage | B30: =COUNTIF(TRACKER!C3:C1275,"Storage") | C30: =IFERROR(COUNTIF(TRACKER!C3:C1275,"Storage")/1273,0) | D30: =COUNTIF(TRACKER!C3:C1275,"Storage") | E30: =IFERROR(COUNTIF(TRACKER!C3:C1275,"Storage")/1273,0)
A31: Tenable Nessus | B31: =COUNTIF(TRACKER!C3:C1275,"Tenable Nessus") | C31: =IFERROR(COUNTIF(TRACKER!C3:C1275,"Tenable Nessus")/1273,0) | D31: =COUNTIF(TRACKER!C3:C1275,"Tenable Nessus") | E31: =IFERROR(COUNTIF(TRACKER!C3:C1275,"Tenable Nessus")/1273,0)
A32: Tenable Security Centre+ | B32: =COUNTIF(TRACKER!C3:C1275,"Tenable Security Centre+") | C32: =IFERROR(COUNTIF(TRACKER!C3:C1275,"Tenable Security Centre+")/1273,0) | D32: =COUNTIF(TRACKER!C3:C1275,"Tenable Security Centre+") | E32: =IFERROR(COUNTIF(TRACKER!C3:C1275,"Tenable Security Centre+")/1273,0)
A33: Virtual Desktop Infrastructure | B33: =COUNTIF(TRACKER!C3:C1275,"Virtual Desktop Infrastructure") | C33: =IFERROR(COUNTIF(TRACKER!C3:C1275,"Virtual Desktop Infrastructure")/1273,0) | D33: =COUNTIF(TRACKER!C3:C1275,"Virtual Desktop Infrastructure") | E33: =IFERROR(COUNTIF(TRACKER!C3:C1275,"Virtual Desktop Infrastructure")/1273,0)
A34: Web | B34: =COUNTIF(TRACKER!C3:C1275,"Web") | C34: =IFERROR(COUNTIF(TRACKER!C3:C1275,"Web")/1273,0) | D34: =COUNTIF(TRACKER!C3:C1275,"Web") | E34: =IFERROR(COUNTIF(TRACKER!C3:C1275,"Web")/1273,0)

Sheet EXECUTIVE DASHBOARD
A1: PBMM Gap Analysis — Executive Dashboard
A2: Technology | B2: Total | C2: Passed | D2: In Progress | E2: Failed | F2: Not Started | G2: % Complete | H2: RAG
A3: Analytics | B3: =COUNTIF(TRACKER!$C$3:$C$1275,A3) | C3: =COUNTIFS(TRACKER!$C$3:$C$1275,A3,TRACKER!$G$3:$G$1275,"Passed")+COUNTIFS(TRACKER!$C$3:$C$1275,A3,TRACKER!$G$3:$G$1275,"Accepted Exception") | D3: =COUNTIFS(TRACKER!$C$3:$C$1275,A3,TRACKER!$G$3:$G$1275,"In Progress")+COUNTIFS(TRACKER!$C$3:$C$1275,A3,TRACKER!$G$3:$G$1275,"Evidence Provided")+COUNTIFS(TRACKER!$C$3:$C$1275,A3,TRACKER!$G$3:$G$1275,"Under Review") | E3: =COUNTIFS(TRACKER!$C$3:$C$1275,A3,TRACKER!$G$3:$G$1275,"Failed") | F3: =COUNTIFS(TRACKER!$C$3:$C$1275,A3,TRACKER!$G$3:$G$1275,"Not Started") | G3: =IFERROR(C3/B3,0) | H3: =IF(G3>=0.9,"GREEN",IF(G3>=0.5,"AMBER","RED"))
A4: Compute | B4: =COUNTIF(TRACKER!$C$3:$C$1275,A4) | C4: =COUNTIFS(TRACKER!$C$3:$C$1275,A4,TRACKER!$G$3:$G$1275,"Passed")+COUNTIFS(TRACKER!$C$3:$C$1275,A4,TRACKER!$G$3:$G$1275,"Accepted Exception") | D4: =COUNTIFS(TRACKER!$C$3:$C$1275,A4,TRACKER!$G$3:$G$1275,"In Progress")+COUNTIFS(TRACKER!$C$3:$C$1275,A4,TRACKER!$G$3:$G$1275,"Evidence Provided")+COUNTIFS(TRACKER!$C$3:$C$1275,A4,TRACKER!$G$3:$G$1275,"Under Review") | E4: =COUNTIFS(TRACKER!$C$3:$C$1275,A4,TRACKER!$G$3:$G$1275,"Failed") | F4: =COUNTIFS(TRACKER!$C$3:$C$1275,A4,TRACKER!$G$3:$G$1275,"Not Started") | G4: =IFERROR(C4/B4,0) | H4: =IF(G4>=0.9,"GREEN",IF(G4>=0.5,"AMBER","RED"))
A5: Containers | B5: =COUNTIF(TRACKER!$C$3:$C$1275,A5) | C5: =COUNTIFS(TRACKER!$C$3:$C$1275,A5,TRACKER!$G$3:$G$1275,"Passed")+COUNTIFS(TRACKER!$C$3:$C$1275,A5,TRACKER!$G$3:$G$1275,"Accepted Exception") | D5: =COUNTIFS(TRACKER!$C$3:$C$1275,A5,TRACKER!$G$3:$G$1275,"In Progress")+COUNTIFS(TRACKER!$C$3:$C$1275,A5,TRACKER!$G$3:$G$1275,"Evidence Provided")+COUNTIFS(TRACKER!$C$3:$C$1275,A5,TRACKER!$G$3:$G$1275,"Under Review") | E5: =COUNTIFS(TRACKER!$C$3:$C$1275,A5,TRACKER!$G$3:$G$1275,"Failed") | F5: =COUNTIFS(TRACKER!$C$3:$C$1275,A5,TRACKER!$G$3:$G$1275,"Not Started") | G5: =IFERROR(C5/B5,0) | H5: =IF(G5>=0.9,"GREEN",IF(G5>=0.5,"AMBER","RED"))
A6: Database | B6: =COUNTIF(TRACKER!$C$3:$C$1275,A6) | C6: =COUNTIFS(TRACKER!$C$3:$C$1275,A6,TRACKER!$G$3:$G$1275,"Passed")+COUNTIFS(TRACKER!$C$3:$C$1275,A6,TRACKER!$G$3:$G$1275,"Accepted Exception") | D6: =COUNTIFS(TRACKER!$C$3:$C$1275,A6,TRACKER!$G$3:$G$1275,"In Progress")+COUNTIFS(TRACKER!$C$3:$C$1275,A6,TRACKER!$G$3:$G$1275,"Evidence Provided")+COUNTIFS(TRACKER!$C$3:$C$1275,A6,TRACKER!$G$3:$G$1275,"Under Review") | E6: =COUNTIFS(TRACKER!$C$3:$C$1275,A6,TRACKER!$G$3:$G$1275,"Failed") | F6: =COUNTIFS(TRACKER!$C$3:$C$1275,A6,TRACKER!$G$3:$G$1275,"Not Started") | G6: =IFERROR(C6/B6,0) | H6: =IF(G6>=0.9,"GREEN",IF(G6>=0.5,"AMBER","RED"))
A7: DevOps | B7: =COUNTIF(TRACKER!$C$3:$C$1275,A7) | C7: =COUNTIFS(TRACKER!$C$3:$C$1275,A7,TRACKER!$G$3:$G$1275,"Passed")+COUNTIFS(TRACKER!$C$3:$C$1275,A7,TRACKER!$G$3:$G$1275,"Accepted Exception") | D7: =COUNTIFS(TRACKER!$C$3:$C$1275,A7,TRACKER!$G$3:$G$1275,"In Progress")+COUNTIFS(TRACKER!$C$3:$C$1275,A7,TRACKER!$G$3:$G$1275,"Evidence Provided")+COUNTIFS(TRACKER!$C$3:$C$1275,A7,TRACKER!$G$3:$G$1275,"Under Review") | E7: =COUNTIFS(TRACKER!$C$3:$C$1275,A7,TRACKER!$G$3:$G$1275,"Failed") | F7: =COUNTIFS(TRACKER!$C$3:$C$1275,A7,TRACKER!$G$3:$G$1275,"Not Started") | G7: =IFERROR(C7/B7,0) | H7: =IF(G7>=0.9,"GREEN",IF(G7>=0.5,"AMBER","RED"))
A8: Developer Tools | B8: =COUNTIF(TRACKER!$C$3:$C$1275,A8) | C8: =COUNTIFS(TRACKER!$C$3:$C$1275,A8,TRACKER!$G$3:$G$1275,"Passed")+COUNTIFS(TRACKER!$C$3:$C$1275,A8,TRACKER!$G$3:$G$1275,"Accepted Exception") | D8: =COUNTIFS(TRACKER!$C$3:$C$1275,A8,TRACKER!$G$3:$G$1275,"In Progress")+COUNTIFS(TRACKER!$C$3:$C$1275,A8,TRACKER!$G$3:$G$1275,"Evidence Provided")+COUNTIFS(TRACKER!$C$3:$C$1275,A8,TRACKER!$G$3:$G$1275,"Under Review") | E8: =COUNTIFS(TRACKER!$C$3:$C$1275,A8,TRACKER!$G$3:$G$1275,"Failed") | F8: =COUNTIFS(TRACKER!$C$3:$C$1275,A8,TRACKER!$G$3:$G$1275,"Not Started") | G8: =IFERROR(C8/B8,0) | H8: =IF(G8>=0.9,"GREEN",IF(G8>=0.5,"AMBER","RED"))
A9: Documentation | B9: =COUNTIF(TRACKER!$C$3:$C$1275,A9) | C9: =COUNTIFS(TRACKER!$C$3:$C$1275,A9,TRACKER!$G$3:$G$1275,"Passed")+COUNTIFS(TRACKER!$C$3:$C$1275,A9,TRACKER!$G$3:$G$1275,"Accepted Exception") | D9: =COUNTIFS(TRACKER!$C$3:$C$1275,A9,TRACKER!$G$3:$G$1275,"In Progress")+COUNTIFS(TRACKER!$C$3:$C$1275,A9,TRACKER!$G$3:$G$1275,"Evidence Provided")+COUNTIFS(TRACKER!$C$3:$C$1275,A9,TRACKER!$G$3:$G$1275,"Under Review") | E9: =COUNTIFS(TRACKER!$C$3:$C$1275,A9,TRACKER!$G$3:$G$1275,"Failed") | F9: =COUNTIFS(TRACKER!$C$3:$C$1275,A9,TRACKER!$G$3:$G$1275,"Not Started") | G9: =IFERROR(C9/B9,0) | H9: =IF(G9>=0.9,"GREEN",IF(G9>=0.5,"AMBER","RED"))
A10: Hybrid + Multicloud | B10: =COUNTIF(TRACKER!$C$3:$C$1275,A10) | C10: =COUNTIFS(TRACKER!$C$3:$C$1275,A10,TRACKER!$G$3:$G$1275,"Passed")+COUNTIFS(TRACKER!$C$3:$C$1275,A10,TRACKER!$G$3:$G$1275,"Accepted Exception") | D10: =COUNTIFS(TRACKER!$C$3:$C$1275,A10,TRACKER!$G$3:$G$1275,"In Progress")+COUNTIFS(TRACKER!$C$3:$C$1275,A10,TRACKER!$G$3:$G$1275,"Evidence Provided")+COUNTIFS(TRACKER!$C$3:$C$1275,A10,TRACKER!$G$3:$G$1275,"Under Review") | E10: =COUNTIFS(TRACKER!$C$3:$C$1275,A10,TRACKER!$G$3:$G$1275,"Failed") | F10: =COUNTIFS(TRACKER!$C$3:$C$1275,A10,TRACKER!$G$3:$G$1275,"Not Started") | G10: =IFERROR(C10/B10,0) | H10: =IF(G10>=0.9,"GREEN",IF(G10>=0.5,"AMBER","RED"))
A11: Identity | B11: =COUNTIF(TRACKER!$C$3:$C$1275,A11) | C11: =COUNTIFS(TRACKER!$C$3:$C$1275,A11,TRACKER!$G$3:$G$1275,"Passed")+COUNTIFS(TRACKER!$C$3:$C$1275,A11,TRACKER!$G$3:$G$1275,"Accepted Exception") | D11: =COUNTIFS(TRACKER!$C$3:$C$1275,A11,TRACKER!$G$3:$G$1275,"In Progress")+COUNTIFS(TRACKER!$C$3:$C$1275,A11,TRACKER!$G$3:$G$1275,"Evidence Provided")+COUNTIFS(TRACKER!$C$3:$C$1275,A11,TRACKER!$G$3:$G$1275,"Under Review") | E11: =COUNTIFS(TRACKER!$C$3:$C$1275,A11,TRACKER!$G$3:$G$1275,"Failed") | F11: =COUNTIFS(TRACKER!$C$3:$C$1275,A11,TRACKER!$G$3:$G$1275,"Not Started") | G11: =IFERROR(C11/B11,0) | H11: =IF(G11>=0.9,"GREEN",IF(G11>=0.5,"AMBER","RED"))
A12: Management and Governance | B12: =COUNTIF(TRACKER!$C$3:$C$1275,A12) | C12: =COUNTIFS(TRACKER!$C$3:$C$1275,A12,TRACKER!$G$3:$G$1275,"Passed")+COUNTIFS(TRACKER!$C$3:$C$1275,A12,TRACKER!$G$3:$G$1275,"Accepted Exception") | D12: =COUNTIFS(TRACKER!$C$3:$C$1275,A12,TRACKER!$G$3:$G$1275,"In Progress")+COUNTIFS(TRACKER!$C$3:$C$1275,A12,TRACKER!$G$3:$G$1275,"Evidence Provided")+COUNTIFS(TRACKER!$C$3:$C$1275,A12,TRACKER!$G$3:$G$1275,"Under Review") | E12: =COUNTIFS(TRACKER!$C$3:$C$1275,A12,TRACKER!$G$3:$G$1275,"Failed") | F12: =COUNTIFS(TRACKER!$C$3:$C$1275,A12,TRACKER!$G$3:$G$1275,"Not Started") | G12: =IFERROR(C12/B12,0) | H12: =IF(G12>=0.9,"GREEN",IF(G12>=0.5,"AMBER","RED"))
A13: Microsoft-Descoped | B13: =COUNTIF(TRACKER!$C$3:$C$1275,A13) | C13: =COUNTIFS(TRACKER!$C$3:$C$1275,A13,TRACKER!$G$3:$G$1275,"Passed")+COUNTIFS(TRACKER!$C$3:$C$1275,A13,TRACKER!$G$3:$G$1275,"Accepted Exception") | D13: =COUNTIFS(TRACKER!$C$3:$C$1275,A13,TRACKER!$G$3:$G$1275,"In Progress")+COUNTIFS(TRACKER!$C$3:$C$1275,A13,TRACKER!$G$3:$G$1275,"Evidence Provided")+COUNTIFS(TRACKER!$C$3:$C$1275,A13,TRACKER!$G$3:$G$1275,"Under Review") | E13: =COUNTIFS(TRACKER!$C$3:$C$1275,A13,TRACKER!$G$3:$G$1275,"Failed") | F13: =COUNTIFS(TRACKER!$C$3:$C$1275,A13,TRACKER!$G$3:$G$1275,"Not Started") | G13: =IFERROR(C13/B13,0) | H13: =IF(G13>=0.9,"GREEN",IF(G13>=0.5,"AMBER","RED"))
A14: Networking | B14: =COUNTIF(TRACKER!$C$3:$C$1275,A14) | C14: =COUNTIFS(TRACKER!$C$3:$C$1275,A14,TRACKER!$G$3:$G$1275,"Passed")+COUNTIFS(TRACKER!$C$3:$C$1275,A14,TRACKER!$G$3:$G$1275,"Accepted Exception") | D14: =COUNTIFS(TRACKER!$C$3:$C$1275,A14,TRACKER!$G$3:$G$1275,"In Progress")+COUNTIFS(TRACKER!$C$3:$C$1275,A14,TRACKER!$G$3:$G$1275,"Evidence Provided")+COUNTIFS(TRACKER!$C$3:$C$1275,A14,TRACKER!$G$3:$G$1275,"Under Review") | E14: =COUNTIFS(TRACKER!$C$3:$C$1275,A14,TRACKER!$G$3:$G$1275,"Failed") | F14: =COUNTIFS(TRACKER!$C$3:$C$1275,A14,TRACKER!$G$3:$G$1275,"Not Started") | G14: =IFERROR(C14/B14,0) | H14: =IF(G14>=0.9,"GREEN",IF(G14>=0.5,"AMBER","RED"))
... A23: Web | B23: =COUNTIF(TRACKER!$C$3:$C$1275,A23) | C23: =COUNTIFS(TRACKER!$C$3:$C$1275,A23,TRACKER!$G$3:$G$1275,"Passed")+COUNTIFS(TRACKER!$C$3:$C$1275,A23,TRACKER!$G$3:$G$1275,"Accepted Exception") | D23: =COUNTIFS(TRACKER!$C$3:$C$1275,A23,TRACKER!$G$3:$G$1275,"In Progress")+COUNTIFS(TRACKER!$C$3:$C$1275,A23,TRACKER!$G$3:$G$1275,"Evidence Provided")+COUNTIFS(TRACKER!$C$3:$C$1275,A23,TRACKER!$G$3:$G$1275,"Under Review") | E23: =COUNTIFS(TRACKER!$C$3:$C$1275,A23,TRACKER!$G$3:$G$1275,"Failed") | F23: =COUNTIFS(TRACKER!$C$3:$C$1275,A23,TRACKER!$G$3:$G$1275,"Not Started") | G23: =IFERROR(C23/B23,0) | H23: =IF(G23>=0.9,"GREEN",IF(G23>=0.5,"AMBER","RED"))
A25: TOTALS
A26: Total Control Entries | B26: =SUM(B3:B23) | C26: =SUM(C3:C23) | D26: =SUM(D3:D23) | E26: =SUM(E3:E23) | F26: =SUM(F3:F23) | G26: =IFERROR(C26/B26,0)
A27: Technologies at RED (< 50%) | B27: =COUNTIF(H3:H23,"RED")
A28: Technologies at AMBER (50-89%) | B28: =COUNTIF(H3:H23,"AMBER")
A29: Technologies at GREEN (90%+) | B29: =COUNTIF(H3:H23,"GREEN")

Sheet GAPS BY FAMILY
A1: Gap Rate by Technology × Control Family (0% = no gaps, 100% = all gaps)
A2: Technology | B2: AC | C2: AT | D2: AU | E2: CA | F2: CM | G2: CP | H2: IA | I2: IR | J2: MA | K2: MP | L2: PE | M2: PL | N2: PS | O2: RA | P2: SA | Q2: SC | R2: SI
A3: Analytics | B3: =IFERROR(1-(COUNTIFS(TRACKER!$C$3:$C$1275,A3,TRACKER!$D$3:$D$1275,"AC",TRACKER!$G$3:$G$1275,"Passed")+COUNTIFS(TRACKER!$C$3:$C$1275,A3,TRACKER!$D$3:$D$1275,"AC",TRACKER!$G$3:$G$1275,"Accepted Exception"))/COUNTIFS(TRACKER!$C$3:$C$1275,A3,TRACKER!$D$3:$D$1275,"AC"),"") | C3: =IFERROR(1-(COUNTIFS(TRACKER!$C$3:$C$1275,A3,TRACKER!$D$3:$D$1275,"AT",TRACKER!$G$3:$G$1275,"Passed")+COUNTIFS(TRACKER!$C$3:$C$1275,A3,TRACKER!$D$3:$D$1275,"AT",TRACKER!$G$3:$G$1275,"Accepted Exception"))/COUNTIFS(TRACKER!$C$3:$C$1275,A3,TRACKER!$D$3:$D$1275,"AT"),"") | D3: =IFERROR(1-(COUNTIFS(TRACKER!$C$3:$C$1275,A3,TRACKER!$D$3:$D$1275,"AU",TRACKER!$G$3:$G$1275,"Passed")+COUNTIFS(TRACKER!$C$3:$C$1275,A3,TRACKER!$D$3:$D$1275,"AU",TRACKER!$G$3:$G$1275,"Accepted Exception"))/COUNTIFS(TRACKER!$C$3:$C$1275,A3,TRACKER!$D$3:$D$1275,"AU"),"") | E3: =IFERROR(1-(COUNTIFS(TRACKER!$C$3:$C$1275,A3,TRACKER!$D$3:$D$1275,"CA",TRACKER!$G$3:$G$1275,"Passed")+COUNTIFS(TRACKER!$C$3:$C$1275,A3,TRACKER!$D$3:$D$1275,"CA",TRACKER!$G$3:$G$1275,"Accepted Exception"))/COUNTIFS(TRACKER!$C$3:$C$1275,A3,TRACKER!$D$3:$D$1275,"CA"),"") | F3: =IFERROR(1-(COUNTIFS(TRACKER!$C$3:$C$1275,A3,TRACKER!$D$3:$D$1275,"CM",TRACKER!$G$3:$G$1275,"Passed")+COUNTIFS(TRACKER!$C$3:$C$1275,A3,TRACKER!$D$3:$D$1275,"CM",TRACKER!$G$3:$G$1275,"Accepted Exception"))/COUNTIFS(TRACKER!$C$3:$C$1275,A3,TRACKER!$D$3:$D$1275,"CM"),"") | G3: =IFERROR(1-(COUNTIFS(TRACKER!$C$3:$C$1275,A3,TRACKER!$D$3:$D$1275,"CP",TRACKER!$G$3:$G$1275,"Passed")+COUNTIFS(TRACKER!$C$3:$C$1275,A3,TRACKER!$D$3:$D$1275,"CP",TRACKER!$G$3:$G$1275,"Accepted Exception"))/COUNTIFS(TRACKER!$C$3:$C$1275,A3,TRACKER!$D$3:$D$1275,"CP"),"") | H3: =IFERROR(1-(COUNTIFS(TRACKER!$C$3:$C$1275,A3,TRACKER!$D$3:$D$1275,"IA",TRACKER!$G$3:$G$1275,"Passed")+COUNTIFS(TRACKER!$C$3:$C$1275,A3,TRACKER!$D$3:$D$1275,"IA",TRACKER!$G$3:$G$1275,"Accepted Exception"))/COUNTIFS(TRACKER!$C$3:$C$1275,A3,TRACKER!$D$3:$D$1275,"IA"),"") | I3: =IFERROR(1-(COUNTIFS(TRACKER!$C$3:$C$1275,A3,TRACKER!$D$3:$D$1275,"IR",TRACKER!$G$3:$G$1275,"Passed")+COUNTIFS(TRACKER!$C$3:$C$1275,A3,TRACKER!$D$3:$D$1275,"IR",TRACKER!$G$3:$G$1275,"Accepted Exception"))/COUNTIFS(TRACKER!$C$3:$C$1275,A3,TRACKER!$D$3:$D$1275,"IR"),"") | J3: =IFERROR(1-(COUNTIFS(TRACKER!$C$3:$C$1275,A3,TRACKER!$D$3:$D$1275,"MA",TRACKER!$G$3:$G$1275,"Passed")+COUNTIFS(TRACKER!$C$3:$C$1275,A3,TRACKER!$D$3:$D$1275,"MA",TRACKER!$G$3:$G$1275,"Accepted Exception"))/COUNTIFS(TRACKER!$C$3:$C$1275,A3,TRACKER!$D$3:$D$1275,"MA"),"") | K3: =IFERROR(1-(COUNTIFS(TRACKER!$C$3:$C$1275,A3,TRACKER!$D$3:$D$1275,"MP",TRACKER!$G$3:$G$1275,"Passed")+COUNTIFS(TRACKER!$C$3:$C$1275,A3,TRACKER!$D$3:$D$1275,"MP",TRACKER!$G$3:$G$1275,"Accepted Exception"))/COUNTIFS(TRACKER!$C$3:$C$1275,A3,TRACKER!$D$3:$D$1275,"MP"),"") | L3: =IFERROR(1-(COUNTIFS(TRACKER!$C$3:$C$1275,A3,TRACKER!$D$3:$D$1275,"PE",TRACKER!$G$3:$G$1275,"Passed")+COUNTIFS(TRACKER!$C$3:$C$1275,A3,TRACKER!$D$3:$D$1275,"PE",TRACKER!$G$3:$G$1275,"Accepted Exception"))/COUNTIFS(TRACKER!$C$3:$C$1275,A3,TRACKER!$D$3:$D$1275,"PE"),"") | M3: =IFERROR(1-(COUNTIFS(TRACKER!$C$3:$C$1275,A3,TRACKER!$D$3:$D$1275,"PL",TRACKER!$G$3:$G$1275,"Passed")+COUNTIFS(TRACKER!$C$3:$C$1275,A3,TRACKER!$D$3:$D$1275,"PL",TRACKER!$G$3:$G$1275,"Accepted Exception"))/COUNTIFS(TRACKER!$C$3:$C$1275,A3,TRACKER!$D$3:$D$1275,"PL"),"") | N3: =IFERROR(1-(COUNTIFS(TRACKER!$C$3:$C$1275,A3,TRACKER!$D$3:$D$1275,"PS",TRACKER!$G$3:$G$1275,"Passed")+COUNTIFS(TRACKER!$C$3:$C$1275,A3,TRACKER!$D$3:$D$1275,"PS",TRACKER!$G$3:$G$1275,"Accepted Exception"))/COUNTIFS(TRACKER!$C$3:$C$1275,A3,TRACKER!$D$3:$D$1275,"PS"),"") | O3: =IFERROR(1-(COUNTIFS(TRACKER!$C$3:$C$1275,A3,TRACKER!$D$3:$D$1275,"RA",TRACKER!$G$3:$G$1275,"Passed")+COUNTIFS(TRACKER!$C$3:$C$1275,A3,TRACKER!$D$3:$D$1275,"RA",TRACKER!$G$3:$G$1275,"Accepted Exception"))/COUNTIFS(TRACKER!$C$3:$C$1275,A3,TRACKER!$D$3:$D$1275,"RA"),"") | P3: =IFERROR(1-(COUNTIFS(TRACKER!$C$3:$C$1275,A3,TRACKER!$D$3:$D$1275,"SA",TRACKER!$G$3:$G$1275,"Passed")+COUNTIFS(TRACKER!$C$3:$C$1275,A3,TRACKER!$D$3:$D$1275,"SA",TRACKER!$G$3:$G$1275,"Accepted Exception"))/COUNTIFS(TRACKER!$C$3:$C$1275,A3,TRACKER!$D$3:$D$1275,"SA"),"") | Q3: =IFERROR(1-(COUNTIFS(TRACKER!$C$3:$C$1275,A3,TRACKER!$D$3:$D$1275,"SC",TRACKER!$G$3:$G$1275,"Passed")+COUNTIFS(TRACKER!$C$3:$C$1275,A3,TRACKER!$D$3:$D$1275,"SC",TRACKER!$G$3:$G$1275,"Accepted Exception"))/COUNTIFS(TRACKER!$C$3:$C$1275,A3,TRACKER!$D$3:$D$1275,"SC"),"") | R3: =IFERROR(1-(COUNTIFS(TRACKER!$C$3:$C$1275,A3,TRACKER!$D$3:$D$1275,"SI",TRACKER!$G$3:$G$1275,"Passed")+COUNTIFS(TRACKER!$C$3:$C$1275,A3,TRACKER!$D$3:$D$1275,"SI",TRACKER!$G$3:$G$1275,"Accepted Exception"))/COUNTIFS(TRACKER!$C$3:$C$1275,A3,TRACKER!$D$3:$D$1275,"SI"),"")
A4: Compute | B4: =IFERROR(1-(COUNTIFS(TRACKER!$C$3:$C$1275,A4,TRACKER!$D$3:$D$1275,"AC",TRACKER!$G$3:$G$1275,"Passed")+COUNTIFS(TRACKER!$C$3:$C$1275,A4,TRACKER!$D$3:$D$1275,"AC",TRACKER!$G$3:$G$1275,"Accepted Exception"))/COUNTIFS(TRACKER!$C$3:$C$1275,A4,TRACKER!$D$3:$D$1275,"AC"),"") | C4: =IFERROR(1-(COUNTIFS(TRACKER!$C$3:$C$1275,A4,TRACKER!$D$3:$D$1275,"AT",TRACKER!$G$3:$G$1275,"Passed")+COUNTIFS(TRACKER!$C$3:$C$1275,A4,TRACKER!$D$3:$D$1275,"AT",TRACKER!$G$3:$G$1275,"Accepted Exception"))/COUNTIFS(TRACKER!$C$3:$C$1275,A4,TRACKER!$D$3:$D$1275,"AT"),"") | D4: =IFERROR(1-(COUNTIFS(TRACKER!$C$3:$C$1275,A4,TRACKER!$D$3:$D$1275,"AU",TRACKER!$G$3:$G$1275,"Passed")+COUNTIFS(TRACKER!$C$3:$C$1275,A4,TRACKER!$D$3:$D$1275,"AU",TRACKER!$G$3:$G$1275,"Accepted Exception"))/COUNTIFS(TRACKER!$C$3:$C$1275,A4,TRACKER!$D$3:$D$1275,"AU"),"") | E4: =IFERROR(1-(COUNTIFS(TRACKER!$C$3:$C$1275,A4,TRACKER!$D$3:$D$1275,"CA",TRACKER!$G$3:$G$1275,"Passed")+COUNTIFS(TRACKER!$C$3:$C$1275,A4,TRACKER!$D$3:$D$1275,"CA",TRACKER!$G$3:$G$1275,"Accepted Exception"))/COUNTIFS(TRACKER!$C$3:$C$1275,A4,TRACKER!$D$3:$D$1275,"CA"),"") | F4: =IFERROR(1-(COUNTIFS(TRACKER!$C$3:$C$1275,A4,TRACKER!$D$3:$D$1275,"CM",TRACKER!$G$3:$G$1275,"Passed")+COUNTIFS(TRACKER!$C$3:$C$1275,A4,TRACKER!$D$3:$D$1275,"CM",TRACKER!$G$3:$G$1275,"Accepted Exception"))/COUNTIFS(TRACKER!$C$3:$C$1275,A4,TRACKER!$D$3:$D$1275,"CM"),"") | G4: =IFERROR(1-(COUNTIFS(TRACKER!$C$3:$C$1275,A4,TRACKER!$D$3:$D$1275,"CP",TRACKER!$G$3:$G$1275,"Passed")+COUNTIFS(TRACKER!$C$3:$C$1275,A4,TRACKER!$D$3:$D$1275,"CP",TRACKER!$G$3:$G$1275,"Accepted Exception"))/COUNTIFS(TRACKER!$C$3:$C$1275,A4,TRACKER!$D$3:$D$1275,"CP"),"") | H4: =IFERROR(1-(COUNTIFS(TRACKER!$C$3:$C$1275,A4,TRACKER!$D$3:$D$1275,"IA",TRACKER!$G$3:$G$1275,"Passed")+COUNTIFS(TRACKER!$C$3:$C$1275,A4,TRACKER!$D$3:$D$1275,"IA",TRACKER!$G$3:$G$1275,"Accepted Exception"))/COUNTIFS(TRACKER!$C$3:$C$1275,A4,TRACKER!$D$3:$D$1275,"IA"),"") | I4: =IFERROR(1-(COUNTIFS(TRACKER!$C$3:$C$1275,A4,TRACKER!$D$3:$D$1275,"IR",TRACKER!$G$3:$G$1275,"Passed")+COUNTIFS(TRACKER!$C$3:$C$1275,A4,TRACKER!$D$3:$D$1275,"IR",TRACKER!$G$3:$G$1275,"Accepted Exception"))/COUNTIFS(TRACKER!$C$3:$C$1275,A4,TRACKER!$D$3:$D$1275,"IR"),"") | J4: =IFERROR(1-(COUNTIFS(TRACKER!$C$3:$C$1275,A4,TRACKER!$D$3:$D$1275,"MA",TRACKER!$G$3:$G$1275,"Passed")+COUNTIFS(TRACKER!$C$3:$C$1275,A4,TRACKER!$D$3:$D$1275,"MA",TRACKER!$G$3:$G$1275,"Accepted Exception"))/COUNTIFS(TRACKER!$C$3:$C$1275,A4,TRACKER!$D$3:$D$1275,"MA"),"") | K4: =IFERROR(1-(COUNTIFS(TRACKER!$C$3:$C$1275,A4,TRACKER!$D$3:$D$1275,"MP",TRACKER!$G$3:$G$1275,"Passed")+COUNTIFS(TRACKER!$C$3:$C$1275,A4,TRACKER!$D$3:$D$1275,"MP",TRACKER!$G$3:$G$1275,"Accepted Exception"))/COUNTIFS(TRACKER!$C$3:$C$1275,A4,TRACKER!$D$3:$D$1275,"MP"),"") | L4: =IFERROR(1-(COUNTIFS(TRACKER!$C$3:$C$1275,A4,TRACKER!$D$3:$D$1275,"PE",TRACKER!$G$3:$G$1275,"Passed")+COUNTIFS(TRACKER!$C$3:$C$1275,A4,TRACKER!$D$3:$D$1275,"PE",TRACKER!$G$3:$G$1275,"Accepted Exception"))/COUNTIFS(TRACKER!$C$3:$C$1275,A4,TRACKER!$D$3:$D$1275,"PE"),"") | M4: =IFERROR(1-(COUNTIFS(TRACKER!$C$3:$C$1275,A4,TRACKER!$D$3:$D$1275,"PL",TRACKER!$G$3:$G$1275,"Passed")+COUNTIFS(TRACKER!$C$3:$C$1275,A4,TRACKER!$D$3:$D$1275,"PL",TRACKER!$G$3:$G$1275,"Accepted Exception"))/COUNTIFS(TRACKER!$C$3:$C$1275,A4,TRACKER!$D$3:$D$1275,"PL"),"") | N4: =IFERROR(1-(COUNTIFS(TRACKER!$C$3:$C$1275,A4,TRACKER!$D$3:$D$1275,"PS",TRACKER!$G$3:$G$1275,"Passed")+COUNTIFS(TRACKER!$C$3:$C$1275,A4,TRACKER!$D$3:$D$1275,"PS",TRACKER!$G$3:$G$1275,"Accepted Exception"))/COUNTIFS(TRACKER!$C$3:$C$1275,A4,TRACKER!$D$3:$D$1275,"PS"),"") | O4: =IFERROR(1-(COUNTIFS(TRACKER!$C$3:$C$1275,A4,TRACKER!$D$3:$D$1275,"RA",TRACKER!$G$3:$G$1275,"Passed")+COUNTIFS(TRACKER!$C$3:$C$1275,A4,TRACKER!$D$3:$D$1275,"RA",TRACKER!$G$3:$G$1275,"Accepted Exception"))/COUNTIFS(TRACKER!$C$3:$C$1275,A4,TRACKER!$D$3:$D$1275,"RA"),"") | P4: =IFERROR(1-(COUNTIFS(TRACKER!$C$3:$C$1275,A4,TRACKER!$D$3:$D$1275,"SA",TRACKER!$G$3:$G$1275,"Passed")+COUNTIFS(TRACKER!$C$3:$C$1275,A4,TRACKER!$D$3:$D$1275,"SA",TRACKER!$G$3:$G$1275,"Accepted Exception"))/COUNTIFS(TRACKER!$C$3:$C$1275,A4,TRACKER!$D$3:$D$1275,"SA"),"") | Q4: =IFERROR(1-(COUNTIFS(TRACKER!$C$3:$C$1275,A4,TRACKER!$D$3:$D$1275,"SC",TRACKER!$G$3:$G$1275,"Passed")+COUNTIFS(TRACKER!$C$3:$C$1275,A4,TRACKER!$D$3:$D$1275,"SC",TRACKER!$G$3:$G$1275,"Accepted Exception"))/COUNTIFS(TRACKER!$C$3:$C$1275,A4,TRACKER!$D$3:$D$1275,"SC"),"") | R4: =IFERROR(1-(COUNTIFS(TRACKER!$C$3:$C$1275,A4,TRACKER!$D$3:$D$1275,"SI",TRACKER!$G$3:$G$1275,"Passed")+COUNTIFS(TRACKER!$C$3:$C$1275,A4,TRACKER!$D$3:$D$1275,"SI",TRACKER!$G$3:$G$1275,"Accepted Exception"))/COUNTIFS(TRACKER!$C$3:$C$1275,A4,TRACKER!$D$3:$D$1275,"SI"),"")
A5: Containers | B5: =IFERROR(1-(COUNTIFS(TRACKER!$C$3:$C$1275,A5,TRACKER!$D$3:$D$1275,"AC",TRACKER!$G$3:$G$1275,"Passed")+COUNTIFS(TRACKER!$C$3:$C$1275,A5,TRACKER!$D$3:$D$1275,"AC",TRACKER!$G$3:$G$1275,"Accepted Exception"))/COUNTIFS(TRACKER!$C$3:$C$1275,A5,TRACKER!$D$3:$D$1275,"AC"),"") | C5: =IFERROR(1-(COUNTIFS(TRACKER!$C$3:$C$1275,A5,TRACKER!$D$3:$D$1275,"AT",TRACKER!$G$3:$G$1275,"Passed")+COUNTIFS(TRACKER!$C$3:$C$1275,A5,TRACKER!$D$3:$D$1275,"AT",TRACKER!$G$3:$G$1275,"Accepted Exception"))/COUNTIFS(TRACKER!$C$3:$C$1275,A5,TRACKER!$D$3:$D$1275,"AT"),"") | D5: =IFERROR(1-(COUNTIFS(TRACKER!$C$3:$C$1275,A5,TRACKER!$D$3:$D$1275,"AU",TRACKER!$G$3:$G$1275,"Passed")+COUNTIFS(TRACKER!$C$3:$C$1275,A5,TRACKER!$D$3:$D$1275,"AU",TRACKER!$G$3:$G$1275,"Accepted Exception"))/COUNTIFS(TRACKER!$C$3:$C$1275,A5,TRACKER!$D$3:$D$1275,"AU"),"") | E5: =IFERROR(1-(COUNTIFS(TRACKER!$C$3:$C$1275,A5,TRACKER!$D$3:$D$1275,"CA",TRACKER!$G$3:$G$1275,"Passed")+COUNTIFS(TRACKER!$C$3:$C$1275,A5,TRACKER!$D$3:$D$1275,"CA",TRACKER!$G$3:$G$1275,"Accepted Exception"))/COUNTIFS(TRACKER!$C$3:$C$1275,A5,TRACKER!$D$3:$D$1275,"CA"),"") | F5: =IFERROR(1-(COUNTIFS(TRACKER!$C$3:$C$1275,A5,TRACKER!$D$3:$D$1275,"CM",TRACKER!$G$3:$G$1275,"Passed")+COUNTIFS(TRACKER!$C$3:$C$1275,A5,TRACKER!$D$3:$D$1275,"CM",TRACKER!$G$3:$G$1275,"Accepted Exception"))/COUNTIFS(TRACKER!$C$3:$C$1275,A5,TRACKER!$D$3:$D$1275,"CM"),"") | G5: =IFERROR(1-(COUNTIFS(TRACKER!$C$3:$C$1275,A5,TRACKER!$D$3:$D$1275,"CP",TRACKER!$G$3:$G$1275,"Passed")+COUNTIFS(TRACKER!$C$3:$C$1275,A5,TRACKER!$D$3:$D$1275,"CP",TRACKER!$G$3:$G$1275,"Accepted Exception"))/COUNTIFS(TRACKER!$C$3:$C$1275,A5,TRACKER!$D$3:$D$1275,"CP"),"") | H5: =IFERROR(1-(COUNTIFS(TRACKER!$C$3:$C$1275,A5,TRACKER!$D$3:$D$1275,"IA",TRACKER!$G$3:$G$1275,"Passed")+COUNTIFS(TRACKER!$C$3:$C$1275,A5,TRACKER!$D$3:$D$1275,"IA",TRACKER!$G$3:$G$1275,"Accepted Exception"))/COUNTIFS(TRACKER!$C$3:$C$1275,A5,TRACKER!$D$3:$D$1275,"IA"),"") | I5: =IFERROR(1-(COUNTIFS(TRACKER!$C$3:$C$1275,A5,TRACKER!$D$3:$D$1275,"IR",TRACKER!$G$3:$G$1275,"Passed")+COUNTIFS(TRACKER!$C$3:$C$1275,A5,TRACKER!$D$3:$D$1275,"IR",TRACKER!$G$3:$G$1275,"Accepted Exception"))/COUNTIFS(TRACKER!$C$3:$C$1275,A5,TRACKER!$D$3:$D$1275,"IR"),"") | J5: =IFERROR(1-(COUNTIFS(TRACKER!$C$3:$C$1275,A5,TRACKER!$D$3:$D$1275,"MA",TRACKER!$G$3:$G$1275,"Passed")+COUNTIFS(TRACKER!$C$3:$C$1275,A5,TRACKER!$D$3:$D$1275,"MA",TRACKER!$G$3:$G$1275,"Accepted Exception"))/COUNTIFS(TRACKER!$C$3:$C$1275,A5,TRACKER!$D$3:$D$1275,"MA"),"") | K5: =IFERROR(1-(COUNTIFS(TRACKER!$C$3:$C$1275,A5,TRACKER!$D$3:$D$1275,"MP",TRACKER!$G$3:$G$1275,"Passed")+COUNTIFS(TRACKER!$C$3:$C$1275,A5,TRACKER!$D$3:$D$1275,"MP",TRACKER!$G$3:$G$1275,"Accepted Exception"))/COUNTIFS(TRACKER!$C$3:$C$1275,A5,TRACKER!$D$3:$D$1275,"MP"),"") | L5: =IFERROR(1-(COUNTIFS(TRACKER!$C$3:$C$1275,A5,TRACKER!$D$3:$D$1275,"PE",TRACKER!$G$3:$G$1275,"Passed")+COUNTIFS(TRACKER!$C$3:$C$1275,A5,TRACKER!$D$3:$D$1275,"PE",TRACKER!$G$3:$G$1275,"Accepted Exception"))/COUNTIFS(TRACKER!$C$3:$C$1275,A5,TRACKER!$D$3:$D$1275,"PE"),"") | M5: =IFERROR(1-(COUNTIFS(TRACKER!$C$3:$C$1275,A5,TRACKER!$D$3:$D$1275,"PL",TRACKER!$G$3:$G$1275,"Passed")+COUNTIFS(TRACKER!$C$3:$C$1275,A5,TRACKER!$D$3:$D$1275,"PL",TRACKER!$G$3:$G$1275,"Accepted Exception"))/COUNTIFS(TRACKER!$C$3:$C$1275,A5,TRACKER!$D$3:$D$1275,"PL"),"") | N5: =IFERROR(1-(COUNTIFS(TRACKER!$C$3:$C$1275,A5,TRACKER!$D$3:$D$1275,"PS",TRACKER!$G$3:$G$1275,"Passed")+COUNTIFS(TRACKER!$C$3:$C$1275,A5,TRACKER!$D$3:$D$1275,"PS",TRACKER!$G$3:$G$1275,"Accepted Exception"))/COUNTIFS(TRACKER!$C$3:$C$1275,A5,TRACKER!$D$3:$D$1275,"PS"),"") | O5: =IFERROR(1-(COUNTIFS(TRACKER!$C$3:$C$1275,A5,TRACKER!$D$3:$D$1275,"RA",TRACKER!$G$3:$G$1275,"Passed")+COUNTIFS(TRACKER!$C$3:$C$1275,A5,TRACKER!$D$3:$D$1275,"RA",TRACKER!$G$3:$G$1275,"Accepted Exception"))/COUNTIFS(TRACKER!$C$3:$C$1275,A5,TRACKER!$D$3:$D$1275,"RA"),"") | P5: =IFERROR(1-(COUNTIFS(TRACKER!$C$3:$C$1275,A5,TRACKER!$D$3:$D$1275,"SA",TRACKER!$G$3:$G$1275,"Passed")+COUNTIFS(TRACKER!$C$3:$C$1275,A5,TRACKER!$D$3:$D$1275,"SA",TRACKER!$G$3:$G$1275,"Accepted Exception"))/COUNTIFS(TRACKER!$C$3:$C$1275,A5,TRACKER!$D$3:$D$1275,"SA"),"") | Q5: =IFERROR(1-(COUNTIFS(TRACKER!$C$3:$C$1275,A5,TRACKER!$D$3:$D$1275,"SC",TRACKER!$G$3:$G$1275,"Passed")+COUNTIFS(TRACKER!$C$3:$C$1275,A5,TRACKER!$D$3:$D$1275,"SC",TRACKER!$G$3:$G$1275,"Accepted Exception"))/COUNTIFS(TRACKER!$C$3:$C$1275,A5,TRACKER!$D$3:$D$1275,"SC"),"") | R5: =IFERROR(1-(COUNTIFS(TRACKER!$C$3:$C$1275,A5,TRACKER!$D$3:$D$1275,"SI",TRACKER!$G$3:$G$1275,"Passed")+COUNTIFS(TRACKER!$C$3:$C$1275,A5,TRACKER!$D$3:$D$1275,"SI",TRACKER!$G$3:$G$1275,"Accepted Exception"))/COUNTIFS(TRACKER!$C$3:$C$1275,A5,TRACKER!$D$3:$D$1275,"SI"),"")
A6: Database | B6: =IFERROR(1-(COUNTIFS(TRACKER!$C$3:$C$1275,A6,TRACKER!$D$3:$D$1275,"AC",TRACKER!$G$3:$G$1275,"Passed")+COUNTIFS(TRACKER!$C$3:$C$1275,A6,TRACKER!$D$3:$D$1275,"AC",TRACKER!$G$3:$G$1275,"Accepted Exception"))/COUNTIFS(TRACKER!$C$3:$C$1275,A6,TRACKER!$D$3:$D$1275,"AC"),"") | C6: =IFERROR(1-(COUNTIFS(TRACKER!$C$3:$C$1275,A6,TRACKER!$D$3:$D$1275,"AT",TRACKER!$G$3:$G$1275,"Passed")+COUNTIFS(TRACKER!$C$3:$C$1275,A6,TRACKER!$D$3:$D$1275,"AT",TRACKER!$G$3:$G$1275,"Accepted Exception"))/COUNTIFS(TRACKER!$C$3:$C$1275,A6,TRACKER!$D$3:$D$1275,"AT"),"") | D6: =IFERROR(1-(COUNTIFS(TRACKER!$C$3:$C$1275,A6,TRACKER!$D$3:$D$1275,"AU",TRACKER!$G$3:$G$1275,"Passed")+COUNTIFS(TRACKER!$C$3:$C$1275,A6,TRACKER!$D$3:$D$1275,"AU",TRACKER!$G$3:$G$1275,"Accepted Exception"))/COUNTIFS(TRACKER!$C$3:$C$1275,A6,TRACKER!$D$3:$D$1275,"AU"),"") | E6: =IFERROR(1-(COUNTIFS(TRACKER!$C$3:$C$1275,A6,TRACKER!$D$3:$D$1275,"CA",TRACKER!$G$3:$G$1275,"Passed")+COUNTIFS(TRACKER!$C$3:$C$1275,A6,TRACKER!$D$3:$D$1275,"CA",TRACKER!$G$3:$G$1275,"Accepted Exception"))/COUNTIFS(TRACKER!$C$3:$C$1275,A6,TRACKER!$D$3:$D$1275,"CA"),"") | F6: =IFERROR(1-(COUNTIFS(TRACKER!$C$3:$C$1275,A6,TRACKER!$D$3:$D$1275,"CM",TRACKER!$G$3:$G$1275,"Passed")+COUNTIFS(TRACKER!$C$3:$C$1275,A6,TRACKER!$D$3:$D$1275,"CM",TRACKER!$G$3:$G$1275,"Accepted Exception"))/COUNTIFS(TRACKER!$C$3:$C$1275,A6,TRACKER!$D$3:$D$1275,"CM"),"") | G6: =IFERROR(1-(COUNTIFS(TRACKER!$C$3:$C$1275,A6,TRACKER!$D$3:$D$1275,"CP",TRACKER!$G$3:$G$1275,"Passed")+COUNTIFS(TRACKER!$C$3:$C$1275,A6,TRACKER!$D$3:$D$1275,"CP",TRACKER!$G$3:$G$1275,"Accepted Exception"))/COUNTIFS(TRACKER!$C$3:$C$1275,A6,TRACKER!$D$3:$D$1275,"CP"),"") | H6: =IFERROR(1-(COUNTIFS(TRACKER!$C$3:$C$1275,A6,TRACKER!$D$3:$D$1275,"IA",TRACKER!$G$3:$G$1275,"Passed")+COUNTIFS(TRACKER!$C$3:$C$1275,A6,TRACKER!$D$3:$D$1275,"IA",TRACKER!$G$3:$G$1275,"Accepted Exception"))/COUNTIFS(TRACKER!$C$3:$C$1275,A6,TRACKER!$D$3:$D$1275,"IA"),"") | I6: =IFERROR(1-(COUNTIFS(TRACKER!$C$3:$C$1275,A6,TRACKER!$D$3:$D$1275,"IR",TRACKER!$G$3:$G$1275,"Passed")+COUNTIFS(TRACKER!$C$3:$C$1275,A6,TRACKER!$D$3:$D$1275,"IR",TRACKER!$G$3:$G$1275,"Accepted Exception"))/COUNTIFS(TRACKER!$C$3:$C$1275,A6,TRACKER!$D$3:$D$1275,"IR"),"") | J6: =IFERROR(1-(COUNTIFS(TRACKER!$C$3:$C$1275,A6,TRACKER!$D$3:$D$1275,"MA",TRACKER!$G$3:$G$1275,"Passed")+COUNTIFS(TRACKER!$C$3:$C$1275,A6,TRACKER!$D$3:$D$1275,"MA",TRACKER!$G$3:$G$1275,"Accepted Exception"))/COUNTIFS(TRACKER!$C$3:$C$1275,A6,TRACKER!$D$3:$D$1275,"MA"),"") | K6: =IFERROR(1-(COUNTIFS(TRACKER!$C$3:$C$1275,A6,TRACKER!$D$3:$D$1275,"MP",TRACKER!$G$3:$G$1275,"Passed")+COUNTIFS(TRACKER!$C$3:$C$1275,A6,TRACKER!$D$3:$D$1275,"MP",TRACKER!$G$3:$G$1275,"Accepted Exception"))/COUNTIFS(TRACKER!$C$3:$C$1275,A6,TRACKER!$D$3:$D$1275,"MP"),"") | L6: =IFERROR(1-(COUNTIFS(TRACKER!$C$3:$C$1275,A6,TRACKER!$D$3:$D$1275,"PE",TRACKER!$G$3:$G$1275,"Passed")+COUNTIFS(TRACKER!$C$3:$C$1275,A6,TRACKER!$D$3:$D$1275,"PE",TRACKER!$G$3:$G$1275,"Accepted Exception"))/COUNTIFS(TRACKER!$C$3:$C$1275,A6,TRACKER!$D$3:$D$1275,"PE"),"") | M6: =IFERROR(1-(COUNTIFS(TRACKER!$C$3:$C$1275,A6,TRACKER!$D$3:$D$1275,"PL",TRACKER!$G$3:$G$1275,"Passed")+COUNTIFS(TRACKER!$C$3:$C$1275,A6,TRACKER!$D$3:$D$1275,"PL",TRACKER!$G$3:$G$1275,"Accepted Exception"))/COUNTIFS(TRACKER!$C$3:$C$1275,A6,TRACKER!$D$3:$D$1275,"PL"),"") | N6: =IFERROR(1-(COUNTIFS(TRACKER!$C$3:$C$1275,A6,TRACKER!$D$3:$D$1275,"PS",TRACKER!$G$3:$G$1275,"Passed")+COUNTIFS(TRACKER!$C$3:$C$1275,A6,TRACKER!$D$3:$D$1275,"PS",TRACKER!$G$3:$G$1275,"Accepted Exception"))/COUNTIFS(TRACKER!$C$3:$C$1275,A6,TRACKER!$D$3:$D$1275,"PS"),"") | O6: =IFERROR(1-(COUNTIFS(TRACKER!$C$3:$C$1275,A6,TRACKER!$D$3:$D$1275,"RA",TRACKER!$G$3:$G$1275,"Passed")+COUNTIFS(TRACKER!$C$3:$C$1275,A6,TRACKER!$D$3:$D$1275,"RA",TRACKER!$G$3:$G$1275,"Accepted Exception"))/COUNTIFS(TRACKER!$C$3:$C$1275,A6,TRACKER!$D$3:$D$1275,"RA"),"") | P6: =IFERROR(1-(COUNTIFS(TRACKER!$C$3:$C$1275,A6,TRACKER!$D$3:$D$1275,"SA",TRACKER!$G$3:$G$1275,"Passed")+COUNTIFS(TRACKER!$C$3:$C$1275,A6,TRACKER!$D$3:$D$1275,"SA",TRACKER!$G$3:$G$1275,"Accepted Exception"))/COUNTIFS(TRACKER!$C$3:$C$1275,A6,TRACKER!$D$3:$D$1275,"SA"),"") | Q6: =IFERROR(1-(COUNTIFS(TRACKER!$C$3:$C$1275,A6,TRACKER!$D$3:$D$1275,"SC",TRACKER!$G$3:$G$1275,"Passed")+COUNTIFS(TRACKER!$C$3:$C$1275,A6,TRACKER!$D$3:$D$1275,"SC",TRACKER!$G$3:$G$1275,"Accepted Exception"))/COUNTIFS(TRACKER!$C$3:$C$1275,A6,TRACKER!$D$3:$D$1275,"SC"),"") | R6: =IFERROR(1-(COUNTIFS(TRACKER!$C$3:$C$1275,A6,TRACKER!$D$3:$D$1275,"SI",TRACKER!$G$3:$G$1275,"Passed")+COUNTIFS(TRACKER!$C$3:$C$1275,A6,TRACKER!$D$3:$D$1275,"SI",TRACKER!$G$3:$G$1275,"Accepted Exception"))/COUNTIFS(TRACKER!$C$3:$C$1275,A6,TRACKER!$D$3:$D$1275,"SI"),"")
A7: DevOps | B7: =IFERROR(1-(COUNTIFS(TRACKER!$C$3:$C$1275,A7,TRACKER!$D$3:$D$1275,"AC",TRACKER!$G$3:$G$1275,"Passed")+COUNTIFS(TRACKER!$C$3:$C$1275,A7,TRACKER!$D$3:$D$1275,"AC",TRACKER!$G$3:$G$1275,"Accepted Exception"))/COUNTIFS(TRACKER!$C$3:$C$1275,A7,TRACKER!$D$3:$D$1275,"AC"),"") | C7: =IFERROR(1-(COUNTIFS(TRACKER!$C$3:$C$1275,A7,TRACKER!$D$3:$D$1275,"AT",TRACKER!$G$3:$G$1275,"Passed")+COUNTIFS(TRACKER!$C$3:$C$1275,A7,TRACKER!$D$3:$D$1275,"AT",TRACKER!$G$3:$G$1275,"Accepted Exception"))/COUNTIFS(TRACKER!$C$3:$C$1275,A7,TRACKER!$D$3:$D$1275,"AT"),"") | D7: =IFERROR(1-(COUNTIFS(TRACKER!$C$3:$C$1275,A7,TRACKER!$D$3:$D$1275,"AU",TRACKER!$G$3:$G$1275,"Passed")+COUNTIFS(TRACKER!$C$3:$C$1275,A7,TRACKER!$D$3:$D$1275,"AU",TRACKER!$G$3:$G$1275,"Accepted Exception"))/COUNTIFS(TRACKER!$C$3:$C$1275,A7,TRACKER!$D$3:$D$1275,"AU"),"") | E7: =IFERROR(1-(COUNTIFS(TRACKER!$C$3:$C$1275,A7,TRACKER!$D$3:$D$1275,"CA",TRACKER!$G$3:$G$1275,"Passed")+COUNTIFS(TRACKER!$C$3:$C$1275,A7,TRACKER!$D$3:$D$1275,"CA",TRACKER!$G$3:$G$1275,"Accepted Exception"))/COUNTIFS(TRACKER!$C$3:$C$1275,A7,TRACKER!$D$3:$D$1275,"CA"),"") | F7: =IFERROR(1-(COUNTIFS(TRACKER!$C$3:$C$1275,A7,TRACKER!$D$3:$D$1275,"CM",TRACKER!$G$3:$G$1275,"Passed")+COUNTIFS(TRACKER!$C$3:$C$1275,A7,TRACKER!$D$3:$D$1275,"CM",TRACKER!$G$3:$G$1275,"Accepted Exception"))/COUNTIFS(TRACKER!$C$3:$C$1275,A7,TRACKER!$D$3:$D$1275,"CM"),"") | G7: =IFERROR(1-(COUNTIFS(TRACKER!$C$3:$C$1275,A7,TRACKER!$D$3:$D$1275,"CP",TRACKER!$G$3:$G$1275,"Passed")+COUNTIFS(TRACKER!$C$3:$C$1275,A7,TRACKER!$D$3:$D$1275,"CP",TRACKER!$G$3:$G$1275,"Accepted Exception"))/COUNTIFS(TRACKER!$C$3:$C$1275,A7,TRACKER!$D$3:$D$1275,"CP"),"") | H7: =IFERROR(1-(COUNTIFS(TRACKER!$C$3:$C$1275,A7,TRACKER!$D$3:$D$1275,"IA",TRACKER!$G$3:$G$1275,"Passed")+COUNTIFS(TRACKER!$C$3:$C$1275,A7,TRACKER!$D$3:$D$1275,"IA",TRACKER!$G$3:$G$1275,"Accepted Exception"))/COUNTIFS(TRACKER!$C$3:$C$1275,A7,TRACKER!$D$3:$D$1275,"IA"),"") | I7: =IFERROR(1-(COUNTIFS(TRACKER!$C$3:$C$1275,A7,TRACKER!$D$3:$D$1275,"IR",TRACKER!$G$3:$G$1275,"Passed")+COUNTIFS(TRACKER!$C$3:$C$1275,A7,TRACKER!$D$3:$D$1275,"IR",TRACKER!$G$3:$G$1275,"Accepted Exception"))/COUNTIFS(TRACKER!$C$3:$C$1275,A7,TRACKER!$D$3:$D$1275,"IR"),"") | J7: =IFERROR(1-(COUNTIFS(TRACKER!$C$3:$C$1275,A7,TRACKER!$D$3:$D$1275,"MA",TRACKER!$G$3:$G$1275,"Passed")+COUNTIFS(TRACKER!$C$3:$C$1275,A7,TRACKER!$D$3:$D$1275,"MA",TRACKER!$G$3:$G$1275,"Accepted Exception"))/COUNTIFS(TRACKER!$C$3:$C$1275,A7,TRACKER!$D$3:$D$1275,"MA"),"") | K7: =IFERROR(1-(COUNTIFS(TRACKER!$C$3:$C$1275,A7,TRACKER!$D$3:$D$1275,"MP",TRACKER!$G$3:$G$1275,"Passed")+COUNTIFS(TRACKER!$C$3:$C$1275,A7,TRACKER!$D$3:$D$1275,"MP",TRACKER!$G$3:$G$1275,"Accepted Exception"))/COUNTIFS(TRACKER!$C$3:$C$1275,A7,TRACKER!$D$3:$D$1275,"MP"),"") | L7: =IFERROR(1-(COUNTIFS(TRACKER!$C$3:$C$1275,A7,TRACKER!$D$3:$D$1275,"PE",TRACKER!$G$3:$G$1275,"Passed")+COUNTIFS(TRACKER!$C$3:$C$1275,A7,TRACKER!$D$3:$D$1275,"PE",TRACKER!$G$3:$G$1275,"Accepted Exception"))/COUNTIFS(TRACKER!$C$3:$C$1275,A7,TRACKER!$D$3:$D$1275,"PE"),"") | M7: =IFERROR(1-(COUNTIFS(TRACKER!$C$3:$C$1275,A7,TRACKER!$D$3:$D$1275,"PL",TRACKER!$G$3:$G$1275,"Passed")+COUNTIFS(TRACKER!$C$3:$C$1275,A7,TRACKER!$D$3:$D$1275,"PL",TRACKER!$G$3:$G$1275,"Accepted Exception"))/COUNTIFS(TRACKER!$C$3:$C$1275,A7,TRACKER!$D$3:$D$1275,"PL"),"") | N7: =IFERROR(1-(COUNTIFS(TRACKER!$C$3:$C$1275,A7,TRACKER!$D$3:$D$1275,"PS",TRACKER!$G$3:$G$1275,"Passed")+COUNTIFS(TRACKER!$C$3:$C$1275,A7,TRACKER!$D$3:$D$1275,"PS",TRACKER!$G$3:$G$1275,"Accepted Exception"))/COUNTIFS(TRACKER!$C$3:$C$1275,A7,TRACKER!$D$3:$D$1275,"PS"),"") | O7: =IFERROR(1-(COUNTIFS(TRACKER!$C$3:$C$1275,A7,TRACKER!$D$3:$D$1275,"RA",TRACKER!$G$3:$G$1275,"Passed")+COUNTIFS(TRACKER!$C$3:$C$1275,A7,TRACKER!$D$3:$D$1275,"RA",TRACKER!$G$3:$G$1275,"Accepted Exception"))/COUNTIFS(TRACKER!$C$3:$C$1275,A7,TRACKER!$D$3:$D$1275,"RA"),"") | P7: =IFERROR(1-(COUNTIFS(TRACKER!$C$3:$C$1275,A7,TRACKER!$D$3:$D$1275,"SA",TRACKER!$G$3:$G$1275,"Passed")+COUNTIFS(TRACKER!$C$3:$C$1275,A7,TRACKER!$D$3:$D$1275,"SA",TRACKER!$G$3:$G$1275,"Accepted Exception"))/COUNTIFS(TRACKER!$C$3:$C$1275,A7,TRACKER!$D$3:$D$1275,"SA"),"") | Q7: =IFERROR(1-(COUNTIFS(TRACKER!$C$3:$C$1275,A7,TRACKER!$D$3:$D$1275,"SC",TRACKER!$G$3:$G$1275,"Passed")+COUNTIFS(TRACKER!$C$3:$C$1275,A7,TRACKER!$D$3:$D$1275,"SC",TRACKER!$G$3:$G$1275,"Accepted Exception"))/COUNTIFS(TRACKER!$C$3:$C$1275,A7,TRACKER!$D$3:$D$1275,"SC"),"") | R7: =IFERROR(1-(COUNTIFS(TRACKER!$C$3:$C$1275,A7,TRACKER!$D$3:$D$1275,"SI",TRACKER!$G$3:$G$1275,"Passed")+COUNTIFS(TRACKER!$C$3:$C$1275,A7,TRACKER!$D$3:$D$1275,"SI",TRACKER!$G$3:$G$1275,"Accepted Exception"))/COUNTIFS(TRACKER!$C$3:$C$1275,A7,TRACKER!$D$3:$D$1275,"SI"),"")
