Workbook

Sheet DASHBOARD
A1: DASHBOARD — PBMM Evidence: Security
A2: Control ID | B2: Control Name | C2: Primary Tool | D2: Tab | E2: Status
A3: AC-2(4) | B3: Account Management | D3: AC-2-4 | E3: ='AC-2-4'!B20 -> Not Started
A4: AC-2(5) | B4: Account Management | D4: AC-2-5 | E4: ='AC-2-5'!B20 -> Not Started
A5: AC-2(7) | B5: Account Management | D5: AC-2-7 | E5: ='AC-2-7'!B20 -> Not Started
A6: AC-4 | B6: Information Flow Enforcement | D6: AC-4 | E6: ='AC-4'!B20 -> Not Started
A7: AC-4(21) | B7: Information Flow Enforcement | D7: AC-4-21 | E7: ='AC-4-21'!B20 -> Not Started
A8: AC-6(9) | B8: Least Privilege | D8: AC-6-9 | E8: ='AC-6-9'!B20 -> Not Started
A9: AC-6(10) | B9: Least Privilege | D9: AC-6-10 | E9: ='AC-6-10'!B20 -> Not Started
A10: AC-17(1) | B10: Remote Access | D10: AC-17-1 | E10: ='AC-17-1'!B20 -> Not Started
A11: AC-17(2) | B11: Remote Access | D11: AC-17-2 | E11: ='AC-17-2'!B20 -> Not Started
A12: AC-17(3) | B12: Remote Access | D12: AC-17-3 | E12: ='AC-17-3'!B20 -> Not Started
A13: AC-17(9) | B13: Remote Access | D13: AC-17-9 | E13: ='AC-17-9'!B20 -> Not Started
A14: AU-2 | B14: Auditable Events | D14: AU-2 | E14: ='AU-2'!B20 -> Not Started
A15: AU-3 | B15: Content of Audit Records | D15: AU-3 | E15: ='AU-3'!B20 -> Not Started
A16: AU-3(1) | B16: Content of Audit Records | D16: AU-3-1 | E16: ='AU-3-1'!B20 -> Not Started
A17: AU-5 | B17: Response To Audit Processing Failures | D17: AU-5 | E17: ='AU-5'!B20 -> Not Started
A18: AU-6(1) | B18: Audit Review, Analysis, and Reporting | D18: AU-6-1 | E18: ='AU-6-1'!B20 -> Not Started
A19: AU-6(3) | B19: Audit Review, Analysis, and Reporting | D19: AU-6-3 | E19: ='AU-6-3'!B20 -> Not Started
A20: AU-7 | B20: Audit Reduction and Report Generation | D20: AU-7 | E20: ='AU-7'!B20 -> Not Started
A21: AU-7(1) | B21: Audit Reduction and Report Generation | D21: AU-7-1 | E21: ='AU-7-1'!B20 -> Not Started
A22: AU-8 | B22: Time Stamps | D22: AU-8 | E22: ='AU-8'!B20 -> Not Started
A23: AU-8(1) | B23: Time Stamps | D23: AU-8-1 | E23: ='AU-8-1'!B20 -> Not Started
A24: AU-9 | B24: Protection of Audit Information | D24: AU-9 | E24: ='AU-9'!B20 -> Not Started
A25: AU-9(2) | B25: Protection of Audit Information | D25: AU-9-2 | E25: ='AU-9-2'!B20 -> Not Started
A26: AU-9(4) | B26: Protection of Audit Information | D26: AU-9-4 | E26: ='AU-9-4'!B20 -> Not Started
A27: AU-11 | B27: Audit Record Retention | D27: AU-11 | E27: ='AU-11'!B20 -> Not Started
A28: AU-12 | B28: Audit Generation | D28: AU-12 | E28: ='AU-12'!B20 -> Not Started
A29: CA-3(5) | B29: Information System Connections | D29: CA-3-5 | E29: ='CA-3-5'!B20 -> Not Started
A30: CA-9 | B30: Internal System Connections | D30: CA-9 | E30: ='CA-9'!B20 -> Not Started
A31: CM-5(1) | B31: Access Restrictions for Change | D31: CM-5-1 | E31: ='CM-5-1'!B20 -> Not Started
A32: CM-6 | B32: Configuration Settings | D32: CM-6 | E32: ='CM-6'!B20 -> Not Started
A33: CM-7 | B33: Least Functionality | D33: CM-7 | E33: ='CM-7'!B20 -> Not Started
A34: CM-7(1) | B34: Least Functionality | D34: CM-7-1 | E34: ='CM-7-1'!B20 -> Not Started
A35: CM-10 | B35: Software Usage Restrictions | D35: CM-10 | E35: ='CM-10'!B20 -> Not Started
A36: CP-6 | B36: Alternate Storage Site | D36: CP-6 | E36: ='CP-6'!B20 -> Not Started
A37: CP-6(2) | B37: Alternate Storage Site | D37: CP-6-2 | E37: ='CP-6-2'!B20 -> Not Started
A38: CP-7 | B38: Alternate Processing Site | D38: CP-7 | E38: ='CP-7'!B20 -> Not Started
A39: CP-7(4) | B39: Alternate Processing Site | D39: CP-7-4 | E39: ='CP-7-4'!B20 -> Not Started
A40: CP-10 | B40: Information System Recovery and Reconstitution | D40: CP-10 | E40: ='CP-10'!B20 -> Not Started
...

Sheet TABLEAU_DE_BORD
A1: TABLEAU DE BORD — Suivi PBMM : Security
A2: ID Contrôle | B2: Nom du contrôle | C2: Outil principal | D2: Onglet | E2: Statut
A3: AC-2(4) | B3: Gestion des comptes | D3: AC-2-4 | E3: ='AC-2-4'!E20 -> Non commencé
A4: AC-2(5) | B4: Gestion des comptes | D4: AC-2-5 | E4: ='AC-2-5'!E20 -> Non commencé
A5: AC-2(7) | B5: Gestion des comptes | D5: AC-2-7 | E5: ='AC-2-7'!E20 -> Non commencé
A6: AC-4 | B6: Application des contrôles du flux d’information | D6: AC-4 | E6: ='AC-4'!E20 -> Non commencé
A7: AC-4(21) | B7: Application des contrôles du flux d’information | D7: AC-4-21 | E7: ='AC-4-21'!E20 -> Non commencé
A8: AC-6(9) | B8: Moindre privilège | D8: AC-6-9 | E8: ='AC-6-9'!E20 -> Non commencé
A9: AC-6(10) | B9: Moindre privilège | D9: AC-6-10 | E9: ='AC-6-10'!E20 -> Non commencé
A10: AC-17(1) | B10: Accès à distance | D10: AC-17-1 | E10: ='AC-17-1'!E20 -> Non commencé
A11: AC-17(2) | B11: Accès à distance | D11: AC-17-2 | E11: ='AC-17-2'!E20 -> Non commencé
A12: AC-17(3) | B12: Accès à distance | D12: AC-17-3 | E12: ='AC-17-3'!E20 -> Non commencé
A13: AC-17(9) | B13: Accès à distance | D13: AC-17-9 | E13: ='AC-17-9'!E20 -> Non commencé
A14: AU-2 | B14: Événements vérifiables | D14: AU-2 | E14: ='AU-2'!E20 -> Non commencé
A15: AU-3 | B15: Contenu des enregistrements de vérification | D15: AU-3 | E15: ='AU-3'!E20 -> Non commencé
A16: AU-3(1) | B16: Contenu des enregistrements de vérification | D16: AU-3-1 | E16: ='AU-3-1'!E20 -> Non commencé
A17: AU-5 | B17: Réponse aux échecs de traitement de vérification | D17: AU-5 | E17: ='AU-5'!E20 -> Non commencé
A18: AU-6(1) | B18: Examen, analyse et rapport de vérification | D18: AU-6-1 | E18: ='AU-6-1'!E20 -> Non commencé
A19: AU-6(3) | B19: Examen, analyse et rapport de vérification | D19: AU-6-3 | E19: ='AU-6-3'!E20 -> Non commencé
A20: AU-7 | B20: Réduction des vérifications et production de rapports | D20: AU-7 | E20: ='AU-7'!E20 -> Non commencé
A21: AU-7(1) | B21: Réduction des vérifications et production de rapports | D21: AU-7-1 | E21: ='AU-7-1'!E20 -> Non commencé
A22: AU-8 | B22: Estampilles temporelles | D22: AU-8 | E22: ='AU-8'!E20 -> Non commencé
A23: AU-8(1) | B23: Estampilles temporelles | D23: AU-8-1 | E23: ='AU-8-1'!E20 -> Non commencé
A24: AU-9 | B24: Protection des renseignements de vérification | D24: AU-9 | E24: ='AU-9'!E20 -> Non commencé
A25: AU-9(2) | B25: Protection des renseignements de vérification | D25: AU-9-2 | E25: ='AU-9-2'!E20 -> Non commencé
A26: AU-9(4) | B26: Protection des renseignements de vérification | D26: AU-9-4 | E26: ='AU-9-4'!E20 -> Non commencé
A27: AU-11 | B27: Conservation des enregistrements de vérification | D27: AU-11 | E27: ='AU-11'!E20 -> Non commencé
A28: AU-12 | B28: Génération des vérifications | D28: AU-12 | E28: ='AU-12'!E20 -> Non commencé
A29: CA-3(5) | B29: Connexions aux systèmes d’information | D29: CA-3-5 | E29: ='CA-3-5'!E20 -> Non commencé
A30: CA-9 | B30: Connexions internes au système | D30: CA-9 | E30: ='CA-9'!E20 -> Non commencé
A31: CM-5(1) | B31: Restrictions d’accès pour les changements | D31: CM-5-1 | E31: ='CM-5-1'!E20 -> Non commencé
A32: CM-6 | B32: Paramètres de configuration | D32: CM-6 | E32: ='CM-6'!E20 -> Non commencé
A33: CM-7 | B33: Moindre fonctionnalité | D33: CM-7 | E33: ='CM-7'!E20 -> Non commencé
A34: CM-7(1) | B34: Moindre fonctionnalité | D34: CM-7-1 | E34: ='CM-7-1'!E20 -> Non commencé
A35: CM-10 | B35: Restrictions d’utilisation des logiciels | D35: CM-10 | E35: ='CM-10'!E20 -> Non commencé
A36: CP-6 | B36: Site de stockage auxiliaire | D36: CP-6 | E36: ='CP-6'!E20 -> Non commencé
A37: CP-6(2) | B37: Site de stockage auxiliaire | D37: CP-6-2 | E37: ='CP-6-2'!E20 -> Non commencé
A38: CP-7 | B38: Site de traitement auxiliaire | D38: CP-7 | E38: ='CP-7'!E20 -> Non commencé
A39: CP-7(4) | B39: Site de traitement auxiliaire | D39: CP-7-4 | E39: ='CP-7-4'!E20 -> Non commencé
A40: CP-10 | B40: Reprise et reconstitution du système d’information | D40: CP-10 | E40: ='CP-10'!E20 -> Non commencé
...

Sheet AC-2-4
A1: Control AC-2(4) — Evidence Tracking | D1: Contrôle AC-2(4) — Suivi des preuves
A2: Control Information | D2: Informations du contrôle
A3: Control Identifier | B3: AC-2(4) | D3: Identifiant du contrôle | E3: AC-2(4)
A4: Family | B4: Account Management | D4: Famille | E4: Gestion des comptes
A5: Profile | B5: CCCS Medium / PBMM Moderate | D5: Profil | E5: CCCS Moyen / PBMM Modéré
A6: Primary Evidence Tool | D6: Outil de preuve principal
A7: Contributing Tools | D7: Outils contributeurs
A8: Control Description | B8: ACCOUNT MANAGEMENT | AUTOMATED AUDIT ACTIONS The information system automatically audits account creation, modification, enabling, disabling, and removal actions, and notifies responsible managers. Related controls: AU-2, AU-12. | D8: Description du contrôle | E8: GESTION DES COMPTES | MESURES DE VÉRIFICATION AUTOMATISÉES Le système d’information vérifie automatiquement les opérations de création, de modification, d’activation, de désactivation et de retrait des comptes, et avise les gestionnaires responsables. Contrôles connexes : AU-2, AU-12.
A9: Supplemental Guidance | D9: Directives supplémentaires
A10: Test Case | D10: Cas de test
A11: Test | B11: TEST-AC-2(4) | D11: Test | E11: TEST-AC-2(4)
A12: Requirement ID | B12: AC-2(4) | D12: ID Exigence | E12: AC-2(4)
A13: Component | D13: Composant
A14: Requirement | D14: Exigence
A15: Contextual Design Description | D15: Description contextuelle du design
A16: Evidence Provided | D16: Preuve fournie
A17: Preparer Sign Off (Initials, Date) | D17: Signataire préparateur (Initiales, Date)
A18: Owner Sign Off (Initials, Date) | D18: Signataire propriétaire (Initiales, Date)
A19: Assessor Sign Off (Initials, Date) | D19: Signataire évaluateur (Initiales, Date)
A20: Status | B20: Not Started | D20: Statut | E20: Non commencé
A21: Comments | D21: Commentaires

Sheet AC-2-5
A1: Control AC-2(5) — Evidence Tracking | D1: Contrôle AC-2(5) — Suivi des preuves
A2: Control Information | D2: Informations du contrôle
A3: Control Identifier | B3: AC-2(5) | D3: Identifiant du contrôle | E3: AC-2(5)
A4: Family | B4: Account Management | D4: Famille | E4: Gestion des comptes
A5: Profile | B5: CCCS Medium / PBMM Moderate | D5: Profil | E5: CCCS Moyen / PBMM Modéré
A6: Primary Evidence Tool | D6: Outil de preuve principal
A7: Contributing Tools | D7: Outils contributeurs
A8: Control Description | B8: ACCOUNT MANAGEMENT | INACTIVITY LOGOUT The organization requires that users log out at the end of the users’ standard work period unless otherwise defined in formal organizational policy. Related controls: SC-23 | D8: Description du contrôle | E8: GESTION DES COMPTES | FERMETURE DE SESSION INACTIVE L’organisation exige que les utilisateurs ferment leur session à la fin de leur période de travail normale, à moins d’indication contraire dans la politique officielle de l’organisation. Contrôles connexes : SC-23
A9: Supplemental Guidance | D9: Directives supplémentaires
A10: Test Case | D10: Cas de test
A11: Test | B11: TEST-AC-2(5) | D11: Test | E11: TEST-AC-2(5)
A12: Requirement ID | B12: AC-2(5) | D12: ID Exigence | E12: AC-2(5)
A13: Component | D13: Composant
A14: Requirement | D14: Exigence
A15: Contextual Design Description | D15: Description contextuelle du design
A16: Evidence Provided | D16: Preuve fournie
A17: Preparer Sign Off (Initials, Date) | D17: Signataire préparateur (Initiales, Date)
A18: Owner Sign Off (Initials, Date) | D18: Signataire propriétaire (Initiales, Date)
A19: Assessor Sign Off (Initials, Date) | D19: Signataire évaluateur (Initiales, Date)
A20: Status | B20: Not Started | D20: Statut | E20: Non commencé
A21: Comments | D21: Commentaires

Sheet AC-2-7
A1: Control AC-2(7) — Evidence Tracking | D1: Contrôle AC-2(7) — Suivi des preuves
A2: Control Information | D2: Informations du contrôle
A3: Control Identifier | B3: AC-2(7) | D3: Identifiant du contrôle | E3: AC-2(7)
A4: Family | B4: Account Management | D4: Famille | E4: Gestion des comptes
A5: Profile | B5: CCCS Medium / PBMM Moderate | D5: Profil | E5: CCCS Moyen / PBMM Modéré
A6: Primary Evidence Tool | D6: Outil de preuve principal
A7: Contributing Tools | D7: Outils contributeurs
A8: Control Description | B8: ACCOUNT MANAGEMENT | ROLE-BASED SCHEMES (a) The organization establishes and administers privileged user accounts in accordance with a role-based access scheme that organizes allowed information system access and privileges into roles; (b) The organization monitors privileged role assignments; and (c) The organization disables (or revokes) privileged user assignments within 24 hours or sooner when privileged role assignments are no longer appropriate. | D8: Description du contrôle | E8: GESTION DES COMPTES | SCHÉMAS FONDÉS SUR LES RÔLES (a) L’organisation établit et administre les comptes d’utilisateurs privilégiés conformément à un système d’accès basé sur les rôles qui organise les autorisations d’accès au système d’information et les privilèges en fonction des rôles; (b) L’organisation surveille les affectations de rôles privilégiés; (c) L’organisation désactive (ou révoque) les affectations d’utilisateurs privilégiés dans les 24 heures ou plus lorsque les affectations de rôles privilégiés ne sont plus appropriées.
A9: Supplemental Guidance | B9: Privileged roles are organization-defined roles assigned to individuals that allow those individuals to perform certain security-relevant functions that ordinary users are not authorized to perform. These privileged roles include, for example, key management, account management, network and system administration, database administration, and web administration. | D9: Directives supplémentaires | E9: Les rôles privilégiés sont des rôles définis par l’organisation et attribués à des personnes pour leur permettre d’exécuter certaines fonctions ayant une influence sur la sécurité que les utilisateurs ordinaires ne sont pas autorisés à exécuter. Ces rôles privilégiés comprennent, par exemple, la gestion des clés, la gestion des comptes, l’administration des réseaux et des systèmes, l’administration des bases de données et l’administration Web.
A10: Test Case | D10: Cas de test
A11: Test | B11: TEST-AC-2(7) | D11: Test | E11: TEST-AC-2(7)
A12: Requirement ID | B12: AC-2(7) | D12: ID Exigence | E12: AC-2(7)
A13: Component | D13: Composant
A14: Requirement | D14: Exigence
A15: Contextual Design Description | D15: Description contextuelle du design
A16: Evidence Provided | D16: Preuve fournie
A17: Preparer Sign Off (Initials, Date) | D17: Signataire préparateur (Initiales, Date)
A18: Owner Sign Off (Initials, Date) | D18: Signataire propriétaire (Initiales, Date)
A19: Assessor Sign Off (Initials, Date) | D19: Signataire évaluateur (Initiales, Date)
A20: Status | B20: Not Started | D20: Statut | E20: Non commencé
A21: Comments | D21: Commentaires

Sheet AC-4
A1: Control AC-4 — Evidence Tracking | D1: Contrôle AC-4 — Suivi des preuves
A2: Control Information | D2: Informations du contrôle
A3: Control Identifier | B3: AC-4 | D3: Identifiant du contrôle | E3: AC-4
A4: Family | B4: Information Flow Enforcement | D4: Famille | E4: Application des contrôles du flux d’information
A5: Profile | B5: CCCS Medium / PBMM Moderate | D5: Profil | E5: CCCS Moyen / PBMM Modéré
A6: Primary Evidence Tool | D6: Outil de preuve principal
A7: Contributing Tools | D7: Outils contributeurs
A8: Control Description | B8: (A) The information system enforces approved authorizations for controlling the flow of information within the system and between interconnected systems based on deny all, approve by exception information flow policies. | D8: Description du contrôle | E8: (A) Le système d’information applique les autorisations approuvées pour contrôler le flux d’information à l’intérieur du système et entre les systèmes interconnectés en fonction des politiques « Refuser tous, approuver par exception » concernant les flux d’information.
A9: Supplemental Guidance | B9: Information flow control regulates where information is allowed to travel within an information system and between information systems (as opposed to who is allowed to access the information) and without explicit regard to subsequent accesses to that information. Flow control restrictions include, for example, keeping export-controlled information from being transmitted in the clear to the Internet, blocking outside traffic that claims to be from within the organization, restricting web requests to the Internet that are not from the internal web proxy server, and limiting information transfers between organizations based on data structures and content. Transferring information between information systems representing different security domains with different security policies introduces risk that such transfers violate one or more domain security policies. In such situations, information owners/stewards provide guidance at designated policy enforcement points between interconnected systems. Organizations should consider mandating specific architectural solutions when required to enforce specific security policies. Enforcement includes, for example: (i) prohibiting information transfers between interconnected systems (i.e., allowing access only); (ii) employing hardware mechanisms to enforce one-way information flows; and (iii) implementing trustworthy re-grading mechanisms to reassign security attributes and security labels. Organizations commonly employ information flow control policies and enforcement mechanisms to control the flow of information between designated sources and destinations (e.g., networks, individuals, and devices) within information systems and between interconnected systems. Flow control is based on the characteristics of the information and/or the information path. Enforcement occurs, for example, in boundary protection devices (e.g., gateways, routers, guards, encrypted tunnels, firewalls) that employ rule sets or establish configuration settings that restrict information system services, provide a packet-filtering capability based on header information, or message-filtering capability based on message content (e.g., implementing key word searches or using document characteristics). Organizations also consider the trustworthiness of filtering/inspection mechanisms (i.e., hardware, firmware, and software components) that are critical to information flow enforcement. Related controls: AC-3, AC-17, AC-19, AC-21, CM-6, CM-7, SA-8, SC-2, SC-5, SC-7, SC-18. | D9: Directives supplémentaires | E9: Le contrôle du flux d’information détermine les endroits auxquels l’information peut être acheminée au sein d’un système d’information et entre des systèmes d’information (et non les personnes autorisées à accéder à l’information) et sans égard explicite aux accès subséquents à cette information. Les restrictions en matière de contrôle du flux consistent, par exemple, à empêcher la transmission en clair sur l’Internet de l’information dont l’exportation est contrôlée, à bloquer le trafic extérieur qui prétend provenir de l’intérieur de l’organisation, à restreindre les demandes Web à l’Internet qui ne proviennent pas du serveur mandataire Web interne, et à limiter les transferts d’information entre les organisations en fonction des structures et du contenu des données. Les transferts d’information entre systèmes d’information représentant différents domaines de sécurité avec différentes politiques de sécurité présentent le risque que de tels transferts contreviennent à une ou plusieurs politiques de sécurité de domaine. Dans de telles situations, les propriétaires/gardiens de l’information donnent des conseils aux points désignés d’application des politiques entre les systèmes interconnectés. Les organisations devraient envisager d’imposer des solutions architecturales particulières au besoin pour appliquer des politiques de sécurité particulières. L’application des contrôles consiste notamment à : (i) interdire le transfert d’information entre des systèmes interconnectés (c.-à-d. permettre l’accès seulement); (ii) utiliser des mécanismes matériels pour imposer les flux d’information unidirectionnels; et (iii) mettre en œuvre des mécanismes de réévaluation fiables pour réaffecter les attributs de sécurité et les étiquettes de sécurité. Les organisations utilisent couramment des politiques de contrôle du flux d’information et des mécanismes d’application entre des sources et des destinations désignées (p. ex., les réseaux, les personnes et les périphériques) au sein des systèmes d’information et entre les systèmes interconnectés. Le contrôle du flux est fonction des caractéristiques de l’information ou du chemin de l’information. Le contrôle a lieu, par exemple, dans les dispositifs de protection des frontières (p. ex., passerelles, routeurs, gardiens, tunnels chiffrés, pare-feu) qui utilisent des ensembles de règles ou établissent des paramètres de configuration restreignant les services du système d’information, et offrent une capacité de filtrage des paquets en fonction de l’information d’en-tête, ou une capacité de filtrage des messages en fonction de leur contenu (p. ex., la mise en œuvre de recherches par mots clés ou l’utilisation des caractéristiques du document). Les organisations tiennent également compte de la fiabilité des mécanismes de filtrage et d’inspection (c.-à-d. le matériel, les micrologiciels et les composants logiciels) qui sont essentiels au contrôle du flux d’information. Contrôles connexes : AC-3, AC-17, AC-19, AC-21, CM-6, CM-7, SA-8, SC-2, SC-5, SC-7, SC-18.
A10: Test Case | D10: Cas de test
A11: Test | B11: TEST-AC-4 | D11: Test | E11: TEST-AC-4
A12: Requirement ID | B12: AC-4 | D12: ID Exigence | E12: AC-4
A13: Component | D13: Composant
A14: Requirement | D14: Exigence
A15: Contextual Design Description | D15: Description contextuelle du design
A16: Evidence Provided | D16: Preuve fournie
A17: Preparer Sign Off (Initials, Date) | D17: Signataire préparateur (Initiales, Date)
A18: Owner Sign Off (Initials, Date) | D18: Signataire propriétaire (Initiales, Date)
A19: Assessor Sign Off (Initials, Date) | D19: Signataire évaluateur (Initiales, Date)
A20: Status | B20: Not Started | D20: Statut | E20: Non commencé
A21: Comments | D21: Commentaires

Sheet AC-4-21
A1: Control AC-4(21) — Evidence Tracking | D1: Contrôle AC-4(21) — Suivi des preuves
A2: Control Information | D2: Informations du contrôle
A3: Control Identifier | B3: AC-4(21) | D3: Identifiant du contrôle | E3: AC-4(21)
A4: Family | B4: Information Flow Enforcement | D4: Famille | E4: Application des contrôles du flux d’information
A5: Profile | B5: CCCS Medium / PBMM Moderate | D5: Profil | E5: CCCS Moyen / PBMM Modéré
A6: Primary Evidence Tool | D6: Outil de preuve principal
A7: Contributing Tools | D7: Outils contributeurs
A8: Control Description | B8: INFORMATION FLOW ENFORCEMENT | PHYSICAL / LOGICAL SEPARATION OF INFORMATION FLOWS The information system separates information flows logically or physically using session encryption to accomplish separation of all sessions. | D8: Description du contrôle | E8: APPLICATION DES CONTRÔLES DU FLUX D’INFORMATION | SÉPARATION PHYSIQUE/LOGIQUE DES FLUX D’INFORMATION Le système d’information sépare les flux d’information de façon logique ou physique en utilisant le chiffrement des sessions pour effectuer la séparation de toutes les sessions.
A9: Supplemental Guidance | B9: Enforcing the separation of information flows by type can enhance protection by ensuring that information is not commingled while in transit and by enabling flow control by transmission paths perhaps not otherwise achievable. Types of separable information include, for example, inbound and outbound communications traffic, service requests and responses, and information of differing security categories. | D9: Directives supplémentaires | E9: La mise en application de la séparation des flux d’information par type peut améliorer la protection en veillant à ce que l’information ne soit pas mélangée pendant le transport et en permettant un contrôle du flux par les voies de transmission qui ne serait peut-être pas possible autrement. Les types d’information séparable comprennent, par exemple, le trafic des communications entrantes et sortantes, les demandes de service et les réponses, ainsi que l’information de différentes catégories de sécurité.
A10: Test Case | D10: Cas de test
A11: Test | B11: TEST-AC-4(21) | D11: Test | E11: TEST-AC-4(21)
A12: Requirement ID | B12: AC-4(21) | D12: ID Exigence | E12: AC-4(21)
A13: Component | D13: Composant
A14: Requirement | D14: Exigence
A15: Contextual Design Description | D15: Description contextuelle du design
A16: Evidence Provided | D16: Preuve fournie
A17: Preparer Sign Off (Initials, Date) | D17: Signataire préparateur (Initiales, Date)
A18: Owner Sign Off (Initials, Date) | D18: Signataire propriétaire (Initiales, Date)
A19: Assessor Sign Off (Initials, Date) | D19: Signataire évaluateur (Initiales, Date)
A20: Status | B20: Not Started | D20: Statut | E20: Non commencé
A21: Comments | D21: Commentaires

Sheet AC-6-9
A1: Control AC-6(9) — Evidence Tracking | D1: Contrôle AC-6(9) — Suivi des preuves
A2: Control Information | D2: Informations du contrôle
A3: Control Identifier | B3: AC-6(9) | D3: Identifiant du contrôle | E3: AC-6(9)
A4: Family | B4: Least Privilege | D4: Famille | E4: Moindre privilège
A5: Profile | B5: CCCS Medium / PBMM Moderate | D5: Profil | E5: CCCS Moyen / PBMM Modéré
A6: Primary Evidence Tool | D6: Outil de preuve principal
A7: Contributing Tools | D7: Outils contributeurs
A8: Control Description | B8: LEAST PRIVILEGE | AUDITING USE OF PRIVILEGED FUNCTIONS The information system audits the execution of privileged functions. | D8: Description du contrôle | E8: MOINDRE PRIVILÈGE | VÉRIFICATION DE L’UTILISATION DES FONCTIONS PRIVILÉGIÉES Le système d’information vérifie l’exécution des fonctions privilégiées.
A9: Supplemental Guidance | B9: Misuse of privileged functions, either intentionally or unintentionally by authorized users, or by unauthorized external entities that have compromised information system accounts, is a serious and ongoing concern and can have significant adverse impacts on organizations. Auditing the use of privileged functions is one way to detect such misuse, and in doing so, help mitigate the risk from insider threats and the advanced persistent threat (APT). Related control: AU-2. | D9: Directives supplémentaires | E9: L’utilisation abusive des fonctions privilégiées, intentionnellement ou non, par des utilisateurs autorisés ou par des entités externes non autorisées qui ont compromis des comptes de système d’information, est une préoccupation grave et constante qui peut avoir des répercussions négatives importantes sur les organisations. La vérification de l’utilisation des fonctions privilégiées est une façon de détecter un tel abus et, ce faisant, de contribuer à atténuer le risque de menaces internes et de menaces persistantes avancées (MPA). Contrôle connexe : AU-2.
A10: Test Case | D10: Cas de test
A11: Test | B11: TEST-AC-6(9) | D11: Test | E11: TEST-AC-6(9)
A12: Requirement ID | B12: AC-6(9) | D12: ID Exigence | E12: AC-6(9)
A13: Component | D13: Composant
A14: Requirement | D14: Exigence
A15: Contextual Design Description | D15: Description contextuelle du design
A16: Evidence Provided | D16: Preuve fournie
A17: Preparer Sign Off (Initials, Date) | D17: Signataire préparateur (Initiales, Date)
A18: Owner Sign Off (Initials, Date) | D18: Signataire propriétaire (Initiales, Date)
A19: Assessor Sign Off (Initials, Date) | D19: Signataire évaluateur (Initiales, Date)
A20: Status | B20: Not Started | D20: Statut | E20: Non commencé
A21: Comments | D21: Commentaires

Sheet AC-6-10
A1: Control AC-6(10) — Evidence Tracking | D1: Contrôle AC-6(10) — Suivi des preuves
A2: Control Information | D2: Informations du contrôle
A3: Control Identifier | B3: AC-6(10) | D3: Identifiant du contrôle | E3: AC-6(10)
A4: Family | B4: Least Privilege | D4: Famille | E4: Moindre privilège
A5: Profile | B5: CCCS Medium / PBMM Moderate | D5: Profil | E5: CCCS Moyen / PBMM Modéré
A6: Primary Evidence Tool | D6: Outil de preuve principal
A7: Contributing Tools | D7: Outils contributeurs
A8: Control Description | B8: LEAST PRIVILEGE | PROHIBIT NON-PRIVILEGED USERS FROM EXECUTING PRIVILEGED FUNCTIONS The information system prevents non-privileged users from executing privileged functions to include disabling, circumventing, or altering implemented security safeguards/countermeasures. | D8: Description du contrôle | E8: MOINDRE PRIVILÈGE | INTERDICTION AUX UTILISATEURS NON PRIVILÉGIÉS D’EXÉCUTER DES FONCTIONS PRIVILÉGIÉES Le système d’information empêche les utilisateurs non privilégiés d’exécuter des fonctions privilégiées, y compris la désactivation, le contournement ou la modification des mécanismes/contre-mesures de sécurité en place.
A9: Supplemental Guidance | B9: Privileged functions include, for example, establishing information system accounts, performing system integrity checks, or administering cryptographic key management activities. Non-privileged users are individuals that do not possess appropriate authorizations. Circumventing intrusion detection and prevention mechanisms or malicious code protection mechanisms are examples of privileged functions that require protection from non-privileged users. | D9: Directives supplémentaires | E9: Les fonctions privilégiées comprennent, par exemple, l’établissement des comptes du système d’information, l’exécution des vérifications de l’intégrité du système ou l’administration des activités de gestion de clés cryptographiques. Les utilisateurs non privilégiés sont des personnes qui ne possèdent pas les autorisations appropriées. Les contournements de mécanismes de détection et de prévention des intrusions ou de mécanismes de protection contre le code malveillant sont des exemples de fonctions privilégiées qui nécessitent une protection contre les utilisateurs non privilégiés.
A10: Test Case | D10: Cas de test
A11: Test | B11: TEST-AC-6(10) | D11: Test | E11: TEST-AC-6(10)
A12: Requirement ID | B12: AC-6(10) | D12: ID Exigence | E12: AC-6(10)
A13: Component | D13: Composant
A14: Requirement | D14: Exigence
A15: Contextual Design Description | D15: Description contextuelle du design
A16: Evidence Provided | D16: Preuve fournie
A17: Preparer Sign Off (Initials, Date) | D17: Signataire préparateur (Initiales, Date)
A18: Owner Sign Off (Initials, Date) | D18: Signataire propriétaire (Initiales, Date)
A19: Assessor Sign Off (Initials, Date) | D19: Signataire évaluateur (Initiales, Date)
A20: Status | B20: Not Started | D20: Statut | E20: Non commencé
A21: Comments | D21: Commentaires

Sheet AC-17-1
A1: Control AC-17(1) — Evidence Tracking | D1: Contrôle AC-17(1) — Suivi des preuves
A2: Control Information | D2: Informations du contrôle
A3: Control Identifier | B3: AC-17(1) | D3: Identifiant du contrôle | E3: AC-17(1)
A4: Family | B4: Remote Access | D4: Famille | E4: Accès à distance
A5: Profile | B5: CCCS Medium / PBMM Moderate | D5: Profil | E5: CCCS Moyen / PBMM Modéré
A6: Primary Evidence Tool | D6: Outil de preuve principal
A7: Contributing Tools | D7: Outils contributeurs
A8: Control Description | B8: REMOTE ACCESS | AUTOMATED MONITORING / CONTROL The information system monitors and controls remote access methods. | D8: Description du contrôle | E8: ACCÈS À DISTANCE | SURVEILLANCE ET CONTRÔLE AUTOMATISÉS Le système d’information surveille et contrôle les méthodes d’accès à distance.
A9: Supplemental Guidance | B9: Automated monitoring and control of remote access sessions allows organizations to detect cyber-attacks and also ensure ongoing compliance with remote access policies by auditing connection activities of remote users on a variety of information system components (e.g., servers, workstations, notebook computers, smart phones, and tablets). Related controls: AU-2, AU-12. | D9: Directives supplémentaires | E9: La surveillance et le contrôle automatisés des sessions avec accès à distance permettent aux organisations de détecter les cyberattaques et d’assurer la conformité continue aux politiques d’accès à distance en vérifiant les activités de connexion des utilisateurs distants sur une variété de composants du système d’information (p. ex., serveurs, postes de travail, ordinateurs portatifs, téléphones intelligents et tablettes). Contrôles connexes : AU-2, AU-12.
A10: Test Case | D10: Cas de test
A11: Test | B11: TEST-AC-17(1) | D11: Test | E11: TEST-AC-17(1)
A12: Requirement ID | B12: AC-17(1) | D12: ID Exigence | E12: AC-17(1)
A13: Component | D13: Composant
A14: Requirement | D14: Exigence
A15: Contextual Design Description | D15: Description contextuelle du design
A16: Evidence Provided | D16: Preuve fournie
A17: Preparer Sign Off (Initials, Date) | D17: Signataire préparateur (Initiales, Date)
A18: Owner Sign Off (Initials, Date) | D18: Signataire propriétaire (Initiales, Date)
A19: Assessor Sign Off (Initials, Date) | D19: Signataire évaluateur (Initiales, Date)
A20: Status | B20: Not Started | D20: Statut | E20: Non commencé
A21: Comments | D21: Commentaires

Sheet AC-17-2
A1: Control AC-17(2) — Evidence Tracking | D1: Contrôle AC-17(2) — Suivi des preuves
A2: Control Information | D2: Informations du contrôle
A3: Control Identifier | B3: AC-17(2) | D3: Identifiant du contrôle | E3: AC-17(2)
A4: Family | B4: Remote Access | D4: Famille | E4: Accès à distance
A5: Profile | B5: CCCS Medium / PBMM Moderate | D5: Profil | E5: CCCS Moyen / PBMM Modéré
A6: Primary Evidence Tool | D6: Outil de preuve principal
A7: Contributing Tools | D7: Outils contributeurs
A8: Control Description | B8: REMOTE ACCESS | PROTECTION OF CONFIDENTIALITY / INTEGRITY USING ENCRYPTION The information system implements cryptographic mechanisms to protect the confidentiality and integrity of remote access sessions. The cryptography must be compliant with the requirements of SC-13. | D8: Description du contrôle | E8: ACCÈS À DISTANCE | PROTECTION DE LA CONFIDENTIALITÉ ET DE L’INTÉGRITÉ AU MOYEN DU CHIFFREMENT Le système d’information met en œuvre des mécanismes cryptographiques pour protéger la confidentialité et l’intégrité des sessions d’accès à distance. La cryptographie doit être conforme aux exigences de SC-13.
A9: Supplemental Guidance | B9: Guidance on the encryption strength of mechanism can be obtained from CSE upon request. | D9: Directives supplémentaires | E9: Le CST peut, sur demande, conseiller l’organisation quant à la puissance de chiffrement du mécanisme.
A10: Test Case | D10: Cas de test
A11: Test | B11: TEST-AC-17(2) | D11: Test | E11: TEST-AC-17(2)
A12: Requirement ID | B12: AC-17(2) | D12: ID Exigence | E12: AC-17(2)
A13: Component | D13: Composant
A14: Requirement | D14: Exigence
A15: Contextual Design Description | D15: Description contextuelle du design
A16: Evidence Provided | D16: Preuve fournie
A17: Preparer Sign Off (Initials, Date) | D17: Signataire préparateur (Initiales, Date)
A18: Owner Sign Off (Initials, Date) | D18: Signataire propriétaire (Initiales, Date)
A19: Assessor Sign Off (Initials, Date) | D19: Signataire évaluateur (Initiales, Date)
A20: Status | B20: Not Started | D20: Statut | E20: Non commencé
A21: Comments | D21: Commentaires

Sheet AC-17-3
A1: Control AC-17(3) — Evidence Tracking | D1: Contrôle AC-17(3) — Suivi des preuves
A2: Control Information | D2: Informations du contrôle
A3: Control Identifier | B3: AC-17(3) | D3: Identifiant du contrôle | E3: AC-17(3)
A4: Family | B4: Remote Access | D4: Famille | E4: Accès à distance
A5: Profile | B5: CCCS Medium / PBMM Moderate | D5: Profil | E5: CCCS Moyen / PBMM Modéré
A6: Primary Evidence Tool | D6: Outil de preuve principal
A7: Contributing Tools | D7: Outils contributeurs
A8: Control Description | B8: REMOTE ACCESS | MANAGED ACCESS CONTROL POINTS The information system routes all remote accesses through approved managed network access control points. | D8: Description du contrôle | E8: ACCÈS À DISTANCE | POINTS DE CONTRÔLE D’ACCÈS GÉRÉS Le système d’information achemine tous les accès à distance au moyen de points de contrôle d’accès au réseau gérés et approuvés.
A9: Supplemental Guidance | B9: Limiting the number of access control points for remote accesses reduces the attack surface for organizations. Related control: SC-7. | D9: Directives supplémentaires | E9: Une limitation du nombre de points de contrôle d’accès à distance réduit la surface d’attaque pour les organisations. Contrôle connexe : SC-7.
A10: Test Case | D10: Cas de test
A11: Test | B11: TEST-AC-17(3) | D11: Test | E11: TEST-AC-17(3)
A12: Requirement ID | B12: AC-17(3) | D12: ID Exigence | E12: AC-17(3)
A13: Component | D13: Composant
A14: Requirement | D14: Exigence
A15: Contextual Design Description | D15: Description contextuelle du design
A16: Evidence Provided | D16: Preuve fournie
A17: Preparer Sign Off (Initials, Date) | D17: Signataire préparateur (Initiales, Date)
A18: Owner Sign Off (Initials, Date) | D18: Signataire propriétaire (Initiales, Date)
A19: Assessor Sign Off (Initials, Date) | D19: Signataire évaluateur (Initiales, Date)
A20: Status | B20: Not Started | D20: Statut | E20: Non commencé
A21: Comments | D21: Commentaires

Sheet AC-17-9
A1: Control AC-17(9) — Evidence Tracking | D1: Contrôle AC-17(9) — Suivi des preuves
A2: Control Information | D2: Informations du contrôle
A3: Control Identifier | B3: AC-17(9) | D3: Identifiant du contrôle | E3: AC-17(9)
A4: Family | B4: Remote Access | D4: Famille | E4: Accès à distance
A5: Profile | B5: CCCS Medium / PBMM Moderate | D5: Profil | E5: CCCS Moyen / PBMM Modéré
A6: Primary Evidence Tool | D6: Outil de preuve principal
A7: Contributing Tools | D7: Outils contributeurs
A8: Control Description | B8: REMOTE ACCESS | DISCONNECT / DISABLE ACCESS The organization provides the capability to expeditiously disconnect or disable remote access to the information system within a period no greater than 15 minutes. | D8: Description du contrôle | E8: ACCÈS À DISTANCE | DÉCONNECTER/DÉSACTIVER L’ACCÈS L’organisation offre la possibilité de déconnecter ou de désactiver rapidement l’accès à distance au système d’information dans un délai maximal de 15 minutes.
A9: Supplemental Guidance | B9: This control enhancement requires organizations to have the capability to rapidly disconnect current users remotely accessing the information system and/or disable further remote access. The speed of disconnect or disablement varies based on the criticality of missions/business functions and the need to eliminate immediate or future remote access to organizational information systems. | D9: Directives supplémentaires | E9: Cette amélioration du contrôle exige que les organisations soient en mesure de déconnecter rapidement les utilisateurs actuels qui accèdent à distance au système d’information ou de désactiver tout accès à distance ultérieur. La rapidité de la déconnexion ou de la désactivation varie en fonction de la criticité des missions et des fonctions opérationnelles et de la nécessité d’éliminer l’accès à distance immédiat ou futur aux systèmes d’information de l’organisation.
A10: Test Case | D10: Cas de test
A11: Test | B11: TEST-AC-17(9) | D11: Test | E11: TEST-AC-17(9)
A12: Requirement ID | B12: AC-17(9) | D12: ID Exigence | E12: AC-17(9)
A13: Component | D13: Composant
A14: Requirement | D14: Exigence
A15: Contextual Design Description | D15: Description contextuelle du design
A16: Evidence Provided | D16: Preuve fournie
A17: Preparer Sign Off (Initials, Date) | D17: Signataire préparateur (Initiales, Date)
A18: Owner Sign Off (Initials, Date) | D18: Signataire propriétaire (Initiales, Date)
A19: Assessor Sign Off (Initials, Date) | D19: Signataire évaluateur (Initiales, Date)
A20: Status | B20: Not Started | D20: Statut | E20: Non commencé
A21: Comments | D21: Commentaires

Sheet AU-2
A1: Control AU-2 — Evidence Tracking | D1: Contrôle AU-2 — Suivi des preuves
A2: Control Information | D2: Informations du contrôle
A3: Control Identifier | B3: AU-2 | D3: Identifiant du contrôle | E3: AU-2
A4: Family | B4: Auditable Events | D4: Famille | E4: Événements vérifiables
A5: Profile | B5: CCCS Medium / PBMM Moderate | D5: Profil | E5: CCCS Moyen / PBMM Modéré
A6: Primary Evidence Tool | D6: Outil de preuve principal
A7: Contributing Tools | D7: Outils contributeurs
A8: Control Description | B8: (A) The organization determines that the information system is capable of auditing the following events: Successful and unsuccessful account logon events, account management events, object access, policy change, privilege functions, process tracking, and system events. For Web applications: all administrator activity, authentication checks, authorization checks, data deletions, data access, data changes, and permission changes. (B) The organization coordinates the security audit function with other organizational entities requiring audit-related information to enhance mutual support and to help guide the selection of auditable events. (C) The organization provides a rationale for why the auditable events are deemed to be adequate to support after-the-fact investigations of security incidents. (D) The organization determines what organizationally-defined audited events (a subset of the auditable events defined in AU-2 a.) and the frequency of (or situation requiring) auditing for each identified event. | D8: Description du contrôle | E8: (A) L’organisation détermine que le système d’information est capable de vérifier les événements suivants : événements d’ouverture de compte, réussis ou non, événements de gestion de compte, accès aux objets, changement de politique, fonctions de privilèges, suivi des processus et événements du système. Pour les applications Web : toutes les activités des administrateurs, les vérifications d’authentification, les vérifications d’autorisation, les suppressions de données, l’accès aux données, les changements de données et les changements d’autorisation. (B) L’organisation coordonne la fonction de vérification de la sécurité avec d’autres entités organisationnelles qui ont besoin de renseignements liés à la vérification pour améliorer le soutien mutuel et aider à orienter le choix des événements vérifiables. (C) L’organisation explique la raison pour laquelle les événements vérifiables sont jugés adéquats pour appuyer les enquêtes effectuées à la suite des incidents de sécurité. (D) L’organisation détermine les événements définis par l’organisation qui sont vérifiés (un sous-ensemble des événements vérifiables définis dans AU-2 a.) et la fréquence (ou la situation exigeant) des vérifications pour chaque événement identifié.
A9: Supplemental Guidance | B9: An event is any observable occurrence in an organizational information system. Organizations identify audit events as those events which are significant and relevant to the security of information systems and the environments in which those systems operate in order to meet specific and ongoing audit needs. Audit events can include, for example, password changes, failed logons, or failed accesses related to information systems, administrative privilege usage, or third-party credential usage. In determining the set of auditable events, organizations consider the auditing appropriate for each of the security controls to be implemented. To balance auditing requirements with other information system needs, this control also requires identifying that subset of auditable events that are audited at a given point in time. For example, organizations may determine that information systems must have the capability to log every file access both successful and unsuccessful, but not activate that capability except for specific circumstances due to the potential burden on system performance. Auditing requirements, including the need for auditable events, may be referenced in other security controls and control enhancements. Organizations also include auditable events that are required by applicable organizational policies, directives, and standards. Audit records can be generated at various levels of abstraction, including at the packet level as information traverses the network. Selecting the appropriate level of abstraction is a critical aspect of an audit capability and can facilitate the identification of root causes to problems. Organizations consider in the definition of auditable events, the auditing necessary to cover related events such as the steps in distributed, transaction-based processes (e.g., processes that are distributed across multiple organizations) and actions that occur in service-oriented architectures. The information system audits the following privileged user/process events at a minimum: (a) Successful and unsuccessful attempts to access, modify, or delete security objects (Security objects include audit data, system configuration files and file or users’ formal access permissions.) (b) Successful and unsuccessful logon attempts (c) Privileged activities or other system level access (see notes for AU-2 (4)) (d) Starting and ending time for user access to the system (e) Concurrent logons from different workstations (f) All program initiations (see notes for AU-2 (4)) In addition, the information system audits the following unprivileged user/process events at a minimum: (a) Successful and unsuccessful attempts to access, modify, or delete security objects (b) Successful and unsuccessful logon attempts (c) Starting and ending time for user access to the system (d) Concurrent logons from different workstations Related controls: AC-6, AC-17, AU-3, AU-12, MA-4, MP-2, MP-4, SI-4 | D9: Directives supplémentaires | E9: Un événement est toute occurrence observable dans un système d’information organisationnel. Les organisations désignent les événements vérifiables comme étant des événements importants et pertinents pour la sécurité des systèmes d’information et des environnements dans lesquels ces systèmes sont utilisés afin de répondre à des exigences de vérification particulières et continues. Les événements vérifiés peuvent comprendre, par exemple, les changements de mot de passe, les échecs d’ouverture de session ou les échecs accès liés aux systèmes d’information, l’utilisation des privilèges administratifs ou l’utilisation de justificatifs d’identité par des tiers. Lorsqu’elles déterminent l’ensemble des événements vérifiables, les organisations considèrent que la vérification est appropriée pour chacun des contrôles de sécurité à mettre en œuvre. Pour assurer l’équilibre entre les exigences en matière de vérification et les autres besoins du système d’information, ce contrôle exige également de déterminer le sous-ensemble d’événements vérifiables qui sont vérifiés à un moment donné. Par exemple, les organisations peuvent déterminer que les systèmes d’information doivent avoir la capacité d’enregistrer chaque accès aux fichiers, qu’il soit réussi ou non, mais n’activeront cette capacité que dans des circonstances particulières en raison du fardeau potentiel sur le rendement du système. Les exigences en matière de vérification, y compris la nécessité de déterminer des événements vérifiables, peuvent être mentionnées dans d’autres contrôles et améliorations des contrôles de sécurité. Les organisations incluent également les événements vérifiables qui sont exigés par les politiques, les directives et les normes organisationnelles applicables. Les enregistrements de vérification peuvent être générés à divers niveaux d’abstraction, y compris au niveau des paquets, à mesure que l’information traverse le réseau. Le choix du niveau d’abstraction approprié est un aspect essentiel d’une capacité de vérification et peut faciliter l’identification des causes profondes des problèmes. Dans la définition des événements vérifiables, les organisations prennent en compte la vérification nécessaire pour couvrir les événements connexes, comme les étapes des processus distribués, fondés sur les transactions (p. ex., les processus qui sont répartis entre de multiples organisations) et les actions qui ont lieu dans les architectures orientées service. Le système d’information vérifie au minimum les événements suivants liés aux utilisateurs/processus privilégiés : (a) Tentatives réussies et infructueuses d’accéder aux objets de sécurité, de les modifier ou de les supprimer (les objets de sécurité comprennent les données de vérification, les fichiers de configuration de système et les autorisations d’accès officielles des utilisateurs). (b) Tentatives d’ouverture de session réussies et infructueuses (c) Activités privilégiées ou autre accès au niveau du système (voir les notes pour AU-2 [4]) (d) Heures de début et de fin de l’accès des utilisateurs au système (e) Ouvertures de session simultanées à partir de différents postes de travail (f) Tous les lancements de programmes (voir les notes pour AU-2 [4]) De plus, le système d’information vérifie au minimum les événements suivants liés aux utilisateurs/processus non privilégiés : (a) Tentatives réussies et infructueuses d’accès, de modification ou de suppression d’objets de sécurité (b) Tentatives d’ouverture de session réussies et infructueuses (c) Heures de début et de fin de l’accès de l’utilisateur au système (d) Ouvertures de session simultanées à partir de différents postes de travail Contrôles connexes : AC-6, AC-17, AU-3, AU-12, MA-4, MP-2, MP-4, SI-4
A10: Test Case | D10: Cas de test
A11: Test | B11: TEST-AU-2 | D11: Test | E11: TEST-AU-2
A12: Requirement ID | B12: AU-2 | D12: ID Exigence | E12: AU-2
A13: Component | D13: Composant
A14: Requirement | D14: Exigence
A15: Contextual Design Description | D15: Description contextuelle du design
A16: Evidence Provided | D16: Preuve fournie
A17: Preparer Sign Off (Initials, Date) | D17: Signataire préparateur (Initiales, Date)
A18: Owner Sign Off (Initials, Date) | D18: Signataire propriétaire (Initiales, Date)
A19: Assessor Sign Off (Initials, Date) | D19: Signataire évaluateur (Initiales, Date)
A20: Status | B20: Not Started | D20: Statut | E20: Non commencé
A21: Comments | D21: Commentaires

Sheet AU-3
A1: Control AU-3 — Evidence Tracking | D1: Contrôle AU-3 — Suivi des preuves
A2: Control Information | D2: Informations du contrôle
A3: Control Identifier | B3: AU-3 | D3: Identifiant du contrôle | E3: AU-3
A4: Family | B4: Content of Audit Records | D4: Famille | E4: Contenu des enregistrements de vérification
A5: Profile | B5: CCCS Medium / PBMM Moderate | D5: Profil | E5: CCCS Moyen / PBMM Modéré
A6: Primary Evidence Tool | D6: Outil de preuve principal
A7: Contributing Tools | D7: Outils contributeurs
A8: Control Description | B8: (A) The information system generates audit records containing information that establishes what type of event occurred, when the event occurred, where the event occurred, the source of the event, the outcome of the event, and the identity of any individuals or subjects associated with the event. | D8: Description du contrôle | E8: (A) Le système d’information génère des enregistrements de vérification qui contiennent les renseignements permettant d’établir le type d’événement qui a eu lieu, le moment et l’endroit où l’événement a eu lieu, la source de l’événement, le résultat de l’événement, ainsi que l’identité de toute personne ou de tout sujet associé à l’événement.
A9: Supplemental Guidance | B9: Audit record content that may be necessary to satisfy the requirement of this control, includes, for example, time stamps, source and destination addresses, user/process identifiers, event descriptions, success/fail indications, filenames involved, and access control or flow control rules invoked. Event outcomes can include indicators of event success or failure and event-specific results (e.g., the security state of the information system after the event occurred). Related controls: AU-2, AU-8, AU-12, SI-11 | D9: Directives supplémentaires | E9: Le contenu des enregistrements de vérification qui peut être nécessaire pour satisfaire à l’exigence de ce contrôle comprend, par exemple, les estampilles temporelles, les adresses de source et de destination, les identifiants d’utilisateurs ou de processus, les descriptions d’événements, les indications de réussite ou d’échec, les noms des fichiers en cause et les règles de contrôle d’accès ou de flux invoquées. Les résultats de l’événement peuvent comprendre des indicateurs de réussite ou d’échec de l’événement et des résultats propres à l’événement (p. ex., l’état de sécurité du système d’information après l’événement). Contrôles connexes : AU-2, AU-8, AU-12, SI-11
A10: Test Case | D10: Cas de test
A11: Test | B11: TEST-AU-3 | D11: Test | E11: TEST-AU-3
A12: Requirement ID | B12: AU-3 | D12: ID Exigence | E12: AU-3
A13: Component | D13: Composant
A14: Requirement | D14: Exigence
A15: Contextual Design Description | D15: Description contextuelle du design
A16: Evidence Provided | D16: Preuve fournie
A17: Preparer Sign Off (Initials, Date) | D17: Signataire préparateur (Initiales, Date)
A18: Owner Sign Off (Initials, Date) | D18: Signataire propriétaire (Initiales, Date)
A19: Assessor Sign Off (Initials, Date) | D19: Signataire évaluateur (Initiales, Date)
A20: Status | B20: Not Started | D20: Statut | E20: Non commencé
A21: Comments | D21: Commentaires

Sheet AU-3-1
A1: Control AU-3(1) — Evidence Tracking | D1: Contrôle AU-3(1) — Suivi des preuves
A2: Control Information | D2: Informations du contrôle
A3: Control Identifier | B3: AU-3(1) | D3: Identifiant du contrôle | E3: AU-3(1)
A4: Family | B4: Content of Audit Records | D4: Famille | E4: Contenu des enregistrements de vérification
A5: Profile | B5: CCCS Medium / PBMM Moderate | D5: Profil | E5: CCCS Moyen / PBMM Modéré
A6: Primary Evidence Tool | D6: Outil de preuve principal
A7: Contributing Tools | D7: Outils contributeurs
A8: Control Description | B8: CONTENT OF AUDIT RECORDS | ADDITIONAL AUDIT INFORMATION The information system generates audit records containing the following additional information: session, connection, transaction, or activity duration; for client-server transactions, the number of bytes received and bytes sent; additional informational messages to diagnose or identify the event; characteristics that describe or identify the object or resource being acted upon. | D8: Description du contrôle | E8: CONTENU DES ENREGISTREMENTS DE VÉRIFICATION | RENSEIGNEMENTS DE VÉRIFICATION SUPPLÉMENTAIRES Le système d’information génère des enregistrements de vérification contenant les renseignements supplémentaires suivants : la durée de la session, de la connexion, de la transaction ou de l’activité; pour les transactions client-serveur, le nombre d’octets reçus et d’octets envoyés; des messages d’information supplémentaires pour diagnostiquer ou identifier l’événement; les caractéristiques qui décrivent ou identifient l’objet ou la ressource concernés.
A9: Supplemental Guidance | B9: Detailed information that organizations may consider in audit records includes, for example, full text recording of privileged commands or the individual identities of group account users. Organizations consider limiting the additional audit information to only that information explicitly needed for specific audit requirements. This facilitates the use of audit trails and audit logs by not including information that could potentially be misleading or could make it more difficult to locate information of interest. Additional guidance for enhancement (1): Audit events should always be capable of being associated with an individual identity. Associating audit events with a group or role is insufficient. | D9: Directives supplémentaires | E9: Les renseignements détaillés dont les organisations peuvent tenir compte dans les enregistrements de vérification comprennent, par exemple, l’enregistrement en texte intégral des commandes privilégiées ou les identités individuelles des utilisateurs de comptes de groupe. Les organisations devraient envisager de limiter les renseignements de vérification supplémentaires aux seuls renseignements explicitement nécessaires pour répondre à des exigences de vérification particulières. Cela facilitera l’utilisation des pistes de vérification et des journaux de vérification en n’incluant pas les renseignements qui pourraient être trompeurs ou rendre plus difficile la recherche de renseignements utiles. Conseils supplémentaires pour l’amélioration (1) : Les événements vérifiés devraient toujours pouvoir être associés à une identité individuelle. Associer des événements vérifiés à un groupe ou à un rôle est insuffisant.
A10: Test Case | D10: Cas de test
A11: Test | B11: TEST-AU-3(1) | D11: Test | E11: TEST-AU-3(1)
A12: Requirement ID | B12: AU-3(1) | D12: ID Exigence | E12: AU-3(1)
A13: Component | D13: Composant
A14: Requirement | D14: Exigence
A15: Contextual Design Description | D15: Description contextuelle du design
A16: Evidence Provided | D16: Preuve fournie
A17: Preparer Sign Off (Initials, Date) | D17: Signataire préparateur (Initiales, Date)
A18: Owner Sign Off (Initials, Date) | D18: Signataire propriétaire (Initiales, Date)
A19: Assessor Sign Off (Initials, Date) | D19: Signataire évaluateur (Initiales, Date)
A20: Status | B20: Not Started | D20: Statut | E20: Non commencé
A21: Comments | D21: Commentaires

Sheet AU-5
A1: Control AU-5 — Evidence Tracking | D1: Contrôle AU-5 — Suivi des preuves
A2: Control Information | D2: Informations du contrôle
A3: Control Identifier | B3: AU-5 | D3: Identifiant du contrôle | E3: AU-5
A4: Family | B4: Response To Audit Processing Failures | D4: Famille | E4: Réponse aux échecs de traitement de vérification
A5: Profile | B5: CCCS Medium / PBMM Moderate | D5: Profil | E5: CCCS Moyen / PBMM Modéré
A6: Primary Evidence Tool | D6: Outil de preuve principal
A7: Contributing Tools | D7: Outils contributeurs
A8: Control Description | B8: (A) The information system alerts organization-defined personnel or roles in the event of an audit processing failure; and (B) The information system overwrites the oldest audit records. | D8: Description du contrôle | E8: (A) Le système d’information alerte le personnel ou les rôles définis par l’organisation en cas d’échec de traitement de vérification; (B) Le système d’information écrase les enregistrements de vérification les plus anciens.
A9: Supplemental Guidance | B9: Audit processing failures include, for example, software/hardware errors, failures in the audit capturing mechanisms, and audit storage capacity being reached or exceeded. Organizations may choose to define additional actions for different audit processing failures (e.g., by type, by location, by severity, or a combination of such factors). This control applies to each audit data storage repository (i.e., distinct information system component where audit records are stored), the total audit storage capacity of organizations (i.e., all audit data storage repositories combined), or both. Related controls: AU-4, SI-12 | D9: Directives supplémentaires | E9: Les échecs de traitement de vérification comprennent, par exemple, les erreurs de logiciel ou de matériel, les défaillances des mécanismes de saisie des vérifications et la capacité de stockage atteinte ou dépassée pour les vérifications. Les organisations peuvent choisir de définir des mesures supplémentaires pour différents échecs de traitement de vérification (p. ex., par type, par emplacement, par gravité ou une combinaison de ces facteurs). Ce contrôle s’applique à chaque répertoire de stockage des données de vérification (c.-à -d. à chaque composant distinct du système d’information dans lequel les enregistrements de vérification sont conservés), à la capacité totale de stockage des vérifications des organisations (c.-à-d. tous les répertoires de stockage des données de vérification combinés), ou aux deux. Contrôles connexes : AU-4, SI-12
A10: Test Case | D10: Cas de test
A11: Test | B11: TEST-AU-5 | D11: Test | E11: TEST-AU-5
A12: Requirement ID | B12: AU-5 | D12: ID Exigence | E12: AU-5
A13: Component | D13: Composant
A14: Requirement | D14: Exigence
A15: Contextual Design Description | D15: Description contextuelle du design
A16: Evidence Provided | D16: Preuve fournie
